Workbook

Sheet 0. User Guide
B2: USER GUIDE
B3: Greek Residential Valuation - Comparative Method Model
B5: MODEL OVERVIEW
B6: This Excel model implements the Greek residential valuation methodology using the Comparative Method (Μέθοδος Συγκριτικών Στοιχείων). Key Features: • Greek weighted area calculation (Ανηγμένη Επιφάνεια) • 10 adjustment categories per Greek standards • Automated calculations with manual input control • Compliant with ΣΕΚΕ 2018, EVS 2016, and IVS • Replicates NOVAL, Danos, and other Greek valuers methodology
B12: WORKFLOW (6 STEPS)
B13: 1. Enter Subject Property Details (Sheet 1) → Complete all property characteristics → System calculates weighted area automatically 2. Enter Comparable Properties (Sheet 2) → Add 5-10 comparable sales data → Include asking prices, areas, characteristics → System calculates weighted areas and €/sqm 3. Review Adjustment Factors (Sheet 3) → Reference table with Greek standard adjustments → Use as guide for Sheet 4 inputs 4. Apply Adjustments (Sheet 4) → Select best 5 comparables → Enter adjustment % for each category → Assign weights (must total 100%) → System calculates adjusted values 5. Review Summary (Sheet 5) → Final valuation result → Executive summary format 6. Validate Results → Check against market expectations → Verify all weights total 100% → Review adjustment logic
B28: GREEK-SPECIFIC ELEMENTS
B29: Weighted Area Calculation: • Main floor: 1.00x • Attic/Loft (σοφίτα): 0.35x • Basement/Storage (υπόγειο): 0.20x • Semi-basement: 0.50x • Large balconies: 0.50x Critical Adjustments: • Transaction type: -15% to -20% for asking prices • Age: ±1.5% per year (Greek composite method) • Floor: ±2-3% per floor • Location: ±15-20% for neighborhood quality
B37: COLOR CODING
B38: Blue cells = Input required (manual entry) Green cells = Formula/Calculated (do not edit) Orange cells = Final results Grey cells = Reference/Information Dark blue headers = Section titles
B42: IMPORTANT NOTES
B43: • All adjustments are applied to comparables, not subject • Positive % = Subject is better than comparable • Negative % = Subject is worse than comparable • Use actual transaction data when possible • Asking prices require -15% to -20% adjustment • Validate against 2-3 actual Greek reports
... B49: Model based on analysis of: • ΣΕΚΕ 2018 Textbook (Greek Valuers Association) • NOVAL Property REIC reports (2023-2024) • Danos Valuation reports • REA Partners valuations • Multiple residential comparables (Kolonaki, Glyfada, etc.)

Sheet 5. Summary & Report
B2: GREEK RESIDENTIAL VALUATION
B3: Comparative Method - Valuation Summary
B4: Report Date: 30 December 2025
B6: EXECUTIVE SUMMARY
B7: Property Address: | E7: ='1. Subject Property'!E7
B8: Location: | E8: ='1. Subject Property'!E8
B9: Building Year: | E9: ='1. Subject Property'!E9
B10: Floor Level: | E10: ='1. Subject Property'!E19
B11: Total Weighted Area: | E11: ='1. Subject Property'!E35
B13: ESTIMATED MARKET VALUE
B14: Value per sqm (Comparative Method): | F14: ='4. Comparative Analysis'!S15
B15: Total Property Value: | F15: ='4. Comparative Analysis'!R17
B17: METHODOLOGY
B18: This valuation applies the Comparative Method (Μέθοδος Συγκριτικών Στοιχείων) following Greek valuation standards (ΣΕΚΕ 2018) and professional practice (EVS 2016/IVS compliant). The methodology includes: • Weighted area calculation using Greek coefficients (basement: 0.2, attic: 0.35) • Systematic adjustments across 10 key categories • Transaction type adjustment for asking vs actual prices • Age adjustment using Greek composite method • Weighted average from multiple comparables This model replicates the methodology used by Greek valuation firms (NOVAL, Danos, etc.) for REIT reporting and professional appraisals.
B25: COMPARABLES SUMMARY
B26: # | C26: Location | D26: Asking €/sqm | E26: Adjusted €/sqm | F26: Weight
B27: 1 | C27: ='4. Comparative Analysis'!D10 | D27: ='4. Comparative Analysis'!H10 | E27: ='4. Comparative Analysis'!S10 | F27: ='4. Comparative Analysis'!T10
B28: 2 | C28: ='4. Comparative Analysis'!D11 | D28: ='4. Comparative Analysis'!H11 | E28: ='4. Comparative Analysis'!S11 | F28: ='4. Comparative Analysis'!T11
B29: 3 | C29: ='4. Comparative Analysis'!D12 | D29: ='4. Comparative Analysis'!H12 | E29: ='4. Comparative Analysis'!S12 | F29: ='4. Comparative Analysis'!T12
B30: 4 | C30: ='4. Comparative Analysis'!D13 | D30: ='4. Comparative Analysis'!H13 | E30: ='4. Comparative Analysis'!S13 | F30: ='4. Comparative Analysis'!T13
B31: 5 | C31: ='4. Comparative Analysis'!D14 | D31: ='4. Comparative Analysis'!H14 | E31: ='4. Comparative Analysis'!S14 | F31: ='4. Comparative Analysis'!T14

Sheet 1. Subject Property
B2: GREEK RESIDENTIAL VALUATION - COMPARATIVE METHOD
B3: Valuation Date: 30/12/2025
B5: SUBJECT PROPERTY DETAILS
B6: Property Characteristic | E6: Value | G6: Unit
B7: Address | G7: text
B8: Area | E8: Kolonaki, Athens | G8: text
B9: Building Year | E9: 1970 | G9: year
B11: AREAS (sqm)
B12: Main Floor Area | E12: 100 | G12: sqm
B13: Attic/Loft Area | E13: 0 | G13: sqm
B14: Basement/Storage Area | E14: 5 | G14: sqm
B15: Semi-basement Area | E15: 0 | G15: sqm
B16: Balconies >10sqm | E16: 0 | G16: sqm
B18: CHARACTERISTICS
B19: Floor Level | E19: 3 | G19: floor
B20: Total Floors in Building | E20: 5 | G20: floors
B21: Condition | E21: Good | G21: dropdown
B22: Layout Type | E22: Through (Διαμπερές) | G22: dropdown
B23: Views | E23: Open horizon | G23: dropdown
B25: AMENITIES (Yes/No)
B26: Parking Space | E26: Yes | G26: Y/N
B27: Storage Room | E27: Yes | G27: Y/N
B28: Elevator | E28: Yes | G28: Y/N
B29: Autonomous Heating | E29: No | G29: Y/N
B30: Air Conditioning | E30: Yes | G30: Y/N
B32: WEIGHTED AREA CALCULATION
B33: Component | C33: Area (sqm) | D33: Weight Factor | E33: Weighted Area
B34: Main Floor Area | C34: =E8 | D34: 1 | E34: =C34*D34
B35: Attic/Loft (σοφίτα) | C35: =E9 | D35: 0.35 | E35: =C35*D35
B36: Basement/Storage (υπόγειο) | C36: =E10 | D36: 0.2 | E36: =C36*D36
B37: Semi-basement | C37: =E11 | D37: 0.5 | E37: =C37*D37
B38: Balconies >10sqm | C38: =E12 | D38: 0.5 | E38: =C38*D38
B39: TOTAL WEIGHTED AREA (Ανηγμένη Επιφάνεια) | E39: =SUM(E34:E38)

Sheet 2. Comparables
B2: COMPARABLE PROPERTIES DATABASE
B4: Instructions: Enter comparable property data. System will calculate weighted areas automatically.
B6: ID | C6: Address / Source | D6: Area | E6: Asking Price (€) | F6: Transaction Type | G6: Date | H6: Floor | I6: Building Year | J6: Main Area | K6: Attic | L6: Basement | M6: Semi-base | N6: Balconies | O6: Weighted Area | P6: €/sqm
B7: COMP-1 | C7: Sample Address 1 | D7: Kolonaki | E7: 200000 | F7: Asking | G7: 46021 | H7: 3 | I7: 1975 | J7: 95 | K7: 0 | L7: 5 | M7: 0 | N7: 0 | O7: =J7+K7*0.35+L7*0.2+M7*0.5+N7*0.5 | P7: =IF(O7>0,E7/O7,"")
B8: COMP-2 | C8: Sample Address 2 | D8: Kolonaki | O8: =J8+K8*0.35+L8*0.2+M8*0.5+N8*0.5 | P8: =IF(O8>0,E8/O8,"")
B9: COMP-3 | C9: Sample Address 3 | D9: Kolonaki | O9: =J9+K9*0.35+L9*0.2+M9*0.5+N9*0.5 | P9: =IF(O9>0,E9/O9,"")
B10: COMP-4 | C10: Sample Address 4 | D10: Kolonaki | O10: =J10+K10*0.35+L10*0.2+M10*0.5+N10*0.5 | P10: =IF(O10>0,E10/O10,"")
B11: COMP-5 | C11: Sample Address 5 | D11: Kolonaki | O11: =J11+K11*0.35+L11*0.2+M11*0.5+N11*0.5 | P11: =IF(O11>0,E11/O11,"")
B12: COMP-6 | C12: Sample Address 6 | D12: Kolonaki | O12: =J12+K12*0.35+L12*0.2+M12*0.5+N12*0.5 | P12: =IF(O12>0,E12/O12,"")
B13: COMP-7 | C13: Sample Address 7 | D13: Kolonaki | O13: =J13+K13*0.35+L13*0.2+M13*0.5+N13*0.5 | P13: =IF(O13>0,E13/O13,"")
B14: COMP-8 | C14: Sample Address 8 | D14: Kolonaki | O14: =J14+K14*0.35+L14*0.2+M14*0.5+N14*0.5 | P14: =IF(O14>0,E14/O14,"")
B15: COMP-9 | C15: Sample Address 9 | D15: Kolonaki | O15: =J15+K15*0.35+L15*0.2+M15*0.5+N15*0.5 | P15: =IF(O15>0,E15/O15,"")
B16: COMP-10 | C16: Sample Address 10 | D16: Kolonaki | O16: =J16+K16*0.35+L16*0.2+M16*0.5+N16*0.5 | P16: =IF(O16>0,E16/O16,"")

Sheet 3. Adjustment Factors
B2: ADJUSTMENT FACTORS TABLE (Συντελεστές Αναγωγής)
B3: Reference: ΣΕΚΕ 2018 + Greek Valuation Practice (NOVAL, Danos, etc.)
B5: 1. TRANSACTION TYPE (Δικαιοπραξία / Ζητούμενη)
B6: Characteristic | E6: Min Adj.
B7: Actual Transaction (Πράξη) | E7: 0%
B8: Asking Price - Fresh (<3mo) | E8: -10%
B9: Asking Price - Standard | E9: -15%
B10: Asking Price - Stale (>6mo) | E10: -20%
B12: 2. LOCATION/MARKETABILITY (Θέση / Εμπορικότητα)
B13: Characteristic | E13: Min Adj.
B14: Prime location - much better | E14: +15%
B15: Better location | E15: +5%
B16: Similar location | E16: 0%
B17: Worse location | E17: -5%
B18: Much worse location | E18: -15%
B20: 3. ACCESS (Πρόσβαση)
B21: Characteristic | E21: Min Adj.
B22: Much better access (metro <200m) | E22: +5%
B23: Better access | E23: +3%
B24: Similar access | E24: 0%
B25: Worse access | E25: -3%
B26: Much worse access | E26: -5%
B28: 4. VIEWS (Προβολή / Θέα)
B29: Characteristic | E29: Min Adj.
B30: Acropolis view | E30: +15%
B31: Sea view | E31: +10%
B32: Open horizon / Mountain view | E32: +5%
B33: Normal view | E33: 0%
B34: Limited/No view | E34: -5%
B36: 5. AGE & CONDITION (Ηλικία / Κατάσταση)
B37: Characteristic | E37: Min Adj.
B38: Fully renovated (within 2 years) | E38: +10%
B39: Partially renovated | E39: +5%
B40: Good condition | E40: +3%
B41: Average condition | E41: 0%
B42: Needs minor renovation | E42: -5%
B43: Needs major renovation | E43: -10%
B45: Age difference per year | E45: ±1.0%
B47: 6. FLOOR LEVEL (Όροφος)
B48: Characteristic | E48: Min Adj.
...

Sheet 4. Comparative Analysis
B2: COMPARATIVE ANALYSIS - ADJUSTMENT SCHEDULE
B3: Αναγωγές Συγκριτικών Στοιχείων - Greek Residential Comparative Method
B5: Instructions: (1) Select comparables from sheet 2, (2) Enter adjustments for each category, (3) System calculates adjusted value
B7: SUBJECT PROPERTY: | C7: ='1. Subject Property'!C7 | G7: Weighted Area: | H7: ='1. Subject Property'!E35
B9: Comparable | D9: Location | F9: Asking Price (€) | G9: Weight. Area | H9: €/sqm Asked | I9: Trans. Type | J9: Location | K9: Access | L9: Views | M9: Age/ Cond. | N9: Floor | O9: Area Size | P9: Light/ Vent | Q9: Amen. | R9: Time | S9: Adj. €/sqm | T9: Weight
B10: ='2. Comparables'!B7 | D10: ='2. Comparables'!C7 | F10: ='2. Comparables'!E7 | G10: ='2. Comparables'!O7 | H10: ='2. Comparables'!P7 | I10: 0 | J10: 0 | K10: 0 | L10: 0 | M10: 0 | N10: 0 | O10: 0 | P10: 0 | Q10: 0 | R10: 0 | S10: =H10*(1+SUM(I10:R10)) | T10: 0.2
B11: ='2. Comparables'!B8 | D11: ='2. Comparables'!C8 | F11: ='2. Comparables'!E8 | G11: ='2. Comparables'!O8 | H11: ='2. Comparables'!P8 | S11: =H11*(1+SUM(I11:R11)) | T11: 0.2
B12: ='2. Comparables'!B9 | D12: ='2. Comparables'!C9 | F12: ='2. Comparables'!E9 | G12: ='2. Comparables'!O9 | H12: ='2. Comparables'!P9 | S12: =H12*(1+SUM(I12:R12)) | T12: 0.2
B13: ='2. Comparables'!B10 | D13: ='2. Comparables'!C10 | F13: ='2. Comparables'!E10 | G13: ='2. Comparables'!O10 | H13: ='2. Comparables'!P10 | S13: =H13*(1+SUM(I13:R13)) | T13: 0.2
B14: ='2. Comparables'!B11 | D14: ='2. Comparables'!C11 | F14: ='2. Comparables'!E11 | G14: ='2. Comparables'!O11 | H14: ='2. Comparables'!P11 | S14: =H14*(1+SUM(I14:R14)) | T14: 0.2
B16: WEIGHTED AVERAGE VALUE | S16: =SUMPRODUCT(S11:S15,T11:T15) | T16: =SUM(T11:T15)
B18: ESTIMATED MARKET VALUE (per Comparative Method): | R18: =S16*'1. Subject Property'!E35
