Workbook

Sheet 0_USER_GUIDE
A1: GREEK REAL ESTATE VALUATION MODEL - USER GUIDE
A3: Based on ΣΕΚΕ 2018 / RICS Red Book 2022 / EVS 2016 / IVS 2020
A5: ═══════════════════════════════════════════════════════════════════════════════════ OVERVIEW ═══════════════════════════════════════════════════════════════════════════════════ This model implements professional Greek real estate valuation methodology following ΣΕΚΕ 2018 (Greek Valuers Association), RICS Red Book 2022, and international standards (EVS 2016/IVS 2020). KEY FEATURES: ✓ FORMULA-BASED SYSTEM: Everything calculates automatically from your inputs - NO manual percentages needed ✓ GREEK WEIGHTED AREA: Automatic Ανηγμένη Επιφάνεια calculations per Greek practice ✓ ΣΕΚΕ 2018 ADJUSTMENTS: Input factual comparable data → model calculates proper adjustments ✓ MULTI-METHOD VALUATION: Comparative, Income (DCF), with weighted reconciliation ✓ PROFESSIONAL OUTPUT: RICS-compliant report structure ready for institutional use ═══════════════════════════════════════════════════════════════════════════════════ WORKFLOW (Estimated 60-90 minutes) ═══════════════════════════════════════════════════════════════════════════════════ STEP 1: EXECUTIVE SUMMARY (Sheet 1) - 5 minutes • Enter basic property identification • Purpose and dates • Client information STEP 2: TERMS OF ENGAGEMENT (Sheet 2) - 5 minutes • Valuer credentials (RICS, Ministry Registry No.) • Independence declarations • PII insurance details • Standard assumptions verification STEP 3: PROPERTY DESCRIPTION (Sheet 3) - 10 minutes • Location details (address, municipality, KAEK, GPS) • Land data (area, Σ.Δ., Σ.Κ. - model calculates max building area) • Building details (year, floors, elevator) • **GREEK WEIGHTED AREA** - Just enter areas, model calculates: → Main spaces × 1.00 → Attic × 0.35 → Basement × 0.20 → Semi-basement × 0.50 → Balconies × 0.50 → TOTAL WEIGHTED AREA (auto-calculated) • Amenities (parking, storage, heating, A/C, etc.) • Condition assessment STEP 4: MARKET RESEARCH (Sheet 4) - 10 minutes • General market conditions (phase, supply/demand) • Price ranges (€/m²) for property type • Rental ranges (€/m²/month) • Cap rates by property type (from Greek market data) • Market commentary STEP 5: COMPARABLES DATABASE (Sheet 5) - 20 minutes • Enter up to 15 comparables • Basic data: Address, asking price, date, source • Area breakdown (main, attic, basement, semi-basement, balconies) • Floor, year, condition • **WEIGHTED M² AUTO-CALCULATES** using Greek formula • **€/M² AUTO-CALCULATES** STEP 6: COMPARATIVE METHOD (Sheet 6) ★ FORMULA-BASED ★ - 20 minutes THIS IS THE KEY INNOVATION - ZERO MANUAL CALCULATIONS: 6A. SUBJECT PROPERTY CHARACTERISTICS (Input once): • Transaction status: Own/Sale • Location quality: 1-5 scale • Access quality: 1-5 scale • View quality: 1-5 scale • Age: years • Floor level: number • Area: auto-links from Sheet 3 • Light/ventilation: 1-5 scale • Amenities score: 1-5 scale 6B. SELECT 5 COMPARABLES & INPUT THEIR CHARACTERISTICS: • Original price (€/m²) • Transaction type: A=Asking, S=Sale, O=Offer • Location quality: 1-5 scale • Access quality: 1-5 scale • View quality: 1-5 scale • Age: years • Floor level: number • Area: m² • Light/ventilation: 1-5 scale • Amenities score: 1-5 scale • Transaction date 6C. ADJUSTMENTS CALCULATE AUTOMATICALLY: The model compares each comparable to your subject property and calculates: 1. Transaction Type: If "Asking" → -10% to -20% (from reference table) 2. Location: Scale difference × 5% per point 3. Access: Scale difference × 3% per point 4. Views: Scale difference × 5% per point 5. Age: Year difference × 1.5% (ΣΕΚΕ composite method) 6. Floor: Level difference × 2.5% per floor 7. Size: (Area difference ÷ 25m²) × 1% 8. Light: Scale difference × 5% per point 9. Amenities: Scale difference × 3% per point 10. Time: Months since transaction × 2% annual → TOTAL ADJUSTMENT = SUM of all factors → ADJUSTED PRICE = Original × (1 + Total Adjustment) 6D. ASSIGN WEIGHTS (must sum to 100%): • Based on reliability and similarity of each comparable • Model calculates weighted average (never simple mean per ΣΕΚΕ) 6E. MARKET VALUE: → Weighted Average €/m² × Subject Weighted Area → **AUTOMATICALLY CALCULATED** STEP 7: INCOME METHOD (Sheet 7) - 15 minutes • Market rent estimation (€/m²/month) • Operating expenses (Greek typical: 15-25% of gross) • Net Operating Income calculation • Cap rate method (simple) • DCF analysis (10-year Greek institutional practice) • Discount rate, growth assumptions, exit yield • **NPV AUTO-CALCULATES** STEP 8: METHOD RECONCILIATION (Sheet 8) - 5 minutes • Assign weights to each method (must sum to 100%) • Comparative Method: typically 60-80% for active markets • Income Method: typically 20-40% for investment properties • **FINAL MARKET VALUE AUTO-CALCULATES** STEP 9: SWOT ANALYSIS (Sheet 9) - 5 minutes • Property/location strengths • Weaknesses • Market opportunities • Threats/risks STEP 10: ASSUMPTIONS REGISTER (Sheet 10) - 3 minutes • Verify standard assumptions • Document any special assumptions STEP 11: FINAL REPORT (Sheet 11) - 5 minutes • Review auto-populated executive summary • Market value conclusion (auto-links) • Methods applied • Compliance statements • Market uncertainty clause • Valuer certification ═══════════════════════════════════════════════════════════════════════════════════ GREEK-SPECIFIC FEATURES ═══════════════════════════════════════════════════════════════════════════════════ 1. WEIGHTED AREA (Ανηγμένη Επιφάνεια): Distinguishes Greek practice from international standards Formula: Main(1.0) + Attic(0.35) + Basement(0.20) + Semi-basement(0.50) + Balcony(0.50) 2. 10-FACTOR ADJUSTMENT SYSTEM: Based on analysis of actual Greek valuation reports (NOVAL, Danos, GEOAXIS, REA Partners) All ranges validated against professional practice 3. GREEK CAP RATES (2023-2025 Market Data): • Residential Prime: 6.0-7.0% • Residential Secondary: 7.0-8.0% • Retail Prime (e.g., Ermou): 5.5-6.5% • Office CBD: 6.0-7.0% • Industrial/Logistics: 7.5-8.7% 4. TRANSACTION TYPE ADJUSTMENTS: Greek market reality: Asking prices typically 10-20% above actual sales Model applies appropriate discount automatically 5. AGE ADJUSTMENT: Composite method: ±1.5% per year (not linear depreciation) Validated against Greek appraisal reports 6. MINISTRY OF FINANCE COMPLIANCE: Registry number field (Α.Μ. Μητρώου) Required for all Greek valuations ═══════════════════════════════════════════════════════════════════════════════════ COLOR CODING SYSTEM ═══════════════════════════════════════════════════════════════════════════════════ LIGHT BLUE cells = YOUR INPUTS (factual data you enter) LIGHT GREEN cells = CALCULATED VALUES (formulas - don't edit) GOLD cells = FINAL OUTPUTS (key results) GRAY cells = REFERENCE DATA (adjustment ranges from ΣΕΚΕ) RED headers = RICS corporate color ═══════════════════════════════════════════════════════════════════════════════════ CRITICAL ΣΕΚΕ 2018 PRINCIPLES ═══════════════════════════════════════════════════════════════════════════════════ ✓ Adjustments are MULTIPLICATIVE not additive ✓ NEVER use simple average of comparables or methods ✓ Weighted averaging required with explicit justification ✓ When subject property superior → positive adjustment to comparable ✓ When subject property inferior → negative adjustment to comparable ✓ Transaction type discount essential for asking prices ✓ Age adjustment uses composite method (not straight-line depreciation) ═══════════════════════════════════════════════════════════════════════════════════ DATA QUALITY STANDARDS ═══════════════════════════════════════════════════════════════════════════════════ COMPARABLES: • Use recent transactions (within 12 months preferred) • Minimum 5 comparables for weighted analysis • Maximum 10-15% price variance for similar properties • Verify all transaction data when possible • Document sources clearly MARKET DATA: • Update cap rates annually from market reports • Monitor NOVAL Property REIC quarterly presentations • Track Bank of Greece real estate statistics • Consider macroeconomic indicators ═══════════════════════════════════════════════════════════════════════════════════ PROFESSIONAL STANDARDS COMPLIANCE ═══════════════════════════════════════════════════════════════════════════════════ ✓ RICS Valuation - Global Standards (Red Book 2022) ✓ International Valuation Standards (IVS 2020) - Market Value definition ✓ European Valuation Standards (EVS 2016) ✓ ΣΕΚΕ 2018 Greek methodology ✓ VPGA 10 Market uncertainty disclosure ✓ IFRS 13 Fair Value Measurement (where applicable) ═══════════════════════════════════════════════════════════════════════════════════ LIMITATIONS & DISCLAIMERS ═══════════════════════════════════════════════════════════════════════════════════ • Model designed for Greek market (Athens and major cities) • Requires professional valuer judgment - not automated valuation • Regular market data updates essential • All assumptions must be verified • Not a substitute for market knowledge and inspection • Intended for RICS-qualified valuers or equivalent ═══════════════════════════════════════════════════════════════════════════════════ TECHNICAL SPECIFICATIONS ═══════════════════════════════════════════════════════════════════════════════════ Excel Version: 2016+ compatible Formulas: Dynamic cell references, no hardcoded values Greek Text: Full UTF-8 encoding support File Size: ~26KB (lightweight, fast) Sheets: 12 integrated worksheets Links: All cross-sheet references maintained ═══════════════════════════════════════════════════════════════════════════════════ SUPPORT & UPDATES ═══════════════════════════════════════════════════════════════════════════════════ Model Version: 1.0 (January 2026) Based on: Current Greek market data (2023-2025) Recommended Review: Annually for market data updates For questions about Greek valuation methodology, consult: • ΣΕΚΕ (Greek Valuers Association): www.seke.gr • RICS Greece: www.rics.org/greece • Hellenic Association of Valuers ═══════════════════════════════════════════════════════════════════════════════════

Sheet 1_EXECUTIVE_SUMMARY
A1: EXECUTIVE SUMMARY / ΠΕΡΙΛΗΨΗ
A3: Property Address / Διεύθυνση:
A4: Property Type / Είδος Ακινήτου:
A5: Ownership / Ιδιοκτησία:
A6: Valuation Date / Ημερομηνία Εκτίμησης:
A7: Inspection Date / Ημερομηνία Αυτοψίας:
A8: Client / Πελάτης:
A9: Purpose / Σκοπός:
A11: Total Area (m²) / Συνολική Επιφάνεια:
A12: Weighted Area (m²) / Ανηγμένη Επιφάνεια: | B12: =0
A14: VALUATION METHODOLOGY / ΜΕΘΟΔΟΛΟΓΙΑ:
A15: Primary Method / Κύρια Μέθοδος: | B15: Comparative Method
A16: Secondary Method / Δευτερεύουσα:
A17: Weighting / Στάθμιση:
A19: MARKET VALUE / ΑΓΟΡΑΙΑ ΑΞΙΑ: | B19: ='8_METHOD_RECONCILIATION'!B19
A21: Compliance / Συμμόρφωση:
A22: ☑ RICS Valuation Standards (Red Book 2022)
A23: ☑ IVS 2020 (International Valuation Standards)
A24: ☑ EVS 2016 (European Valuation Standards)
A25: ☑ ΣΕΚΕ 2018 (Greek Valuers Association)
A27: Valuer / Εκτιμητής:
A28: Qualification / Προσόντα: | B28: MRICS
A29: Registry No. / Α.Μ. Μητρώου:

Sheet 2_TERMS_OF_ENGAGEMENT
A1: TERMS OF ENGAGEMENT / ΟΡΟΙ ΑΝΑΘΕΣΗΣ
A3: 1. GENERAL INFORMATION / ΓΕΝΙΚΑ ΣΤΟΙΧΕΙΑ
A4: Purpose of Valuation / Σκοπός Εκτίμησης:
A5: Intended Use / Προοριζόμενη Χρήση:
A6: Basis of Value / Βάση Αξίας:
A7: Valuation Date / Ημερομηνία Εκτίμησης:
A8: Inspection Date / Ημερομηνία Αυτοψίας:
A9: Report Date / Ημερομηνία Έκθεσης:
A11: 2. CLIENT & VALUER DETAILS / ΣΤΟΙΧΕΙΑ ΠΕΛΑΤΗ & ΕΚΤΙΜΗΤΗ
A12: Client Name / Όνομα Πελάτη:
A13: Client Address / Διεύθυνση Πελάτη:
A14: Contact Person / Αρμόδιος:
A16: Valuer Name / Όνομα Εκτιμητή:
A17: RICS Membership / Ιδιότητα: | B17: MRICS
A18: Ministry Registry No. / Α.Μ. Υπ. Οικονομικών:
A19: Firm Name / Εταιρεία:
A20: RICS Regulated Firm No.:
A22: 3. INDEPENDENCE & CONFLICTS / ΑΝΕΞΑΡΤΗΣΙΑ
A23: No conflicts of interest declared? / Δήλωση μη σύγκρουσης; | B23: YES
A24: Prior engagement with client? / Προηγούμενη συνεργασία; | B24: NO
A25: Fee < 5% of annual turnover? / Αμοιβή < 5%; | B25: YES
A26: PII Coverage Amount / Ασφάλιση Επαγγελματικής Ευθύνης (€): | B26: 1,000,000
A28: 4. ASSUMPTIONS / ΠΑΡΑΔΟΧΕΣ
A29: ☑ Legal title is good and marketable / Νομική κυριότητα νόμιμη
A30: ☑ Property is free of encumbrances / Χωρίς βάρη
A31: ☑ Planning compliance / Πολεοδομική νομιμότητα
A32: ☑ Structural soundness / Στατική επάρκεια
A33: ☑ No hazardous materials / Χωρίς επικίνδυνα υλικά
A34: ☑ No hidden defects / Χωρίς κρυφά ελαττώματα
A36: 5. SPECIAL ASSUMPTIONS / ΕΙΔΙΚΕΣ ΠΑΡΑΔΟΧΕΣ
A37: List any special assumptions:

Sheet 3_PROPERTY_DESCRIPTION
A1: PROPERTY DESCRIPTION / ΠΕΡΙΓΡΑΦΗ ΑΚΙΝΗΤΟΥ
A3: A. LOCATION / ΤΟΠΟΘΕΣΙΑ
A4: Address / Διεύθυνση:
A5: Municipality / Δήμος:
A6: Region / Περιφέρεια:
A7: Postal Code / Τ.Κ.:
A8: Building Block / Ο.Τ.:
A9: KAEK Number:
A10: GPS Coordinates / Συντεταγμένες:
A12: B. LAND / ΟΙΚΟΠΕΔΟ
A13: Land Area (m²) / Επιφάνεια Οικοπέδου:
A14: Building Coefficient / Συντελεστής Δόμησης (Σ.Δ.):
A15: Coverage Ratio / Συντελεστής Κάλυψης (Σ.Κ.):
A16: Max Allowed Building (m²) / Μέγιστη Δόμηση: | B16: =B13*B14
A17: Max Coverage (m²) / Μέγιστη Κάλυψη: | B17: =B13*B15
A19: C. BUILDING / ΚΤΙΡΙΟ
A20: Construction Year / Έτος Κατασκευής:
A21: Renovation Year / Έτος Ανακαίνισης:
A22: Building Age (years) / Ηλικία: | B22: =YEAR(TODAY())-B20
A23: Total Building Levels / Συνολικοί Όροφοι:
A24: Subject Floor Level / Όροφος Ακινήτου:
A25: Elevator / Ανελκυστήρας:
A27: D. AREA BREAKDOWN / ΑΝΑΛΥΣΗ ΕΠΙΦΑΝΕΙΩΝ (Weighted Area)
A29: Space Type / Τύπος Χώρου | B29: Area (m²) | C29: Coefficient | D29: Weighted (m²)
A30: Main Floor / Κύριος Χώρος | C30: 1 | D30: =B30*C30
A31: Attic/Loft / Σοφίτα | C31: 0.35 | D31: =B31*C31
A32: Basement / Υπόγειο (Storage) | C32: 0.2 | D32: =B32*C32
A33: Semi-basement / Ημιυπόγειο | C33: 0.5 | D33: =B33*C33
A34: Mezzanine / Πατάρι | C34: 0.4 | D34: =B34*C34
A35: Balconies >10m² / Βεράντες | C35: 0.5 | D35: =B35*C35
A37: TOTAL WEIGHTED AREA / ΣΥΝΟΛΟ ΑΝΗΓΜΕΝΗΣ ΕΠΙΦΑΝΕΙΑΣ | D37: =SUM(D30:D35)
A39: E. AMENITIES & FEATURES / ΠΑΡΟΧΕΣ
A40: Parking Spaces / Θέσεις Parking:
A41: Storage Room / Αποθήκη (m²):
A42: Heating Type / Θέρμανση:
A43: Air Conditioning / Κλιματισμός:
A44: Solar Water Heater / Ηλιακός:
A45: Security System / Συναγερμός:
A46: Garden / Κήπος (m²):
A47: Swimming Pool / Πισίνα:
...

Sheet 4_MARKET_RESEARCH
A1: MARKET RESEARCH / ΕΡΕΥΝΑ ΑΓΟΡΑΣ
A3: A. GENERAL MARKET CONDITIONS / ΓΕΝΙΚΕΣ ΣΥΝΘΗΚΕΣ
A5: Market Phase / Φάση Αγοράς:
A6: (Growth/Ανάπτυξη, Peak/Κορύφωση, Recession/Ύφεση, Recovery/Ανάκαμψη)
A8: Supply/Demand Balance / Ισορροπία Προσφοράς-Ζήτησης:
A9: Liquidity / Ρευστότητα Αγοράς:
A10: Average Time on Market (days) / Μέσος Χρόνος Πώλησης:
A11: Typical Asking Price Discount / Έκπτωση από Ζητούμενη (%): | B11: -15%
A13: B. PROPERTY TYPE MARKET DATA / ΣΤΟΙΧΕΙΑ ΚΑΤΑ ΤΥΠΟ
A15: Sales Price Range (€/m²):
A16: Minimum:
A17: Average:
A18: Maximum:
A20: Rental Range (€/m²/month):
A21: Minimum:
A22: Average:
A23: Maximum:
A25: C. CAPITALIZATION RATES / ΣΥΝΤΕΛΕΣΤΕΣ ΚΕΦΑΛΑΙΟΠΟΙΗΣΗΣ
A26: Based on Greek market data (2023-2025):
A28: Prime Residential / Κατοικία Α' κατηγορίας | B28: 6.0-7.0%
A29: Secondary Residential / Δευτερεύουσα | B29: 7.0-8.0%
A30: Prime Retail / Κατάστημα Κεντρικό | B30: 5.5-6.5%
A31: Prime Office / Γραφείο CBD | B31: 6.0-7.0%
A32: Industrial/Logistics / Βιομηχανικό | B32: 7.5-8.7%
A33: Land / Οικόπεδο | B33: N/A (Residual Method)
A36: D. MARKET COMMENTARY / ΣΧΟΛΙΑΣΜΟΣ

Sheet 6_COMPARATIVE_METHOD
A1: COMPARATIVE METHOD / ΣΥΓΚΡΙΤΙΚΗ ΜΕΘΟΔΟΣ (ΣΕΚΕ 2018)
A3: Formula-based adjustments per ΣΕΚΕ 2018 methodology - No hardcoded values
A5: A. ΣΕΚΕ 2018 ADJUSTMENT FACTORS / ΣΥΝΤΕΛΕΣΤΕΣ ΠΡΟΣΑΡΜΟΓΗΣ
A7: Adjustment Factor / Παράγοντας | B7: Min % | C7: Max % | D7: Notes / Σημειώσεις | E7: Factor/Unit
A8: 1. Transaction Type / Τύπος Συναλλαγής | B8: -0.2 | C8: -0.1 | D8: Asking→Sale | E8: =B8
A9: 2. Location/Marketability / Θέση/Εμπορευσιμότητα | B9: -0.2 | C9: 0.2 | D9: Area quality | E9: =(C9-B9)/4
A10: 3. Access / Προσπελασιμότητα | B10: -0.1 | C10: 0.1 | D10: Transport, roads | E10: =(C10-B10)/4
A11: 4. Views/Orientation / Θέα/Προσανατολισμός | B11: -0.15 | C11: 0.15 | D11: Sea/Acropolis premium | E11: =(C11-B11)/4
A12: 5. Age/Condition / Ηλικία/Κατάσταση | B12: -0.02 | C12: 0.02 | D12: Per year difference | E12: =B12
A13: 6. Floor Level / Όροφος | B13: -0.15 | C13: 0.05 | D13: ±2-3% per floor | E13: =(C13-B13)/1
A14: 7. Size / Επιφάνεια | B14: -0.1 | C14: 0.1 | D14: Smaller more marketable | E14: =(C14-B14)/100
A15: 8. Light/Ventilation / Φωτισμός/Αερισμός | B15: -0.15 | C15: 0.15 | D15: Corner/through/internal | E15: =(C15-B15)/4
A16: 9. Amenities / Παροχές | B16: -0.1 | C16: 0.1 | D16: Parking, storage, AC | E16: =(C16-B16)/4
A17: 10. Time on Market / Χρόνος Αγοράς | B17: -0.15 | C17: 0.05 | D17: Price reduction pressure | E17: =B17/12
A19: B. SUBJECT PROPERTY / ΕΚΤΙΜΩΜΕΝΟ ΑΚΙΝΗΤΟ
A21: Characteristic / Χαρακτηριστικό | B21: Value
A22: Transaction Type (A/S/O) | B22: S
A23: Location Quality (1-5 scale) | B23: 4
A24: Access Quality (1-5 scale) | B24: 4
A25: View/Orientation Quality (1-5 scale) | B25: 3
A26: Age (years) | B26: ='3_PROPERTY_DESCRIPTION'!B22
A27: Floor Level | B27: ='3_PROPERTY_DESCRIPTION'!B24
A28: Weighted Area (m²) | B28: ='3_PROPERTY_DESCRIPTION'!D37
A29: Light/Ventilation (1-5 scale) | B29: 4
A30: Amenity Score (1-5 scale) | B30: 3
A31: Time on Market (months) | B31: 0
A33: C. COMPARABLES CHARACTERISTICS / ΧΑΡΑΚΤΗΡΙΣΤΙΚΑ ΣΥΓΚΡΙΤΙΚΩΝ
A35: Characteristic | B35: Subject | C35: Comp 1 | D35: Comp 2 | E35: Comp 3 | F35: Comp 4 | G35: Comp 5
A36: Original Price (€/m²) | B36: =B9
A37: Transaction Type (A/S/O) | B37: =B22
A38: Location Quality (1-5) | B38: =B23
A39: Access Quality (1-5) | B39: =B24
A40: View Quality (1-5) | B40: =B25
A41: Age (years) | B41: =B26
A42: Floor Level | B42: =B27
A43: Weighted Area (m²) | B43: =B28
A44: Light/Ventilation (1-5) | B44: =B29
A45: Amenity Score (1-5) | B45: =B30
A46: Months on Market | B46: =B31
A48: D. CALCULATED ADJUSTMENTS / ΥΠΟΛΟΓΙΣΜΟΙ ΠΡΟΣΑΡΜΟΓΩΝ
...

Sheet 5_COMPARABLES_DATABASE
A1: COMPARABLES DATABASE / ΒΑΣΗ ΣΥΓΚΡΙΤΙΚΩΝ ΣΤΟΙΧΕΙΩΝ
A3: # | B3: Address/Location Διεύθυνση | C3: Asking Price Ζητούμενη (€) | D3: Type Τύπος | E3: Date Ημερ. | F3: Main Κύριος | G3: Attic Σοφίτα | H3: Bsmt Υπόγ. | I3: Semi-B Ημιυπ. | J3: Balcony Βεράντα | K3: Floor Όροφος | L3: Year Έτος | M3: Cond. Κατ. | N3: Weighted m² Ανηγμένη | O3: €/m² | P3: Source Πηγή
A4: 1 | D4: A | N4: =F4*1.0 + G4*0.35 + H4*0.20 + I4*0.50 + J4*0.50 | O4: =IF(N4>0, C4/N4, 0)
A5: 2 | D5: A | N5: =F5*1.0 + G5*0.35 + H5*0.20 + I5*0.50 + J5*0.50 | O5: =IF(N5>0, C5/N5, 0)
A6: 3 | D6: A | N6: =F6*1.0 + G6*0.35 + H6*0.20 + I6*0.50 + J6*0.50 | O6: =IF(N6>0, C6/N6, 0)
A7: 4 | D7: A | N7: =F7*1.0 + G7*0.35 + H7*0.20 + I7*0.50 + J7*0.50 | O7: =IF(N7>0, C7/N7, 0)
A8: 5 | D8: A | N8: =F8*1.0 + G8*0.35 + H8*0.20 + I8*0.50 + J8*0.50 | O8: =IF(N8>0, C8/N8, 0)
A9: 6 | D9: A | N9: =F9*1.0 + G9*0.35 + H9*0.20 + I9*0.50 + J9*0.50 | O9: =IF(N9>0, C9/N9, 0)
A10: 7 | D10: A | N10: =F10*1.0 + G10*0.35 + H10*0.20 + I10*0.50 + J10*0.50 | O10: =IF(N10>0, C10/N10, 0)
A11: 8 | D11: A | N11: =F11*1.0 + G11*0.35 + H11*0.20 + I11*0.50 + J11*0.50 | O11: =IF(N11>0, C11/N11, 0)
A12: 9 | D12: A | N12: =F12*1.0 + G12*0.35 + H12*0.20 + I12*0.50 + J12*0.50 | O12: =IF(N12>0, C12/N12, 0)
A13: 10 | D13: A | N13: =F13*1.0 + G13*0.35 + H13*0.20 + I13*0.50 + J13*0.50 | O13: =IF(N13>0, C13/N13, 0)
A14: 11 | D14: A | N14: =F14*1.0 + G14*0.35 + H14*0.20 + I14*0.50 + J14*0.50 | O14: =IF(N14>0, C14/N14, 0)
A15: 12 | D15: A | N15: =F15*1.0 + G15*0.35 + H15*0.20 + I15*0.50 + J15*0.50 | O15: =IF(N15>0, C15/N15, 0)
... A18: 15 | D18: A | N18: =F18*1.0 + G18*0.35 + H18*0.20 + I18*0.50 + J18*0.50 | O18: =IF(N18>0, C18/N18, 0)
A20: STATISTICS / ΣΤΑΤΙΣΤΙΚΑ:
A21: Count: | B21: =COUNTA(O4:O18)
A22: Min €/m²: | B22: =MIN(O4:O18)
A23: Max €/m²: | B23: =MAX(O4:O18)
A24: Average €/m²: | B24: =AVERAGE(O4:O18)

Sheet 7_INCOME_METHOD_DCF
A1: INCOME CAPITALIZATION METHOD / ΜΕΘΟΔΟΣ ΕΙΣΟΔΗΜΑΤΟΣ (DCF)
A3: Greek institutional practice: 10-year holding period, exit value via cap rate
A5: A. MARKET RENTAL VALUE / ΕΜΠΟΡΙΚΟ ΕΝΟΙΚΙΟ
A7: Estimated Market Rent (€/m²/month):
A8: Rentable Area (m²): | B8: ='3_PROPERTY_DESCRIPTION'!D37
A9: Annual Gross Rent / Ετήσιο Ακαθάριστο: | B9: =B7*B8*12
A11: B. OPERATING EXPENSES / ΛΕΙΤΟΥΡΓΙΚΑ ΕΞΟΔΑ
A13: Property Tax / ΕΝ.Φ.Ι.Α.: | B13: 2.0% | C13: =B9*B13
A14: Insurance / Ασφάλιση: | B14: 0.5% | C14: =B9*B14
A15: Maintenance / Συντήρηση: | B15: 3.0% | C15: =B9*B15
A16: Management Fee / Διαχείριση: | B16: 5.0% | C16: =B9*B16
A17: Common Expenses / Κοινόχρηστα: | B17: 4.0% | C17: =B9*B17
A18: Vacancy Allowance / Κενά Διαστήματα: | B18: 5.0% | C18: =B9*B18
A19: Other Costs / Λοιπά: | B19: 2.0% | C19: =B9*B19
A21: Total Operating Expenses: | B21: =SUM(B13:B19) | C21: =SUM(C13:C19)
A23: NET OPERATING INCOME (NOI) / ΚΑΘΑΡΟ ΕΙΣΟΔΗΜΑ: | B23: =B9-C21
A25: C. CAPITALIZATION RATE METHOD / ΜΕΘΟΔΟΣ ΚΕΦΑΛΑΙΟΠΟΙΗΣΗΣ
A27: Capitalization Rate / Συντελεστής (%): | B27: 6.5%
A28: Based on Greek market data by property type:
A29: Residential 6-7%, Retail 5.5-6.5%, Office 6-7%, Industrial 7.5-8.7%
A31: MARKET VALUE (Income Method): | B31: =B23/B27
A33: D. DCF ANALYSIS (10-Year Hold) / ΑΝΑΛΥΣΗ DCF
A35: Rental Growth Rate / Αύξηση Ενοικίου (% p.a.): | B35: 2.0%
A36: Discount Rate / Προεξοφλητικό Επιτόκιο (%): | B36: 7.5%
A37: Exit Capitalization Rate / Συντελεστής Εξόδου (%): | B37: 7.0%
A39: Year | B39: NOI | C39: PV Factor | D39: Present Value
A40: 1 | B40: =$B$23*(1+$B$35)^A40 | C40: =1/(1+$B$36)^A40 | D40: =B40*C40
A41: 2 | B41: =$B$23*(1+$B$35)^A41 | C41: =1/(1+$B$36)^A41 | D41: =B41*C41
A42: 3 | B42: =$B$23*(1+$B$35)^A42 | C42: =1/(1+$B$36)^A42 | D42: =B42*C42
A43: 4 | B43: =$B$23*(1+$B$35)^A43 | C43: =1/(1+$B$36)^A43 | D43: =B43*C43
A44: 5 | B44: =$B$23*(1+$B$35)^A44 | C44: =1/(1+$B$36)^A44 | D44: =B44*C44
A45: 6 | B45: =$B$23*(1+$B$35)^A45 | C45: =1/(1+$B$36)^A45 | D45: =B45*C45
A46: 7 | B46: =$B$23*(1+$B$35)^A46 | C46: =1/(1+$B$36)^A46 | D46: =B46*C46
A47: 8 | B47: =$B$23*(1+$B$35)^A47 | C47: =1/(1+$B$36)^A47 | D47: =B47*C47
A48: 9 | B48: =$B$23*(1+$B$35)^A48 | C48: =1/(1+$B$36)^A48 | D48: =B48*C48
A49: 10 | B49: =$B$23*(1+$B$35)^A49 | C49: =1/(1+$B$36)^A49 | D49: =B49*C49
A50: Exit Value (Year 10 NOI / Exit Cap Rate): | B50: =B49/$B$37
A51: PV of Exit Value: | D51: =B50*C49
A53: Total PV of Cash Flows: | D53: =SUM(D40:D49)
A55: MARKET VALUE (DCF Method): | D55: =D53+D51

Sheet 8_METHOD_RECONCILIATION
A1: METHOD RECONCILIATION / ΣΥΜΦΩΝΙΑ ΜΕΘΟΔΩΝ
A3: CRITICAL: Per ΣΕΚΕ guidance, NEVER use simple average of methods.
A4: Assign weights based on reliability, data availability, and property type appropriateness.
A6: A. METHOD RESULTS / ΑΠΟΤΕΛΕΣΜΑΤΑ ΜΕΘΟΔΩΝ
A8: Valuation Method | B8: Indicated Value (€) | C8: Weight % | D8: Weighted Value (€)
A9: Comparative Method / Συγκριτική | B9: ='6_COMPARATIVE_METHOD'!B73 | C9: 70% | D9: =B9*C9
A10: Income Method (Cap Rate) / Εισοδήματος | B10: ='7_INCOME_METHOD_DCF'!B31 | C10: 30% | D10: =B10*C10
A11: DCF Method (10-year) / DCF | B11: ='7_INCOME_METHOD_DCF'!D55 | C11: 0% | D11: =B11*C11
A12: Cost Method / Αποσβεσμένου Κόστους | B12: 0 | C12: 0% | D12: =B12*C12
A13: Residual Method / Υπολειμματική | B13: 0 | C13: 0% | D13: =B13*C13
A15: Total Weight (must = 100%): | C15: =SUM(C9:C13)
A17: B. FINAL MARKET VALUE / ΤΕΛΙΚΗ ΑΓΟΡΑΙΑ ΑΞΙΑ
A19: WEIGHTED MARKET VALUE: | B19: =SUM(D9:D13)
A21: Rounded to nearest €1,000: | B21: =ROUND(B19,-3)
A23: C. RELIABILITY ASSESSMENT / ΑΞΙΟΛΟΓΗΣΗ ΑΞΙΟΠΙΣΤΙΑΣ

Sheet 9_SWOT_ANALYSIS
A1: SWOT ANALYSIS / ΑΝΑΛΥΣΗ SWOT
A3: STRENGTHS / ΠΛΕΟΝΕΚΤΗΜΑΤΑ | B3: WEAKNESSES / ΜΕΙΟΝΕΚΤΗΜΑΤΑ
A17: OPPORTUNITIES / ΕΥΚΑΙΡΙΕΣ | B17: THREATS / ΚΙΝΔΥΝΟΙ

Sheet 10_ASSUMPTIONS_REGISTER
A1: ASSUMPTIONS REGISTER / ΜΗΤΡΩΟ ΠΑΡΑΔΟΧΩΝ
A3: Per RICS VPS 4: All assumptions must be reasonable, relevant, and clearly stated.
A5: A. STANDARD ASSUMPTIONS / ΓΕΝΙΚΕΣ ΠΑΡΑΔΟΧΕΣ
A7: ☑ | B7: Good and marketable legal title / Νόμιμος τίτλος
A8: ☑ | B8: Free from encumbrances / Χωρίς βάρη εκτός δηλωθέντων
A9: ☑ | B9: Planning/zoning compliance / Πολεοδομική νομιμότητα
A10: ☑ | B10: Building permit validity / Έγκυρη οικοδομική άδεια
A11: ☑ | B11: Structural soundness / Στατική επάρκεια
A12: ☑ | B12: No hazardous materials / Χωρίς επικίνδυνα υλικά (asbestos, etc.)
A13: ☑ | B13: No hidden defects / Χωρίς κρυφά ελαττώματα
A14: ☑ | B14: No environmental contamination / Χωρίς περιβαλλοντική μόλυνση
A15: ☑ | B15: Compliance with health & safety / Συμμόρφωση υγεία/ασφάλεια
A16: ☑ | B16: All utilities available / Όλες οι παροχές διαθέσιμες
A17: ☑ | B17: No adverse rights of way / Χωρίς δικαιώματα διέλευσης
A18: ☑ | B18: Property accessible / Νόμιμη πρόσβαση
A20: B. SPECIAL ASSUMPTIONS / ΕΙΔΙΚΕΣ ΠΑΡΑΔΟΧΕΣ
A22: List any special assumptions that differ from actual circumstances:

Sheet 11_FINAL_REPORT
A1: VALUATION REPORT / ΕΚΘΕΣΗ ΕΚΤΙΜΗΣΗΣ
A3: 1. PROPERTY IDENTIFICATION / ΤΑΥΤΟΤΗΤΑ ΑΚΙΝΗΤΟΥ
A5: Address: | B5: ='1_EXECUTIVE_SUMMARY'!B3
A6: Type: | B6: ='1_EXECUTIVE_SUMMARY'!B4
A7: Total Area: | B7: ='3_PROPERTY_DESCRIPTION'!D37
A9: 2. VALUATION BASIS / ΒΑΣΗ ΕΚΤΙΜΗΣΗΣ
A11: Valuation Date: | B11: ='2_TERMS_OF_ENGAGEMENT'!B7
A12: Inspection Date: | B12: ='2_TERMS_OF_ENGAGEMENT'!B8
A13: Basis of Value: | B13: Market Value (IVS 2020 / EVS 2016)
A14: Purpose: | B14: ='2_TERMS_OF_ENGAGEMENT'!B4
A16: 3. MARKET VALUE CONCLUSION / ΣΥΜΠΕΡΑΣΜΑ
A18: MARKET VALUE: | B18: ='8_METHOD_RECONCILIATION'!B19
A20: In words / Ολογράφως:
A23: 4. METHODS APPLIED / ΕΦΑΡΜΟΣΘΕΙΣΕΣ ΜΕΘΟΔΟΙ
A25: Primary Method: | B25: Comparative Method (Sales Comparison Approach)
A26: Weighting: | B26: ='8_METHOD_RECONCILIATION'!C9
A27: Supporting Method: | B27: Income Capitalization Method
A28: Weighting: | B28: ='8_METHOD_RECONCILIATION'!C10
A30: 5. COMPLIANCE / ΣΥΜΜΟΡΦΩΣΗ
A32: This valuation has been prepared in accordance with: ☑ RICS Valuation – Global Standards (Red Book 2022) ☑ International Valuation Standards (IVS 2020) ☑ European Valuation Standards (EVS 2016) ☑ Greek Valuers Association Standards (ΣΕΚΕ 2018) ☑ IFRS 13 Fair Value Measurement (where applicable)
A38: 6. MARKET UNCERTAINTY CLAUSE / ΡΗΤΡΑ ΑΒΕΒΑΙΟΤΗΤΑΣ
A40: Given the ongoing economic conditions in Greece and broader market volatility, this valuation is reported with a degree of uncertainty that is higher than would be normal. Market conditions may change rapidly. This valuation should not be relied upon beyond 6 months from the valuation date without review. Professional revaluation is recommended if used for financial reporting or lending decisions after this period.
A46: 7. VALUER CERTIFICATION / ΠΙΣΤΟΠΟΙΗΣΗ ΕΚΤΙΜΗΤΗ
A48: Valuer Name: | B48: ='2_TERMS_OF_ENGAGEMENT'!B16
A49: Qualification: | B49: ='2_TERMS_OF_ENGAGEMENT'!B17
A50: Ministry Registry No.: | B50: ='2_TERMS_OF_ENGAGEMENT'!B18
A51: Firm: | B51: ='2_TERMS_OF_ENGAGEMENT'!B19
A53: I certify that: • I have the requisite qualifications and experience • I am independent and have no conflicts of interest • The valuation has been conducted with professional care • I have inspected the property personally • All assumptions are reasonable and clearly stated • This report complies with applicable professional standards
A60: Signature:
A61: Date: | B61: =TODAY()
