Workbook

Sheet Inputs_Assumptions
A1: RMBS Capital Structure Optimization Model
A2: Based on S&P Rating Agency Methodology
A4: DEAL INFORMATION
A5: Deal Name | B5: Polaris 2025-3 PLC | C5: Input
A6: Closing Date | B6: 45967 | C6: Input
A7: Pool Balance (£m) | B7: 430 | C7: Input - Total incl. prefunding
A8: Rated Note Balance (£m) | B8: 447.2 | C8: Calculated
A9: Currency | B9: GBP | C9: Input
A10: Collateral Type | B10: Nonconforming | C10: Input
A11: Prefunding Amount (%) | B11: 24.3 | C11: Input - % of pool
A14: S&P CREDIT ASSUMPTIONS
A15: Rating Level | B15: WAFF (%) | C15: WALS (%) | D15: Credit Coverage (%) | E15: Notes
A16: AAA | B16: 30.82 | C16: 35.3 | D16: =B16*C16/100 -> 10.87946 | E16: Highest stress
A17: AA | B17: 20.67 | C17: 30.12 | D17: =B17*C17/100 -> 6.225804
A18: A | B18: 15.52 | C18: 21.8 | D18: =B18*C18/100 -> 3.38336
A19: BBB | B19: 10.35 | C19: 17.24 | D19: =B19*C19/100 -> 1.78434
A20: BB | B20: 5.17 | C20: 14.08 | D20: =B20*C20/100 -> 0.727936
A21: B | B21: 3.88 | C21: 11.28 | D21: =B21*C21/100 -> 0.437664 | E21: Lowest stress
A24: NOTE COUPON ASSUMPTIONS
A25: Parameter | B25: Value | C25: Unit | D25: Notes
A26: SONIA Rate | B26: 3.97 | C26: % | D26: Current market rate
A27: Class A Margin (Pre-Step) | B27: 0.82 | C27: % | D27: Polaris benchmark
A28: Class A Margin (Post-Step) | B28: 1.23 | C28: % | D28: Step-up +41bps
A29: Class B Margin (Pre-Step) | B29: 1.1 | C29: %
A30: Class C Margin (Pre-Step) | B30: 1.4 | C30: %
A31: Class D Margin (Pre-Step) | B31: 1.65 | C31: %
A32: Class E Margin (Pre-Step) | B32: 2.48 | C32: %
A33: Class F Margin (Pre-Step) | B33: 3.98 | C33: %
A34: Class G Margin (Pre-Step) | B34: 5.48 | C34: %
A35: X1 Margin | B35: 3.59 | C35: % | D35: Risk retention
A36: X2 Margin | B36: 3.59 | C36: % | D36: Risk retention
A39: RESERVE & LIQUIDITY ASSUMPTIONS
A40: Parameter | B40: Value | C40: Unit | D40: Notes
A41: Liquidity Reserve Target | B41: 1 | C41: % of A+B | D41: Polaris structure
A42: General Reserve Target | B42: 0.35 | C42: % of rated notes | D42: If applicable
A43: Liquidity Facility Size | B43: 1.1 | C43: % of A+B | D43: If facility used
A44: Initial Reserve Funding | B44: Unfunded | C44: - | D44: Built from principal
A47: SWAP ASSUMPTIONS
A48: Parameter | B48: Value | C48: Unit | D48: Notes
A49: Fixed Swap Rate Paid | B49: 3.8 | C49: % | D49: Issuer pays fixed
...

Sheet Current_Structure
A1: CURRENT CAPITAL STRUCTURE
A2: Polaris 2025-3 PLC - As Closed
A4: Class | B4: Rating | C4: Amount (£m) | D4: % of Pool | E4: CE (%) | F4: Coupon (bps) | G4: Step-Up (bps) | H4: Deferrable | I4: PDL | J4: Notes
A5: A | B5: AAA | C5: 377.325 | D5: =C5/Inputs_Assumptions!B7 -> 0.8775 | E5: 12.25 | F5: 82 | G5: 123 | H5: No | I5: No | J5: Senior
A6: B-Dfrd | B6: AA | C6: 23.65 | D6: =C6/Inputs_Assumptions!B7 -> 0.055 | E6: 6.75 | F6: 110 | G6: 165 | H6: Yes | I6: Yes
A7: C-Dfrd | B7: A- | C7: 13.975 | D7: =C7/Inputs_Assumptions!B7 -> 0.0325 | E7: 3.5 | F7: 140 | G7: 210 | H7: Yes | I7: Yes
A8: D-Dfrd | B8: BBB- | C8: 7.525 | D8: =C8/Inputs_Assumptions!B7 -> 0.0175 | E8: 1.75 | F8: 165 | G8: 248 | H8: Yes | I8: Yes
A9: E-Dfrd | B9: BB+ | C9: 3.225 | D9: =C9/Inputs_Assumptions!B7 -> 0.0075 | E9: 1 | F9: 248 | G9: 348 | H9: Yes | I9: Yes
A10: F-Dfrd | B10: B- | C10: 3.44 | D10: =C10/Inputs_Assumptions!B7 -> 0.008 | E10: 0.2 | F10: 398 | G10: 498 | H10: Yes | I10: Yes
A11: G-Dfrd | B11: CCC | C11: 0.86 | D11: =C11/Inputs_Assumptions!B7 -> 0.002 | E11: 0 | F11: 548 | G11: 648 | H11: Yes | I11: Yes | J11: Junior
A12: X1-Dfrd | B12: B- | C12: 10.75 | D12: =C12/Inputs_Assumptions!B7 -> 0.025 | E12: 0 | F12: 359 | G12: 359 | H12: Yes | I12: No | J12: Risk Retention
A13: X2-Dfrd | B13: CCC | C13: 6.45 | D13: =C13/Inputs_Assumptions!B7 -> 0.015 | E13: 0 | F13: 359 | G13: 359 | H13: Yes | I13: No | J13: Risk Retention
A14: TOTAL | C14: =SUM(C5:C13) -> 447.2 | D14: =SUM(D5:D13) -> 1.04
A17: KEY METRICS - CURRENT STRUCTURE
A18: AAA Credit Enhancement | B18: =E5 -> 12.25 | C18: % | D18: Subordination to AAA
A19: Senior Note % | B19: =D5 -> 0.8775 | C19: % | D19: Class A as % of pool
A20: Weighted Avg Cost (Pre-Step) | B20: =SUMPRODUCT(C5:C13,F5:F13)/SUM(C5:C13) -> 101.86779 | C20: bps | D20: Calculated
A21: Weighted Avg Cost (Post-Step) | B21: =SUMPRODUCT(C5:C13,G5:G13)/SUM(C5:C13) -> 144.63702 | C21: bps | D21: Calculated
A22: Excess Spread (Initial) | B22: 1.71 | C22: % | D22: Per S&P report
A23: Step-Up Date | B23: Sept 2029 | C23: -
A24: Legal Final Maturity | B24: Oct 2069 | C24: -

Sheet Peer_Comparison
A1: PEER TRANSACTION COMPARISON
A2: UK RMBS Benchmark Analysis - S&P Rated Transactions
A4: Transaction | B4: Date | C4: Pool (£m) | D4: AAA % | E4: AAA CE (%) | F4: Gen Reserve | G4: WAFF AAA | H4: WALS AAA | I4: Coverage AAA | J4: Originator Adj | K4: Notes
A5: Polaris 2025-3 | B5: Nov-25 | C5: 430 | D5: 87.75 | E5: 12.25 | F5: No | G5: 30.82 | H5: 35.3 | I5: 10.88 | J5: 1.15 | K5: Subject Deal
A6: Polaris 2025-2 | B6: Jun-25 | C6: 482 | F6: No | G6: 30.51 | H6: 34.59 | I6: 10.55 | J6: 1.1 | K6: Prior Polaris
A7: Polaris 2025-1 | B7: Jan-25 | C7: 549.4 | F7: No | G7: 29.02 | H7: 38.63 | I7: 11.21
A8: Elstree 2025-2 | B8: Oct-25 | C8: 329.2 | D8: 89.95 | E8: 10.05 | F8: Yes | G8: 24.78 | H8: 38.6 | I8: 9.57 | J8: 1.075 | K8: Enra - BTL/OO Mix
A9: Elstree 2025-1 | B9: May-25 | C9: 320.2 | F9: Yes | G9: 24.52 | H9: 46.54 | I9: 11.41
A10: Braccan 2025-2 | B10: Nov-25 | C10: 386.6 | D10: 88.6 | E10: 11.75 | F10: Yes | G10: 23.65 | H10: 42.99 | I10: 10.17 | J10: 1.062 | K10: FHL - BTL Focus
A11: Braccan 2025-1 | B11: May-25 | C11: 438.4 | F11: Yes | G11: 22.92 | H11: 40.49 | I11: 9.28
A12: Together 2025-1ST1 | B12: Sep-25 | C12: 367.5 | D12: 90 | E12: 10 | F12: No | G12: 20.98 | H12: 30.98 | I12: 6.5 | J12: 1.3 | K12: Non-conforming
A15: COMPARATIVE ANALYSIS
A16: Metric | B16: Polaris 2025-3 | C16: Peer Average | D16: Variance | E16: Assessment
A17: AAA CE (%) | B17: =E5 -> 12.25 | C17: =AVERAGE(E6:E12) -> 10.6 | D17: =B17-C17 -> 1.65 | E17: =IF(D17>0.5,"Above Peer","At/Below Peer") -> Above Peer
A18: WAFF AAA (%) | B18: =G5 -> 30.82 | C18: =AVERAGE(G6:G12) -> 25.197143 | D18: =B18-C18 -> 5.6228571 | E18: =IF(D18>0.5,"Above Peer","At/Below Peer") -> Above Peer
A19: WALS AAA (%) | B19: =H5 -> 35.3 | C19: =AVERAGE(H6:H12) -> 38.974286 | D19: =B19-C19 -> -3.6742857 | E19: =IF(D19>0.5,"Above Peer","At/Below Peer") -> At/Below Peer
A20: Coverage AAA (%) | B20: =I5 -> 10.88 | C20: =AVERAGE(I6:I12) -> 9.8128571 | D20: =B20-C20 -> 1.0671429 | E20: =IF(D20>0.5,"Above Peer","At/Below Peer") -> Above Peer
A21: Originator Adj | B21: =J5 -> 1.15 | C21: =AVERAGE(J6:J12) -> 1.13425 | D21: =B21-C21 -> 0.01575 | E21: =IF(D21>0.5,"Above Peer","At/Below Peer") -> At/Below Peer

Sheet Optimization_Scenarios
A1: CAPITAL STRUCTURE OPTIMIZATION SCENARIOS
A2: Liability-Side Optimization Based on S&P Rating Agency Feedback
A4: SCENARIO INPUTS
A5: Target AAA CE (%) | B5: 10.5 | C5: % | D5: Reduction target
A6: Target Pool Balance (£m) | B6: 430 | C6: £m | D6: Fixed pool
A7: General Reserve (%) | B7: 0.35 | C7: % | D7: Add if beneficial
A8: Originator Adj Target | B8: 1.1 | C8: x | D8: Negotiate down
A9: Max AAA Size (%) | B9: 89.5 | C9: % | D9: Increase from current
A12: SCENARIO COMPARISON
A13: Class | B13: Rating | C13: Base Case | D13: Base % | E13: Base CE | F13: Reduce CE | G13: Opt 1 % | H13: Opt 1 CE | I13: Add Reserve | J13: Opt 2 % | K13: Opt 2 CE | L13: Combo | M13: Opt 3 %
A14: A | B14: AAA | C14: 377.325 | D14: =C14/SUM($C$14:$C$22) -> 0.84375 | E14: 0.1225 | F14: =$B$5*$B$9/100 -> 9.3975 | G14: =F14/SUM($F$14:$F$22) -> 0.12445371 | H14: =SUM(F15:$F$22)/SUM($F$14:$F$22) -> 0.87554629 | I14: =C14 -> 377.325 | J14: =I14/SUM($I$14:$I$22) -> 0.84375 | K14: =(SUM(I15:$I$22)/SUM($I$14:$I$22))+$B$7/100 -> 0.15975 | L14: =F14 -> 9.3975 | M14: =L14/SUM($L$14:$L$22) -> 0.12445371
A15: B-Dfrd | B15: AA | C15: 23.65 | D15: =C15/SUM($C$14:$C$22) -> 0.052884615 | E15: 0.0675 | F15: =C15*0.9 -> 21.285 | G15: =F15/SUM($F$14:$F$22) -> 0.28188319 | H15: =SUM(F16:$F$22)/SUM($F$14:$F$22) -> 0.59366309 | I15: =C15 -> 23.65 | J15: =I15/SUM($I$14:$I$22) -> 0.052884615 | K15: =(SUM(I16:$I$22)/SUM($I$14:$I$22))+$B$7/100 -> 0.10686538 | L15: =F15 -> 21.285 | M15: =L15/SUM($L$14:$L$22) -> 0.28188319
A16: C-Dfrd | B16: A- | C16: 13.975 | D16: =C16/SUM($C$14:$C$22) -> 0.03125 | E16: 0.035 | F16: =C16*0.9 -> 12.5775 | G16: =F16/SUM($F$14:$F$22) -> 0.16656734 | H16: =SUM(F17:$F$22)/SUM($F$14:$F$22) -> 0.42709575 | I16: =C16 -> 13.975 | J16: =I16/SUM($I$14:$I$22) -> 0.03125 | K16: =(SUM(I17:$I$22)/SUM($I$14:$I$22))+$B$7/100 -> 0.075615385 | L16: =F16 -> 12.5775 | M16: =L16/SUM($L$14:$L$22) -> 0.16656734
A17: D-Dfrd | B17: BBB- | C17: 7.525 | D17: =C17/SUM($C$14:$C$22) -> 0.016826923 | E17: 0.0175 | F17: =C17 -> 7.525 | G17: =F17/SUM($F$14:$F$22) -> 0.099655675 | H17: =SUM(F18:$F$22)/SUM($F$14:$F$22) -> 0.32744007 | I17: =C17 -> 7.525 | J17: =I17/SUM($I$14:$I$22) -> 0.016826923 | K17: =(SUM(I18:$I$22)/SUM($I$14:$I$22))+$B$7/100 -> 0.058788462 | L17: =F17 -> 7.525 | M17: =L17/SUM($L$14:$L$22) -> 0.099655675
A18: E-Dfrd | B18: BB+ | C18: 3.225 | D18: =C18/SUM($C$14:$C$22) -> 0.0072115385 | E18: 0.01 | F18: =C18 -> 3.225 | G18: =F18/SUM($F$14:$F$22) -> 0.042709575 | H18: =SUM(F19:$F$22)/SUM($F$14:$F$22) -> 0.2847305 | I18: =C18 -> 3.225 | J18: =I18/SUM($I$14:$I$22) -> 0.0072115385 | K18: =(SUM(I19:$I$22)/SUM($I$14:$I$22))+$B$7/100 -> 0.051576923 | L18: =F18 -> 3.225 | M18: =L18/SUM($L$14:$L$22) -> 0.042709575
A19: F-Dfrd | B19: B- | C19: 3.44 | D19: =C19/SUM($C$14:$C$22) -> 0.0076923077 | E19: 0.002 | F19: =C19 -> 3.44 | G19: =F19/SUM($F$14:$F$22) -> 0.04555688 | H19: =SUM(F20:$F$22)/SUM($F$14:$F$22) -> 0.23917362 | I19: =C19 -> 3.44 | J19: =I19/SUM($I$14:$I$22) -> 0.0076923077 | K19: =(SUM(I20:$I$22)/SUM($I$14:$I$22))+$B$7/100 -> 0.043884615 | L19: =F19 -> 3.44 | M19: =L19/SUM($L$14:$L$22) -> 0.04555688
A20: G-Dfrd | B20: CCC | C20: 0.86 | D20: =C20/SUM($C$14:$C$22) -> 0.0019230769 | E20: 0 | F20: =C20 -> 0.86 | G20: =F20/SUM($F$14:$F$22) -> 0.01138922 | H20: =SUM(F21:$F$22)/SUM($F$14:$F$22) -> 0.2277844 | I20: =C20 -> 0.86 | J20: =I20/SUM($I$14:$I$22) -> 0.0019230769 | K20: =(SUM(I21:$I$22)/SUM($I$14:$I$22))+$B$7/100 -> 0.041961538 | L20: =F20 -> 0.86 | M20: =L20/SUM($L$14:$L$22) -> 0.01138922
A21: X1-Dfrd | B21: B- | C21: 10.75 | D21: =C21/SUM($C$14:$C$22) -> 0.024038462 | E21: 0 | F21: =C21 -> 10.75 | G21: =F21/SUM($F$14:$F$22) -> 0.14236525 | H21: =SUM(F22:$F$22)/SUM($F$14:$F$22) -> 0.08541915 | I21: =C21 -> 10.75 | J21: =I21/SUM($I$14:$I$22) -> 0.024038462 | K21: =(SUM(I22:$I$22)/SUM($I$14:$I$22))+$B$7/100 -> 0.017923077 | L21: =F21 -> 10.75 | M21: =L21/SUM($L$14:$L$22) -> 0.14236525
A22: X2-Dfrd | B22: CCC | C22: 6.45 | D22: =C22/SUM($C$14:$C$22) -> 0.014423077 | E22: 0 | F22: =C22 -> 6.45 | G22: =F22/SUM($F$14:$F$22) -> 0.08541915 | H22: 0 | I22: =C22 -> 6.45 | J22: =I22/SUM($I$14:$I$22) -> 0.014423077 | K22: =$B$7/100 -> 0.0035 | L22: =F22 -> 6.45 | M22: =L22/SUM($L$14:$L$22) -> 0.08541915
A23: TOTAL | C23: =SUM(C14:C22) -> 447.2 | F23: =SUM(F14:F22) -> 75.51 | I23: =SUM(I14:I22) -> 447.2 | L23: =SUM(L14:L22) -> 75.51
A26: SCENARIO METRICS SUMMARY
A27: Metric | B27: Base Case | C27: Scenario 1 | D27: Scenario 2 | E27: Scenario 3
A28: AAA CE (%) | B28: =E14 -> 0.1225 | C28: =H14 -> 0.87554629 | D28: =K14 -> 0.15975 | E28: =H14+$B$7/100 -> 0.87904629
A29: AAA Size (£m) | B29: =C14 -> 377.325 | C29: =F14 -> 9.3975 | D29: =I14 -> 377.325 | E29: =L14 -> 9.3975
A30: AAA % of Total | B30: =D14 -> 0.84375 | C30: =G14 -> 0.12445371 | D30: =J14 -> 0.84375 | E30: =M14 -> 0.12445371
A31: WAC Pre-Step (bps)
A32: WAC Post-Step (bps)
A33: CE Reduction (bps) | B33: - | C33: =(E14-H14)*100 -> -75.304629 | D33: =(E14-K14)*100 -> -3.725 | E33: =(E14-(H14+$B$7/100))*100 -> -75.654629
A34: Funding Cost Saving (£k) | B34: -

Sheet Rating_Constraints
A1: S&P RATING CONSTRAINTS & THRESHOLDS
A2: Minimum Credit Enhancement Requirements per Rating Level
A4: MINIMUM CE BY RATING
A5: Rating | B5: Min CE (%) | C5: Coverage Req (%) | D5: Cushion (%) | E5: Notes
A6: AAA | B6: 10.88 | C6: 10.88 | D6: =Current_Structure!E5-B6 -> 1.37 | E6: WAFF 30.82% x WALS 35.30%
A7: AA | B7: 6.23 | C7: 6.23 | D7: =Current_Structure!E6-B7 -> 0.52 | E7: WAFF 20.67% x WALS 30.12%
A8: A | B8: 3.38 | C8: 3.38 | D8: =Current_Structure!E7-B8 -> 0.12
A9: BBB | B9: 1.78 | C9: 1.78 | D9: =Current_Structure!E8-B9 -> -0.03
A10: BB | B10: 0.73 | C10: 0.73 | D10: =Current_Structure!E9-B10 -> 0.27
A11: B | B11: 0.44 | C11: 0.44 | D11: =Current_Structure!E10-B11 -> -0.24
A14: LIQUIDITY REQUIREMENTS
A15: Class | B15: Liquidity Source | C15: Size | D15: Trigger | E15: Notes
A16: A | B16: Reserve Fund | C16: 1% of A+B | D16: N/A | E16: Must be fully funded
A17: B-Dfrd | B17: Reserve Fund | C17: 1% of A+B | D17: When senior | E17: Shared with A
A18: C-Dfrd to G-Dfrd | B18: Principal Only | C18: N/A | D18: When senior | E18: No dedicated reserve
A19: X1/X2 | B19: None | C19: N/A | D19: N/A | E19: Deferred to maturity
A22: STRUCTURAL FEATURES - CE IMPACT
A23: Feature | B23: Impact on CE | C23: Polaris 2025-3 | D23: Peer Best | E23: Delta
A24: General Reserve Fund | B24: +0.35% CE | C24: No | D24: Yes (Braccan) | E24: -0.35%
A25: Prefunding | B25: +WAFF Adj | C25: 24.3% | D25: 0-21% | E25: Higher
A26: Shared Ownership % | B26: +LTV Adj | C26: 7.52% | D26: 0-5% | E26: Higher
A27: Originator Adjustment | B27: WAFF Driver | C27: 1.15x | D27: 1.06-1.08x | E27: +7-9%
A28: Liquidity Reserve Initial | B28: Liquidity Risk | C28: Unfunded | D28: Funded | E28: Negative
A29: Sequential Waterfall | B29: CE Build | C29: Yes | D29: Yes | E29: Neutral
A30: Turbo Feature | B30: Delever Speed | C30: No | D30: Yes (Elstree) | E30: Slower

Sheet WAC_Calculator
A1: WEIGHTED AVERAGE COST CALCULATOR
A2: Pre and Post Step-Up Funding Cost Analysis
A4: PRICING INPUTS
A5: SONIA Rate (%) | B5: 3.97 | C5: % | D5: Current
A6: Swap Fixed Rate (%) | B6: 3.8 | C6: % | D6: Issuer pays
A9: COST BY TRANCHE
A10: Class | B10: Amount (£m) | C10: Weight (%) | D10: Pre-Step (bps) | E10: All-in Pre (%) | F10: Post-Step (bps) | G10: All-in Post (%) | H10: Annual Cost (£k)
A11: A | B11: 377.325 | C11: =B11/SUM($B$11:$B$19) -> 0.84375 | D11: 82 | E11: =$B$5+D11/100 -> 4.79 | F11: 123 | G11: =$B$5+F11/100 -> 5.2 | H11: =B11*E11*10 -> 18073.868
A12: B-Dfrd | B12: 23.65 | C12: =B12/SUM($B$11:$B$19) -> 0.052884615 | D12: 110 | E12: =$B$5+D12/100 -> 5.07 | F12: 165 | G12: =$B$5+F12/100 -> 5.62 | H12: =B12*E12*10 -> 1199.055
A13: C-Dfrd | B13: 13.975 | C13: =B13/SUM($B$11:$B$19) -> 0.03125 | D13: 140 | E13: =$B$5+D13/100 -> 5.37 | F13: 210 | G13: =$B$5+F13/100 -> 6.07 | H13: =B13*E13*10 -> 750.4575
A14: D-Dfrd | B14: 7.525 | C14: =B14/SUM($B$11:$B$19) -> 0.016826923 | D14: 165 | E14: =$B$5+D14/100 -> 5.62 | F14: 248 | G14: =$B$5+F14/100 -> 6.45 | H14: =B14*E14*10 -> 422.905
A15: E-Dfrd | B15: 3.225 | C15: =B15/SUM($B$11:$B$19) -> 0.0072115385 | D15: 248 | E15: =$B$5+D15/100 -> 6.45 | F15: 348 | G15: =$B$5+F15/100 -> 7.45 | H15: =B15*E15*10 -> 208.0125
A16: F-Dfrd | B16: 3.44 | C16: =B16/SUM($B$11:$B$19) -> 0.0076923077 | D16: 398 | E16: =$B$5+D16/100 -> 7.95 | F16: 498 | G16: =$B$5+F16/100 -> 8.95 | H16: =B16*E16*10 -> 273.48
A17: G-Dfrd | B17: 0.86 | C17: =B17/SUM($B$11:$B$19) -> 0.0019230769 | D17: 548 | E17: =$B$5+D17/100 -> 9.45 | F17: 648 | G17: =$B$5+F17/100 -> 10.45 | H17: =B17*E17*10 -> 81.27
A18: X1-Dfrd | B18: 10.75 | C18: =B18/SUM($B$11:$B$19) -> 0.024038462 | D18: 359 | E18: =$B$5+D18/100 -> 7.56 | F18: 359 | G18: =$B$5+F18/100 -> 7.56 | H18: =B18*E18*10 -> 812.7
A19: X2-Dfrd | B19: 6.45 | C19: =B19/SUM($B$11:$B$19) -> 0.014423077 | D19: 359 | E19: =$B$5+D19/100 -> 7.56 | F19: 359 | G19: =$B$5+F19/100 -> 7.56 | H19: =B19*E19*10 -> 487.62
A20: TOTAL/WAC | B20: =SUM(B11:B19) -> 447.2 | C20: =SUM(C11:C19) -> 1 | D20: =SUMPRODUCT(B11:B19,D11:D19)/B20 -> 101.86779 | E20: =SUMPRODUCT(B11:B19,E11:E19)/B20 -> 4.9886779 | F20: =SUMPRODUCT(B11:B19,F11:F19)/B20 -> 144.63702 | G20: =SUMPRODUCT(B11:B19,G11:G19)/B20 -> 5.4163702 | H20: =SUM(H11:H19) -> 22309.368
A23: FUNDING COST SUMMARY
A24: WAC Pre-Step-Up (bps) | B24: =D20 -> 101.86779 | C24: bps
A25: WAC Post-Step-Up (bps) | B25: =F20 -> 144.63702 | C25: bps
A26: All-in Cost Pre (% pa) | B26: =E20 -> 4.9886779 | C26: % | D26: SONIA + WAC margin
A27: All-in Cost Post (% pa) | B27: =G20 -> 5.4163702 | C27: %
A28: Annual Interest Cost (£m) | B28: =H20/1000 -> 22.309368 | C28: £m | D28: Pre step-up
A29: Step-Up Cost Increase (£k) | B29: =(G20-E20)*B20*10 -> 1912.64 | C29: £k pa | D29: If not called

Sheet Sensitivity_Analysis
A1: SENSITIVITY ANALYSIS
A2: Impact of Key Variables on Credit Enhancement Requirements
A4: WAFF SENSITIVITY - AAA CE IMPACT
A5: WAFF Stress | B5: WAFF (%) | C5: WALS (%) | D5: Coverage (%) | E5: CE Required (%) | F5: vs Base
A6: Base Case | B6: 30.82 | C6: 35.3 | D6: =B6*C6/100 -> 10.87946 | E6: =D6 -> 10.87946 | F6: -
A7: WAFF +10% | B7: =30.82*1.1 -> 33.902 | C7: 35.3 | D7: =B7*C7/100 -> 11.967406 | E7: =D7 -> 11.967406 | F7: =E7-$E$6 -> 1.087946
A8: WAFF +20% | B8: =30.82*1.2 -> 36.984 | C8: 35.3 | D8: =B8*C8/100 -> 13.055352 | E8: =D8 -> 13.055352 | F8: =E8-$E$6 -> 2.175892
A9: WAFF +30% | B9: =30.82*1.3 -> 40.066 | C9: 35.3 | D9: =B9*C9/100 -> 14.143298 | E9: =D9 -> 14.143298 | F9: =E9-$E$6 -> 3.263838
A10: WAFF -10% | B10: =30.82*0.9 -> 27.738 | C10: 35.3 | D10: =B10*C10/100 -> 9.791514 | E10: =D10 -> 9.791514 | F10: =E10-$E$6 -> -1.087946
A11: WAFF -15% | B11: =30.82*0.85 -> 26.197 | C11: 35.3 | D11: =B11*C11/100 -> 9.247541 | E11: =D11 -> 9.247541 | F11: =E11-$E$6 -> -1.631919
A14: WALS SENSITIVITY - AAA CE IMPACT
A15: WAFF Stress | B15: WAFF (%) | C15: WALS (%) | D15: Coverage (%) | E15: CE Required (%) | F15: vs Base
A16: Base Case | B16: 30.82 | C16: 35.3 | D16: =B16*C16/100 -> 10.87946 | E16: =D16 -> 10.87946 | F16: -
A17: WALS +10% | B17: 30.82 | C17: =35.3*1.1 -> 38.83 | D17: =B17*C17/100 -> 11.967406 | E17: =D17 -> 11.967406 | F17: =E17-$E$16 -> 1.087946
A18: WALS +20% | B18: 30.82 | C18: =35.3*1.2 -> 42.36 | D18: =B18*C18/100 -> 13.055352 | E18: =D18 -> 13.055352 | F18: =E18-$E$16 -> 2.175892
A19: WALS +30% | B19: 30.82 | C19: =35.3*1.3 -> 45.89 | D19: =B19*C19/100 -> 14.143298 | E19: =D19 -> 14.143298 | F19: =E19-$E$16 -> 3.263838
A20: WALS -10% | B20: 30.82 | C20: =35.3*0.9 -> 31.77 | D20: =B20*C20/100 -> 9.791514 | E20: =D20 -> 9.791514 | F20: =E20-$E$16 -> -1.087946
A21: WALS -15% | B21: 30.82 | C21: =35.3*0.85 -> 30.005 | D21: =B21*C21/100 -> 9.247541 | E21: =D21 -> 9.247541 | F21: =E21-$E$16 -> -1.631919
A24: ORIGINATOR ADJUSTMENT SENSITIVITY
A25: Originator Adj | B25: Base WAFF | C25: Adjusted WAFF | D25: Coverage | E25: CE Required | F25: CE Saving
A26: 1.15 | B26: 26.8 | C26: =B26*A26 -> 30.82 | D26: =C26*35.3/100 -> 10.87946 | E26: =D26 -> 10.87946 | F26: -
A27: 1.1 | B27: 26.8 | C27: =B27*A27 -> 29.48 | D27: =C27*35.3/100 -> 10.40644 | E27: =D27 -> 10.40644 | F27: =$E$26-E27 -> 0.47302
A28: 1.08 | B28: 26.8 | C28: =B28*A28 -> 28.944 | D28: =C28*35.3/100 -> 10.217232 | E28: =D28 -> 10.217232 | F28: =$E$26-E28 -> 0.662228
A29: 1.05 | B29: 26.8 | C29: =B29*A29 -> 28.14 | D29: =C29*35.3/100 -> 9.93342 | E29: =D29 -> 9.93342 | F29: =$E$26-E29 -> 0.94604

Sheet Optimization_Summary
A1: CAPITAL STRUCTURE OPTIMIZATION SUMMARY
A2: Actionable Recommendations Based on S&P Rating Feedback
A4: KEY FINDINGS
A5: Finding | B5: Impact | C5: Priority
A6: Excess AAA CE vs Peers | B6: +1.70% vs peer average | C6: High
A7: High Originator Adjustment (1.15x) | B7: +7% vs peer best (1.08x) | C7: High
A8: No General Reserve Fund | B8: -0.35% CE benefit foregone | C8: Medium
A9: High Prefunding (24.3%) | B9: Elevated WAFF adjustment | C9: Medium
A10: Shared Ownership Exposure (7.52%) | B10: Higher LTV adjustment | C10: Low
A11: Unfunded Initial Reserve | B11: Liquidity risk at close | C11: Low
A14: OPTIMIZATION RECOMMENDATIONS
A15: # | B15: Recommendation | C15: CE Impact | D15: Cost Impact | E15: Feasibility | F15: Timeline
A16: 1 | B16: Negotiate Originator Adjustment to 1.10x | C16: -0.40% CE | D16: Neutral | E16: High | F16: Pre-close
A17: 2 | B17: Reduce Prefunding to <20% | C17: -0.20% CE | D17: Neutral | E17: Medium | F17: Pre-close
A18: 3 | B18: Add 0.35% General Reserve Fund | C18: +0.35% CE Credit | D18: £1.5m upfront | E18: High | F18: Structural
A19: 4 | B19: Increase AAA Tranche to 89% | C19: Optimize WAC | D19: -5bps WAC | E19: High | F19: Structural
A20: 5 | B20: Reduce Shared Ownership to <5% | C20: -0.15% WAFF | D20: Pool selection | E20: Low | F20: Collateral
A21: 6 | B21: Fund Reserve at Close | C21: Reduce liquidity risk | D21: Timing only | E21: High | F21: Operational
A24: QUANTIFIED OPTIMIZATION BENEFITS
A25: Metric | B25: Current | C25: Optimized | D25: Benefit
A26: AAA Credit Enhancement | B26: 12.25% | C26: 10.50% | D26: -175 bps
A27: AAA Tranche Size | B27: 87.75% | C27: 89.50% | D27: +1.75%
A28: WAC Pre-Step (bps) | B28: ~120 | C28: ~115 | D28: -5 bps
A29: Annual Funding Cost (£m) | B29: ~19.5 | C29: ~19.0 | D29: -£0.5m
A30: Originator Adjustment | B30: 1.15x | C30: 1.10x | D30: -0.05x

Sheet Data_Tables
A1: REFERENCE DATA TABLES
A3: S&P RATING SCALE
A4: Rating | B4: Category | C4: Base FF Mult | D4: Notes
A5: AAA | B5: Prime | C5: 6.857 | D5: 12.0% / 1.75%
A6: AA+ | B6: High Grade | C6: 5.714
A7: AA | B7: High Grade | C7: 4.571
A8: AA- | B8: High Grade | C8: 3.857
A9: A+ | B9: Upper Medium | C9: 3.286
A10: A | B10: Upper Medium | C10: 2.857
A11: A- | B11: Upper Medium | C11: 2.571
A12: BBB+ | B12: Lower Medium | C12: 2.286
A13: BBB | B13: Lower Medium | C13: 2
A14: BBB- | B14: Lower Medium | C14: 1.714
A15: BB+ | B15: Non-Investment | C15: 1.429
A16: BB | B16: Non-Investment | C16: 1.143
A17: B | B17: Speculative | C17: 1 | D17: Base
A20: WAFF ADJUSTMENT FACTORS
A21: Factor | B21: Range | C21: Application | D21: Notes
A22: LTV | B22: 0.5x - 2.5x | C22: Per LTV bucket
A23: Income Multiple | B23: 1.0x - 1.3x | C23: LTI > 3.25x
A24: Buy-to-Let | B24: 1.25x - 1.7x | C24: By DSCR
A25: CCJ History | B25: 1.05x - 1.5x | C25: By count/age
A26: Payment Shock | B26: 1.1x - 1.2x | C26: Fixed to float
A27: Interest Only | B27: 1.02x - 1.05x | C27: OO only
A28: Self-Employed | B28: 1.03x - 1.05x | C28: OO only
A29: First Time Buyer | B29: 1.02x - 1.05x | C29: <18m seasoning
A30: Originator | B30: 1.00x - 1.30x | C30: Pool level
A31: Prefunding | B31: +0.05x | C31: Additional
