Workbook

Sheet Cascaded Summary
A1: CASCADED SUMMARY: STRUCTURAL VALUE DECOMPOSITION
A2: Actual Deal Pricing: A=73bps, B=90bps, C=120bps, D=155bps, E=209bps, F=383bps
A4: THE COMPLETE PICTURE
A5: Metric | B5: Old Deal | C5: New Deal | D5: Change | E5: Impact
A6: WACD | B6: =Calculations!B6 | C6: =Calculations!B7 | D6: =C7-B7 | E6: Client saves £/year
A7: Portfolio WAFF×WAL | B7: ='Input Data'!C14 | C7: ='Input Data'!C25 | D7: =C8-B8 | E7: Credit deterioration
A8: Number of Classes | B8: 7 | C8: 6 | D8: =-1 | E8: Structural simplification
A9: AAA Class Size | B9: ='Input Data'!C6 | C9: ='Input Data'!C18 | D9: =C10-B10 | E9: Senior sizing
A10: Total Subordination | B10: ='Input Data'!D6 | C10: ='Input Data'!D18 | D10: =C11-B11 | E10: CE requirements
A12: SCENARIO CASCADE ANALYSIS
A13: Scenario | B13: Description | C13: Credit Quality | D13: Pricing | E13: Structure | F13: WACD (bps) | G13: Δ Marginal | H13: Δ Cumulative
A14: 0: Baseline | B14: Old structure on old pool | C14: Old (10.04) | D14: Old | E14: Old (7 cls) | F14: =Calculations!F40 | G14: - | H14: -
A15: 1: Credit Δ | B15: Old CE Mult × New WAFF×WAL | C15: New (11.39) | D15: Old | E15: Old scaled | F15: =Calculations!F41 | G15: =Calculations!G41 | H15: =Calculations!H41
A16: 2: Credit+Pricing | B16: Scenario 1 with new pricing | C16: New (11.39) | D16: New | E16: Old scaled | F16: =Calculations!F42 | G16: =Calculations!G42 | H16: =Calculations!H42
A17: 3: Actual New | B17: Delivered optimized structure | C17: New (11.39) | D17: New | E17: New (6 cls) | F17: =Calculations!F43 | G17: =Calculations!G43 | H17: =Calculations!H43
A18: 4: Pure Structure | B18: New CE Mult × Old WAFF×WAL | C18: Old (10.04) | D18: Old | E18: New (6 cls) | F18: =Calculations!F44 | G18: =Calculations!G44 | H18: =Calculations!H44
A20: VALUE DECOMPOSITION
A21: Component | B21: Calculation | C21: Impact (bps) | D21: Type | E21: Interpretation
A22: Credit Deterioration | B22: Scenario 1 - Scenario 0 | C22: =Calculations!G41 | D22: Headwind | E22: Pool quality worsened 13.4%
A23: Pricing Tightening | B23: Scenario 2 - Scenario 1 | C23: =Calculations!G42 | D23: Tailwind | E23: Market spreads tightened significantly
A24: Structural Optimization | B24: Scenario 3 - Scenario 2 | C24: =Calculations!G43 | D24: Benefit | E24: 6-class optimization vs old approach
A25: Pure Design Innovation | B25: Scenario 4 - Scenario 0 | C25: =Calculations!G44 | D25: Innovation | E25: Design value independent of credit
A26: TOTAL NET CHANGE | B26: Scenario 3 - Scenario 0 | C26: =Calculations!H43 | D26: Result | E26: What client actually experiences
A28: KEY MESSAGES FOR SPONSOR
A29: 1. MARKET TIMING BENEFIT: Spreads tightened dramatically (≈10 bps) between the old and new deals - favorable market conditions
A30: 2. CREDIT MANAGEMENT: Despite 13.4% credit quality deterioration, we limited the cost impact to +1.63 bps through structural efficiency
A31: 3. STRUCTURAL OPTIMIZATION: Delivered additional 2.11 bps savings through 6-class design vs mechanical scaling approach
A32: 4. PURE INNOVATION VALUE: Our CE Multiple methodology would save 1.48 bps even on the old, better-quality pool
A33: 5. NET CLIENT BENEFIT: 10.64 bps lower cost = £41.6k annual savings on £391m collateral
A34: 6. VALUE ATTRIBUTION: Credit absorb (+1.63), Optimization (-2.11), Innovation (-1.48), Market timing (-10.16) = -10.64 bps total

Sheet Client Presentation
A1: VALUE DELIVERED TO SPONSOR
A2: Isolating Structural Innovation from Market and Credit Effects
A4: THE CHALLENGE
A5: Credit Quality Deteriorated: | B5: WAFF×WAL increased from 10.04 to 11.39 (+13.4%) | C5: Cost Impact: +1.63 bps
A6: Market Pricing Widened: | B6: Spreads widened across all ratings | C6: Cost Impact: +5.34 bps
A7: Combined Headwinds: | B7: Without intervention, cost would increase by 6.97 bps
A9: THE VALUE WE DELIVERED
A10: Component | B10: Description | C10: WACD (bps) | D10: Impact (bps) | E10: Value Type
A11: Baseline | B11: Old structure, old credit, old pricing | C11: =Calculations!F40 | D11: - | E11: Starting point
A12: Structural Innovation | B12: Pure value of new 6-class structure | C12: =Calculations!F44 | D12: =Calculations!G44 | E12: INNOVATION
A13: + Credit Impact | B13: Applied to actual deteriorated pool | C13: =Calculations!F41 | D13: =Calculations!G41-Calculations!G44 | E13: Market reality
A14: + Pricing Impact | B14: Applied new market spreads | C14: =Calculations!F42 | D14: =Calculations!G42 | E14: Market reality
A15: Total Cost Impact (before optimization) | B15: Net effect before optimization | C15: =Calculations!F42 | D15: =Calculations!H42 | E15: Combined headwind
A16: - Structural Optimization | B16: Efficiency gains vs. unoptimized | C16: =Calculations!F43 | D16: =Calculations!G43 | E16: YOUR BENEFIT
A17: ACTUAL FINAL COST | B17: What client actually pays | C17: =Calculations!F43 | D17: =Calculations!H43 | E17: Net result
A19: KEY TAKEAWAYS FOR SPONSOR
A20: 1. PURE STRUCTURAL VALUE: Our 6-class structure would save 1.27 bps even on your OLD, better-quality pool
A21: 2. CREDIT CHALLENGE ABSORBED: Your pool quality deteriorated 13%, yet we limited cost impact to +1.63 bps (vs +2.90 bps with old structure)
A22: 1. PURE STRUCTURAL VALUE: Our 6-class structure would save 1.48 bps even on your OLD, better-quality pool (uses actual old pool WAFF×WAL)
A23: 2. CREDIT CHALLENGE ABSORBED: Your pool quality deteriorated 13%, yet we limited cost impact through efficient CE Multiple design
A24: 3. MARKET HEADWINDS MITIGATED: Spreads widened +5.34 bps, but our optimization saved 2.34 bps of this impact
A25: 4. NET RESULT: Despite 6.97 bps of combined headwinds (credit + pricing), you're only paying 4.63 bps more
A26: 5. OUR VALUE: 2.34 bps direct savings + 1.48 bps structural innovation = 3.82 bps total value created
A28: NOTE: Scenario 4 uses actual old pool class-specific WAFF×WAL values (10.88, 6.23, 3.38, etc.) from the 7-class structure. This assumes class position drives WAFF×WAL characteristics.

Sheet Input Data
A1: RMBS Structural Efficiency Analysis
A2: CE Multiple Methodology: Interactive Effects Decomposition
A4: OLD STRUCTURE
A5: Class | B5: Rating | C5: % of Coll | D5: CE % | E5: £ Balance | F5: CE Multiple | G5: Margin | H5: WAFF×WAL | I5: Calc CE Mult | J5: Notes
A6: A | B6: AAA | C6: 0.8775 | D6: 0.1225 | E6: 342225000 | F6: 0.0113 | G6: 0.0082 | H6: 10.88 | I6: =D6/H6 | J6: =D6 / H6
A7: B | B7: AA | C7: 0.055 | D7: 0.0675 | E7: 21450000 | F7: 0.0108 | G7: 0.011 | H7: 6.23 | I7: =D7/H7 | J7: =D7 / H7
A8: C | B8: A | C8: 0.0325 | D8: 0.035 | E8: 12675000 | F8: 0.0104 | G8: 0.014 | H8: 3.38 | I8: =D8/H8 | J8: =D8 / H8
A9: D | B9: BBB | C9: 0.0175 | D9: 0.0175 | E9: 6825000 | F9: 0.0098 | G9: 0.0165 | H9: 1.78 | I9: =D9/H9 | J9: =D9 / H9
A10: E | B10: BB | C10: 0.0075 | D10: 0.01 | E10: 2925000 | F10: 0.0137 | G10: 0.0248 | H10: 0.73 | I10: =D10/H10 | J10: =D10 / H10
A11: F | B11: B | C11: 0.008 | D11: 0.002 | E11: 3120000 | F11: 0.0045 | G11: 0.0398 | H11: 0.44 | I11: =D11/H11 | J11: =D11 / H11
A12: G | B12: CCC | C12: 0.002 | D12: 0 | E12: 780000 | F12: - | G12: 0.0548 | H12: - | I12: - | J12: First Loss
A13: Total / Weighted Avg | C13: =SUM(C6:C12) | E13: =SUM(E6:E12)
A14: Portfolio WAFF×WAL | C14: =SUMPRODUCT(C6:C11,H6:H11) | J14: Σ(% Coll × WAFF×WAL)
A16: NEW STRUCTURE
A17: Class | B17: Rating | C17: % of Coll | D17: CE % | E17: £ Balance | F17: CE Multiple | G17: Margin | H17: WAFF×WAL | I17: Calc CE Mult | J17: Notes
A18: A | B18: AAA | C18: 0.8665 | D18: 0.1335 | E18: 338930000 | F18: 0.0107 | G18: 0.0073 | H18: 12.44 | I18: =D18/H18 | J18: =D18 / H18
A19: B | B19: AA | C19: 0.0535 | D19: 0.08 | E19: 20926000 | F19: 0.0111 | G19: 0.009 | H19: 7.21 | I19: =D19/H19 | J19: =D19 / H19
A20: C | B20: A | C20: 0.044 | D20: 0.036 | E20: 17211000 | F20: 0.009 | G20: 0.012 | H20: 3.99 | I20: =D20/H20 | J20: =D20 / H20
A21: D | B21: BBB | C21: 0.018 | D21: 0.018 | E21: 7041000 | F21: 0.0085 | G21: 0.0155 | H21: 2.13 | I21: =D21/H21 | J21: =D21 / H21
A22: E | B22: BB | C22: 0.012 | D22: 0.006 | E22: 4694000 | F22: 0.0068 | G22: 0.0209 | H22: 0.88 | I22: =D22/H22 | J22: =D22 / H22
A23: F | B23: B | C23: 0.006 | D23: 0 | E23: 2347000 | F23: - | G23: 0.0383 | H23: 0.54 | I23: =D23/H23 | J23: =D23 / H23
A24: Total / Weighted Avg | C24: =SUM(C18:C23) | E24: =SUM(E18:E23)
A25: Portfolio WAFF×WAL | C25: =SUMPRODUCT(C18:C23,H18:H23) | J25: Σ(% Coll × WAFF×WAL)
A26: Risk Ratio (New/Old) | C26: =C25/C14 | J26: New Portfolio Risk / Old Portfolio Risk

Sheet Calculations
A1: INTERACTIVE EFFECTS CALCULATIONS
A2: Using CE Multiple Methodology with Actual Class-Specific WAFF×WAL Values
A4: 1. WEIGHTED AVERAGE COST OF DEBT (WACD)
A5: Structure | B5: WACD (bps) | C5: Formula
A6: Old Structure | B6: =SUMPRODUCT('Input Data'!C6:C12,'Input Data'!G6:G12)*10000 | C6: SUMPRODUCT(% of Coll, Margin) × 10000
A7: New Structure | B7: =SUMPRODUCT('Input Data'!C18:C23,'Input Data'!G18:G23)*10000 | C7: SUMPRODUCT(% of Coll, Margin) × 10000
A8: Raw Difference | B8: =B7-B6
A10: 2. PORTFOLIO RISK METRICS
A11: Metric | B11: Old Structure | C11: New Structure | D11: Risk Ratio | E11: Formula
A12: Portfolio WAFF×WAL | B12: ='Input Data'!C14 | C12: ='Input Data'!C25 | D12: ='Input Data'!C26 | E12: New / Old
A14: 3. SCENARIO 1: CREDIT QUALITY IMPACT (CE Multiple Methodology)
A15: Approach: Apply Old Structure CE Multiples to New Pool's Actual Class-Specific WAFF×WAL
A16: Class | B16: Old CE Multiple | C16: New Class WAFF×WAL | D16: Required CE | E16: Class Size | F16: Old Margin | G16: Contribution | H16: Formula CE | I16: Formula Size
A17: A | B17: ='Input Data'!I6 | C17: ='Input Data'!H18 | D17: =B17*C17 | E17: =1-D17 | F17: ='Input Data'!G6 | G17: =E17*F17*10000 | H17: =B17*C17 | I17: =1-D17
A18: B | B18: ='Input Data'!I7 | C18: ='Input Data'!H19 | D18: =B18*C18 | E18: =D17-D18 | F18: ='Input Data'!G7 | G18: =E18*F18*10000 | H18: =B18*C18 | I18: =D17-D18
A19: C | B19: ='Input Data'!I8 | C19: ='Input Data'!H20 | D19: =B19*C19 | E19: =D18-D19 | F19: ='Input Data'!G8 | G19: =E19*F19*10000 | H19: =B19*C19 | I19: =D18-D19
A20: D | B20: ='Input Data'!I9 | C20: ='Input Data'!H21 | D20: =B20*C20 | E20: =D19-D20 | F20: ='Input Data'!G9 | G20: =E20*F20*10000 | H20: =B20*C20 | I20: =D19-D20
A21: E | B21: ='Input Data'!I10 | C21: ='Input Data'!H22 | D21: =B21*C21 | E21: =D20-D21 | F21: ='Input Data'!G10 | G21: =E21*F21*10000 | H21: =B21*C21 | I21: =D20-D21
A22: F | B22: ='Input Data'!I11 | C22: ='Input Data'!H23 | D22: =B22*C22 | E22: =D21-D22 | F22: ='Input Data'!G11 | G22: =E22*F22*10000 | H22: =B22*C22 | I22: =D21-D22
A23: G | B23: ='Input Data'!I12 | C23: 0.00 | D23: 0.00% | E23: =D22 | F23: ='Input Data'!G12 | G23: =E23*F23*10000 | H23: N/A - First Loss | I23: =D22-D23
A24: TOTAL | E24: =SUM(E17:E23) | G24: =SUM(G17:G23)
A26: 4. SCENARIO 2: CREDIT + PRICING IMPACT
A27: Approach: Apply New Market Pricing to Scenario 1 Structure
A28: Class | B28: Scenario 1 Size | C28: New Margin | D28: Contribution | E28: Formula
A29: A | B29: =E17 | C29: ='Input Data'!G18 | D29: =B29*C29*10000 | E29: =B29*C29*10000
A30: B | B30: =E18 | C30: ='Input Data'!G19 | D30: =B30*C30*10000 | E30: =B30*C30*10000
A31: C | B31: =E19 | C31: ='Input Data'!G20 | D31: =B31*C31*10000 | E31: =B31*C31*10000
A32: D | B32: =E20 | C32: ='Input Data'!G21 | D32: =B32*C32*10000 | E32: =B32*C32*10000
A33: E | B33: =E21 | C33: ='Input Data'!G22 | D33: =B33*C33*10000 | E33: =B33*C33*10000
A34: F | B34: =E22 | C34: ='Input Data'!G23 | D34: =B34*C34*10000 | E34: =B34*C34*10000
A35: G | B35: =E23 | C35: 0.065 | D35: =B35*C35*10000 | E35: =B35*C35*10000
A36: TOTAL | B36: =SUM(B29:B35) | D36: =SUM(D29:D35)
A38: 5. SCENARIO CASCADE SUMMARY
A39: Scenario | B39: Description | C39: Credit | D39: Pricing | E39: Structure | F39: WACD (bps) | G39: Δ Marginal | H39: Δ Cumulative
A40: 0: Baseline | B40: Old structure, old credit, old pricing | C40: Old | D40: Old | E40: Old (7 classes) | F40: =B6 | G40: - | H40: -
A41: 1: Credit Δ | B41: Old CE Multiples × New Class WAFF×WAL, old pricing | C41: New | D41: Old | E41: Old (7 cls scaled) | F41: =G24 | G41: =F41-F40 | H41: =F41-F40
A42: 2: Credit+Pricing Δ | B42: Scenario 1 structure with new market pricing | C42: New | D42: New | E42: Old (7 cls scaled) | F42: =D36 | G42: =F42-F41 | H42: =F42-F40
A43: 3: Actual New | B43: Actual new structure (optimized, 6 classes) | C43: New | D43: New | E43: New (6 classes) | F43: =B7 | G43: =F43-F42 | H43: =F43-F40
A44: 4: Pure Structure | B44: New structure applied to OLD credit (hypothetical) | C44: Old | D44: Old | E44: New (6 cls) | F44: =G66 | G44: =F44-F40 | H44: =F44-F40
A57: SCENARIO 4: PURE STRUCTURAL VALUE (Hypothetical)
...

Sheet CE Multiple Analysis
A1: CE MULTIPLE EFFICIENCY ANALYSIS
A2: Quantifying Structural Optimization by Rating Level
A4: CE Multiple Comparison
A5: Class | B5: Rating | C5: Old CE Mult | D5: New CE Mult | E5: Efficiency Gain | F5: Scen1 Req CE | G5: Actual New CE | H5: Subord. Saved (pp) | I5: Interpretation
A6: A | B6: ='Input Data'!B18 | C6: ='Input Data'!I6 | D6: ='Input Data'!I18 | E6: =C6-D6 | F6: =Calculations!D17 | G6: ='Input Data'!D18 | H6: =F6-G6 | I6: 0.66pp less CE needed
A7: B | B7: ='Input Data'!B19 | C7: ='Input Data'!I7 | D7: ='Input Data'!I19 | E7: =C7-D7 | F7: =Calculations!D18 | G7: ='Input Data'!D19 | H7: =F7-G7 | I7: Slight increase (0.13pp)
A8: C | B8: ='Input Data'!B20 | C8: ='Input Data'!I8 | D8: ='Input Data'!I20 | E8: =C8-D8 | F8: =Calculations!D19 | G8: ='Input Data'!D20 | H8: =F8-G8 | I8: 0.37pp efficiency gain
A9: D | B9: ='Input Data'!B21 | C9: ='Input Data'!I9 | D9: ='Input Data'!I21 | E9: =C9-D9 | F9: =Calculations!D20 | G9: ='Input Data'!D21 | H9: =F9-G9 | I9: 0.20pp saved
A10: E | B10: ='Input Data'!B22 | C10: ='Input Data'!I10 | D10: ='Input Data'!I22 | E10: =C10-D10 | F10: =Calculations!D21 | G10: ='Input Data'!D22 | H10: =F10-G10 | I10: 0.54pp major saving
A11: F | B11: ='Input Data'!B23 | C11: ='Input Data'!I11 | D11: ='Input Data'!I23 | E11: =C11-D11 | F11: =Calculations!D22 | G11: ='Input Data'!D23 | H11: =F11-G11 | I11: 100% efficiency - eliminated
A12: TOTAL SUBORDINATION SAVED | F12: =SUM(F6:F11) | G12: =SUM(G6:G11) | H12: =SUM(H6:H11) | I12: Net structural efficiency
A14: Note on Class F:
A15: Class F achieved 100% efficiency gain (completely eliminated). CE Multiple went from 0.45% to 0.00%. Absolute subordination saved: 0.25pp.
A16: 1. Total subordination saved: Sum of (Required CE - Actual CE) across all classes
A17: Key Metrics Explained:
A18: • Efficiency Gain (Column E): Change in CE Multiple = Old CE Mult - New CE Mult (in percentage points)
A19: • Subordination Saved (Column H): Actual CE saved = Required CE (Scenario 1) - Actual CE (New Structure) in pp
A20: • Class F: 100% efficiency (eliminated entirely), saving 0.25pp of absolute subordination
A21: • Total 2.14pp saved: Cumulative structural efficiency across capital structure = cost saving driver

Sheet Summary
A1: EXECUTIVE SUMMARY
A3: Decomposition of Cost Change
A4: Component | B4: Impact (bps) | C4: % of Total Δ | D4: Cumulative (bps) | E4: Formula
A5: Baseline (Old Structure) | B5: =Calculations!F40 | C5: - | D5: =B5 | E5: Old WACD
A6: Credit Quality Deterioration | B6: =Calculations!G41 | C6: =B6/B9 | D6: =B5+B6 | E6: Scen1 - Scen0
A7: Market Pricing Widening | B7: =Calculations!G42 | C7: =B7/B9 | D7: =D6+B7 | E7: Scen2 - Scen1
A8: Structural Optimization | B8: =Calculations!G43 | C8: =B8/B9 | D8: =D7+B8 | E8: Scen3 - Scen2
A9: Total Change | B9: =Calculations!H43 | C9: 100.0% | D9: =Calculations!F43 | E9: New - Old WACD
A11: Monetary Value of Structural Optimization
A12: Structural Saving (bps) | B12: =ABS(B8) | E12: =ABS(B8)
A13: New Structure Collateral (£) | B13: ='Input Data'!E24 | E13: Total new collateral
A14: Annual Saving (£) | B14: =B13*(B12/10000) | E14: Collateral × bps / 10000
