Workbook

Sheet Control Panel
A1: S&P WAFF/WALS MODEL - CONTROL PANEL
A2: Version 2.0 - Complete S&P Exclusion Logic | Rating-Driven | BoE Field Mapping
A3: Created: 14-Jan-2026 11:40
A5: MODEL SETTINGS | E5: POOL STATISTICS
A6: Jurisdiction | B6: UK | C6: Select: UK, Ireland, or Netherlands
A7: Parameter | B7: Value | C7: Description | E7: Metric | F7: Value | G7: Note
A8: Target Rating Level | B8: AAA | C8: Drives Base FF, MVD, FSD, Stress Multiple | E8: Loan Count | F8: =COUNTA('Loan Tape (S&P)'!A:A)-1 | G8: After BoE conversion
A9: Analysis Date | B9: 46036.487 | C9: For seasoning and CCJ age calculations | E9: Total Balance | F9: =SUM('Loan Tape (S&P)'!B:B) | G9: £ millions
A10: Portfolio Cutoff Date | B10: 46036.487 | C10: Loan tape as-of date | E10: Avg S&P LTV | F10: =AVERAGE('FF Calculations'!E:E) | G10: Pool average
A11: OLTV Weight | B11: 0.8 | C11: S&P LTV: OLTV weight (typically 80%) | E11: Pool WAFF (%) | F11: =SUMPRODUCT('FF Calculations'!Z5:Z104,'FF Calculations'!B5:B104)/SUM('FF Calculations'!B5:B104) | G11: Balance-weighted FF
A12: CLTV Weight | B12: =VLOOKUP($B$6,'Jurisdiction Parameters'!$A:$B,2,FALSE) | C12: S&P LTV: CLTV weight (typically 20%)
A13: Originator Adjustment | B13: =VLOOKUP($B$6,'Jurisdiction Parameters'!$A:$C,3,FALSE) | C13: Global originator quality (0.70-1.30)
A15: RATING-DRIVEN PARAMETERS (AUTO) | E15: QUICK START GUIDE
A17: Parameter | B17: Value | C17: Source | E17: 1. Input loan data in Loan Tape (BoE) using Bank of England codes
A18: Base FF (%) | B18: =VLOOKUP($B$8,'Rating Parameters'!$A$6:$C$17,2,FALSE) | C18: From Rating Parameters | E18: 2. Data auto-converts to Loan Tape (S&P) format
A19: MVD (%) | B19: =VLOOKUP($B$8,'Rating Parameters'!$A$6:$C$17,3,FALSE) | C19: Market Value Decline | E19: 3. Select target rating level above (drives FF/MVD/FSD)
A20: FSD (%) | B20: =VLOOKUP($B$8,'Rating Parameters'!$A$6:$D$17,4,FALSE) | C20: Forced Sale Discount | E20: 4. Set originator adjustment (0.70-1.30, default 1.00)
A21: Stress Multiple | B21: =VLOOKUP($B$8,'Rating Parameters'!$F$6:$G$17,2,FALSE) | C21: For CE calculation | E21: 5. Review FF Calculations for loan-level results
E22: 6. Check Pool WAFF in statistics panel
E24: CRITICAL NOTES:
E25: • BTL identified from BV27 (Occupancy), not BV29 (Payment Method)
E26: • All S&P exclusion rules automatically applied
E27: • Joint borrower logic uses minimum of joint vs individual
E28: • Self-cert vs income: uses higher (not both)

Sheet BoE Auto-Mapper
A1: BOE AUTO-MAPPER CONFIGURATION
A2: This sheet defines the mapping from Bank of England PRA110 codes to S&P format fields
A4: BoE Code | B4: BoE Description | C4: S&P Column | D4: S&P Field Name | E4: Data Type | F4: Conversion Rule
A5: BV1 | B5: Loan Identifier | C5: A | D5: Loan Identifier | E5: Text | F5: Direct
A6: BV5 | B6: Current Balance | C6: M | D6: Current Balance | E6: Number | F6: Direct
A7: BV6 | B7: Original Balance | C7: D | D7: Original Balance | E7: Number | F7: Direct
A8: BV7 | B8: Current Property Value | C8: F | D8: Current Property Value | E8: Number | F8: Direct
A9: BV8 | B9: Original Property Value | C9: E | D9: Original Property Value | E9: Number | F9: Direct
A10: BV10 | B10: Origination Date | C10: K | D10: Origination Date | E10: Date | F10: Direct
A11: BV11 | B11: Maturity Date | C11: L | D11: Maturity Date | E11: Date | F11: Direct
A12: BV12 | B12: Property Type | C12: B | D12: Property Type | E12: Text | F12: 1=House,2=Flat,3=Bungalow,4=Maisonette
A13: BV15 | B13: Interest Rate | C13: O | D13: Interest Rate | E13: Percentage | F13: Direct
A14: BV25 | B14: Interest Rate Type | C14: AS | D14: Interest Rate Type | E14: Text | F14: 1=Fixed,2=Variable,3=Tracker
A15: BV27 | B15: Occupancy Status | C15: N | D15: Occupancy Status | E15: Text | F15: 1=Owner Occupied,2=Buy to Let,3=Second Home
... A19: BV50 | B19: Last 90+ Days Date | C19: AR | D19: Last 90+ Days Date | E19: Date | F19: Direct

Sheet Loan Tape (BoE Raw)
A1: LOAN TAPE INPUT - BANK OF ENGLAND FORMAT (PRA110)
A2: INSTRUCTIONS FOR USE:
A3: 1. Paste your Bank of England PRA110 loan tape below (starting at row 5)
A4: 2. Keep the BoE field codes in the header row (BV1, BV5, BV27, etc.)
A5: 3. The tape can be in ANY column order - the mapper will find the fields automatically
A6: 4. After pasting, click the "Map BoE Fields" button (if VBA macro is installed)
A7: 5. Data will automatically populate in the "Loan Tape (S&P)" sheet
A9: NOTES:
A10: • Do NOT delete or modify the BoE field codes in your headers
A11: • Dates should be in a recognizable format (DD/MM/YYYY or Excel date serial)
A12: • Numeric codes will be automatically converted to text descriptions
A13: • Empty cells are allowed for optional fields
A16: BV1 (Loan ID) | B16: BV5 (Balance) | C16: BV12 (Property Type) | D16: BV27 (Occupancy) | E16: BV29 (Payment) | F16: BV25 (Rate Type) | G16: BV48 (Perf Arr) | H16: BV49 (Perf Date) | I16: BV50 (Last 90+ Date) | J16: ...more BoE fields...
A17: [Paste your loan tape starting here - replace this sample data]

Sheet Jurisdiction Parameters
A1: JURISDICTION-SPECIFIC PARAMETERS
A2: All jurisdiction-specific values - Model references this sheet dynamically
A4: Jurisdiction | B4: OLTV Weight | C4: CLTV Weight | D4: Valuation Haircut | E4: Interest Cost (BTL) | F4: Seasoning Periods | G4: Income Mult Threshold 1 | H4: Income Mult Threshold 2 | I4: Income Mult Joint Threshold 1 | J4: Income Mult Joint Threshold 2 | K4: Arrears 1mo Mult | L4: Arrears 2mo Mult | M4: Arrears 3mo Mult | N4: Foreclosure Cost % | O4: LTV Curve Reference | P4: Regional Adj Enabled | Q4: Reperform Threshold (Years)
A5: UK | B5: 0.8 | C5: 0.2 | D5: 0.05 | E5: 0.055 | F5: 18 | G5: 5 | H5: 3.5 | I5: 3.25 | J5: 2.75 | K5: 2.5 | L5: 5 | M5: 100 | N5: 0.08 | O5: LTV Curve UK | P5: Yes | Q5: 3
A6: Ireland | B6: 0.75 | C6: 0.25 | D6: 0.07 | E6: 0.06 | F6: 24 | G6: 4.5 | H6: 3 | I6: 3 | J6: 2.5 | K6: 3 | L6: 6 | M6: 100 | N6: 0.1 | O6: LTV Curve Ireland | P6: Yes | Q6: 3
A7: Netherlands | B7: 0.8 | C7: 0.2 | D7: 0.04 | E7: 0.05 | F7: 12 | G7: 6 | H7: 4 | I7: 4 | J7: 3 | K7: 2 | L7: 4 | M7: 100 | N7: 0.07 | O7: LTV Curve Netherlands | P7: No | Q7: 3

Sheet Rating Parameters
A1: RATING-DRIVEN PARAMETERS
A3: All parameters that vary by target rating level
A5: Rating | B5: Base FF (%) | C5: MVD (%) | D5: FSD (%) | E5: Source | F5: Rating | G5: Stress Multiple
A6: AAA | B6: 0.12 | C6: 0.45 | D6: 0.15 | E6: Table 72 / S&P MVD assumptions | F6: AAA | G6: 14
A7: AA+ | B7: 0.105 | C7: 0.42 | D7: 0.14 | E7: Interpolated | F7: AA+ | G7: 12
A8: AA | B8: 0.08 | C8: 0.4 | D8: 0.13 | E8: Table 72 | F8: AA | G8: 10.5
A9: AA- | B9: 0.07 | C9: 0.37 | D9: 0.12 | E9: Interpolated | F9: AA- | G9: 9
A10: A+ | B10: 0.065 | C10: 0.34 | D10: 0.11 | E10: Interpolated | F10: A+ | G10: 7.5
A11: A | B11: 0.06 | C11: 0.32 | D11: 0.1 | E11: Table 72 | F11: A | G11: 6.5
A12: A- | B12: 0.055 | C12: 0.3 | D12: 0.1 | E12: Interpolated | F12: A- | G12: 5.5
A13: BBB+ | B13: 0.05 | C13: 0.27 | D13: 0.09 | E13: Interpolated | F13: BBB+ | G13: 4.5
A14: BBB | B14: 0.04 | C14: 0.25 | D14: 0.08 | E14: Table 72 | F14: BBB | G14: 4
A15: BBB- | B15: 0.035 | C15: 0.22 | D15: 0.08 | E15: Interpolated | F15: BBB- | G15: 3.5
A16: BB | B16: 0.02 | C16: 0.2 | D16: 0.07 | E16: Table 72 | F16: BB | G16: 3
A17: B | B17: 0.015 | C17: 0.18 | D17: 0.07 | E17: Table 72 | F17: B | G17: 2.5

Sheet LTV Curve
A1: S&P UK LTV CURVE - TYPE 2 FULL RECOURSE (131 Points)
A3: LTV % | B3: FF Multiplier | C3: Named Range | D3: Notes
A4: 0.2 | B4: 0.2889 | C4: LTV_20 | D4: Minimum LTV in curve
A5: 0.21 | B5: 0.2907 | C5: LTV_21
A6: 0.22 | B6: 0.2925 | C6: LTV_22
A7: 0.23 | B7: 0.2945 | C7: LTV_23
A8: 0.24 | B8: 0.2966 | C8: LTV_24
A9: 0.25 | B9: 0.2988 | C9: LTV_25
A10: 0.26 | B10: 0.3011 | C10: LTV_26
A11: 0.27 | B11: 0.3037 | C11: LTV_27
A12: 0.28 | B12: 0.3063 | C12: LTV_28
A13: 0.29 | B13: 0.3092 | C13: LTV_29
A14: 0.3 | B14: 0.3122 | C14: LTV_30
A15: 0.31 | B15: 0.3155 | C15: LTV_31
A16: 0.32 | B16: 0.3189 | C16: LTV_32
... A53: 0.69 | B53: 0.8368 | C53: LTV_69
A54: 0.7 | B54: 0.8739 | C54: LTV_70 | D54: Archetypal (1.0x multiplier at 73% per curve)
A55: 0.71 | B55: 0.9134 | C55: LTV_71
A56: 0.72 | B56: 0.9553 | C56: LTV_72
A57: 0.73 | B57: 1 | C57: LTV_73
A58: 0.74 | B58: 1.0475 | C58: LTV_74
A59: 0.75 | B59: 1.098 | C59: LTV_75
A60: 0.76 | B60: 1.1518 | C60: LTV_76
A61: 0.77 | B61: 1.2089 | C61: LTV_77
A62: 0.78 | B62: 1.2696 | C62: LTV_78
A63: 0.79 | B63: 1.3341 | C63: LTV_79
A64: 0.8 | B64: 1.4025 | C64: LTV_80
A65: 0.81 | B65: 1.4751 | C65: LTV_81
A66: 0.82 | B66: 1.552 | C66: LTV_82
... A133: 1.49 | B133: 4.02 | C133: LTV_149
A134: 1.5 | B134: 4.02 | C134: LTV_150 | D134: Maximum LTV (cap at 4.02x)

Sheet FF Adj Parameters
A1: FF ADJUSTMENT PARAMETERS - COMPLETE LOOKUP TABLES
A3: SEASONING ADJUSTMENTS
A4: Threshold (Years)
A5: 5 | B5: 1 | C5: <5 years - No credit
A6: 6 | B6: 0.75 | C6: 5-6 years - 25% credit
A7: 7 | B7: 0.7 | C7: 6-7 years - 30% credit
A8: 8 | B8: 0.65 | C8: 7-8 years - 35% credit
A9: 9 | B9: 0.6 | C9: 8-9 years - 40% credit
A10: 10
A11: 999 | B11: 0.5 | C11: >10 years - 50% credit
A13: INCOME MULTIPLE ADJUSTMENTS
A14: Threshold | B14: Multiplier | C14: Description
A15: 3.5 | B15: 1 | C15: ≤3.5 single or ≤2.75 joint
A16: 5 | B16: 1.2 | C16: >3.5 to 5.0 single or >2.75 to 3.25 joint
A17: 999 | B17: 1.5 | C17: >5.0 single or >3.25 joint
A19: BTL DSCR ADJUSTMENTS
A20: DSCR Threshold | B20: Multiplier | C20: Description
A21: 0 | B21: 1.7 | C21: No rental income
A22: 1 | B22: 1.55 | C22: <1.00 - Inadequate
A23: 1.2 | B23: 1.45 | C23: 1.00-1.20 - Minimal
A24: 1.35
A25: 999 | B25: 1.25 | C25: ≥1.35 - Strong
A27: INTEREST ONLY ADJUSTMENTS (NON-BTL)
A28: Years to Maturity | B28: Multiplier | C28: Description
A29: 5 | B29: 1.25 | C29: <5 years
A30: 15
A31: 25 | B31: 1.2 | C31: 15-25 years
A32: 999 | B32: 1.1 | C32: >25 years
A34: FIXED ADJUSTMENT MULTIPLIERS
A35: Adjustment Type | B35: Multiplier | C35: Notes
A36: First Time Buyer | B36: 1.1 | C36: If seasoning <18 months
A37: Help to Buy | B37: 1 | C37: No adjustment per S&P
A38: Shared Ownership | B38: 1.15 | C38: Complexity premium
A39: Right to Buy | B39: 1.2 | C39: Discount unwind risk
A40: Self-Certification
A41: Payment Shock | B41: 1.1 | C41: Fixed rate <60mo to maturity
A42: Self-Employed | B42: 1.15 | C42: Income stability risk
A43: Commercial Property | B43: 1.85 | C43: Commercial use risk
A44: CCJ | B44: 1.3 | C44: County Court Judgment
A45: Bankruptcy | B45: 4 | C45: Floor at 0.50
...

Sheet LS Parameters
A1: LOSS SEVERITY ADJUSTMENT PARAMETERS
A2: S&P Table 78 & 79: Property Type and Regional Adjustments for MVD
A4: PROPERTY TYPE MVD ADJUSTMENTS (S&P Table 78)
A5: Property Type | B5: MVD Adjustment | C5: Notes
A6: House | B6: 0 | C6: Baseline - no adjustment
A7: Flat | B7: 0.05 | C7: +5% MVD for flats (higher volatility)
A8: Bungalow | B8: -0.02 | C8: -2% MVD for bungalows (stable)
A9: Maisonette | B9: 0.03 | C9: +3% MVD for maisonettes
A10: Other | B10: 0.05 | C10: +5% MVD for other property types
A12: REGIONAL MVD ADJUSTMENTS (S&P Table 79 - Optional)
A13: Region | B13: MVD Adjustment | C13: Notes
A14: London | B14: -0.03 | C14: -3% MVD (more liquid market)
A15: South East | B15: -0.02 | C15: -2% MVD
A16: East | B16: -0.01 | C16: -1% MVD
A17: South West | B17: 0 | C17: Baseline
A18: West Midlands | B18: 0.01 | C18: +1% MVD
A19: East Midlands | B19: 0.01 | C19: +1% MVD
A20: North West | B20: 0.02 | C20: +2% MVD
A21: Yorkshire | B21: 0.02 | C21: +2% MVD
A22: North East | B22: 0.03 | C22: +3% MVD (less liquid)
A23: Wales | B23: 0.02 | C23: +2% MVD
A24: Scotland | B24: 0.01 | C24: +1% MVD
A25: Northern Ireland | B25: 0.03 | C25: +3% MVD
A28: FORECLOSURE COSTS
A29: Cost Component | B29: % of Property Value | C29: Notes
A30: Legal & Professional Fees | B30: 0.03 | C30: Solicitors, surveyors, court costs
A31: Maintenance & Repairs | B31: 0.02 | C31: Property upkeep during foreclosure
A32: Sales Costs | B32: 0.02 | C32: Estate agent, marketing
A33: Holding Costs | B33: 0.01 | C33: Utilities, insurance, security
A34: TOTAL Foreclosure Costs | B34: 0.08 | C34: Sum of all components

Sheet BoE Mapping
A1: BANK OF ENGLAND TO S&P FIELD MAPPING & CONVERSION
A2: Complete PRA110 field mapping with conversion formulas
A4: BoE Code | B4: BoE Field Name | C4: BoE Value/Code | D4: S&P Field | E4: S&P Value | F4: Conversion Formula
A5: BV1 | B5: Loan Identifier | C5: Direct | D5: loan_id | E5: Same | F5: =BoE!A[row]
F6: ='Loan Tape (BoE)'!A5
A7: BV5 | B7: Current Loan Balance | C7: Direct | D7: current_balance | E7: Same | F7: =BoE!B[row]
A8: BV6 | B8: Original Balance | C8: Direct | D8: original_balance | E8: Same | F8: ='Loan Tape (BoE)'!B5
A9: BV7 | B9: Current Property Value | C9: Direct | D9: property_value_current | E9: Indexed | F9: ='Loan Tape (BoE)'!C5
A10: BV8 | B10: Original Property Value | C10: Direct | D10: property_value_original | E10: Same | F10: ='Loan Tape (BoE)'!D5*(1+regional_HPI_factor)
F11: ='Loan Tape (BoE)'!E5
A12: BV11 | B12: Origination Date | C12: Direct | D12: origination_date | E12: Same | F12: =BoE!F[row]
A13: BV12 | B13: Maturity Date | C13: Direct | D13: maturity_date | E13: Same | F13: =BoE!G[row]
F14: ='Loan Tape (BoE)'!F5
A15: BV13 | B15: Current Interest Rate | C15: Direct | D15: interest_rate | E15: Same | F15: ='Loan Tape (BoE)'!G5
A17: BV22 | B17: Property Type | C17: 1 | D17: property_type | E17: House | F17: =IFS(BoE!I[row]=1,"House",BoE!I[row]=2,"Flat",BoE!I[row]=3,"Bungalow",BoE!I[row]=4,"Maisonette")
A18: BV22 | B18: Property Type | C18: 2 | D18: property_type | E18: Flat | F18: ='Loan Tape (BoE)'!H5
A19: BV22 | B19: Property Type | C19: 3 | D19: property_type | E19: Bungalow
A20: BV22 | B20: Property Type | C20: 4 | D20: property_type | E20: Maisonette
F21: =IFS(I5=1,"House",I5=2,"Flat",I5=3,"Bungalow",I5=4,"Maisonette")
A22: BV23 | B22: Region | C22: Direct | D22: region | E22: Same | F22: =BoE!J[row]
A23: BV24 | B23: Postcode | C23: Direct | D23: postcode | E23: Same | F23: =BoE!K[row]
A25: BV27 | B25: Occupancy Status | C25: 1 | D25: occupancy_type | E25: Owner Occupied | F25: =IFS(BoE!L[row]=1,"Owner Occupied",BoE!L[row]=2,"BTL",BoE!L[row]=3,"Second Home",BoE!L[row]=4,"Investment")
A26: BV27 | B26: Occupancy Status | C26: 2 | D26: occupancy_type | E26: BTL | F26: ='Loan Tape (BoE)'!J5
A27: BV27 | B27: Occupancy Status | C27: 3 | D27: occupancy_type | E27: Second Home | F27: ='Loan Tape (BoE)'!K5
A28: BV27 | B28: Occupancy Status | C28: 4 | D28: occupancy_type | E28: Investment
A30: BV28 | B30: Loan Purpose | C30: 1 | D30: loan_purpose | E30: Purchase | F30: =IFS(BoE!M[row]=1,"Purchase",BoE!M[row]=2,"Remortgage",OR(BoE!M[row]=3,BoE!M[row]=4),"Cash-out")
A31: BV28 | B31: Loan Purpose | C31: 2 | D31: loan_purpose | E31: Remortgage | F31: =IFS(L5=1,"Owner Occupied",L5=2,"BTL",L5=3,"Second Home",L5=4,"Investment")
A32: BV28 | B32: Loan Purpose | C32: 3 | D32: loan_purpose | E32: Cash-out | F32: Further advance
A33: BV28 | B33: Loan Purpose | C33: 4 | D33: loan_purpose | E33: Cash-out | F33: Debt consolidation
A35: BV29 | B35: Payment Method | C35: 1 | D35: product_type | E35: Repayment | F35: =IFS(BoE!N[row]=1,"Repayment",BoE!N[row]=2,"Interest Only",BoE!N[row]=3,"Part & Part")
A36: BV29 | B36: Payment Method | C36: 2 | D36: product_type | E36: Interest Only | F36: =IFS(M5=1,"Purchase",M5=2,"Remortgage",OR(M5=3,M5=4),"Cash-out")
A37: BV29 | B37: Payment Method | C37: 3 | D37: product_type | E37: Part & Part | F37: Mixed repayment/IO
A39: BV33 | B39: Right to Buy | C39: 1 | D39: right_to_buy_flag | E39: Yes | F39: =IF(BoE!O[row]=1,"Yes","No")
A40: BV33 | B40: Right to Buy | C40: 2 | D40: right_to_buy_flag | E40: No
F41: =IFS(N5=1,"Repayment",N5=2,"Interest Only",N5=3,"Part & Part")
A42: BV34 | B42: Shared Ownership | C42: 1 | D42: shared_ownership_flag | E42: Yes | F42: =IF(BoE!P[row]=1,"Yes","No")
A43: BV34 | B43: Shared Ownership | C43: 2 | D43: shared_ownership_flag | E43: No | F43: LTV uses mortgage portion only
A45: BV35 | B45: Help to Buy | C45: 1 | D45: help_to_buy_flag | E45: Yes | F45: =IF(BoE!Q[row]=1,"Yes","No")
A46: BV35 | B46: Help to Buy | C46: 2 | D46: help_to_buy_flag | E46: No | F46: Excludes FTB & payment shock adj
A48: BV40 | B48: Borrower 1 Income | C48: Direct | D48: borrower1_income | E48: Same | F48: =BoE!R[row]
...

Sheet Loan Tape (BoE)
A1: LOAN TAPE - BANK OF ENGLAND PRA110 FORMAT (INPUT SHEET)
A2: Enter loan data in yellow cells using Bank of England field codes and values
A4: BV1 | B4: BV5 | C4: BV6 | D4: BV7 | E4: BV8 | F4: BV11 | G4: BV12 | H4: BV13 | I4: BV22 | J4: BV23 | K4: BV24 | L4: BV27 | M4: BV28 | N4: BV29 | O4: BV33 | P4: BV34 | Q4: BV35 | R4: BV40 | S4: BV41 | T4: BV42 | U4: BV45 | V4: BV46 | W4: BV50 | X4: BV51 | Y4: BV55 | Z4: BV56 | AA4: BV57 | AB4: BV58 | AC4: BV59 | AD4: BV60 | AE4: BV61 | AF4: BV65 | AG4: BV66 | AH4: BV67 | AI4: BV68 | AJ4: BV70 | AK4: BV71 | AL4: BV72 | AM4: BV75 | AN4: BV76 | AO4: BV80 | AP4: BV85 | AQ4: BV90 | AR4: BV91
A5: Loan ID | B5: Current Balance (£) | C5: Original Balance (£) | D5: Current Property Value (£) | E5: Original Property Value (£) | F5: Origination Date | G5: Maturity Date | H5: Current Interest Rate (%) | I5: Property Type (1-4) | J5: Region | K5: Postcode | L5: Occupancy Status (1-4) | M5: Loan Purpose (1-4) | N5: Payment Method (1-3) | O5: Right to Buy (1-2) | P5: Shared Ownership (1-2) | Q5: Help to Buy (1-2) | R5: Borrower 1 Income (£) | S5: Borrower 2 Income (£) | T5: Number of Borrowers (1-2) | U5: Employ Status Borr1 (1-4) | V5: Employ Status Borr2 (1-4) | W5: Credit Score Borr1 | X5: Credit Score Borr2 | Y5: CCJ Count Borr1 | Z5: CCJ Count Borr2 | AA5: CCJ Value Borr1 (£) | AB5: CCJ Value Borr2 (£) | AC5: CCJ Date Borr1 | AD5: CCJ Date Borr2 | AE5: Arrears Balance (£) | AF5: Bankruptcy Flag (1-2) | AG5: Bankruptcy Date | AH5: IVA Flag (1-2) | AI5: Prior Repossession (1-2) | AJ5: Self-Certified (1-2) | AK5: First Time Buyer (1-2) | AL5: Payment Shock (1-2) | AM5: Reperforming (1-2) | AN5: Date Last 90+ dpd | AO5: Lien Position (1/2/3+) | AP5: Valuation Method (1-3) | AQ5: Commercial Property (1-2) | AR5: Rental Income Annual (£)

Sheet Loan Tape (S&P)
A1: LOAN TAPE - S&P FORMAT (AUTO-CONVERTED FROM BoE)
A2: Auto-populated from Loan Tape (BoE) using conversion formulas - DO NOT EDIT
A4: loan_id | B4: current_balance | C4: original_balance | D4: property_value_current | E4: property_value_original | F4: origination_date | G4: maturity_date | H4: interest_rate | I4: property_type | J4: region | K4: postcode | L4: occupancy_type | M4: loan_purpose | N4: product_type | O4: right_to_buy_flag | P4: shared_ownership_flag | Q4: help_to_buy_flag | R4: borrower1_income | S4: borrower2_income | T4: num_borrowers | U4: total_income | V4: employment_status_borr1 | W4: employment_status_borr2 | X4: self_employed_flag | Y4: credit_score_borr1 | Z4: credit_score_borr2 | AA4: credit_score | AB4: ccj_count_borr1 | AC4: ccj_count_borr2 | AD4: ccj_count | AE4: ccj_value_borr1 | AF4: ccj_value_borr2 | AG4: ccj_total_value | AH4: ccj_date_most_recent | AI4: arrears_balance | AJ4: monthly_payment | AK4: arrears_months | AL4: bankruptcy_flag | AM4: iva_flag | AN4: prior_repossession_flag | AO4: self_certified_flag | AP4: Performance Arrangement | AQ4: Performance Arrangement Date | AR4: Last 90+ Days Date | AS4: Interest Rate Type | AT4: Monthly Payment (Full Amort) | AU4: Months to Maturity | AV4: Maturity Date Check | AW4: Loan Age (Months)
A5: ='Loan Tape (BoE)'!A6 | B5: =IFERROR(INDEX('FF Adj Parameters'!$A$89:$B$92,MATCH('Loan Tape (BoE)'!C5,INDEX('FF Adj Parameters'!$A$89:$B$92,,1),0),2),"Unknown") | C5: ='Loan Tape (BoE)'!C6 | D5: ='Loan Tape (BoE)'!D6 | E5: ='Loan Tape (BoE)'!E6 | F5: ='Loan Tape (BoE)'!F6 | G5: ='Loan Tape (BoE)'!G6 | H5: ='Loan Tape (BoE)'!H6/100 | I5: =IFERROR(IFS('Loan Tape (BoE)'!I6=1,"House",'Loan Tape (BoE)'!I6=2,"Flat",'Loan Tape (BoE)'!I6=3,"Bungalow",'Loan Tape (BoE)'!I6=4,"Maisonette"),"") | J5: ='Loan Tape (BoE)'!J6 | K5: ='Loan Tape (BoE)'!K6 | L5: =IFERROR(IFS('Loan Tape (BoE)'!L6=1,"Owner Occupied",'Loan Tape (BoE)'!L6=2,"BTL",'Loan Tape (BoE)'!L6=3,"Second Home",'Loan Tape (BoE)'!L6=4,"Investment"),"") | M5: =IFERROR(IFS('Loan Tape (BoE)'!M6=1,"Purchase",'Loan Tape (BoE)'!M6=2,"Remortgage",OR('Loan Tape (BoE)'!M6=3,'Loan Tape (BoE)'!M6=4),"Cash-out"),"") | N5: =IFERROR(INDEX('FF Adj Parameters'!$A$96:$B$99,MATCH('Loan Tape (BoE)'!R5,INDEX('FF Adj Parameters'!$A$96:$B$99,,1),0),2),"Unknown") | O5: =IF('Loan Tape (BoE)'!O6=1,"Yes","No") | P5: =IF('Loan Tape (BoE)'!P5=1,"Yes",IF('Loan Tape (BoE)'!P5=0,"No","")) | Q5: =IF('Loan Tape (BoE)'!Q5=1,"Yes",IF('Loan Tape (BoE)'!Q5=0,"No","")) | R5: =IF('Loan Tape (BoE)'!R5=1,"Yes",IF('Loan Tape (BoE)'!R5=0,"No","")) | S5: =IF('Loan Tape (BoE)'!S5=1,"Yes",IF('Loan Tape (BoE)'!S5=0,"No","")) | T5: =IF('Loan Tape (BoE)'!T5=1,"Yes",IF('Loan Tape (BoE)'!T5=0,"No","")) | U5: =R5+S5 | V5: =IFERROR(IFS('Loan Tape (BoE)'!U6=1,"Employed",'Loan Tape (BoE)'!U6=2,"Self-Employed",'Loan Tape (BoE)'!U6=3,"Unemployed",'Loan Tape (BoE)'!U6=4,"Retired"),"") | W5: =IFERROR(IFS('Loan Tape (BoE)'!V6=1,"Employed",'Loan Tape (BoE)'!V6=2,"Self-Employed",'Loan Tape (BoE)'!V6=3,"Unemployed",'Loan Tape (BoE)'!V6=4,"Retired"),"") | X5: =IF(OR(V5="Self-Employed",W5="Self-Employed"),"Yes","No") | Y5: ='Loan Tape (BoE)'!W6 | Z5: ='Loan Tape (BoE)'!X6 | AA5: =IF(T5=1,Y5,MIN(Y5,Z5)) | AB5: ='Loan Tape (BoE)'!Y6 | AC5: ='Loan Tape (BoE)'!Z6 | AD5: =AB5+AC5 | AE5: ='Loan Tape (BoE)'!AA6 | AF5: ='Loan Tape (BoE)'!AB6 | AG5: =AE5+AF5 | AH5: =MAX('Loan Tape (BoE)'!AC6,'Loan Tape (BoE)'!AD6) | AI5: ='Loan Tape (BoE)'!AE6 | AJ5: =B5*H5/12 | AK5: =IF(AJ5>0,AI5/AJ5,0) | AL5: =IF('Loan Tape (BoE)'!AF6=1,"Yes","No") | AM5: =IF('Loan Tape (BoE)'!AH6=1,"Yes","No") | AN5: =IF('Loan Tape (BoE)'!AI6=1,"Yes","No") | AO5: =IF('Loan Tape (BoE)'!AJ6=1,"Yes","No") | AP5: =IF(OR('Loan Tape (BoE)'!AQ5=1,'Loan Tape (BoE)'!AQ5=2),"Yes",IF('Loan Tape (BoE)'!AQ5=0,"No","")) | AQ5: =IF('Loan Tape (BoE)'!BV49_5<>"",'Loan Tape (BoE)'!BV49_5,"") | AR5: =IF('Loan Tape (BoE)'!BV50_5<>"",'Loan Tape (BoE)'!BV50_5,"") | AS5: =IFERROR(INDEX('FF Adj Parameters'!$A$103:$B$105,MATCH('Loan Tape (BoE)'!P5,INDEX('FF Adj Parameters'!$A$103:$B$105,,1),0),2),"Unknown") | AT5: =IF(N5="Interest Only",M5*O5/12,IF(AND(O5>0,ISNUMBER(O5),ISNUMBER(M5)),ABS(PMT(O5/12,AU5,-M5)),0)) | AU5: =IF(ISNUMBER(L5),MAX(0,(L5-'Control Panel'!$B$10)*12/365.25),0) | AV5: =IF(ISNUMBER(L5),IF(L5>'Control Panel'!$B$10,"Valid","Past Maturity"),"No Date") | AW5: =IF(ISNUMBER(K5),MAX(0,('Control Panel'!$B$10-K5)*12/365.25),0)
A6: ='Loan Tape (BoE)'!A7 | B6: =IFERROR(INDEX('FF Adj Parameters'!$A$89:$B$92,MATCH('Loan Tape (BoE)'!C6,INDEX('FF Adj Parameters'!$A$89:$B$92,,1),0),2),"Unknown") | C6: ='Loan Tape (BoE)'!C7 | D6: ='Loan Tape (BoE)'!D7 | E6: ='Loan Tape (BoE)'!E7 | F6: ='Loan Tape (BoE)'!F7 | G6: ='Loan Tape (BoE)'!G7 | H6: ='Loan Tape (BoE)'!H7/100 | I6: =IFERROR(IFS('Loan Tape (BoE)'!I7=1,"House",'Loan Tape (BoE)'!I7=2,"Flat",'Loan Tape (BoE)'!I7=3,"Bungalow",'Loan Tape (BoE)'!I7=4,"Maisonette"),"") | J6: ='Loan Tape (BoE)'!J7 | K6: ='Loan Tape (BoE)'!K7 | L6: =IFERROR(IFS('Loan Tape (BoE)'!L7=1,"Owner Occupied",'Loan Tape (BoE)'!L7=2,"BTL",'Loan Tape (BoE)'!L7=3,"Second Home",'Loan Tape (BoE)'!L7=4,"Investment"),"") | M6: =IFERROR(IFS('Loan Tape (BoE)'!M7=1,"Purchase",'Loan Tape (BoE)'!M7=2,"Remortgage",OR('Loan Tape (BoE)'!M7=3,'Loan Tape (BoE)'!M7=4),"Cash-out"),"") | N6: =IFERROR(INDEX('FF Adj Parameters'!$A$96:$B$99,MATCH('Loan Tape (BoE)'!R6,INDEX('FF Adj Parameters'!$A$96:$B$99,,1),0),2),"Unknown") | O6: =IF('Loan Tape (BoE)'!O7=1,"Yes","No") | P6: =IF('Loan Tape (BoE)'!P6=1,"Yes",IF('Loan Tape (BoE)'!P6=0,"No","")) | Q6: =IF('Loan Tape (BoE)'!Q6=1,"Yes",IF('Loan Tape (BoE)'!Q6=0,"No","")) | R6: =IF('Loan Tape (BoE)'!R6=1,"Yes",IF('Loan Tape (BoE)'!R6=0,"No","")) | S6: =IF('Loan Tape (BoE)'!S6=1,"Yes",IF('Loan Tape (BoE)'!S6=0,"No","")) | T6: =IF('Loan Tape (BoE)'!T6=1,"Yes",IF('Loan Tape (BoE)'!T6=0,"No","")) | U6: =R6+S6 | V6: =IFERROR(IFS('Loan Tape (BoE)'!U7=1,"Employed",'Loan Tape (BoE)'!U7=2,"Self-Employed",'Loan Tape (BoE)'!U7=3,"Unemployed",'Loan Tape (BoE)'!U7=4,"Retired"),"") | W6: =IFERROR(IFS('Loan Tape (BoE)'!V7=1,"Employed",'Loan Tape (BoE)'!V7=2,"Self-Employed",'Loan Tape (BoE)'!V7=3,"Unemployed",'Loan Tape (BoE)'!V7=4,"Retired"),"") | X6: =IF(OR(V6="Self-Employed",W6="Self-Employed"),"Yes","No") | Y6: ='Loan Tape (BoE)'!W7 | Z6: ='Loan Tape (BoE)'!X7 | AA6: =IF(T6=1,Y6,MIN(Y6,Z6)) | AB6: ='Loan Tape (BoE)'!Y7 | AC6: ='Loan Tape (BoE)'!Z7 | AD6: =AB6+AC6 | AE6: ='Loan Tape (BoE)'!AA7 | AF6: ='Loan Tape (BoE)'!AB7 | AG6: =AE6+AF6 | AH6: =MAX('Loan Tape (BoE)'!AC7,'Loan Tape (BoE)'!AD7) | AI6: ='Loan Tape (BoE)'!AE7 | AJ6: =B6*H6/12 | AK6: =IF(AJ6>0,AI6/AJ6,0) | AL6: =IF('Loan Tape (BoE)'!AF7=1,"Yes","No") | AM6: =IF('Loan Tape (BoE)'!AH7=1,"Yes","No") | AN6: =IF('Loan Tape (BoE)'!AI7=1,"Yes","No") | AO6: =IF('Loan Tape (BoE)'!AJ7=1,"Yes","No") | AP6: =IF(OR('Loan Tape (BoE)'!AQ6=1,'Loan Tape (BoE)'!AQ6=2),"Yes",IF('Loan Tape (BoE)'!AQ6=0,"No","")) | AQ6: =IF('Loan Tape (BoE)'!BV49_6<>"",'Loan Tape (BoE)'!BV49_6,"") | AR6: =IF('Loan Tape (BoE)'!BV60_6<>"",'Loan Tape (BoE)'!BV50_6,"") | AS6: =IFERROR(INDEX('FF Adj Parameters'!$A$103:$B$106,MATCH('Loan Tape (BoE)'!P6,INDEX('FF Adj Parameters'!$A$103:$B$106,,1),0),2),"Unknown") | AT6: =IF(N6="Interest Only",M5*O5/12,IF(AND(O5>0,ISNUMBER(O5),ISNUMBER(M5)),ABS(PMT(O5/12,AU5,-M5)),0)) | AU6: =IF(ISNUMBER(L6),MAX(0,(L5-'Control Panel'!$B$10)*12/365.25),0) | AV6: =IF(ISNUMBER(L6),IF(L5>'Control Panel'!$B$10,"Valid","Past Maturity"),"No Date") | AW6: =IF(ISNUMBER(K6),MAX(0,('Control Panel'!$B$10-K5)*12/365.25),0)
A7: ='Loan Tape (BoE)'!A8 | B7: =IFERROR(INDEX('FF Adj Parameters'!$A$89:$B$92,MATCH('Loan Tape (BoE)'!C7,INDEX('FF Adj Parameters'!$A$89:$B$92,,1),0),2),"Unknown") | C7: ='Loan Tape (BoE)'!C8 | D7: ='Loan Tape (BoE)'!D8 | E7: ='Loan Tape (BoE)'!E8 | F7: ='Loan Tape (BoE)'!F8 | G7: ='Loan Tape (BoE)'!G8 | H7: ='Loan Tape (BoE)'!H8/100 | I7: =IFERROR(IFS('Loan Tape (BoE)'!I8=1,"House",'Loan Tape (BoE)'!I8=2,"Flat",'Loan Tape (BoE)'!I8=3,"Bungalow",'Loan Tape (BoE)'!I8=4,"Maisonette"),"") | J7: ='Loan Tape (BoE)'!J8 | K7: ='Loan Tape (BoE)'!K8 | L7: =IFERROR(IFS('Loan Tape (BoE)'!L8=1,"Owner Occupied",'Loan Tape (BoE)'!L8=2,"BTL",'Loan Tape (BoE)'!L8=3,"Second Home",'Loan Tape (BoE)'!L8=4,"Investment"),"") | M7: =IFERROR(IFS('Loan Tape (BoE)'!M8=1,"Purchase",'Loan Tape (BoE)'!M8=2,"Remortgage",OR('Loan Tape (BoE)'!M8=3,'Loan Tape (BoE)'!M8=4),"Cash-out"),"") | N7: =IFERROR(INDEX('FF Adj Parameters'!$A$96:$B$99,MATCH('Loan Tape (BoE)'!R7,INDEX('FF Adj Parameters'!$A$96:$B$99,,1),0),2),"Unknown") | O7: =IF('Loan Tape (BoE)'!O8=1,"Yes","No") | P7: =IF('Loan Tape (BoE)'!P7=1,"Yes",IF('Loan Tape (BoE)'!P7=0,"No","")) | Q7: =IF('Loan Tape (BoE)'!Q7=1,"Yes",IF('Loan Tape (BoE)'!Q7=0,"No","")) | R7: =IF('Loan Tape (BoE)'!R7=1,"Yes",IF('Loan Tape (BoE)'!R7=0,"No","")) | S7: =IF('Loan Tape (BoE)'!S7=1,"Yes",IF('Loan Tape (BoE)'!S7=0,"No","")) | T7: =IF('Loan Tape (BoE)'!T7=1,"Yes",IF('Loan Tape (BoE)'!T7=0,"No","")) | U7: =R7+S7 | V7: =IFERROR(IFS('Loan Tape (BoE)'!U8=1,"Employed",'Loan Tape (BoE)'!U8=2,"Self-Employed",'Loan Tape (BoE)'!U8=3,"Unemployed",'Loan Tape (BoE)'!U8=4,"Retired"),"") | W7: =IFERROR(IFS('Loan Tape (BoE)'!V8=1,"Employed",'Loan Tape (BoE)'!V8=2,"Self-Employed",'Loan Tape (BoE)'!V8=3,"Unemployed",'Loan Tape (BoE)'!V8=4,"Retired"),"") | X7: =IF(OR(V7="Self-Employed",W7="Self-Employed"),"Yes","No") | Y7: ='Loan Tape (BoE)'!W8 | Z7: ='Loan Tape (BoE)'!X8 | AA7: =IF(T7=1,Y7,MIN(Y7,Z7)) | AB7: ='Loan Tape (BoE)'!Y8 | AC7: ='Loan Tape (BoE)'!Z8 | AD7: =AB7+AC7 | AE7: ='Loan Tape (BoE)'!AA8 | AF7: ='Loan Tape (BoE)'!AB8 | AG7: =AE7+AF7 | AH7: =MAX('Loan Tape (BoE)'!AC8,'Loan Tape (BoE)'!AD8) | AI7: ='Loan Tape (BoE)'!AE8 | AJ7: =B7*H7/12 | AK7: =IF(AJ7>0,AI7/AJ7,0) | AL7: =IF('Loan Tape (BoE)'!AF8=1,"Yes","No") | AM7: =IF('Loan Tape (BoE)'!AH8=1,"Yes","No") | AN7: =IF('Loan Tape (BoE)'!AI8=1,"Yes","No") | AO7: =IF('Loan Tape (BoE)'!AJ8=1,"Yes","No") | AP7: =IF(OR('Loan Tape (BoE)'!AQ7=1,'Loan Tape (BoE)'!AQ7=2),"Yes",IF('Loan Tape (BoE)'!AQ7=0,"No","")) | AQ7: =IF('Loan Tape (BoE)'!BV49_7<>"",'Loan Tape (BoE)'!BV49_7,"") | AR7: =IF('Loan Tape (BoE)'!BV70_7<>"",'Loan Tape (BoE)'!BV50_7,"") | AS7: =IFERROR(INDEX('FF Adj Parameters'!$A$103:$B$107,MATCH('Loan Tape (BoE)'!P7,INDEX('FF Adj Parameters'!$A$103:$B$107,,1),0),2),"Unknown") | AT7: =IF(N7="Interest Only",M5*O5/12,IF(AND(O5>0,ISNUMBER(O5),ISNUMBER(M5)),ABS(PMT(O5/12,AU5,-M5)),0)) | AU7: =IF(ISNUMBER(L7),MAX(0,(L5-'Control Panel'!$B$10)*12/365.25),0) | AV7: =IF(ISNUMBER(L7),IF(L5>'Control Panel'!$B$10,"Valid","Past Maturity"),"No Date") | AW7: =IF(ISNUMBER(K7),MAX(0,('Control Panel'!$B$10-K5)*12/365.25),0)
A8: ='Loan Tape (BoE)'!A9 | B8: =IFERROR(INDEX('FF Adj Parameters'!$A$89:$B$92,MATCH('Loan Tape (BoE)'!C8,INDEX('FF Adj Parameters'!$A$89:$B$92,,1),0),2),"Unknown") | C8: ='Loan Tape (BoE)'!C9 | D8: ='Loan Tape (BoE)'!D9 | E8: ='Loan Tape (BoE)'!E9 | F8: ='Loan Tape (BoE)'!F9 | G8: ='Loan Tape (BoE)'!G9 | H8: ='Loan Tape (BoE)'!H9/100 | I8: =IFERROR(IFS('Loan Tape (BoE)'!I9=1,"House",'Loan Tape (BoE)'!I9=2,"Flat",'Loan Tape (BoE)'!I9=3,"Bungalow",'Loan Tape (BoE)'!I9=4,"Maisonette"),"") | J8: ='Loan Tape (BoE)'!J9 | K8: ='Loan Tape (BoE)'!K9 | L8: =IFERROR(IFS('Loan Tape (BoE)'!L9=1,"Owner Occupied",'Loan Tape (BoE)'!L9=2,"BTL",'Loan Tape (BoE)'!L9=3,"Second Home",'Loan Tape (BoE)'!L9=4,"Investment"),"") | M8: =IFERROR(IFS('Loan Tape (BoE)'!M9=1,"Purchase",'Loan Tape (BoE)'!M9=2,"Remortgage",OR('Loan Tape (BoE)'!M9=3,'Loan Tape (BoE)'!M9=4),"Cash-out"),"") | N8: =IFERROR(INDEX('FF Adj Parameters'!$A$96:$B$99,MATCH('Loan Tape (BoE)'!R8,INDEX('FF Adj Parameters'!$A$96:$B$99,,1),0),2),"Unknown") | O8: =IF('Loan Tape (BoE)'!O9=1,"Yes","No") | P8: =IF('Loan Tape (BoE)'!P8=1,"Yes",IF('Loan Tape (BoE)'!P8=0,"No","")) | Q8: =IF('Loan Tape (BoE)'!Q8=1,"Yes",IF('Loan Tape (BoE)'!Q8=0,"No","")) | R8: =IF('Loan Tape (BoE)'!R8=1,"Yes",IF('Loan Tape (BoE)'!R8=0,"No","")) | S8: =IF('Loan Tape (BoE)'!S8=1,"Yes",IF('Loan Tape (BoE)'!S8=0,"No","")) | T8: =IF('Loan Tape (BoE)'!T8=1,"Yes",IF('Loan Tape (BoE)'!T8=0,"No","")) | U8: =R8+S8 | V8: =IFERROR(IFS('Loan Tape (BoE)'!U9=1,"Employed",'Loan Tape (BoE)'!U9=2,"Self-Employed",'Loan Tape (BoE)'!U9=3,"Unemployed",'Loan Tape (BoE)'!U9=4,"Retired"),"") | W8: =IFERROR(IFS('Loan Tape (BoE)'!V9=1,"Employed",'Loan Tape (BoE)'!V9=2,"Self-Employed",'Loan Tape (BoE)'!V9=3,"Unemployed",'Loan Tape (BoE)'!V9=4,"Retired"),"") | X8: =IF(OR(V8="Self-Employed",W8="Self-Employed"),"Yes","No") | Y8: ='Loan Tape (BoE)'!W9 | Z8: ='Loan Tape (BoE)'!X9 | AA8: =IF(T8=1,Y8,MIN(Y8,Z8)) | AB8: ='Loan Tape (BoE)'!Y9 | AC8: ='Loan Tape (BoE)'!Z9 | AD8: =AB8+AC8 | AE8: ='Loan Tape (BoE)'!AA9 | AF8: ='Loan Tape (BoE)'!AB9 | AG8: =AE8+AF8 | AH8: =MAX('Loan Tape (BoE)'!AC9,'Loan Tape (BoE)'!AD9) | AI8: ='Loan Tape (BoE)'!AE9 | AJ8: =B8*H8/12 | AK8: =IF(AJ8>0,AI8/AJ8,0) | AL8: =IF('Loan Tape (BoE)'!AF9=1,"Yes","No") | AM8: =IF('Loan Tape (BoE)'!AH9=1,"Yes","No") | AN8: =IF('Loan Tape (BoE)'!AI9=1,"Yes","No") | AO8: =IF('Loan Tape (BoE)'!AJ9=1,"Yes","No") | AP8: =IF(OR('Loan Tape (BoE)'!AQ8=1,'Loan Tape (BoE)'!AQ8=2),"Yes",IF('Loan Tape (BoE)'!AQ8=0,"No","")) | AQ8: =IF('Loan Tape (BoE)'!BV49_8<>"",'Loan Tape (BoE)'!BV49_8,"") | AR8: =IF('Loan Tape (BoE)'!BV80_8<>"",'Loan Tape (BoE)'!BV50_8,"") | AS8: =IFERROR(INDEX('FF Adj Parameters'!$A$103:$B$108,MATCH('Loan Tape (BoE)'!P8,INDEX('FF Adj Parameters'!$A$103:$B$108,,1),0),2),"Unknown") | AT8: =IF(N8="Interest Only",M5*O5/12,IF(AND(O5>0,ISNUMBER(O5),ISNUMBER(M5)),ABS(PMT(O5/12,AU5,-M5)),0)) | AU8: =IF(ISNUMBER(L8),MAX(0,(L5-'Control Panel'!$B$10)*12/365.25),0) | AV8: =IF(ISNUMBER(L8),IF(L5>'Control Panel'!$B$10,"Valid","Past Maturity"),"No Date") | AW8: =IF(ISNUMBER(K8),MAX(0,('Control Panel'!$B$10-K5)*12/365.25),0)
A9: ='Loan Tape (BoE)'!A10 | B9: =IFERROR(INDEX('FF Adj Parameters'!$A$89:$B$92,MATCH('Loan Tape (BoE)'!C9,INDEX('FF Adj Parameters'!$A$89:$B$92,,1),0),2),"Unknown") | C9: ='Loan Tape (BoE)'!C10 | D9: ='Loan Tape (BoE)'!D10 | E9: ='Loan Tape (BoE)'!E10 | F9: ='Loan Tape (BoE)'!F10 | G9: ='Loan Tape (BoE)'!G10 | H9: ='Loan Tape (BoE)'!H10/100 | I9: =IFERROR(IFS('Loan Tape (BoE)'!I10=1,"House",'Loan Tape (BoE)'!I10=2,"Flat",'Loan Tape (BoE)'!I10=3,"Bungalow",'Loan Tape (BoE)'!I10=4,"Maisonette"),"") | J9: ='Loan Tape (BoE)'!J10 | K9: ='Loan Tape (BoE)'!K10 | L9: =IFERROR(IFS('Loan Tape (BoE)'!L10=1,"Owner Occupied",'Loan Tape (BoE)'!L10=2,"BTL",'Loan Tape (BoE)'!L10=3,"Second Home",'Loan Tape (BoE)'!L10=4,"Investment"),"") | M9: =IFERROR(IFS('Loan Tape (BoE)'!M10=1,"Purchase",'Loan Tape (BoE)'!M10=2,"Remortgage",OR('Loan Tape (BoE)'!M10=3,'Loan Tape (BoE)'!M10=4),"Cash-out"),"") | N9: =IFERROR(INDEX('FF Adj Parameters'!$A$96:$B$99,MATCH('Loan Tape (BoE)'!R9,INDEX('FF Adj Parameters'!$A$96:$B$99,,1),0),2),"Unknown") | O9: =IF('Loan Tape (BoE)'!O10=1,"Yes","No") | P9: =IF('Loan Tape (BoE)'!P9=1,"Yes",IF('Loan Tape (BoE)'!P9=0,"No","")) | Q9: =IF('Loan Tape (BoE)'!Q9=1,"Yes",IF('Loan Tape (BoE)'!Q9=0,"No","")) | R9: =IF('Loan Tape (BoE)'!R9=1,"Yes",IF('Loan Tape (BoE)'!R9=0,"No","")) | S9: =IF('Loan Tape (BoE)'!S9=1,"Yes",IF('Loan Tape (BoE)'!S9=0,"No","")) | T9: =IF('Loan Tape (BoE)'!T9=1,"Yes",IF('Loan Tape (BoE)'!T9=0,"No","")) | U9: =R9+S9 | V9: =IFERROR(IFS('Loan Tape (BoE)'!U10=1,"Employed",'Loan Tape (BoE)'!U10=2,"Self-Employed",'Loan Tape (BoE)'!U10=3,"Unemployed",'Loan Tape (BoE)'!U10=4,"Retired"),"") | W9: =IFERROR(IFS('Loan Tape (BoE)'!V10=1,"Employed",'Loan Tape (BoE)'!V10=2,"Self-Employed",'Loan Tape (BoE)'!V10=3,"Unemployed",'Loan Tape (BoE)'!V10=4,"Retired"),"") | X9: =IF(OR(V9="Self-Employed",W9="Self-Employed"),"Yes","No") | Y9: ='Loan Tape (BoE)'!W10 | Z9: ='Loan Tape (BoE)'!X10 | AA9: =IF(T9=1,Y9,MIN(Y9,Z9)) | AB9: ='Loan Tape (BoE)'!Y10 | AC9: ='Loan Tape (BoE)'!Z10 | AD9: =AB9+AC9 | AE9: ='Loan Tape (BoE)'!AA10 | AF9: ='Loan Tape (BoE)'!AB10 | AG9: =AE9+AF9 | AH9: =MAX('Loan Tape (BoE)'!AC10,'Loan Tape (BoE)'!AD10) | AI9: ='Loan Tape (BoE)'!AE10 | AJ9: =B9*H9/12 | AK9: =IF(AJ9>0,AI9/AJ9,0) | AL9: =IF('Loan Tape (BoE)'!AF10=1,"Yes","No") | AM9: =IF('Loan Tape (BoE)'!AH10=1,"Yes","No") | AN9: =IF('Loan Tape (BoE)'!AI10=1,"Yes","No") | AO9: =IF('Loan Tape (BoE)'!AJ10=1,"Yes","No") | AP9: =IF(OR('Loan Tape (BoE)'!AQ9=1,'Loan Tape (BoE)'!AQ9=2),"Yes",IF('Loan Tape (BoE)'!AQ9=0,"No","")) | AQ9: =IF('Loan Tape (BoE)'!BV49_9<>"",'Loan Tape (BoE)'!BV49_9,"") | AR9: =IF('Loan Tape (BoE)'!BV90_9<>"",'Loan Tape (BoE)'!BV50_9,"") | AS9: =IFERROR(INDEX('FF Adj Parameters'!$A$103:$B$109,MATCH('Loan Tape (BoE)'!P9,INDEX('FF Adj Parameters'!$A$103:$B$109,,1),0),2),"Unknown") | AT9: =IF(N9="Interest Only",M5*O5/12,IF(AND(O5>0,ISNUMBER(O5),ISNUMBER(M5)),ABS(PMT(O5/12,AU5,-M5)),0)) | AU9: =IF(ISNUMBER(L9),MAX(0,(L5-'Control Panel'!$B$10)*12/365.25),0) | AV9: =IF(ISNUMBER(L9),IF(L5>'Control Panel'!$B$10,"Valid","Past Maturity"),"No Date") | AW9: =IF(ISNUMBER(K9),MAX(0,('Control Panel'!$B$10-K5)*12/365.25),0)
A10: ='Loan Tape (BoE)'!A11 | B10: =IFERROR(INDEX('FF Adj Parameters'!$A$89:$B$92,MATCH('Loan Tape (BoE)'!C10,INDEX('FF Adj Parameters'!$A$89:$B$92,,1),0),2),"Unknown") | C10: ='Loan Tape (BoE)'!C11 | D10: ='Loan Tape (BoE)'!D11 | E10: ='Loan Tape (BoE)'!E11 | F10: ='Loan Tape (BoE)'!F11 | G10: ='Loan Tape (BoE)'!G11 | H10: ='Loan Tape (BoE)'!H11/100 | I10: =IFERROR(IFS('Loan Tape (BoE)'!I11=1,"House",'Loan Tape (BoE)'!I11=2,"Flat",'Loan Tape (BoE)'!I11=3,"Bungalow",'Loan Tape (BoE)'!I11=4,"Maisonette"),"") | J10: ='Loan Tape (BoE)'!J11 | K10: ='Loan Tape (BoE)'!K11 | L10: =IFERROR(IFS('Loan Tape (BoE)'!L11=1,"Owner Occupied",'Loan Tape (BoE)'!L11=2,"BTL",'Loan Tape (BoE)'!L11=3,"Second Home",'Loan Tape (BoE)'!L11=4,"Investment"),"") | M10: =IFERROR(IFS('Loan Tape (BoE)'!M11=1,"Purchase",'Loan Tape (BoE)'!M11=2,"Remortgage",OR('Loan Tape (BoE)'!M11=3,'Loan Tape (BoE)'!M11=4),"Cash-out"),"") | N10: =IFERROR(INDEX('FF Adj Parameters'!$A$96:$B$99,MATCH('Loan Tape (BoE)'!R10,INDEX('FF Adj Parameters'!$A$96:$B$99,,1),0),2),"Unknown") | O10: =IF('Loan Tape (BoE)'!O11=1,"Yes","No") | P10: =IF('Loan Tape (BoE)'!P10=1,"Yes",IF('Loan Tape (BoE)'!P10=0,"No","")) | Q10: =IF('Loan Tape (BoE)'!Q10=1,"Yes",IF('Loan Tape (BoE)'!Q10=0,"No","")) | R10: =IF('Loan Tape (BoE)'!R10=1,"Yes",IF('Loan Tape (BoE)'!R10=0,"No","")) | S10: =IF('Loan Tape (BoE)'!S10=1,"Yes",IF('Loan Tape (BoE)'!S10=0,"No","")) | T10: =IF('Loan Tape (BoE)'!T10=1,"Yes",IF('Loan Tape (BoE)'!T10=0,"No","")) | U10: =R10+S10 | V10: =IFERROR(IFS('Loan Tape (BoE)'!U11=1,"Employed",'Loan Tape (BoE)'!U11=2,"Self-Employed",'Loan Tape (BoE)'!U11=3,"Unemployed",'Loan Tape (BoE)'!U11=4,"Retired"),"") | W10: =IFERROR(IFS('Loan Tape (BoE)'!V11=1,"Employed",'Loan Tape (BoE)'!V11=2,"Self-Employed",'Loan Tape (BoE)'!V11=3,"Unemployed",'Loan Tape (BoE)'!V11=4,"Retired"),"") | X10: =IF(OR(V10="Self-Employed",W10="Self-Employed"),"Yes","No") | Y10: ='Loan Tape (BoE)'!W11 | Z10: ='Loan Tape (BoE)'!X11 | AA10: =IF(T10=1,Y10,MIN(Y10,Z10)) | AB10: ='Loan Tape (BoE)'!Y11 | AC10: ='Loan Tape (BoE)'!Z11 | AD10: =AB10+AC10 | AE10: ='Loan Tape (BoE)'!AA11 | AF10: ='Loan Tape (BoE)'!AB11 | AG10: =AE10+AF10 | AH10: =MAX('Loan Tape (BoE)'!AC11,'Loan Tape (BoE)'!AD11) | AI10: ='Loan Tape (BoE)'!AE11 | AJ10: =B10*H10/12 | AK10: =IF(AJ10>0,AI10/AJ10,0) | AL10: =IF('Loan Tape (BoE)'!AF11=1,"Yes","No") | AM10: =IF('Loan Tape (BoE)'!AH11=1,"Yes","No") | AN10: =IF('Loan Tape (BoE)'!AI11=1,"Yes","No") | AO10: =IF('Loan Tape (BoE)'!AJ11=1,"Yes","No") | AP10: =IF(OR('Loan Tape (BoE)'!AQ10=1,'Loan Tape (BoE)'!AQ10=2),"Yes",IF('Loan Tape (BoE)'!AQ10=0,"No","")) | AQ10: =IF('Loan Tape (BoE)'!BV49_10<>"",'Loan Tape (BoE)'!BV49_10,"") | AR10: =IF('Loan Tape (BoE)'!BV100_10<>"",'Loan Tape (BoE)'!BV50_10,"") | AS10: =IFERROR(INDEX('FF Adj Parameters'!$A$103:$B$1010,MATCH('Loan Tape (BoE)'!P10,INDEX('FF Adj Parameters'!$A$103:$B$1010,,1),0),2),"Unknown") | AT10: =IF(N10="Interest Only",M5*O5/12,IF(AND(O5>0,ISNUMBER(O5),ISNUMBER(M5)),ABS(PMT(O5/12,AU5,-M5)),0)) | AU10: =IF(ISNUMBER(L10),MAX(0,(L5-'Control Panel'!$B$10)*12/365.25),0) | AV10: =IF(ISNUMBER(L10),IF(L5>'Control Panel'!$B$10,"Valid","Past Maturity"),"No Date") | AW10: =IF(ISNUMBER(K10),MAX(0,('Control Panel'!$B$10-K5)*12/365.25),0)
A11: ='Loan Tape (BoE)'!A12 | B11: =IFERROR(INDEX('FF Adj Parameters'!$A$89:$B$92,MATCH('Loan Tape (BoE)'!C11,INDEX('FF Adj Parameters'!$A$89:$B$92,,1),0),2),"Unknown") | C11: ='Loan Tape (BoE)'!C12 | D11: ='Loan Tape (BoE)'!D12 | E11: ='Loan Tape (BoE)'!E12 | F11: ='Loan Tape (BoE)'!F12 | G11: ='Loan Tape (BoE)'!G12 | H11: ='Loan Tape (BoE)'!H12/100 | I11: =IFERROR(IFS('Loan Tape (BoE)'!I12=1,"House",'Loan Tape (BoE)'!I12=2,"Flat",'Loan Tape (BoE)'!I12=3,"Bungalow",'Loan Tape (BoE)'!I12=4,"Maisonette"),"") | J11: ='Loan Tape (BoE)'!J12 | K11: ='Loan Tape (BoE)'!K12 | L11: =IFERROR(IFS('Loan Tape (BoE)'!L12=1,"Owner Occupied",'Loan Tape (BoE)'!L12=2,"BTL",'Loan Tape (BoE)'!L12=3,"Second Home",'Loan Tape (BoE)'!L12=4,"Investment"),"") | M11: =IFERROR(IFS('Loan Tape (BoE)'!M12=1,"Purchase",'Loan Tape (BoE)'!M12=2,"Remortgage",OR('Loan Tape (BoE)'!M12=3,'Loan Tape (BoE)'!M12=4),"Cash-out"),"") | N11: =IFERROR(INDEX('FF Adj Parameters'!$A$96:$B$99,MATCH('Loan Tape (BoE)'!R11,INDEX('FF Adj Parameters'!$A$96:$B$99,,1),0),2),"Unknown") | O11: =IF('Loan Tape (BoE)'!O12=1,"Yes","No") | P11: =IF('Loan Tape (BoE)'!P11=1,"Yes",IF('Loan Tape (BoE)'!P11=0,"No","")) | Q11: =IF('Loan Tape (BoE)'!Q11=1,"Yes",IF('Loan Tape (BoE)'!Q11=0,"No","")) | R11: =IF('Loan Tape (BoE)'!R11=1,"Yes",IF('Loan Tape (BoE)'!R11=0,"No","")) | S11: =IF('Loan Tape (BoE)'!S11=1,"Yes",IF('Loan Tape (BoE)'!S11=0,"No","")) | T11: =IF('Loan Tape (BoE)'!T11=1,"Yes",IF('Loan Tape (BoE)'!T11=0,"No","")) | U11: =R11+S11 | V11: =IFERROR(IFS('Loan Tape (BoE)'!U12=1,"Employed",'Loan Tape (BoE)'!U12=2,"Self-Employed",'Loan Tape (BoE)'!U12=3,"Unemployed",'Loan Tape (BoE)'!U12=4,"Retired"),"") | W11: =IFERROR(IFS('Loan Tape (BoE)'!V12=1,"Employed",'Loan Tape (BoE)'!V12=2,"Self-Employed",'Loan Tape (BoE)'!V12=3,"Unemployed",'Loan Tape (BoE)'!V12=4,"Retired"),"") | X11: =IF(OR(V11="Self-Employed",W11="Self-Employed"),"Yes","No") | Y11: ='Loan Tape (BoE)'!W12 | Z11: ='Loan Tape (BoE)'!X12 | AA11: =IF(T11=1,Y11,MIN(Y11,Z11)) | AB11: ='Loan Tape (BoE)'!Y12 | AC11: ='Loan Tape (BoE)'!Z12 | AD11: =AB11+AC11 | AE11: ='Loan Tape (BoE)'!AA12 | AF11: ='Loan Tape (BoE)'!AB12 | AG11: =AE11+AF11 | AH11: =MAX('Loan Tape (BoE)'!AC12,'Loan Tape (BoE)'!AD12) | AI11: ='Loan Tape (BoE)'!AE12 | AJ11: =B11*H11/12 | AK11: =IF(AJ11>0,AI11/AJ11,0) | AL11: =IF('Loan Tape (BoE)'!AF12=1,"Yes","No") | AM11: =IF('Loan Tape (BoE)'!AH12=1,"Yes","No") | AN11: =IF('Loan Tape (BoE)'!AI12=1,"Yes","No") | AO11: =IF('Loan Tape (BoE)'!AJ12=1,"Yes","No") | AP11: =IF(OR('Loan Tape (BoE)'!AQ11=1,'Loan Tape (BoE)'!AQ11=2),"Yes",IF('Loan Tape (BoE)'!AQ11=0,"No","")) | AQ11: =IF('Loan Tape (BoE)'!BV49_11<>"",'Loan Tape (BoE)'!BV49_11,"") | AR11: =IF('Loan Tape (BoE)'!BV110_11<>"",'Loan Tape (BoE)'!BV50_11,"") | AS11: =IFERROR(INDEX('FF Adj Parameters'!$A$103:$B$1011,MATCH('Loan Tape (BoE)'!P11,INDEX('FF Adj Parameters'!$A$103:$B$1011,,1),0),2),"Unknown") | AT11: =IF(N11="Interest Only",M5*O5/12,IF(AND(O5>0,ISNUMBER(O5),ISNUMBER(M5)),ABS(PMT(O5/12,AU5,-M5)),0)) | AU11: =IF(ISNUMBER(L11),MAX(0,(L5-'Control Panel'!$B$10)*12/365.25),0) | AV11: =IF(ISNUMBER(L11),IF(L5>'Control Panel'!$B$10,"Valid","Past Maturity"),"No Date") | AW11: =IF(ISNUMBER(K11),MAX(0,('Control Panel'!$B$10-K5)*12/365.25),0)
A12: ='Loan Tape (BoE)'!A13 | B12: =IFERROR(INDEX('FF Adj Parameters'!$A$89:$B$92,MATCH('Loan Tape (BoE)'!C12,INDEX('FF Adj Parameters'!$A$89:$B$92,,1),0),2),"Unknown") | C12: ='Loan Tape (BoE)'!C13 | D12: ='Loan Tape (BoE)'!D13 | E12: ='Loan Tape (BoE)'!E13 | F12: ='Loan Tape (BoE)'!F13 | G12: ='Loan Tape (BoE)'!G13 | H12: ='Loan Tape (BoE)'!H13/100 | I12: =IFERROR(IFS('Loan Tape (BoE)'!I13=1,"House",'Loan Tape (BoE)'!I13=2,"Flat",'Loan Tape (BoE)'!I13=3,"Bungalow",'Loan Tape (BoE)'!I13=4,"Maisonette"),"") | J12: ='Loan Tape (BoE)'!J13 | K12: ='Loan Tape (BoE)'!K13 | L12: =IFERROR(IFS('Loan Tape (BoE)'!L13=1,"Owner Occupied",'Loan Tape (BoE)'!L13=2,"BTL",'Loan Tape (BoE)'!L13=3,"Second Home",'Loan Tape (BoE)'!L13=4,"Investment"),"") | M12: =IFERROR(IFS('Loan Tape (BoE)'!M13=1,"Purchase",'Loan Tape (BoE)'!M13=2,"Remortgage",OR('Loan Tape (BoE)'!M13=3,'Loan Tape (BoE)'!M13=4),"Cash-out"),"") | N12: =IFERROR(INDEX('FF Adj Parameters'!$A$96:$B$99,MATCH('Loan Tape (BoE)'!R12,INDEX('FF Adj Parameters'!$A$96:$B$99,,1),0),2),"Unknown") | O12: =IF('Loan Tape (BoE)'!O13=1,"Yes","No") | P12: =IF('Loan Tape (BoE)'!P12=1,"Yes",IF('Loan Tape (BoE)'!P12=0,"No","")) | Q12: =IF('Loan Tape (BoE)'!Q12=1,"Yes",IF('Loan Tape (BoE)'!Q12=0,"No","")) | R12: =IF('Loan Tape (BoE)'!R12=1,"Yes",IF('Loan Tape (BoE)'!R12=0,"No","")) | S12: =IF('Loan Tape (BoE)'!S12=1,"Yes",IF('Loan Tape (BoE)'!S12=0,"No","")) | T12: =IF('Loan Tape (BoE)'!T12=1,"Yes",IF('Loan Tape (BoE)'!T12=0,"No","")) | U12: =R12+S12 | V12: =IFERROR(IFS('Loan Tape (BoE)'!U13=1,"Employed",'Loan Tape (BoE)'!U13=2,"Self-Employed",'Loan Tape (BoE)'!U13=3,"Unemployed",'Loan Tape (BoE)'!U13=4,"Retired"),"") | W12: =IFERROR(IFS('Loan Tape (BoE)'!V13=1,"Employed",'Loan Tape (BoE)'!V13=2,"Self-Employed",'Loan Tape (BoE)'!V13=3,"Unemployed",'Loan Tape (BoE)'!V13=4,"Retired"),"") | X12: =IF(OR(V12="Self-Employed",W12="Self-Employed"),"Yes","No") | Y12: ='Loan Tape (BoE)'!W13 | Z12: ='Loan Tape (BoE)'!X13 | AA12: =IF(T12=1,Y12,MIN(Y12,Z12)) | AB12: ='Loan Tape (BoE)'!Y13 | AC12: ='Loan Tape (BoE)'!Z13 | AD12: =AB12+AC12 | AE12: ='Loan Tape (BoE)'!AA13 | AF12: ='Loan Tape (BoE)'!AB13 | AG12: =AE12+AF12 | AH12: =MAX('Loan Tape (BoE)'!AC13,'Loan Tape (BoE)'!AD13) | AI12: ='Loan Tape (BoE)'!AE13 | AJ12: =B12*H12/12 | AK12: =IF(AJ12>0,AI12/AJ12,0) | AL12: =IF('Loan Tape (BoE)'!AF13=1,"Yes","No") | AM12: =IF('Loan Tape (BoE)'!AH13=1,"Yes","No") | AN12: =IF('Loan Tape (BoE)'!AI13=1,"Yes","No") | AO12: =IF('Loan Tape (BoE)'!AJ13=1,"Yes","No") | AP12: =IF(OR('Loan Tape (BoE)'!AQ12=1,'Loan Tape (BoE)'!AQ12=2),"Yes",IF('Loan Tape (BoE)'!AQ12=0,"No","")) | AQ12: =IF('Loan Tape (BoE)'!BV49_12<>"",'Loan Tape (BoE)'!BV49_12,"") | AR12: =IF('Loan Tape (BoE)'!BV120_12<>"",'Loan Tape (BoE)'!BV50_12,"") | AS12: =IFERROR(INDEX('FF Adj Parameters'!$A$103:$B$1012,MATCH('Loan Tape (BoE)'!P12,INDEX('FF Adj Parameters'!$A$103:$B$1012,,1),0),2),"Unknown") | AT12: =IF(N12="Interest Only",M5*O5/12,IF(AND(O5>0,ISNUMBER(O5),ISNUMBER(M5)),ABS(PMT(O5/12,AU5,-M5)),0)) | AU12: =IF(ISNUMBER(L12),MAX(0,(L5-'Control Panel'!$B$10)*12/365.25),0) | AV12: =IF(ISNUMBER(L12),IF(L5>'Control Panel'!$B$10,"Valid","Past Maturity"),"No Date") | AW12: =IF(ISNUMBER(K12),MAX(0,('Control Panel'!$B$10-K5)*12/365.25),0)
A13: ='Loan Tape (BoE)'!A14 | B13: =IFERROR(INDEX('FF Adj Parameters'!$A$89:$B$92,MATCH('Loan Tape (BoE)'!C13,INDEX('FF Adj Parameters'!$A$89:$B$92,,1),0),2),"Unknown") | C13: ='Loan Tape (BoE)'!C14 | D13: ='Loan Tape (BoE)'!D14 | E13: ='Loan Tape (BoE)'!E14 | F13: ='Loan Tape (BoE)'!F14 | G13: ='Loan Tape (BoE)'!G14 | H13: ='Loan Tape (BoE)'!H14/100 | I13: =IFERROR(IFS('Loan Tape (BoE)'!I14=1,"House",'Loan Tape (BoE)'!I14=2,"Flat",'Loan Tape (BoE)'!I14=3,"Bungalow",'Loan Tape (BoE)'!I14=4,"Maisonette"),"") | J13: ='Loan Tape (BoE)'!J14 | K13: ='Loan Tape (BoE)'!K14 | L13: =IFERROR(IFS('Loan Tape (BoE)'!L14=1,"Owner Occupied",'Loan Tape (BoE)'!L14=2,"BTL",'Loan Tape (BoE)'!L14=3,"Second Home",'Loan Tape (BoE)'!L14=4,"Investment"),"") | M13: =IFERROR(IFS('Loan Tape (BoE)'!M14=1,"Purchase",'Loan Tape (BoE)'!M14=2,"Remortgage",OR('Loan Tape (BoE)'!M14=3,'Loan Tape (BoE)'!M14=4),"Cash-out"),"") | N13: =IFERROR(INDEX('FF Adj Parameters'!$A$96:$B$99,MATCH('Loan Tape (BoE)'!R13,INDEX('FF Adj Parameters'!$A$96:$B$99,,1),0),2),"Unknown") | O13: =IF('Loan Tape (BoE)'!O14=1,"Yes","No") | P13: =IF('Loan Tape (BoE)'!P13=1,"Yes",IF('Loan Tape (BoE)'!P13=0,"No","")) | Q13: =IF('Loan Tape (BoE)'!Q13=1,"Yes",IF('Loan Tape (BoE)'!Q13=0,"No","")) | R13: =IF('Loan Tape (BoE)'!R13=1,"Yes",IF('Loan Tape (BoE)'!R13=0,"No","")) | S13: =IF('Loan Tape (BoE)'!S13=1,"Yes",IF('Loan Tape (BoE)'!S13=0,"No","")) | T13: =IF('Loan Tape (BoE)'!T13=1,"Yes",IF('Loan Tape (BoE)'!T13=0,"No","")) | U13: =R13+S13 | V13: =IFERROR(IFS('Loan Tape (BoE)'!U14=1,"Employed",'Loan Tape (BoE)'!U14=2,"Self-Employed",'Loan Tape (BoE)'!U14=3,"Unemployed",'Loan Tape (BoE)'!U14=4,"Retired"),"") | W13: =IFERROR(IFS('Loan Tape (BoE)'!V14=1,"Employed",'Loan Tape (BoE)'!V14=2,"Self-Employed",'Loan Tape (BoE)'!V14=3,"Unemployed",'Loan Tape (BoE)'!V14=4,"Retired"),"") | X13: =IF(OR(V13="Self-Employed",W13="Self-Employed"),"Yes","No") | Y13: ='Loan Tape (BoE)'!W14 | Z13: ='Loan Tape (BoE)'!X14 | AA13: =IF(T13=1,Y13,MIN(Y13,Z13)) | AB13: ='Loan Tape (BoE)'!Y14 | AC13: ='Loan Tape (BoE)'!Z14 | AD13: =AB13+AC13 | AE13: ='Loan Tape (BoE)'!AA14 | AF13: ='Loan Tape (BoE)'!AB14 | AG13: =AE13+AF13 | AH13: =MAX('Loan Tape (BoE)'!AC14,'Loan Tape (BoE)'!AD14) | AI13: ='Loan Tape (BoE)'!AE14 | AJ13: =B13*H13/12 | AK13: =IF(AJ13>0,AI13/AJ13,0) | AL13: =IF('Loan Tape (BoE)'!AF14=1,"Yes","No") | AM13: =IF('Loan Tape (BoE)'!AH14=1,"Yes","No") | AN13: =IF('Loan Tape (BoE)'!AI14=1,"Yes","No") | AO13: =IF('Loan Tape (BoE)'!AJ14=1,"Yes","No") | AP13: =IF(OR('Loan Tape (BoE)'!AQ13=1,'Loan Tape (BoE)'!AQ13=2),"Yes",IF('Loan Tape (BoE)'!AQ13=0,"No","")) | AQ13: =IF('Loan Tape (BoE)'!BV49_13<>"",'Loan Tape (BoE)'!BV49_13,"") | AR13: =IF('Loan Tape (BoE)'!BV130_13<>"",'Loan Tape (BoE)'!BV50_13,"") | AS13: =IFERROR(INDEX('FF Adj Parameters'!$A$103:$B$1013,MATCH('Loan Tape (BoE)'!P13,INDEX('FF Adj Parameters'!$A$103:$B$1013,,1),0),2),"Unknown") | AT13: =IF(N13="Interest Only",M5*O5/12,IF(AND(O5>0,ISNUMBER(O5),ISNUMBER(M5)),ABS(PMT(O5/12,AU5,-M5)),0)) | AU13: =IF(ISNUMBER(L13),MAX(0,(L5-'Control Panel'!$B$10)*12/365.25),0) | AV13: =IF(ISNUMBER(L13),IF(L5>'Control Panel'!$B$10,"Valid","Past Maturity"),"No Date") | AW13: =IF(ISNUMBER(K13),MAX(0,('Control Panel'!$B$10-K5)*12/365.25),0)
A14: ='Loan Tape (BoE)'!A15 | B14: =IFERROR(INDEX('FF Adj Parameters'!$A$89:$B$92,MATCH('Loan Tape (BoE)'!C14,INDEX('FF Adj Parameters'!$A$89:$B$92,,1),0),2),"Unknown") | C14: ='Loan Tape (BoE)'!C15 | D14: ='Loan Tape (BoE)'!D15 | E14: ='Loan Tape (BoE)'!E15 | F14: ='Loan Tape (BoE)'!F15 | G14: ='Loan Tape (BoE)'!G15 | H14: ='Loan Tape (BoE)'!H15/100 | I14: =IFERROR(IFS('Loan Tape (BoE)'!I15=1,"House",'Loan Tape (BoE)'!I15=2,"Flat",'Loan Tape (BoE)'!I15=3,"Bungalow",'Loan Tape (BoE)'!I15=4,"Maisonette"),"") | J14: ='Loan Tape (BoE)'!J15 | K14: ='Loan Tape (BoE)'!K15 | L14: =IFERROR(IFS('Loan Tape (BoE)'!L15=1,"Owner Occupied",'Loan Tape (BoE)'!L15=2,"BTL",'Loan Tape (BoE)'!L15=3,"Second Home",'Loan Tape (BoE)'!L15=4,"Investment"),"") | M14: =IFERROR(IFS('Loan Tape (BoE)'!M15=1,"Purchase",'Loan Tape (BoE)'!M15=2,"Remortgage",OR('Loan Tape (BoE)'!M15=3,'Loan Tape (BoE)'!M15=4),"Cash-out"),"") | N14: =IFERROR(INDEX('FF Adj Parameters'!$A$96:$B$99,MATCH('Loan Tape (BoE)'!R14,INDEX('FF Adj Parameters'!$A$96:$B$99,,1),0),2),"Unknown") | O14: =IF('Loan Tape (BoE)'!O15=1,"Yes","No") | P14: =IF('Loan Tape (BoE)'!P14=1,"Yes",IF('Loan Tape (BoE)'!P14=0,"No","")) | Q14: =IF('Loan Tape (BoE)'!Q14=1,"Yes",IF('Loan Tape (BoE)'!Q14=0,"No","")) | R14: =IF('Loan Tape (BoE)'!R14=1,"Yes",IF('Loan Tape (BoE)'!R14=0,"No","")) | S14: =IF('Loan Tape (BoE)'!S14=1,"Yes",IF('Loan Tape (BoE)'!S14=0,"No","")) | T14: =IF('Loan Tape (BoE)'!T14=1,"Yes",IF('Loan Tape (BoE)'!T14=0,"No","")) | U14: =R14+S14 | V14: =IFERROR(IFS('Loan Tape (BoE)'!U15=1,"Employed",'Loan Tape (BoE)'!U15=2,"Self-Employed",'Loan Tape (BoE)'!U15=3,"Unemployed",'Loan Tape (BoE)'!U15=4,"Retired"),"") | W14: =IFERROR(IFS('Loan Tape (BoE)'!V15=1,"Employed",'Loan Tape (BoE)'!V15=2,"Self-Employed",'Loan Tape (BoE)'!V15=3,"Unemployed",'Loan Tape (BoE)'!V15=4,"Retired"),"") | X14: =IF(OR(V14="Self-Employed",W14="Self-Employed"),"Yes","No") | Y14: ='Loan Tape (BoE)'!W15 | Z14: ='Loan Tape (BoE)'!X15 | AA14: =IF(T14=1,Y14,MIN(Y14,Z14)) | AB14: ='Loan Tape (BoE)'!Y15 | AC14: ='Loan Tape (BoE)'!Z15 | AD14: =AB14+AC14 | AE14: ='Loan Tape (BoE)'!AA15 | AF14: ='Loan Tape (BoE)'!AB15 | AG14: =AE14+AF14 | AH14: =MAX('Loan Tape (BoE)'!AC15,'Loan Tape (BoE)'!AD15) | AI14: ='Loan Tape (BoE)'!AE15 | AJ14: =B14*H14/12 | AK14: =IF(AJ14>0,AI14/AJ14,0) | AL14: =IF('Loan Tape (BoE)'!AF15=1,"Yes","No") | AM14: =IF('Loan Tape (BoE)'!AH15=1,"Yes","No") | AN14: =IF('Loan Tape (BoE)'!AI15=1,"Yes","No") | AO14: =IF('Loan Tape (BoE)'!AJ15=1,"Yes","No") | AP14: =IF(OR('Loan Tape (BoE)'!AQ14=1,'Loan Tape (BoE)'!AQ14=2),"Yes",IF('Loan Tape (BoE)'!AQ14=0,"No","")) | AQ14: =IF('Loan Tape (BoE)'!BV49_14<>"",'Loan Tape (BoE)'!BV49_14,"") | AR14: =IF('Loan Tape (BoE)'!BV140_14<>"",'Loan Tape (BoE)'!BV50_14,"") | AS14: =IFERROR(INDEX('FF Adj Parameters'!$A$103:$B$1014,MATCH('Loan Tape (BoE)'!P14,INDEX('FF Adj Parameters'!$A$103:$B$1014,,1),0),2),"Unknown") | AT14: =IF(N14="Interest Only",M5*O5/12,IF(AND(O5>0,ISNUMBER(O5),ISNUMBER(M5)),ABS(PMT(O5/12,AU5,-M5)),0)) | AU14: =IF(ISNUMBER(L14),MAX(0,(L5-'Control Panel'!$B$10)*12/365.25),0) | AV14: =IF(ISNUMBER(L14),IF(L5>'Control Panel'!$B$10,"Valid","Past Maturity"),"No Date") | AW14: =IF(ISNUMBER(K14),MAX(0,('Control Panel'!$B$10-K5)*12/365.25),0)
A15: ='Loan Tape (BoE)'!A16 | B15: =IFERROR(INDEX('FF Adj Parameters'!$A$89:$B$92,MATCH('Loan Tape (BoE)'!C15,INDEX('FF Adj Parameters'!$A$89:$B$92,,1),0),2),"Unknown") | C15: ='Loan Tape (BoE)'!C16 | D15: ='Loan Tape (BoE)'!D16 | E15: ='Loan Tape (BoE)'!E16 | F15: ='Loan Tape (BoE)'!F16 | G15: ='Loan Tape (BoE)'!G16 | H15: ='Loan Tape (BoE)'!H16/100 | I15: =IFERROR(IFS('Loan Tape (BoE)'!I16=1,"House",'Loan Tape (BoE)'!I16=2,"Flat",'Loan Tape (BoE)'!I16=3,"Bungalow",'Loan Tape (BoE)'!I16=4,"Maisonette"),"") | J15: ='Loan Tape (BoE)'!J16 | K15: ='Loan Tape (BoE)'!K16 | L15: =IFERROR(IFS('Loan Tape (BoE)'!L16=1,"Owner Occupied",'Loan Tape (BoE)'!L16=2,"BTL",'Loan Tape (BoE)'!L16=3,"Second Home",'Loan Tape (BoE)'!L16=4,"Investment"),"") | M15: =IFERROR(IFS('Loan Tape (BoE)'!M16=1,"Purchase",'Loan Tape (BoE)'!M16=2,"Remortgage",OR('Loan Tape (BoE)'!M16=3,'Loan Tape (BoE)'!M16=4),"Cash-out"),"") | N15: =IFERROR(INDEX('FF Adj Parameters'!$A$96:$B$99,MATCH('Loan Tape (BoE)'!R15,INDEX('FF Adj Parameters'!$A$96:$B$99,,1),0),2),"Unknown") | O15: =IF('Loan Tape (BoE)'!O16=1,"Yes","No") | P15: =IF('Loan Tape (BoE)'!P15=1,"Yes",IF('Loan Tape (BoE)'!P15=0,"No","")) | Q15: =IF('Loan Tape (BoE)'!Q15=1,"Yes",IF('Loan Tape (BoE)'!Q15=0,"No","")) | R15: =IF('Loan Tape (BoE)'!R15=1,"Yes",IF('Loan Tape (BoE)'!R15=0,"No","")) | S15: =IF('Loan Tape (BoE)'!S15=1,"Yes",IF('Loan Tape (BoE)'!S15=0,"No","")) | T15: =IF('Loan Tape (BoE)'!T15=1,"Yes",IF('Loan Tape (BoE)'!T15=0,"No","")) | U15: =R15+S15 | V15: =IFERROR(IFS('Loan Tape (BoE)'!U16=1,"Employed",'Loan Tape (BoE)'!U16=2,"Self-Employed",'Loan Tape (BoE)'!U16=3,"Unemployed",'Loan Tape (BoE)'!U16=4,"Retired"),"") | W15: =IFERROR(IFS('Loan Tape (BoE)'!V16=1,"Employed",'Loan Tape (BoE)'!V16=2,"Self-Employed",'Loan Tape (BoE)'!V16=3,"Unemployed",'Loan Tape (BoE)'!V16=4,"Retired"),"") | X15: =IF(OR(V15="Self-Employed",W15="Self-Employed"),"Yes","No") | Y15: ='Loan Tape (BoE)'!W16 | Z15: ='Loan Tape (BoE)'!X16 | AA15: =IF(T15=1,Y15,MIN(Y15,Z15)) | AB15: ='Loan Tape (BoE)'!Y16 | AC15: ='Loan Tape (BoE)'!Z16 | AD15: =AB15+AC15 | AE15: ='Loan Tape (BoE)'!AA16 | AF15: ='Loan Tape (BoE)'!AB16 | AG15: =AE15+AF15 | AH15: =MAX('Loan Tape (BoE)'!AC16,'Loan Tape (BoE)'!AD16) | AI15: ='Loan Tape (BoE)'!AE16 | AJ15: =B15*H15/12 | AK15: =IF(AJ15>0,AI15/AJ15,0) | AL15: =IF('Loan Tape (BoE)'!AF16=1,"Yes","No") | AM15: =IF('Loan Tape (BoE)'!AH16=1,"Yes","No") | AN15: =IF('Loan Tape (BoE)'!AI16=1,"Yes","No") | AO15: =IF('Loan Tape (BoE)'!AJ16=1,"Yes","No") | AP15: =IF(OR('Loan Tape (BoE)'!AQ15=1,'Loan Tape (BoE)'!AQ15=2),"Yes",IF('Loan Tape (BoE)'!AQ15=0,"No","")) | AQ15: =IF('Loan Tape (BoE)'!BV49_115<>"",'Loan Tape (BoE)'!BV49_15,"") | AR15: =IF('Loan Tape (BoE)'!BV150_15<>"",'Loan Tape (BoE)'!BV50_15,"") | AS15: =IFERROR(INDEX('FF Adj Parameters'!$A$103:$B$1015,MATCH('Loan Tape (BoE)'!P15,INDEX('FF Adj Parameters'!$A$103:$B$1015,,1),0),2),"Unknown") | AT15: =IF(N15="Interest Only",M5*O5/12,IF(AND(O5>0,ISNUMBER(O5),ISNUMBER(M5)),ABS(PMT(O5/12,AU5,-M5)),0)) | AU15: =IF(ISNUMBER(L15),MAX(0,(L5-'Control Panel'!$B$10)*12/365.25),0) | AV15: =IF(ISNUMBER(L15),IF(L5>'Control Panel'!$B$10,"Valid","Past Maturity"),"No Date") | AW15: =IF(ISNUMBER(K15),MAX(0,('Control Panel'!$B$10-K5)*12/365.25),0)
A16: ='Loan Tape (BoE)'!A17 | B16: =IFERROR(INDEX('FF Adj Parameters'!$A$89:$B$92,MATCH('Loan Tape (BoE)'!C16,INDEX('FF Adj Parameters'!$A$89:$B$92,,1),0),2),"Unknown") | C16: ='Loan Tape (BoE)'!C17 | D16: ='Loan Tape (BoE)'!D17 | E16: ='Loan Tape (BoE)'!E17 | F16: ='Loan Tape (BoE)'!F17 | G16: ='Loan Tape (BoE)'!G17 | H16: ='Loan Tape (BoE)'!H17/100 | I16: =IFERROR(IFS('Loan Tape (BoE)'!I17=1,"House",'Loan Tape (BoE)'!I17=2,"Flat",'Loan Tape (BoE)'!I17=3,"Bungalow",'Loan Tape (BoE)'!I17=4,"Maisonette"),"") | J16: ='Loan Tape (BoE)'!J17 | K16: ='Loan Tape (BoE)'!K17 | L16: =IFERROR(IFS('Loan Tape (BoE)'!L17=1,"Owner Occupied",'Loan Tape (BoE)'!L17=2,"BTL",'Loan Tape (BoE)'!L17=3,"Second Home",'Loan Tape (BoE)'!L17=4,"Investment"),"") | M16: =IFERROR(IFS('Loan Tape (BoE)'!M17=1,"Purchase",'Loan Tape (BoE)'!M17=2,"Remortgage",OR('Loan Tape (BoE)'!M17=3,'Loan Tape (BoE)'!M17=4),"Cash-out"),"") | N16: =IFERROR(INDEX('FF Adj Parameters'!$A$96:$B$99,MATCH('Loan Tape (BoE)'!R16,INDEX('FF Adj Parameters'!$A$96:$B$99,,1),0),2),"Unknown") | O16: =IF('Loan Tape (BoE)'!O17=1,"Yes","No") | P16: =IF('Loan Tape (BoE)'!P16=1,"Yes",IF('Loan Tape (BoE)'!P16=0,"No","")) | Q16: =IF('Loan Tape (BoE)'!Q16=1,"Yes",IF('Loan Tape (BoE)'!Q16=0,"No","")) | R16: =IF('Loan Tape (BoE)'!R16=1,"Yes",IF('Loan Tape (BoE)'!R16=0,"No","")) | S16: =IF('Loan Tape (BoE)'!S16=1,"Yes",IF('Loan Tape (BoE)'!S16=0,"No","")) | T16: =IF('Loan Tape (BoE)'!T16=1,"Yes",IF('Loan Tape (BoE)'!T16=0,"No","")) | U16: =R16+S16 | V16: =IFERROR(IFS('Loan Tape (BoE)'!U17=1,"Employed",'Loan Tape (BoE)'!U17=2,"Self-Employed",'Loan Tape (BoE)'!U17=3,"Unemployed",'Loan Tape (BoE)'!U17=4,"Retired"),"") | W16: =IFERROR(IFS('Loan Tape (BoE)'!V17=1,"Employed",'Loan Tape (BoE)'!V17=2,"Self-Employed",'Loan Tape (BoE)'!V17=3,"Unemployed",'Loan Tape (BoE)'!V17=4,"Retired"),"") | X16: =IF(OR(V16="Self-Employed",W16="Self-Employed"),"Yes","No") | Y16: ='Loan Tape (BoE)'!W17 | Z16: ='Loan Tape (BoE)'!X17 | AA16: =IF(T16=1,Y16,MIN(Y16,Z16)) | AB16: ='Loan Tape (BoE)'!Y17 | AC16: ='Loan Tape (BoE)'!Z17 | AD16: =AB16+AC16 | AE16: ='Loan Tape (BoE)'!AA17 | AF16: ='Loan Tape (BoE)'!AB17 | AG16: =AE16+AF16 | AH16: =MAX('Loan Tape (BoE)'!AC17,'Loan Tape (BoE)'!AD17) | AI16: ='Loan Tape (BoE)'!AE17 | AJ16: =B16*H16/12 | AK16: =IF(AJ16>0,AI16/AJ16,0) | AL16: =IF('Loan Tape (BoE)'!AF17=1,"Yes","No") | AM16: =IF('Loan Tape (BoE)'!AH17=1,"Yes","No") | AN16: =IF('Loan Tape (BoE)'!AI17=1,"Yes","No") | AO16: =IF('Loan Tape (BoE)'!AJ17=1,"Yes","No") | AP16: =IF(OR('Loan Tape (BoE)'!AQ16=1,'Loan Tape (BoE)'!AQ16=2),"Yes",IF('Loan Tape (BoE)'!AQ16=0,"No","")) | AQ16: =IF('Loan Tape (BoE)'!BV49_16<>"",'Loan Tape (BoE)'!BV49_16,"") | AR16: =IF('Loan Tape (BoE)'!BV160_16<>"",'Loan Tape (BoE)'!BV50_16,"") | AS16: =IFERROR(INDEX('FF Adj Parameters'!$A$103:$B$1016,MATCH('Loan Tape (BoE)'!P16,INDEX('FF Adj Parameters'!$A$103:$B$1016,,1),0),2),"Unknown") | AT16: =IF(N16="Interest Only",M5*O5/12,IF(AND(O5>0,ISNUMBER(O5),ISNUMBER(M5)),ABS(PMT(O5/12,AU5,-M5)),0)) | AU16: =IF(ISNUMBER(L16),MAX(0,(L5-'Control Panel'!$B$10)*12/365.25),0) | AV16: =IF(ISNUMBER(L16),IF(L5>'Control Panel'!$B$10,"Valid","Past Maturity"),"No Date") | AW16: =IF(ISNUMBER(K16),MAX(0,('Control Panel'!$B$10-K5)*12/365.25),0)
