Workbook

Sheet Control Panel
A1: S&P WAFF/WALS CALCULATION MODEL
A2: UK Residential Mortgage Pool Analysis - Bank of England Loan Tape Format
A3: Version: 1.0
A4: Created: 14-Jan-2026
A6: MODEL SETTINGS | E6: INSTRUCTIONS
A8: Parameter | B8: Value | C8: Description | E8: 1. Input loan tape data in "Loan Tape" sheet using Bank of England format
A9: Jurisdiction | B9: UK | C9: UK, Ireland, or Netherlands | E9: 2. Configure model settings in yellow cells above
A10: Analysis Date | B10: 46036.342 | C10: Date for seasoning and CCJ calculations | E10: 3. Review FF and LS calculations in respective sheets
A11: Portfolio Cutoff Date | B11: 46036.342 | C11: Loan tape cutoff date | E11: 4. Check "Pool Summary" for WAFF/WALS results
A12: Use Indexed Property Values | B12: YES | C12: Use regional HPI to index property values | E12: 5. Review "Rating CE" for credit enhancement by rating
A13: OLTV Weight | B13: 0.8 | C13: Weight for Original LTV in S&P LTV formula
A14: CLTV Weight | B14: 0.2 | C14: Weight for Current LTV in S&P LTV formula | E14: Color Coding:
A15: Apply Valuation Haircuts | B15: YES | C15: Apply 5% haircut for non-full appraisals | E15: Yellow = User Input
E16: Grey = Calculated (Do not edit)
A17: POOL STATISTICS (READ-ONLY) | E17: Green = Output/Results
A19: Metric | B19: Value
A20: Total Loans | B20: =COUNTA('Loan Tape'!A:A)-1
A21: Total Balance | B21: =SUM('Loan Tape'!D:D)
A22: Weighted Average LTV | B22: =IFERROR(SUMPRODUCT('FF Calculations'!E:E,'Loan Tape'!D:D)/SUM('Loan Tape'!D:D),0)
A23: Weighted Average FICO | B23: =IFERROR(SUMPRODUCT('Loan Tape'!F:F,'Loan Tape'!D:D)/SUM('Loan Tape'!D:D),0)
A24: Pool WAFF (%) | B24: ='Pool Summary'!B5
A25: Pool WALS (%) | B25: ='Pool Summary'!B6
A26: Pool Expected Loss (%) | B26: ='Pool Summary'!B7

Sheet Loan Tape
A1: LOAN TAPE - BANK OF ENGLAND FORMAT
A2: Input loan-level data in yellow cells below. Use Bank of England loan tape field names.
A3: loan_id | B3: property_value_current | C3: property_value_original | D3: current_balance | E3: original_balance | F3: borrower_credit_score | G3: origination_date | H3: maturity_date | I3: interest_rate | J3: product_type | K3: occupancy_type | L3: property_type | M3: region | N3: postcode | O3: borrower_income | P3: rental_income | Q3: arrears_balance | R3: borrower_employment_status | S3: num_borrowers | T3: first_time_buyer | U3: lien_position | V3: loan_purpose | W3: valuation_type | X3: ccj_count | Y3: ccj_date_most_recent | Z3: ccj_total_value | AA3: bankruptcy_flag | AB3: bankruptcy_date | AC3: prior_repossession_flag | AD3: self_certified_flag | AE3: help_to_buy_flag | AF3: payment_shock_flag | AG3: commercial_property_flag | AH3: reperforming_flag | AI3: date_last_90dpd
A4: Unique loan identifier | B4: Current property value | C4: Original property valuation | D4: Current loan balance | E4: Original loan amount | F4: Credit score (e.g., Equifax) | G4: Loan origination date | H4: Loan maturity date | I4: Current interest rate | J4: Repayment/Interest Only/BTL | K4: Owner Occupied/BTL/Second Home | L4: House/Flat/Bungalow/Maisonette | M4: UK region | N4: Property postcode | O4: Annual income (£) | P4: Annual rental income (BTL) | Q4: Current arrears balance | R4: Employed/Self-Employed | S4: Number of borrowers (1/2) | T4: Yes/No | U4: First/Second/Third+ | V4: Purchase/Remortgage/Cash-out | W4: Full/AVM/Drive-by | X4: Number of CCJs | Y4: Date of most recent CCJ | Z4: Total value of CCJs (£) | AA4: Yes/No | AB4: Date of bankruptcy | AC4: Yes/No | AD4: Yes/No | AE4: Yes/No | AF4: Yes/No (discount/fixed-float) | AG4: Yes/No | AH4: Yes/No | AI4: Date last 90+ days past due

Sheet FF Calculations
A1: FORECLOSURE FREQUENCY CALCULATIONS
A2: S&P Global Ratings - UK RMBS Methodology - All formulas are dynamic
A3: Loan ID | B3: Current Balance | C3: FICO Score | D3: OLTV (%) | E3: CLTV (%) | F3: S&P LTV (%) | G3: Base FF (%) | H3: LTV Mult | I3: Originator Adj | J3: Income Mult Adj | K3: BTL/DSCR Adj | L3: Lien Position Adj | M3: Loan Purpose Adj | N3: Arrears Adj | O3: Seasoning Adj | P3: First Time Buyer Adj | Q3: Help to Buy Adj | R3: Self-Cert Adj | S3: Payment Shock Adj | T3: Interest Only Adj | U3: Geographic Adj | V3: Commercial Adj | W3: Self-Employed Adj | X3: CCJ Adj | Y3: Reperforming Adj | Z3: Adjusted FF (%)
A4: ='Loan Tape'!A5 | B4: ='Loan Tape'!D5 | C4: ='Loan Tape'!F5 | D4: =IFERROR('Loan Tape'!E5/'Loan Tape'!C5,0) | E4: =IFERROR( 'Loan Tape'!D5/ ('Loan Tape'!B5* (1-IF(AND('Control Panel'!$B$15="YES",'Loan Tape'!W5<>"Full"),0.05,0))), 0) | F4: ='Control Panel'!$B$13*D4+'Control Panel'!$B$14*E4 | G4: ='Parameter Tables'!$B$5 | H4: =IFERROR( IF(F4<=0.70, 0.1+F4*1.2857, IF(F4<=1.00, 1+F4*2.5, IF(F4<=1.50, MIN(3.5+F4*1.5,5), 5 ) ) ), 1) | I4: =1.00 | J4: =IFERROR( LET( income_mult,'Loan Tape'!D5/'Loan Tape'!O5, num_borr,'Loan Tape'!S5, seasoning,(DATE('Control Panel'!$B$10,1,1)-'Loan Tape'!G5)/365.25, single_adj,IF(income_mult>5,1.5,IF(income_mult>3.5,1.2,1)), joint_adj,IF(income_mult>3.25,1.5,IF(income_mult>2.75,1.2,1)), adj,IF(num_borr=1,single_adj,joint_adj), IF(AND(adj>1,seasoning<=1.5),adj,1) ), 1) | K4: =IFERROR( IF('Loan Tape'!K5="BTL", LET( rental,'Loan Tape'!P5, int_cost,'Loan Tape'!D5*0.055, dscr,rental/int_cost, IF(rental=0,1.7, IF(dscr>1.35,1.25, IF(dscr>1.20,1.35, IF(dscr>=1.00,1.45,1.55) ) ) ) ), 1), 1) | L4: =IFERROR( IF('Loan Tape'!U5="Second",1.5, IF('Loan Tape'!U5="Third+",1.7,1) ), 1) | M4: =IFERROR( IF(AND('Loan Tape'!V5="Cash-out",'Loan Tape'!U5="First"),1.2,1), 1) | N4: =IFERROR( LET( arrears,'Loan Tape'!Q5, monthly_pmt,'Loan Tape'!D5*'Loan Tape'!I5/12, months_arrears,arrears/monthly_pmt, IF(months_arrears>=3,100, IF(months_arrears>=2,5.0, IF(months_arrears>=1,2.5,1) ) ) ), 1) | O4: =IFERROR( IF('Loan Tape'!Q5=0, LET( seasoning,(DATE('Control Panel'!$B$10,1,1)-'Loan Tape'!G5)/365.25, IF(seasoning>10,0.50, IF(seasoning>9,0.55, IF(seasoning>8,0.60, IF(seasoning>7,0.65, IF(seasoning>6,0.70, IF(seasoning>5,0.75,1) ) ) ) ) ) ), 1), 1) | P4: =IFERROR( IF(AND('Loan Tape'!T5="Yes", (DATE('Control Panel'!$B$10,1,1)-'Loan Tape'!G5)/365.25<=1.5), 1.10,1), 1) | Q4: =IFERROR(IF('Loan Tape'!AE5="Yes",1.35,1),1) | R4: =IFERROR( IF('Loan Tape'!AD5="Yes", LET( seasoning,(DATE('Control Panel'!$B$10,1,1)-'Loan Tape'!G5)/365.25*12, base,1.5, factor,IF(seasoning>72,0, IF(seasoning>60,0.15, IF(seasoning>48,0.35, IF(seasoning>36,0.55, IF(seasoning>24,0.80, IF(seasoning>12,0.85,1) ) ) ) ) ), 1+((base-1)*factor) ), 1), 1) | S4: =IFERROR(IF('Loan Tape'!AF5="Yes",1.10,1),1) | T4: =IFERROR( IF('Loan Tape'!J5="Interest Only", LET( yrs_to_mat,('Loan Tape'!H5-DATE('Control Panel'!$B$10,1,1))/365.25, is_btl,'Loan Tape'!K5="BTL", IF(is_btl,1, IF(yrs_to_mat>25,1.10, IF(yrs_to_mat>=15,1.20, IF(yrs_to_mat>=5,1.25,1.25) ) ) ) ), 1), 1) | U4: =1.00 | V4: =IFERROR(IF('Loan Tape'!AG5="Yes",1.85,1),1) | W4: =IFERROR(IF('Loan Tape'!R5="Self-Employed",1.15,1),1) | X4: =IFERROR( LET( ccj_count,'Loan Tape'!X5, ccj_date,'Loan Tape'!Y5, ccj_value,'Loan Tape'!Z5, years_since,(DATE('Control Panel'!$B$10,1,1)-ccj_date)/365.25, IF(ccj_count=0,1, IF(years_since>6,1.075, LET( is_recent,years_since<1, count_adj,IF(ccj_count=1,IF(is_recent,1.10,1.075), IF(ccj_count=2,IF(is_recent,1.50,1.375), IF(ccj_count=3,IF(is_recent,2.50,2.125), IF(ccj_count=4,IF(is_recent,3.80,3.100), IF(is_recent,4.00,3.250) ) ) ) ), value_adj,IF(ccj_value>=10000,MAX(count_adj,4.0), IF(ccj_value>=5000,MAX(count_adj,2.5),count_adj) ), value_adj ) ) ) ), 1) | Y4: =IFERROR( IF('Loan Tape'!AH5="Yes", LET( months_since,(DATE('Control Panel'!$B$10,1,1)-'Loan Tape'!AI5)/30.44, IF(months_since<=12,2.0, IF(months_since<=24,1.5, IF(months_since<=36,1.2,1) ) ) ), 1), 1) | Z4: =IFERROR( IF(N4>=100,1, G4*H4*I4*J4*K4*L4*M4*N4*O4*P4*Q4*R4*S4*T4*U4*V4*W4*X4*Y4 ), 0)
A5: ='Loan Tape'!A6 | B5: ='Loan Tape'!D6 | C5: ='Loan Tape'!F6 | D5: =IFERROR('Loan Tape'!E6/'Loan Tape'!C6,0) | E5: =IFERROR( 'Loan Tape'!D6/ ('Loan Tape'!B6* (1-IF(AND('Control Panel'!$B$15="YES",'Loan Tape'!W6<>"Full"),0.05,0))), 0) | F5: ='Control Panel'!$B$13*D5+'Control Panel'!$B$14*E5 | G5: ='Parameter Tables'!$B$5 | H5: =IFERROR( IF(F5<=0.70, 0.1+F5*1.2857, IF(F5<=1.00, 1+F5*2.5, IF(F5<=1.50, MIN(3.5+F5*1.5,5), 5 ) ) ), 1) | I5: =1.00 | J5: =IFERROR( LET( income_mult,'Loan Tape'!D6/'Loan Tape'!O6, num_borr,'Loan Tape'!S6, seasoning,(DATE('Control Panel'!$B$10,1,1)-'Loan Tape'!G6)/365.25, single_adj,IF(income_mult>5,1.5,IF(income_mult>3.5,1.2,1)), joint_adj,IF(income_mult>3.25,1.5,IF(income_mult>2.75,1.2,1)), adj,IF(num_borr=1,single_adj,joint_adj), IF(AND(adj>1,seasoning<=1.5),adj,1) ), 1) | K5: =IFERROR( IF('Loan Tape'!K6="BTL", LET( rental,'Loan Tape'!P6, int_cost,'Loan Tape'!D6*0.055, dscr,rental/int_cost, IF(rental=0,1.7, IF(dscr>1.35,1.25, IF(dscr>1.20,1.35, IF(dscr>=1.00,1.45,1.55) ) ) ) ), 1), 1) | L5: =IFERROR( IF('Loan Tape'!U6="Second",1.5, IF('Loan Tape'!U6="Third+",1.7,1) ), 1) | M5: =IFERROR( IF(AND('Loan Tape'!V6="Cash-out",'Loan Tape'!U6="First"),1.2,1), 1) | N5: =IFERROR( LET( arrears,'Loan Tape'!Q6, monthly_pmt,'Loan Tape'!D6*'Loan Tape'!I6/12, months_arrears,arrears/monthly_pmt, IF(months_arrears>=3,100, IF(months_arrears>=2,5.0, IF(months_arrears>=1,2.5,1) ) ) ), 1) | O5: =IFERROR( IF('Loan Tape'!Q6=0, LET( seasoning,(DATE('Control Panel'!$B$10,1,1)-'Loan Tape'!G6)/365.25, IF(seasoning>10,0.50, IF(seasoning>9,0.55, IF(seasoning>8,0.60, IF(seasoning>7,0.65, IF(seasoning>6,0.70, IF(seasoning>5,0.75,1) ) ) ) ) ) ), 1), 1) | P5: =IFERROR( IF(AND('Loan Tape'!T6="Yes", (DATE('Control Panel'!$B$10,1,1)-'Loan Tape'!G6)/365.25<=1.5), 1.10,1), 1) | Q5: =IFERROR(IF('Loan Tape'!AE6="Yes",1.35,1),1) | R5: =IFERROR( IF('Loan Tape'!AD6="Yes", LET( seasoning,(DATE('Control Panel'!$B$10,1,1)-'Loan Tape'!G6)/365.25*12, base,1.5, factor,IF(seasoning>72,0, IF(seasoning>60,0.15, IF(seasoning>48,0.35, IF(seasoning>36,0.55, IF(seasoning>24,0.80, IF(seasoning>12,0.85,1) ) ) ) ) ), 1+((base-1)*factor) ), 1), 1) | S5: =IFERROR(IF('Loan Tape'!AF6="Yes",1.10,1),1) | T5: =IFERROR( IF('Loan Tape'!J6="Interest Only", LET( yrs_to_mat,('Loan Tape'!H6-DATE('Control Panel'!$B$10,1,1))/365.25, is_btl,'Loan Tape'!K6="BTL", IF(is_btl,1, IF(yrs_to_mat>25,1.10, IF(yrs_to_mat>=15,1.20, IF(yrs_to_mat>=5,1.25,1.25) ) ) ) ), 1), 1) | U5: =1.00 | V5: =IFERROR(IF('Loan Tape'!AG6="Yes",1.85,1),1) | W5: =IFERROR(IF('Loan Tape'!R6="Self-Employed",1.15,1),1) | X5: =IFERROR( LET( ccj_count,'Loan Tape'!X6, ccj_date,'Loan Tape'!Y6, ccj_value,'Loan Tape'!Z6, years_since,(DATE('Control Panel'!$B$10,1,1)-ccj_date)/365.25, IF(ccj_count=0,1, IF(years_since>6,1.075, LET( is_recent,years_since<1, count_adj,IF(ccj_count=1,IF(is_recent,1.10,1.075), IF(ccj_count=2,IF(is_recent,1.50,1.375), IF(ccj_count=3,IF(is_recent,2.50,2.125), IF(ccj_count=4,IF(is_recent,3.80,3.100), IF(is_recent,4.00,3.250) ) ) ) ), value_adj,IF(ccj_value>=10000,MAX(count_adj,4.0), IF(ccj_value>=5000,MAX(count_adj,2.5),count_adj) ), value_adj ) ) ) ), 1) | Y5: =IFERROR( IF('Loan Tape'!AH6="Yes", LET( months_since,(DATE('Control Panel'!$B$10,1,1)-'Loan Tape'!AI6)/30.44, IF(months_since<=12,2.0, IF(months_since<=24,1.5, IF(months_since<=36,1.2,1) ) ) ), 1), 1) | Z5: =IFERROR( IF(N5>=100,1, G5*H5*I5*J5*K5*L5*M5*N5*O5*P5*Q5*R5*S5*T5*U5*V5*W5*X5*Y5 ), 0)
A6: ='Loan Tape'!A7 | B6: ='Loan Tape'!D7 | C6: ='Loan Tape'!F7 | D6: =IFERROR('Loan Tape'!E7/'Loan Tape'!C7,0) | E6: =IFERROR( 'Loan Tape'!D7/ ('Loan Tape'!B7* (1-IF(AND('Control Panel'!$B$15="YES",'Loan Tape'!W7<>"Full"),0.05,0))), 0) | F6: ='Control Panel'!$B$13*D6+'Control Panel'!$B$14*E6 | G6: ='Parameter Tables'!$B$5 | H6: =IFERROR( IF(F6<=0.70, 0.1+F6*1.2857, IF(F6<=1.00, 1+F6*2.5, IF(F6<=1.50, MIN(3.5+F6*1.5,5), 5 ) ) ), 1) | I6: =1.00 | J6: =IFERROR( LET( income_mult,'Loan Tape'!D7/'Loan Tape'!O7, num_borr,'Loan Tape'!S7, seasoning,(DATE('Control Panel'!$B$10,1,1)-'Loan Tape'!G7)/365.25, single_adj,IF(income_mult>5,1.5,IF(income_mult>3.5,1.2,1)), joint_adj,IF(income_mult>3.25,1.5,IF(income_mult>2.75,1.2,1)), adj,IF(num_borr=1,single_adj,joint_adj), IF(AND(adj>1,seasoning<=1.5),adj,1) ), 1) | K6: =IFERROR( IF('Loan Tape'!K7="BTL", LET( rental,'Loan Tape'!P7, int_cost,'Loan Tape'!D7*0.055, dscr,rental/int_cost, IF(rental=0,1.7, IF(dscr>1.35,1.25, IF(dscr>1.20,1.35, IF(dscr>=1.00,1.45,1.55) ) ) ) ), 1), 1) | L6: =IFERROR( IF('Loan Tape'!U7="Second",1.5, IF('Loan Tape'!U7="Third+",1.7,1) ), 1) | M6: =IFERROR( IF(AND('Loan Tape'!V7="Cash-out",'Loan Tape'!U7="First"),1.2,1), 1) | N6: =IFERROR( LET( arrears,'Loan Tape'!Q7, monthly_pmt,'Loan Tape'!D7*'Loan Tape'!I7/12, months_arrears,arrears/monthly_pmt, IF(months_arrears>=3,100, IF(months_arrears>=2,5.0, IF(months_arrears>=1,2.5,1) ) ) ), 1) | O6: =IFERROR( IF('Loan Tape'!Q7=0, LET( seasoning,(DATE('Control Panel'!$B$10,1,1)-'Loan Tape'!G7)/365.25, IF(seasoning>10,0.50, IF(seasoning>9,0.55, IF(seasoning>8,0.60, IF(seasoning>7,0.65, IF(seasoning>6,0.70, IF(seasoning>5,0.75,1) ) ) ) ) ) ), 1), 1) | P6: =IFERROR( IF(AND('Loan Tape'!T7="Yes", (DATE('Control Panel'!$B$10,1,1)-'Loan Tape'!G7)/365.25<=1.5), 1.10,1), 1) | Q6: =IFERROR(IF('Loan Tape'!AE7="Yes",1.35,1),1) | R6: =IFERROR( IF('Loan Tape'!AD7="Yes", LET( seasoning,(DATE('Control Panel'!$B$10,1,1)-'Loan Tape'!G7)/365.25*12, base,1.5, factor,IF(seasoning>72,0, IF(seasoning>60,0.15, IF(seasoning>48,0.35, IF(seasoning>36,0.55, IF(seasoning>24,0.80, IF(seasoning>12,0.85,1) ) ) ) ) ), 1+((base-1)*factor) ), 1), 1) | S6: =IFERROR(IF('Loan Tape'!AF7="Yes",1.10,1),1) | T6: =IFERROR( IF('Loan Tape'!J7="Interest Only", LET( yrs_to_mat,('Loan Tape'!H7-DATE('Control Panel'!$B$10,1,1))/365.25, is_btl,'Loan Tape'!K7="BTL", IF(is_btl,1, IF(yrs_to_mat>25,1.10, IF(yrs_to_mat>=15,1.20, IF(yrs_to_mat>=5,1.25,1.25) ) ) ) ), 1), 1) | U6: =1.00 | V6: =IFERROR(IF('Loan Tape'!AG7="Yes",1.85,1),1) | W6: =IFERROR(IF('Loan Tape'!R7="Self-Employed",1.15,1),1) | X6: =IFERROR( LET( ccj_count,'Loan Tape'!X7, ccj_date,'Loan Tape'!Y7, ccj_value,'Loan Tape'!Z7, years_since,(DATE('Control Panel'!$B$10,1,1)-ccj_date)/365.25, IF(ccj_count=0,1, IF(years_since>6,1.075, LET( is_recent,years_since<1, count_adj,IF(ccj_count=1,IF(is_recent,1.10,1.075), IF(ccj_count=2,IF(is_recent,1.50,1.375), IF(ccj_count=3,IF(is_recent,2.50,2.125), IF(ccj_count=4,IF(is_recent,3.80,3.100), IF(is_recent,4.00,3.250) ) ) ) ), value_adj,IF(ccj_value>=10000,MAX(count_adj,4.0), IF(ccj_value>=5000,MAX(count_adj,2.5),count_adj) ), value_adj ) ) ) ), 1) | Y6: =IFERROR( IF('Loan Tape'!AH7="Yes", LET( months_since,(DATE('Control Panel'!$B$10,1,1)-'Loan Tape'!AI7)/30.44, IF(months_since<=12,2.0, IF(months_since<=24,1.5, IF(months_since<=36,1.2,1) ) ) ), 1), 1) | Z6: =IFERROR( IF(N6>=100,1, G6*H6*I6*J6*K6*L6*M6*N6*O6*P6*Q6*R6*S6*T6*U6*V6*W6*X6*Y6 ), 0)
A7: ='Loan Tape'!A8 | B7: ='Loan Tape'!D8 | C7: ='Loan Tape'!F8 | D7: =IFERROR('Loan Tape'!E8/'Loan Tape'!C8,0) | E7: =IFERROR( 'Loan Tape'!D8/ ('Loan Tape'!B8* (1-IF(AND('Control Panel'!$B$15="YES",'Loan Tape'!W8<>"Full"),0.05,0))), 0) | F7: ='Control Panel'!$B$13*D7+'Control Panel'!$B$14*E7 | G7: ='Parameter Tables'!$B$5 | H7: =IFERROR( IF(F7<=0.70, 0.1+F7*1.2857, IF(F7<=1.00, 1+F7*2.5, IF(F7<=1.50, MIN(3.5+F7*1.5,5), 5 ) ) ), 1) | I7: =1.00 | J7: =IFERROR( LET( income_mult,'Loan Tape'!D8/'Loan Tape'!O8, num_borr,'Loan Tape'!S8, seasoning,(DATE('Control Panel'!$B$10,1,1)-'Loan Tape'!G8)/365.25, single_adj,IF(income_mult>5,1.5,IF(income_mult>3.5,1.2,1)), joint_adj,IF(income_mult>3.25,1.5,IF(income_mult>2.75,1.2,1)), adj,IF(num_borr=1,single_adj,joint_adj), IF(AND(adj>1,seasoning<=1.5),adj,1) ), 1) | K7: =IFERROR( IF('Loan Tape'!K8="BTL", LET( rental,'Loan Tape'!P8, int_cost,'Loan Tape'!D8*0.055, dscr,rental/int_cost, IF(rental=0,1.7, IF(dscr>1.35,1.25, IF(dscr>1.20,1.35, IF(dscr>=1.00,1.45,1.55) ) ) ) ), 1), 1) | L7: =IFERROR( IF('Loan Tape'!U8="Second",1.5, IF('Loan Tape'!U8="Third+",1.7,1) ), 1) | M7: =IFERROR( IF(AND('Loan Tape'!V8="Cash-out",'Loan Tape'!U8="First"),1.2,1), 1) | N7: =IFERROR( LET( arrears,'Loan Tape'!Q8, monthly_pmt,'Loan Tape'!D8*'Loan Tape'!I8/12, months_arrears,arrears/monthly_pmt, IF(months_arrears>=3,100, IF(months_arrears>=2,5.0, IF(months_arrears>=1,2.5,1) ) ) ), 1) | O7: =IFERROR( IF('Loan Tape'!Q8=0, LET( seasoning,(DATE('Control Panel'!$B$10,1,1)-'Loan Tape'!G8)/365.25, IF(seasoning>10,0.50, IF(seasoning>9,0.55, IF(seasoning>8,0.60, IF(seasoning>7,0.65, IF(seasoning>6,0.70, IF(seasoning>5,0.75,1) ) ) ) ) ) ), 1), 1) | P7: =IFERROR( IF(AND('Loan Tape'!T8="Yes", (DATE('Control Panel'!$B$10,1,1)-'Loan Tape'!G8)/365.25<=1.5), 1.10,1), 1) | Q7: =IFERROR(IF('Loan Tape'!AE8="Yes",1.35,1),1) | R7: =IFERROR( IF('Loan Tape'!AD8="Yes", LET( seasoning,(DATE('Control Panel'!$B$10,1,1)-'Loan Tape'!G8)/365.25*12, base,1.5, factor,IF(seasoning>72,0, IF(seasoning>60,0.15, IF(seasoning>48,0.35, IF(seasoning>36,0.55, IF(seasoning>24,0.80, IF(seasoning>12,0.85,1) ) ) ) ) ), 1+((base-1)*factor) ), 1), 1) | S7: =IFERROR(IF('Loan Tape'!AF8="Yes",1.10,1),1) | T7: =IFERROR( IF('Loan Tape'!J8="Interest Only", LET( yrs_to_mat,('Loan Tape'!H8-DATE('Control Panel'!$B$10,1,1))/365.25, is_btl,'Loan Tape'!K8="BTL", IF(is_btl,1, IF(yrs_to_mat>25,1.10, IF(yrs_to_mat>=15,1.20, IF(yrs_to_mat>=5,1.25,1.25) ) ) ) ), 1), 1) | U7: =1.00 | V7: =IFERROR(IF('Loan Tape'!AG8="Yes",1.85,1),1) | W7: =IFERROR(IF('Loan Tape'!R8="Self-Employed",1.15,1),1) | X7: =IFERROR( LET( ccj_count,'Loan Tape'!X8, ccj_date,'Loan Tape'!Y8, ccj_value,'Loan Tape'!Z8, years_since,(DATE('Control Panel'!$B$10,1,1)-ccj_date)/365.25, IF(ccj_count=0,1, IF(years_since>6,1.075, LET( is_recent,years_since<1, count_adj,IF(ccj_count=1,IF(is_recent,1.10,1.075), IF(ccj_count=2,IF(is_recent,1.50,1.375), IF(ccj_count=3,IF(is_recent,2.50,2.125), IF(ccj_count=4,IF(is_recent,3.80,3.100), IF(is_recent,4.00,3.250) ) ) ) ), value_adj,IF(ccj_value>=10000,MAX(count_adj,4.0), IF(ccj_value>=5000,MAX(count_adj,2.5),count_adj) ), value_adj ) ) ) ), 1) | Y7: =IFERROR( IF('Loan Tape'!AH8="Yes", LET( months_since,(DATE('Control Panel'!$B$10,1,1)-'Loan Tape'!AI8)/30.44, IF(months_since<=12,2.0, IF(months_since<=24,1.5, IF(months_since<=36,1.2,1) ) ) ), 1), 1) | Z7: =IFERROR( IF(N7>=100,1, G7*H7*I7*J7*K7*L7*M7*N7*O7*P7*Q7*R7*S7*T7*U7*V7*W7*X7*Y7 ), 0)
A8: ='Loan Tape'!A9 | B8: ='Loan Tape'!D9 | C8: ='Loan Tape'!F9 | D8: =IFERROR('Loan Tape'!E9/'Loan Tape'!C9,0) | E8: =IFERROR( 'Loan Tape'!D9/ ('Loan Tape'!B9* (1-IF(AND('Control Panel'!$B$15="YES",'Loan Tape'!W9<>"Full"),0.05,0))), 0) | F8: ='Control Panel'!$B$13*D8+'Control Panel'!$B$14*E8 | G8: ='Parameter Tables'!$B$5 | H8: =IFERROR( IF(F8<=0.70, 0.1+F8*1.2857, IF(F8<=1.00, 1+F8*2.5, IF(F8<=1.50, MIN(3.5+F8*1.5,5), 5 ) ) ), 1) | I8: =1.00 | J8: =IFERROR( LET( income_mult,'Loan Tape'!D9/'Loan Tape'!O9, num_borr,'Loan Tape'!S9, seasoning,(DATE('Control Panel'!$B$10,1,1)-'Loan Tape'!G9)/365.25, single_adj,IF(income_mult>5,1.5,IF(income_mult>3.5,1.2,1)), joint_adj,IF(income_mult>3.25,1.5,IF(income_mult>2.75,1.2,1)), adj,IF(num_borr=1,single_adj,joint_adj), IF(AND(adj>1,seasoning<=1.5),adj,1) ), 1) | K8: =IFERROR( IF('Loan Tape'!K9="BTL", LET( rental,'Loan Tape'!P9, int_cost,'Loan Tape'!D9*0.055, dscr,rental/int_cost, IF(rental=0,1.7, IF(dscr>1.35,1.25, IF(dscr>1.20,1.35, IF(dscr>=1.00,1.45,1.55) ) ) ) ), 1), 1) | L8: =IFERROR( IF('Loan Tape'!U9="Second",1.5, IF('Loan Tape'!U9="Third+",1.7,1) ), 1) | M8: =IFERROR( IF(AND('Loan Tape'!V9="Cash-out",'Loan Tape'!U9="First"),1.2,1), 1) | N8: =IFERROR( LET( arrears,'Loan Tape'!Q9, monthly_pmt,'Loan Tape'!D9*'Loan Tape'!I9/12, months_arrears,arrears/monthly_pmt, IF(months_arrears>=3,100, IF(months_arrears>=2,5.0, IF(months_arrears>=1,2.5,1) ) ) ), 1) | O8: =IFERROR( IF('Loan Tape'!Q9=0, LET( seasoning,(DATE('Control Panel'!$B$10,1,1)-'Loan Tape'!G9)/365.25, IF(seasoning>10,0.50, IF(seasoning>9,0.55, IF(seasoning>8,0.60, IF(seasoning>7,0.65, IF(seasoning>6,0.70, IF(seasoning>5,0.75,1) ) ) ) ) ) ), 1), 1) | P8: =IFERROR( IF(AND('Loan Tape'!T9="Yes", (DATE('Control Panel'!$B$10,1,1)-'Loan Tape'!G9)/365.25<=1.5), 1.10,1), 1) | Q8: =IFERROR(IF('Loan Tape'!AE9="Yes",1.35,1),1) | R8: =IFERROR( IF('Loan Tape'!AD9="Yes", LET( seasoning,(DATE('Control Panel'!$B$10,1,1)-'Loan Tape'!G9)/365.25*12, base,1.5, factor,IF(seasoning>72,0, IF(seasoning>60,0.15, IF(seasoning>48,0.35, IF(seasoning>36,0.55, IF(seasoning>24,0.80, IF(seasoning>12,0.85,1) ) ) ) ) ), 1+((base-1)*factor) ), 1), 1) | S8: =IFERROR(IF('Loan Tape'!AF9="Yes",1.10,1),1) | T8: =IFERROR( IF('Loan Tape'!J9="Interest Only", LET( yrs_to_mat,('Loan Tape'!H9-DATE('Control Panel'!$B$10,1,1))/365.25, is_btl,'Loan Tape'!K9="BTL", IF(is_btl,1, IF(yrs_to_mat>25,1.10, IF(yrs_to_mat>=15,1.20, IF(yrs_to_mat>=5,1.25,1.25) ) ) ) ), 1), 1) | U8: =1.00 | V8: =IFERROR(IF('Loan Tape'!AG9="Yes",1.85,1),1) | W8: =IFERROR(IF('Loan Tape'!R9="Self-Employed",1.15,1),1) | X8: =IFERROR( LET( ccj_count,'Loan Tape'!X9, ccj_date,'Loan Tape'!Y9, ccj_value,'Loan Tape'!Z9, years_since,(DATE('Control Panel'!$B$10,1,1)-ccj_date)/365.25, IF(ccj_count=0,1, IF(years_since>6,1.075, LET( is_recent,years_since<1, count_adj,IF(ccj_count=1,IF(is_recent,1.10,1.075), IF(ccj_count=2,IF(is_recent,1.50,1.375), IF(ccj_count=3,IF(is_recent,2.50,2.125), IF(ccj_count=4,IF(is_recent,3.80,3.100), IF(is_recent,4.00,3.250) ) ) ) ), value_adj,IF(ccj_value>=10000,MAX(count_adj,4.0), IF(ccj_value>=5000,MAX(count_adj,2.5),count_adj) ), value_adj ) ) ) ), 1) | Y8: =IFERROR( IF('Loan Tape'!AH9="Yes", LET( months_since,(DATE('Control Panel'!$B$10,1,1)-'Loan Tape'!AI9)/30.44, IF(months_since<=12,2.0, IF(months_since<=24,1.5, IF(months_since<=36,1.2,1) ) ) ), 1), 1) | Z8: =IFERROR( IF(N8>=100,1, G8*H8*I8*J8*K8*L8*M8*N8*O8*P8*Q8*R8*S8*T8*U8*V8*W8*X8*Y8 ), 0)
A9: ='Loan Tape'!A10 | B9: ='Loan Tape'!D10 | C9: ='Loan Tape'!F10 | D9: =IFERROR('Loan Tape'!E10/'Loan Tape'!C10,0) | E9: =IFERROR( 'Loan Tape'!D10/ ('Loan Tape'!B10* (1-IF(AND('Control Panel'!$B$15="YES",'Loan Tape'!W10<>"Full"),0.05,0))), 0) | F9: ='Control Panel'!$B$13*D9+'Control Panel'!$B$14*E9 | G9: ='Parameter Tables'!$B$5 | H9: =IFERROR( IF(F9<=0.70, 0.1+F9*1.2857, IF(F9<=1.00, 1+F9*2.5, IF(F9<=1.50, MIN(3.5+F9*1.5,5), 5 ) ) ), 1) | I9: =1.00 | J9: =IFERROR( LET( income_mult,'Loan Tape'!D10/'Loan Tape'!O10, num_borr,'Loan Tape'!S10, seasoning,(DATE('Control Panel'!$B$10,1,1)-'Loan Tape'!G10)/365.25, single_adj,IF(income_mult>5,1.5,IF(income_mult>3.5,1.2,1)), joint_adj,IF(income_mult>3.25,1.5,IF(income_mult>2.75,1.2,1)), adj,IF(num_borr=1,single_adj,joint_adj), IF(AND(adj>1,seasoning<=1.5),adj,1) ), 1) | K9: =IFERROR( IF('Loan Tape'!K10="BTL", LET( rental,'Loan Tape'!P10, int_cost,'Loan Tape'!D10*0.055, dscr,rental/int_cost, IF(rental=0,1.7, IF(dscr>1.35,1.25, IF(dscr>1.20,1.35, IF(dscr>=1.00,1.45,1.55) ) ) ) ), 1), 1) | L9: =IFERROR( IF('Loan Tape'!U10="Second",1.5, IF('Loan Tape'!U10="Third+",1.7,1) ), 1) | M9: =IFERROR( IF(AND('Loan Tape'!V10="Cash-out",'Loan Tape'!U10="First"),1.2,1), 1) | N9: =IFERROR( LET( arrears,'Loan Tape'!Q10, monthly_pmt,'Loan Tape'!D10*'Loan Tape'!I10/12, months_arrears,arrears/monthly_pmt, IF(months_arrears>=3,100, IF(months_arrears>=2,5.0, IF(months_arrears>=1,2.5,1) ) ) ), 1) | O9: =IFERROR( IF('Loan Tape'!Q10=0, LET( seasoning,(DATE('Control Panel'!$B$10,1,1)-'Loan Tape'!G10)/365.25, IF(seasoning>10,0.50, IF(seasoning>9,0.55, IF(seasoning>8,0.60, IF(seasoning>7,0.65, IF(seasoning>6,0.70, IF(seasoning>5,0.75,1) ) ) ) ) ) ), 1), 1) | P9: =IFERROR( IF(AND('Loan Tape'!T10="Yes", (DATE('Control Panel'!$B$10,1,1)-'Loan Tape'!G10)/365.25<=1.5), 1.10,1), 1) | Q9: =IFERROR(IF('Loan Tape'!AE10="Yes",1.35,1),1) | R9: =IFERROR( IF('Loan Tape'!AD10="Yes", LET( seasoning,(DATE('Control Panel'!$B$10,1,1)-'Loan Tape'!G10)/365.25*12, base,1.5, factor,IF(seasoning>72,0, IF(seasoning>60,0.15, IF(seasoning>48,0.35, IF(seasoning>36,0.55, IF(seasoning>24,0.80, IF(seasoning>12,0.85,1) ) ) ) ) ), 1+((base-1)*factor) ), 1), 1) | S9: =IFERROR(IF('Loan Tape'!AF10="Yes",1.10,1),1) | T9: =IFERROR( IF('Loan Tape'!J10="Interest Only", LET( yrs_to_mat,('Loan Tape'!H10-DATE('Control Panel'!$B$10,1,1))/365.25, is_btl,'Loan Tape'!K10="BTL", IF(is_btl,1, IF(yrs_to_mat>25,1.10, IF(yrs_to_mat>=15,1.20, IF(yrs_to_mat>=5,1.25,1.25) ) ) ) ), 1), 1) | U9: =1.00 | V9: =IFERROR(IF('Loan Tape'!AG10="Yes",1.85,1),1) | W9: =IFERROR(IF('Loan Tape'!R10="Self-Employed",1.15,1),1) | X9: =IFERROR( LET( ccj_count,'Loan Tape'!X10, ccj_date,'Loan Tape'!Y10, ccj_value,'Loan Tape'!Z10, years_since,(DATE('Control Panel'!$B$10,1,1)-ccj_date)/365.25, IF(ccj_count=0,1, IF(years_since>6,1.075, LET( is_recent,years_since<1, count_adj,IF(ccj_count=1,IF(is_recent,1.10,1.075), IF(ccj_count=2,IF(is_recent,1.50,1.375), IF(ccj_count=3,IF(is_recent,2.50,2.125), IF(ccj_count=4,IF(is_recent,3.80,3.100), IF(is_recent,4.00,3.250) ) ) ) ), value_adj,IF(ccj_value>=10000,MAX(count_adj,4.0), IF(ccj_value>=5000,MAX(count_adj,2.5),count_adj) ), value_adj ) ) ) ), 1) | Y9: =IFERROR( IF('Loan Tape'!AH10="Yes", LET( months_since,(DATE('Control Panel'!$B$10,1,1)-'Loan Tape'!AI10)/30.44, IF(months_since<=12,2.0, IF(months_since<=24,1.5, IF(months_since<=36,1.2,1) ) ) ), 1), 1) | Z9: =IFERROR( IF(N9>=100,1, G9*H9*I9*J9*K9*L9*M9*N9*O9*P9*Q9*R9*S9*T9*U9*V9*W9*X9*Y9 ), 0)
A10: ='Loan Tape'!A11 | B10: ='Loan Tape'!D11 | C10: ='Loan Tape'!F11 | D10: =IFERROR('Loan Tape'!E11/'Loan Tape'!C11,0) | E10: =IFERROR( 'Loan Tape'!D11/ ('Loan Tape'!B11* (1-IF(AND('Control Panel'!$B$15="YES",'Loan Tape'!W11<>"Full"),0.05,0))), 0) | F10: ='Control Panel'!$B$13*D10+'Control Panel'!$B$14*E10 | G10: ='Parameter Tables'!$B$5 | H10: =IFERROR( IF(F10<=0.70, 0.1+F10*1.2857, IF(F10<=1.00, 1+F10*2.5, IF(F10<=1.50, MIN(3.5+F10*1.5,5), 5 ) ) ), 1) | I10: =1.00 | J10: =IFERROR( LET( income_mult,'Loan Tape'!D11/'Loan Tape'!O11, num_borr,'Loan Tape'!S11, seasoning,(DATE('Control Panel'!$B$10,1,1)-'Loan Tape'!G11)/365.25, single_adj,IF(income_mult>5,1.5,IF(income_mult>3.5,1.2,1)), joint_adj,IF(income_mult>3.25,1.5,IF(income_mult>2.75,1.2,1)), adj,IF(num_borr=1,single_adj,joint_adj), IF(AND(adj>1,seasoning<=1.5),adj,1) ), 1) | K10: =IFERROR( IF('Loan Tape'!K11="BTL", LET( rental,'Loan Tape'!P11, int_cost,'Loan Tape'!D11*0.055, dscr,rental/int_cost, IF(rental=0,1.7, IF(dscr>1.35,1.25, IF(dscr>1.20,1.35, IF(dscr>=1.00,1.45,1.55) ) ) ) ), 1), 1) | L10: =IFERROR( IF('Loan Tape'!U11="Second",1.5, IF('Loan Tape'!U11="Third+",1.7,1) ), 1) | M10: =IFERROR( IF(AND('Loan Tape'!V11="Cash-out",'Loan Tape'!U11="First"),1.2,1), 1) | N10: =IFERROR( LET( arrears,'Loan Tape'!Q11, monthly_pmt,'Loan Tape'!D11*'Loan Tape'!I11/12, months_arrears,arrears/monthly_pmt, IF(months_arrears>=3,100, IF(months_arrears>=2,5.0, IF(months_arrears>=1,2.5,1) ) ) ), 1) | O10: =IFERROR( IF('Loan Tape'!Q11=0, LET( seasoning,(DATE('Control Panel'!$B$10,1,1)-'Loan Tape'!G11)/365.25, IF(seasoning>10,0.50, IF(seasoning>9,0.55, IF(seasoning>8,0.60, IF(seasoning>7,0.65, IF(seasoning>6,0.70, IF(seasoning>5,0.75,1) ) ) ) ) ) ), 1), 1) | P10: =IFERROR( IF(AND('Loan Tape'!T11="Yes", (DATE('Control Panel'!$B$10,1,1)-'Loan Tape'!G11)/365.25<=1.5), 1.10,1), 1) | Q10: =IFERROR(IF('Loan Tape'!AE11="Yes",1.35,1),1) | R10: =IFERROR( IF('Loan Tape'!AD11="Yes", LET( seasoning,(DATE('Control Panel'!$B$10,1,1)-'Loan Tape'!G11)/365.25*12, base,1.5, factor,IF(seasoning>72,0, IF(seasoning>60,0.15, IF(seasoning>48,0.35, IF(seasoning>36,0.55, IF(seasoning>24,0.80, IF(seasoning>12,0.85,1) ) ) ) ) ), 1+((base-1)*factor) ), 1), 1) | S10: =IFERROR(IF('Loan Tape'!AF11="Yes",1.10,1),1) | T10: =IFERROR( IF('Loan Tape'!J11="Interest Only", LET( yrs_to_mat,('Loan Tape'!H11-DATE('Control Panel'!$B$10,1,1))/365.25, is_btl,'Loan Tape'!K11="BTL", IF(is_btl,1, IF(yrs_to_mat>25,1.10, IF(yrs_to_mat>=15,1.20, IF(yrs_to_mat>=5,1.25,1.25) ) ) ) ), 1), 1) | U10: =1.00 | V10: =IFERROR(IF('Loan Tape'!AG11="Yes",1.85,1),1) | W10: =IFERROR(IF('Loan Tape'!R11="Self-Employed",1.15,1),1) | X10: =IFERROR( LET( ccj_count,'Loan Tape'!X11, ccj_date,'Loan Tape'!Y11, ccj_value,'Loan Tape'!Z11, years_since,(DATE('Control Panel'!$B$10,1,1)-ccj_date)/365.25, IF(ccj_count=0,1, IF(years_since>6,1.075, LET( is_recent,years_since<1, count_adj,IF(ccj_count=1,IF(is_recent,1.10,1.075), IF(ccj_count=2,IF(is_recent,1.50,1.375), IF(ccj_count=3,IF(is_recent,2.50,2.125), IF(ccj_count=4,IF(is_recent,3.80,3.100), IF(is_recent,4.00,3.250) ) ) ) ), value_adj,IF(ccj_value>=10000,MAX(count_adj,4.0), IF(ccj_value>=5000,MAX(count_adj,2.5),count_adj) ), value_adj ) ) ) ), 1) | Y10: =IFERROR( IF('Loan Tape'!AH11="Yes", LET( months_since,(DATE('Control Panel'!$B$10,1,1)-'Loan Tape'!AI11)/30.44, IF(months_since<=12,2.0, IF(months_since<=24,1.5, IF(months_since<=36,1.2,1) ) ) ), 1), 1) | Z10: =IFERROR( IF(N10>=100,1, G10*H10*I10*J10*K10*L10*M10*N10*O10*P10*Q10*R10*S10*T10*U10*V10*W10*X10*Y10 ), 0)
A11: ='Loan Tape'!A12 | B11: ='Loan Tape'!D12 | C11: ='Loan Tape'!F12 | D11: =IFERROR('Loan Tape'!E12/'Loan Tape'!C12,0) | E11: =IFERROR( 'Loan Tape'!D12/ ('Loan Tape'!B12* (1-IF(AND('Control Panel'!$B$15="YES",'Loan Tape'!W12<>"Full"),0.05,0))), 0) | F11: ='Control Panel'!$B$13*D11+'Control Panel'!$B$14*E11 | G11: ='Parameter Tables'!$B$5 | H11: =IFERROR( IF(F11<=0.70, 0.1+F11*1.2857, IF(F11<=1.00, 1+F11*2.5, IF(F11<=1.50, MIN(3.5+F11*1.5,5), 5 ) ) ), 1) | I11: =1.00 | J11: =IFERROR( LET( income_mult,'Loan Tape'!D12/'Loan Tape'!O12, num_borr,'Loan Tape'!S12, seasoning,(DATE('Control Panel'!$B$10,1,1)-'Loan Tape'!G12)/365.25, single_adj,IF(income_mult>5,1.5,IF(income_mult>3.5,1.2,1)), joint_adj,IF(income_mult>3.25,1.5,IF(income_mult>2.75,1.2,1)), adj,IF(num_borr=1,single_adj,joint_adj), IF(AND(adj>1,seasoning<=1.5),adj,1) ), 1) | K11: =IFERROR( IF('Loan Tape'!K12="BTL", LET( rental,'Loan Tape'!P12, int_cost,'Loan Tape'!D12*0.055, dscr,rental/int_cost, IF(rental=0,1.7, IF(dscr>1.35,1.25, IF(dscr>1.20,1.35, IF(dscr>=1.00,1.45,1.55) ) ) ) ), 1), 1) | L11: =IFERROR( IF('Loan Tape'!U12="Second",1.5, IF('Loan Tape'!U12="Third+",1.7,1) ), 1) | M11: =IFERROR( IF(AND('Loan Tape'!V12="Cash-out",'Loan Tape'!U12="First"),1.2,1), 1) | N11: =IFERROR( LET( arrears,'Loan Tape'!Q12, monthly_pmt,'Loan Tape'!D12*'Loan Tape'!I12/12, months_arrears,arrears/monthly_pmt, IF(months_arrears>=3,100, IF(months_arrears>=2,5.0, IF(months_arrears>=1,2.5,1) ) ) ), 1) | O11: =IFERROR( IF('Loan Tape'!Q12=0, LET( seasoning,(DATE('Control Panel'!$B$10,1,1)-'Loan Tape'!G12)/365.25, IF(seasoning>10,0.50, IF(seasoning>9,0.55, IF(seasoning>8,0.60, IF(seasoning>7,0.65, IF(seasoning>6,0.70, IF(seasoning>5,0.75,1) ) ) ) ) ) ), 1), 1) | P11: =IFERROR( IF(AND('Loan Tape'!T12="Yes", (DATE('Control Panel'!$B$10,1,1)-'Loan Tape'!G12)/365.25<=1.5), 1.10,1), 1) | Q11: =IFERROR(IF('Loan Tape'!AE12="Yes",1.35,1),1) | R11: =IFERROR( IF('Loan Tape'!AD12="Yes", LET( seasoning,(DATE('Control Panel'!$B$10,1,1)-'Loan Tape'!G12)/365.25*12, base,1.5, factor,IF(seasoning>72,0, IF(seasoning>60,0.15, IF(seasoning>48,0.35, IF(seasoning>36,0.55, IF(seasoning>24,0.80, IF(seasoning>12,0.85,1) ) ) ) ) ), 1+((base-1)*factor) ), 1), 1) | S11: =IFERROR(IF('Loan Tape'!AF12="Yes",1.10,1),1) | T11: =IFERROR( IF('Loan Tape'!J12="Interest Only", LET( yrs_to_mat,('Loan Tape'!H12-DATE('Control Panel'!$B$10,1,1))/365.25, is_btl,'Loan Tape'!K12="BTL", IF(is_btl,1, IF(yrs_to_mat>25,1.10, IF(yrs_to_mat>=15,1.20, IF(yrs_to_mat>=5,1.25,1.25) ) ) ) ), 1), 1) | U11: =1.00 | V11: =IFERROR(IF('Loan Tape'!AG12="Yes",1.85,1),1) | W11: =IFERROR(IF('Loan Tape'!R12="Self-Employed",1.15,1),1) | X11: =IFERROR( LET( ccj_count,'Loan Tape'!X12, ccj_date,'Loan Tape'!Y12, ccj_value,'Loan Tape'!Z12, years_since,(DATE('Control Panel'!$B$10,1,1)-ccj_date)/365.25, IF(ccj_count=0,1, IF(years_since>6,1.075, LET( is_recent,years_since<1, count_adj,IF(ccj_count=1,IF(is_recent,1.10,1.075), IF(ccj_count=2,IF(is_recent,1.50,1.375), IF(ccj_count=3,IF(is_recent,2.50,2.125), IF(ccj_count=4,IF(is_recent,3.80,3.100), IF(is_recent,4.00,3.250) ) ) ) ), value_adj,IF(ccj_value>=10000,MAX(count_adj,4.0), IF(ccj_value>=5000,MAX(count_adj,2.5),count_adj) ), value_adj ) ) ) ), 1) | Y11: =IFERROR( IF('Loan Tape'!AH12="Yes", LET( months_since,(DATE('Control Panel'!$B$10,1,1)-'Loan Tape'!AI12)/30.44, IF(months_since<=12,2.0, IF(months_since<=24,1.5, IF(months_since<=36,1.2,1) ) ) ), 1), 1) | Z11: =IFERROR( IF(N11>=100,1, G11*H11*I11*J11*K11*L11*M11*N11*O11*P11*Q11*R11*S11*T11*U11*V11*W11*X11*Y11 ), 0)
A12: ='Loan Tape'!A13 | B12: ='Loan Tape'!D13 | C12: ='Loan Tape'!F13 | D12: =IFERROR('Loan Tape'!E13/'Loan Tape'!C13,0) | E12: =IFERROR( 'Loan Tape'!D13/ ('Loan Tape'!B13* (1-IF(AND('Control Panel'!$B$15="YES",'Loan Tape'!W13<>"Full"),0.05,0))), 0) | F12: ='Control Panel'!$B$13*D12+'Control Panel'!$B$14*E12 | G12: ='Parameter Tables'!$B$5 | H12: =IFERROR( IF(F12<=0.70, 0.1+F12*1.2857, IF(F12<=1.00, 1+F12*2.5, IF(F12<=1.50, MIN(3.5+F12*1.5,5), 5 ) ) ), 1) | I12: =1.00 | J12: =IFERROR( LET( income_mult,'Loan Tape'!D13/'Loan Tape'!O13, num_borr,'Loan Tape'!S13, seasoning,(DATE('Control Panel'!$B$10,1,1)-'Loan Tape'!G13)/365.25, single_adj,IF(income_mult>5,1.5,IF(income_mult>3.5,1.2,1)), joint_adj,IF(income_mult>3.25,1.5,IF(income_mult>2.75,1.2,1)), adj,IF(num_borr=1,single_adj,joint_adj), IF(AND(adj>1,seasoning<=1.5),adj,1) ), 1) | K12: =IFERROR( IF('Loan Tape'!K13="BTL", LET( rental,'Loan Tape'!P13, int_cost,'Loan Tape'!D13*0.055, dscr,rental/int_cost, IF(rental=0,1.7, IF(dscr>1.35,1.25, IF(dscr>1.20,1.35, IF(dscr>=1.00,1.45,1.55) ) ) ) ), 1), 1) | L12: =IFERROR( IF('Loan Tape'!U13="Second",1.5, IF('Loan Tape'!U13="Third+",1.7,1) ), 1) | M12: =IFERROR( IF(AND('Loan Tape'!V13="Cash-out",'Loan Tape'!U13="First"),1.2,1), 1) | N12: =IFERROR( LET( arrears,'Loan Tape'!Q13, monthly_pmt,'Loan Tape'!D13*'Loan Tape'!I13/12, months_arrears,arrears/monthly_pmt, IF(months_arrears>=3,100, IF(months_arrears>=2,5.0, IF(months_arrears>=1,2.5,1) ) ) ), 1) | O12: =IFERROR( IF('Loan Tape'!Q13=0, LET( seasoning,(DATE('Control Panel'!$B$10,1,1)-'Loan Tape'!G13)/365.25, IF(seasoning>10,0.50, IF(seasoning>9,0.55, IF(seasoning>8,0.60, IF(seasoning>7,0.65, IF(seasoning>6,0.70, IF(seasoning>5,0.75,1) ) ) ) ) ) ), 1), 1) | P12: =IFERROR( IF(AND('Loan Tape'!T13="Yes", (DATE('Control Panel'!$B$10,1,1)-'Loan Tape'!G13)/365.25<=1.5), 1.10,1), 1) | Q12: =IFERROR(IF('Loan Tape'!AE13="Yes",1.35,1),1) | R12: =IFERROR( IF('Loan Tape'!AD13="Yes", LET( seasoning,(DATE('Control Panel'!$B$10,1,1)-'Loan Tape'!G13)/365.25*12, base,1.5, factor,IF(seasoning>72,0, IF(seasoning>60,0.15, IF(seasoning>48,0.35, IF(seasoning>36,0.55, IF(seasoning>24,0.80, IF(seasoning>12,0.85,1) ) ) ) ) ), 1+((base-1)*factor) ), 1), 1) | S12: =IFERROR(IF('Loan Tape'!AF13="Yes",1.10,1),1) | T12: =IFERROR( IF('Loan Tape'!J13="Interest Only", LET( yrs_to_mat,('Loan Tape'!H13-DATE('Control Panel'!$B$10,1,1))/365.25, is_btl,'Loan Tape'!K13="BTL", IF(is_btl,1, IF(yrs_to_mat>25,1.10, IF(yrs_to_mat>=15,1.20, IF(yrs_to_mat>=5,1.25,1.25) ) ) ) ), 1), 1) | U12: =1.00 | V12: =IFERROR(IF('Loan Tape'!AG13="Yes",1.85,1),1) | W12: =IFERROR(IF('Loan Tape'!R13="Self-Employed",1.15,1),1) | X12: =IFERROR( LET( ccj_count,'Loan Tape'!X13, ccj_date,'Loan Tape'!Y13, ccj_value,'Loan Tape'!Z13, years_since,(DATE('Control Panel'!$B$10,1,1)-ccj_date)/365.25, IF(ccj_count=0,1, IF(years_since>6,1.075, LET( is_recent,years_since<1, count_adj,IF(ccj_count=1,IF(is_recent,1.10,1.075), IF(ccj_count=2,IF(is_recent,1.50,1.375), IF(ccj_count=3,IF(is_recent,2.50,2.125), IF(ccj_count=4,IF(is_recent,3.80,3.100), IF(is_recent,4.00,3.250) ) ) ) ), value_adj,IF(ccj_value>=10000,MAX(count_adj,4.0), IF(ccj_value>=5000,MAX(count_adj,2.5),count_adj) ), value_adj ) ) ) ), 1) | Y12: =IFERROR( IF('Loan Tape'!AH13="Yes", LET( months_since,(DATE('Control Panel'!$B$10,1,1)-'Loan Tape'!AI13)/30.44, IF(months_since<=12,2.0, IF(months_since<=24,1.5, IF(months_since<=36,1.2,1) ) ) ), 1), 1) | Z12: =IFERROR( IF(N12>=100,1, G12*H12*I12*J12*K12*L12*M12*N12*O12*P12*Q12*R12*S12*T12*U12*V12*W12*X12*Y12 ), 0)
A13: ='Loan Tape'!A14 | B13: ='Loan Tape'!D14 | C13: ='Loan Tape'!F14 | D13: =IFERROR('Loan Tape'!E14/'Loan Tape'!C14,0) | E13: =IFERROR( 'Loan Tape'!D14/ ('Loan Tape'!B14* (1-IF(AND('Control Panel'!$B$15="YES",'Loan Tape'!W14<>"Full"),0.05,0))), 0) | F13: ='Control Panel'!$B$13*D13+'Control Panel'!$B$14*E13 | G13: ='Parameter Tables'!$B$5 | H13: =IFERROR( IF(F13<=0.70, 0.1+F13*1.2857, IF(F13<=1.00, 1+F13*2.5, IF(F13<=1.50, MIN(3.5+F13*1.5,5), 5 ) ) ), 1) | I13: =1.00 | J13: =IFERROR( LET( income_mult,'Loan Tape'!D14/'Loan Tape'!O14, num_borr,'Loan Tape'!S14, seasoning,(DATE('Control Panel'!$B$10,1,1)-'Loan Tape'!G14)/365.25, single_adj,IF(income_mult>5,1.5,IF(income_mult>3.5,1.2,1)), joint_adj,IF(income_mult>3.25,1.5,IF(income_mult>2.75,1.2,1)), adj,IF(num_borr=1,single_adj,joint_adj), IF(AND(adj>1,seasoning<=1.5),adj,1) ), 1) | K13: =IFERROR( IF('Loan Tape'!K14="BTL", LET( rental,'Loan Tape'!P14, int_cost,'Loan Tape'!D14*0.055, dscr,rental/int_cost, IF(rental=0,1.7, IF(dscr>1.35,1.25, IF(dscr>1.20,1.35, IF(dscr>=1.00,1.45,1.55) ) ) ) ), 1), 1) | L13: =IFERROR( IF('Loan Tape'!U14="Second",1.5, IF('Loan Tape'!U14="Third+",1.7,1) ), 1) | M13: =IFERROR( IF(AND('Loan Tape'!V14="Cash-out",'Loan Tape'!U14="First"),1.2,1), 1) | N13: =IFERROR( LET( arrears,'Loan Tape'!Q14, monthly_pmt,'Loan Tape'!D14*'Loan Tape'!I14/12, months_arrears,arrears/monthly_pmt, IF(months_arrears>=3,100, IF(months_arrears>=2,5.0, IF(months_arrears>=1,2.5,1) ) ) ), 1) | O13: =IFERROR( IF('Loan Tape'!Q14=0, LET( seasoning,(DATE('Control Panel'!$B$10,1,1)-'Loan Tape'!G14)/365.25, IF(seasoning>10,0.50, IF(seasoning>9,0.55, IF(seasoning>8,0.60, IF(seasoning>7,0.65, IF(seasoning>6,0.70, IF(seasoning>5,0.75,1) ) ) ) ) ) ), 1), 1) | P13: =IFERROR( IF(AND('Loan Tape'!T14="Yes", (DATE('Control Panel'!$B$10,1,1)-'Loan Tape'!G14)/365.25<=1.5), 1.10,1), 1) | Q13: =IFERROR(IF('Loan Tape'!AE14="Yes",1.35,1),1) | R13: =IFERROR( IF('Loan Tape'!AD14="Yes", LET( seasoning,(DATE('Control Panel'!$B$10,1,1)-'Loan Tape'!G14)/365.25*12, base,1.5, factor,IF(seasoning>72,0, IF(seasoning>60,0.15, IF(seasoning>48,0.35, IF(seasoning>36,0.55, IF(seasoning>24,0.80, IF(seasoning>12,0.85,1) ) ) ) ) ), 1+((base-1)*factor) ), 1), 1) | S13: =IFERROR(IF('Loan Tape'!AF14="Yes",1.10,1),1) | T13: =IFERROR( IF('Loan Tape'!J14="Interest Only", LET( yrs_to_mat,('Loan Tape'!H14-DATE('Control Panel'!$B$10,1,1))/365.25, is_btl,'Loan Tape'!K14="BTL", IF(is_btl,1, IF(yrs_to_mat>25,1.10, IF(yrs_to_mat>=15,1.20, IF(yrs_to_mat>=5,1.25,1.25) ) ) ) ), 1), 1) | U13: =1.00 | V13: =IFERROR(IF('Loan Tape'!AG14="Yes",1.85,1),1) | W13: =IFERROR(IF('Loan Tape'!R14="Self-Employed",1.15,1),1) | X13: =IFERROR( LET( ccj_count,'Loan Tape'!X14, ccj_date,'Loan Tape'!Y14, ccj_value,'Loan Tape'!Z14, years_since,(DATE('Control Panel'!$B$10,1,1)-ccj_date)/365.25, IF(ccj_count=0,1, IF(years_since>6,1.075, LET( is_recent,years_since<1, count_adj,IF(ccj_count=1,IF(is_recent,1.10,1.075), IF(ccj_count=2,IF(is_recent,1.50,1.375), IF(ccj_count=3,IF(is_recent,2.50,2.125), IF(ccj_count=4,IF(is_recent,3.80,3.100), IF(is_recent,4.00,3.250) ) ) ) ), value_adj,IF(ccj_value>=10000,MAX(count_adj,4.0), IF(ccj_value>=5000,MAX(count_adj,2.5),count_adj) ), value_adj ) ) ) ), 1) | Y13: =IFERROR( IF('Loan Tape'!AH14="Yes", LET( months_since,(DATE('Control Panel'!$B$10,1,1)-'Loan Tape'!AI14)/30.44, IF(months_since<=12,2.0, IF(months_since<=24,1.5, IF(months_since<=36,1.2,1) ) ) ), 1), 1) | Z13: =IFERROR( IF(N13>=100,1, G13*H13*I13*J13*K13*L13*M13*N13*O13*P13*Q13*R13*S13*T13*U13*V13*W13*X13*Y13 ), 0)
A14: ='Loan Tape'!A15 | B14: ='Loan Tape'!D15 | C14: ='Loan Tape'!F15 | D14: =IFERROR('Loan Tape'!E15/'Loan Tape'!C15,0) | E14: =IFERROR( 'Loan Tape'!D15/ ('Loan Tape'!B15* (1-IF(AND('Control Panel'!$B$15="YES",'Loan Tape'!W15<>"Full"),0.05,0))), 0) | F14: ='Control Panel'!$B$13*D14+'Control Panel'!$B$14*E14 | G14: ='Parameter Tables'!$B$5 | H14: =IFERROR( IF(F14<=0.70, 0.1+F14*1.2857, IF(F14<=1.00, 1+F14*2.5, IF(F14<=1.50, MIN(3.5+F14*1.5,5), 5 ) ) ), 1) | I14: =1.00 | J14: =IFERROR( LET( income_mult,'Loan Tape'!D15/'Loan Tape'!O15, num_borr,'Loan Tape'!S15, seasoning,(DATE('Control Panel'!$B$10,1,1)-'Loan Tape'!G15)/365.25, single_adj,IF(income_mult>5,1.5,IF(income_mult>3.5,1.2,1)), joint_adj,IF(income_mult>3.25,1.5,IF(income_mult>2.75,1.2,1)), adj,IF(num_borr=1,single_adj,joint_adj), IF(AND(adj>1,seasoning<=1.5),adj,1) ), 1) | K14: =IFERROR( IF('Loan Tape'!K15="BTL", LET( rental,'Loan Tape'!P15, int_cost,'Loan Tape'!D15*0.055, dscr,rental/int_cost, IF(rental=0,1.7, IF(dscr>1.35,1.25, IF(dscr>1.20,1.35, IF(dscr>=1.00,1.45,1.55) ) ) ) ), 1), 1) | L14: =IFERROR( IF('Loan Tape'!U15="Second",1.5, IF('Loan Tape'!U15="Third+",1.7,1) ), 1) | M14: =IFERROR( IF(AND('Loan Tape'!V15="Cash-out",'Loan Tape'!U15="First"),1.2,1), 1) | N14: =IFERROR( LET( arrears,'Loan Tape'!Q15, monthly_pmt,'Loan Tape'!D15*'Loan Tape'!I15/12, months_arrears,arrears/monthly_pmt, IF(months_arrears>=3,100, IF(months_arrears>=2,5.0, IF(months_arrears>=1,2.5,1) ) ) ), 1) | O14: =IFERROR( IF('Loan Tape'!Q15=0, LET( seasoning,(DATE('Control Panel'!$B$10,1,1)-'Loan Tape'!G15)/365.25, IF(seasoning>10,0.50, IF(seasoning>9,0.55, IF(seasoning>8,0.60, IF(seasoning>7,0.65, IF(seasoning>6,0.70, IF(seasoning>5,0.75,1) ) ) ) ) ) ), 1), 1) | P14: =IFERROR( IF(AND('Loan Tape'!T15="Yes", (DATE('Control Panel'!$B$10,1,1)-'Loan Tape'!G15)/365.25<=1.5), 1.10,1), 1) | Q14: =IFERROR(IF('Loan Tape'!AE15="Yes",1.35,1),1) | R14: =IFERROR( IF('Loan Tape'!AD15="Yes", LET( seasoning,(DATE('Control Panel'!$B$10,1,1)-'Loan Tape'!G15)/365.25*12, base,1.5, factor,IF(seasoning>72,0, IF(seasoning>60,0.15, IF(seasoning>48,0.35, IF(seasoning>36,0.55, IF(seasoning>24,0.80, IF(seasoning>12,0.85,1) ) ) ) ) ), 1+((base-1)*factor) ), 1), 1) | S14: =IFERROR(IF('Loan Tape'!AF15="Yes",1.10,1),1) | T14: =IFERROR( IF('Loan Tape'!J15="Interest Only", LET( yrs_to_mat,('Loan Tape'!H15-DATE('Control Panel'!$B$10,1,1))/365.25, is_btl,'Loan Tape'!K15="BTL", IF(is_btl,1, IF(yrs_to_mat>25,1.10, IF(yrs_to_mat>=15,1.20, IF(yrs_to_mat>=5,1.25,1.25) ) ) ) ), 1), 1) | U14: =1.00 | V14: =IFERROR(IF('Loan Tape'!AG15="Yes",1.85,1),1) | W14: =IFERROR(IF('Loan Tape'!R15="Self-Employed",1.15,1),1) | X14: =IFERROR( LET( ccj_count,'Loan Tape'!X15, ccj_date,'Loan Tape'!Y15, ccj_value,'Loan Tape'!Z15, years_since,(DATE('Control Panel'!$B$10,1,1)-ccj_date)/365.25, IF(ccj_count=0,1, IF(years_since>6,1.075, LET( is_recent,years_since<1, count_adj,IF(ccj_count=1,IF(is_recent,1.10,1.075), IF(ccj_count=2,IF(is_recent,1.50,1.375), IF(ccj_count=3,IF(is_recent,2.50,2.125), IF(ccj_count=4,IF(is_recent,3.80,3.100), IF(is_recent,4.00,3.250) ) ) ) ), value_adj,IF(ccj_value>=10000,MAX(count_adj,4.0), IF(ccj_value>=5000,MAX(count_adj,2.5),count_adj) ), value_adj ) ) ) ), 1) | Y14: =IFERROR( IF('Loan Tape'!AH15="Yes", LET( months_since,(DATE('Control Panel'!$B$10,1,1)-'Loan Tape'!AI15)/30.44, IF(months_since<=12,2.0, IF(months_since<=24,1.5, IF(months_since<=36,1.2,1) ) ) ), 1), 1) | Z14: =IFERROR( IF(N14>=100,1, G14*H14*I14*J14*K14*L14*M14*N14*O14*P14*Q14*R14*S14*T14*U14*V14*W14*X14*Y14 ), 0)
A15: ='Loan Tape'!A16 | B15: ='Loan Tape'!D16 | C15: ='Loan Tape'!F16 | D15: =IFERROR('Loan Tape'!E16/'Loan Tape'!C16,0) | E15: =IFERROR( 'Loan Tape'!D16/ ('Loan Tape'!B16* (1-IF(AND('Control Panel'!$B$15="YES",'Loan Tape'!W16<>"Full"),0.05,0))), 0) | F15: ='Control Panel'!$B$13*D15+'Control Panel'!$B$14*E15 | G15: ='Parameter Tables'!$B$5 | H15: =IFERROR( IF(F15<=0.70, 0.1+F15*1.2857, IF(F15<=1.00, 1+F15*2.5, IF(F15<=1.50, MIN(3.5+F15*1.5,5), 5 ) ) ), 1) | I15: =1.00 | J15: =IFERROR( LET( income_mult,'Loan Tape'!D16/'Loan Tape'!O16, num_borr,'Loan Tape'!S16, seasoning,(DATE('Control Panel'!$B$10,1,1)-'Loan Tape'!G16)/365.25, single_adj,IF(income_mult>5,1.5,IF(income_mult>3.5,1.2,1)), joint_adj,IF(income_mult>3.25,1.5,IF(income_mult>2.75,1.2,1)), adj,IF(num_borr=1,single_adj,joint_adj), IF(AND(adj>1,seasoning<=1.5),adj,1) ), 1) | K15: =IFERROR( IF('Loan Tape'!K16="BTL", LET( rental,'Loan Tape'!P16, int_cost,'Loan Tape'!D16*0.055, dscr,rental/int_cost, IF(rental=0,1.7, IF(dscr>1.35,1.25, IF(dscr>1.20,1.35, IF(dscr>=1.00,1.45,1.55) ) ) ) ), 1), 1) | L15: =IFERROR( IF('Loan Tape'!U16="Second",1.5, IF('Loan Tape'!U16="Third+",1.7,1) ), 1) | M15: =IFERROR( IF(AND('Loan Tape'!V16="Cash-out",'Loan Tape'!U16="First"),1.2,1), 1) | N15: =IFERROR( LET( arrears,'Loan Tape'!Q16, monthly_pmt,'Loan Tape'!D16*'Loan Tape'!I16/12, months_arrears,arrears/monthly_pmt, IF(months_arrears>=3,100, IF(months_arrears>=2,5.0, IF(months_arrears>=1,2.5,1) ) ) ), 1) | O15: =IFERROR( IF('Loan Tape'!Q16=0, LET( seasoning,(DATE('Control Panel'!$B$10,1,1)-'Loan Tape'!G16)/365.25, IF(seasoning>10,0.50, IF(seasoning>9,0.55, IF(seasoning>8,0.60, IF(seasoning>7,0.65, IF(seasoning>6,0.70, IF(seasoning>5,0.75,1) ) ) ) ) ) ), 1), 1) | P15: =IFERROR( IF(AND('Loan Tape'!T16="Yes", (DATE('Control Panel'!$B$10,1,1)-'Loan Tape'!G16)/365.25<=1.5), 1.10,1), 1) | Q15: =IFERROR(IF('Loan Tape'!AE16="Yes",1.35,1),1) | R15: =IFERROR( IF('Loan Tape'!AD16="Yes", LET( seasoning,(DATE('Control Panel'!$B$10,1,1)-'Loan Tape'!G16)/365.25*12, base,1.5, factor,IF(seasoning>72,0, IF(seasoning>60,0.15, IF(seasoning>48,0.35, IF(seasoning>36,0.55, IF(seasoning>24,0.80, IF(seasoning>12,0.85,1) ) ) ) ) ), 1+((base-1)*factor) ), 1), 1) | S15: =IFERROR(IF('Loan Tape'!AF16="Yes",1.10,1),1) | T15: =IFERROR( IF('Loan Tape'!J16="Interest Only", LET( yrs_to_mat,('Loan Tape'!H16-DATE('Control Panel'!$B$10,1,1))/365.25, is_btl,'Loan Tape'!K16="BTL", IF(is_btl,1, IF(yrs_to_mat>25,1.10, IF(yrs_to_mat>=15,1.20, IF(yrs_to_mat>=5,1.25,1.25) ) ) ) ), 1), 1) | U15: =1.00 | V15: =IFERROR(IF('Loan Tape'!AG16="Yes",1.85,1),1) | W15: =IFERROR(IF('Loan Tape'!R16="Self-Employed",1.15,1),1) | X15: =IFERROR( LET( ccj_count,'Loan Tape'!X16, ccj_date,'Loan Tape'!Y16, ccj_value,'Loan Tape'!Z16, years_since,(DATE('Control Panel'!$B$10,1,1)-ccj_date)/365.25, IF(ccj_count=0,1, IF(years_since>6,1.075, LET( is_recent,years_since<1, count_adj,IF(ccj_count=1,IF(is_recent,1.10,1.075), IF(ccj_count=2,IF(is_recent,1.50,1.375), IF(ccj_count=3,IF(is_recent,2.50,2.125), IF(ccj_count=4,IF(is_recent,3.80,3.100), IF(is_recent,4.00,3.250) ) ) ) ), value_adj,IF(ccj_value>=10000,MAX(count_adj,4.0), IF(ccj_value>=5000,MAX(count_adj,2.5),count_adj) ), value_adj ) ) ) ), 1) | Y15: =IFERROR( IF('Loan Tape'!AH16="Yes", LET( months_since,(DATE('Control Panel'!$B$10,1,1)-'Loan Tape'!AI16)/30.44, IF(months_since<=12,2.0, IF(months_since<=24,1.5, IF(months_since<=36,1.2,1) ) ) ), 1), 1) | Z15: =IFERROR( IF(N15>=100,1, G15*H15*I15*J15*K15*L15*M15*N15*O15*P15*Q15*R15*S15*T15*U15*V15*W15*X15*Y15 ), 0)
... A103: ='Loan Tape'!A104 | B103: ='Loan Tape'!D104 | C103: ='Loan Tape'!F104 | D103: =IFERROR('Loan Tape'!E104/'Loan Tape'!C104,0) | E103: =IFERROR( 'Loan Tape'!D104/ ('Loan Tape'!B104* (1-IF(AND('Control Panel'!$B$15="YES",'Loan Tape'!W104<>"Full"),0.05,0))), 0) | F103: ='Control Panel'!$B$13*D103+'Control Panel'!$B$14*E103 | G103: ='Parameter Tables'!$B$5 | H103: =IFERROR( IF(F103<=0.70, 0.1+F103*1.2857, IF(F103<=1.00, 1+F103*2.5, IF(F103<=1.50, MIN(3.5+F103*1.5,5), 5 ) ) ), 1) | I103: =1.00 | J103: =IFERROR( LET( income_mult,'Loan Tape'!D104/'Loan Tape'!O104, num_borr,'Loan Tape'!S104, seasoning,(DATE('Control Panel'!$B$10,1,1)-'Loan Tape'!G104)/365.25, single_adj,IF(income_mult>5,1.5,IF(income_mult>3.5,1.2,1)), joint_adj,IF(income_mult>3.25,1.5,IF(income_mult>2.75,1.2,1)), adj,IF(num_borr=1,single_adj,joint_adj), IF(AND(adj>1,seasoning<=1.5),adj,1) ), 1) | K103: =IFERROR( IF('Loan Tape'!K104="BTL", LET( rental,'Loan Tape'!P104, int_cost,'Loan Tape'!D104*0.055, dscr,rental/int_cost, IF(rental=0,1.7, IF(dscr>1.35,1.25, IF(dscr>1.20,1.35, IF(dscr>=1.00,1.45,1.55) ) ) ) ), 1), 1) | L103: =IFERROR( IF('Loan Tape'!U104="Second",1.5, IF('Loan Tape'!U104="Third+",1.7,1) ), 1) | M103: =IFERROR( IF(AND('Loan Tape'!V104="Cash-out",'Loan Tape'!U104="First"),1.2,1), 1) | N103: =IFERROR( LET( arrears,'Loan Tape'!Q104, monthly_pmt,'Loan Tape'!D104*'Loan Tape'!I104/12, months_arrears,arrears/monthly_pmt, IF(months_arrears>=3,100, IF(months_arrears>=2,5.0, IF(months_arrears>=1,2.5,1) ) ) ), 1) | O103: =IFERROR( IF('Loan Tape'!Q104=0, LET( seasoning,(DATE('Control Panel'!$B$10,1,1)-'Loan Tape'!G104)/365.25, IF(seasoning>10,0.50, IF(seasoning>9,0.55, IF(seasoning>8,0.60, IF(seasoning>7,0.65, IF(seasoning>6,0.70, IF(seasoning>5,0.75,1) ) ) ) ) ) ), 1), 1) | P103: =IFERROR( IF(AND('Loan Tape'!T104="Yes", (DATE('Control Panel'!$B$10,1,1)-'Loan Tape'!G104)/365.25<=1.5), 1.10,1), 1) | Q103: =IFERROR(IF('Loan Tape'!AE104="Yes",1.35,1),1) | R103: =IFERROR( IF('Loan Tape'!AD104="Yes", LET( seasoning,(DATE('Control Panel'!$B$10,1,1)-'Loan Tape'!G104)/365.25*12, base,1.5, factor,IF(seasoning>72,0, IF(seasoning>60,0.15, IF(seasoning>48,0.35, IF(seasoning>36,0.55, IF(seasoning>24,0.80, IF(seasoning>12,0.85,1) ) ) ) ) ), 1+((base-1)*factor) ), 1), 1) | S103: =IFERROR(IF('Loan Tape'!AF104="Yes",1.10,1),1) | T103: =IFERROR( IF('Loan Tape'!J104="Interest Only", LET( yrs_to_mat,('Loan Tape'!H104-DATE('Control Panel'!$B$10,1,1))/365.25, is_btl,'Loan Tape'!K104="BTL", IF(is_btl,1, IF(yrs_to_mat>25,1.10, IF(yrs_to_mat>=15,1.20, IF(yrs_to_mat>=5,1.25,1.25) ) ) ) ), 1), 1) | U103: =1.00 | V103: =IFERROR(IF('Loan Tape'!AG104="Yes",1.85,1),1) | W103: =IFERROR(IF('Loan Tape'!R104="Self-Employed",1.15,1),1) | X103: =IFERROR( LET( ccj_count,'Loan Tape'!X104, ccj_date,'Loan Tape'!Y104, ccj_value,'Loan Tape'!Z104, years_since,(DATE('Control Panel'!$B$10,1,1)-ccj_date)/365.25, IF(ccj_count=0,1, IF(years_since>6,1.075, LET( is_recent,years_since<1, count_adj,IF(ccj_count=1,IF(is_recent,1.10,1.075), IF(ccj_count=2,IF(is_recent,1.50,1.375), IF(ccj_count=3,IF(is_recent,2.50,2.125), IF(ccj_count=4,IF(is_recent,3.80,3.100), IF(is_recent,4.00,3.250) ) ) ) ), value_adj,IF(ccj_value>=10000,MAX(count_adj,4.0), IF(ccj_value>=5000,MAX(count_adj,2.5),count_adj) ), value_adj ) ) ) ), 1) | Y103: =IFERROR( IF('Loan Tape'!AH104="Yes", LET( months_since,(DATE('Control Panel'!$B$10,1,1)-'Loan Tape'!AI104)/30.44, IF(months_since<=12,2.0, IF(months_since<=24,1.5, IF(months_since<=36,1.2,1) ) ) ), 1), 1) | Z103: =IFERROR( IF(N103>=100,1, G103*H103*I103*J103*K103*L103*M103*N103*O103*P103*Q103*R103*S103*T103*U103*V103*W103*X103*Y103 ), 0)

Sheet LS Calculations
A1: LOSS SEVERITY CALCULATIONS
A2: S&P Global Ratings - UK RMBS Methodology - Market Value Decline & Loss Given Default
A3: Loan ID | B3: Current Balance | C3: Property Value | D3: S&P LTV (%) | E3: Jumbo Adj (£) | F3: MVD Applied (%) | G3: Post-Repo Value (£) | H3: Fixed FC (£) | I3: Variable FC (£) | J3: Total FC (£) | K3: Accrued Int (£) | L3: Total Claim (£) | M3: Recoveries (£) | N3: Loss Amount (£) | O3: Loss Severity (%)
A4: ='Loan Tape'!A5 | B4: ='Loan Tape'!D5 | C4: ='Loan Tape'!B5*(1-IF(AND('Control Panel'!$B$15="YES",'Loan Tape'!W5<>"Full"),0.05,0)) | D4: ='FF Calculations'!F4 | E4: =IFERROR( LET( region,'Loan Tape'!M5, prop_val,C4, london_thresh,'Parameter Tables'!$G$36, south_thresh,'Parameter Tables'!$G$35, north_thresh,'Parameter Tables'!$G$34, threshold,IF(region="Greater London",london_thresh, IF(OR(region="South East",region="South West"),south_thresh,north_thresh) ), IF(prop_val>threshold,(prop_val-threshold)*0.20,0) ), 0) | F4: =0.45 | G4: =(C4-E4)*(1-F4) | H4: =IFERROR( IF('Loan Tape'!U5="First",5000,7000), 5000) | I4: =G4*0.03 | J4: =H4+I4 | K4: =IFERROR( LET( is_btl,'Loan Tape'!K5="BTL", is_subsequent,'Loan Tape'!U5<>"First", months,IF(is_subsequent,21,IF(is_btl,12,18)), B4*'Loan Tape'!I5*months/12 ), 0) | L4: =B4+J4+K4 | M4: =MAX(G4-J4,0) | N4: =L4-M4 | O4: =IFERROR(N4/B4,0)
A5: ='Loan Tape'!A6 | B5: ='Loan Tape'!D6 | C5: ='Loan Tape'!B6*(1-IF(AND('Control Panel'!$B$15="YES",'Loan Tape'!W6<>"Full"),0.05,0)) | D5: ='FF Calculations'!F5 | E5: =IFERROR( LET( region,'Loan Tape'!M6, prop_val,C5, london_thresh,'Parameter Tables'!$G$36, south_thresh,'Parameter Tables'!$G$35, north_thresh,'Parameter Tables'!$G$34, threshold,IF(region="Greater London",london_thresh, IF(OR(region="South East",region="South West"),south_thresh,north_thresh) ), IF(prop_val>threshold,(prop_val-threshold)*0.20,0) ), 0) | F5: =0.45 | G5: =(C5-E5)*(1-F5) | H5: =IFERROR( IF('Loan Tape'!U6="First",5000,7000), 5000) | I5: =G5*0.03 | J5: =H5+I5 | K5: =IFERROR( LET( is_btl,'Loan Tape'!K6="BTL", is_subsequent,'Loan Tape'!U6<>"First", months,IF(is_subsequent,21,IF(is_btl,12,18)), B5*'Loan Tape'!I6*months/12 ), 0) | L5: =B5+J5+K5 | M5: =MAX(G5-J5,0) | N5: =L5-M5 | O5: =IFERROR(N5/B5,0)
A6: ='Loan Tape'!A7 | B6: ='Loan Tape'!D7 | C6: ='Loan Tape'!B7*(1-IF(AND('Control Panel'!$B$15="YES",'Loan Tape'!W7<>"Full"),0.05,0)) | D6: ='FF Calculations'!F6 | E6: =IFERROR( LET( region,'Loan Tape'!M7, prop_val,C6, london_thresh,'Parameter Tables'!$G$36, south_thresh,'Parameter Tables'!$G$35, north_thresh,'Parameter Tables'!$G$34, threshold,IF(region="Greater London",london_thresh, IF(OR(region="South East",region="South West"),south_thresh,north_thresh) ), IF(prop_val>threshold,(prop_val-threshold)*0.20,0) ), 0) | F6: =0.45 | G6: =(C6-E6)*(1-F6) | H6: =IFERROR( IF('Loan Tape'!U7="First",5000,7000), 5000) | I6: =G6*0.03 | J6: =H6+I6 | K6: =IFERROR( LET( is_btl,'Loan Tape'!K7="BTL", is_subsequent,'Loan Tape'!U7<>"First", months,IF(is_subsequent,21,IF(is_btl,12,18)), B6*'Loan Tape'!I7*months/12 ), 0) | L6: =B6+J6+K6 | M6: =MAX(G6-J6,0) | N6: =L6-M6 | O6: =IFERROR(N6/B6,0)
A7: ='Loan Tape'!A8 | B7: ='Loan Tape'!D8 | C7: ='Loan Tape'!B8*(1-IF(AND('Control Panel'!$B$15="YES",'Loan Tape'!W8<>"Full"),0.05,0)) | D7: ='FF Calculations'!F7 | E7: =IFERROR( LET( region,'Loan Tape'!M8, prop_val,C7, london_thresh,'Parameter Tables'!$G$36, south_thresh,'Parameter Tables'!$G$35, north_thresh,'Parameter Tables'!$G$34, threshold,IF(region="Greater London",london_thresh, IF(OR(region="South East",region="South West"),south_thresh,north_thresh) ), IF(prop_val>threshold,(prop_val-threshold)*0.20,0) ), 0) | F7: =0.45 | G7: =(C7-E7)*(1-F7) | H7: =IFERROR( IF('Loan Tape'!U8="First",5000,7000), 5000) | I7: =G7*0.03 | J7: =H7+I7 | K7: =IFERROR( LET( is_btl,'Loan Tape'!K8="BTL", is_subsequent,'Loan Tape'!U8<>"First", months,IF(is_subsequent,21,IF(is_btl,12,18)), B7*'Loan Tape'!I8*months/12 ), 0) | L7: =B7+J7+K7 | M7: =MAX(G7-J7,0) | N7: =L7-M7 | O7: =IFERROR(N7/B7,0)
A8: ='Loan Tape'!A9 | B8: ='Loan Tape'!D9 | C8: ='Loan Tape'!B9*(1-IF(AND('Control Panel'!$B$15="YES",'Loan Tape'!W9<>"Full"),0.05,0)) | D8: ='FF Calculations'!F8 | E8: =IFERROR( LET( region,'Loan Tape'!M9, prop_val,C8, london_thresh,'Parameter Tables'!$G$36, south_thresh,'Parameter Tables'!$G$35, north_thresh,'Parameter Tables'!$G$34, threshold,IF(region="Greater London",london_thresh, IF(OR(region="South East",region="South West"),south_thresh,north_thresh) ), IF(prop_val>threshold,(prop_val-threshold)*0.20,0) ), 0) | F8: =0.45 | G8: =(C8-E8)*(1-F8) | H8: =IFERROR( IF('Loan Tape'!U9="First",5000,7000), 5000) | I8: =G8*0.03 | J8: =H8+I8 | K8: =IFERROR( LET( is_btl,'Loan Tape'!K9="BTL", is_subsequent,'Loan Tape'!U9<>"First", months,IF(is_subsequent,21,IF(is_btl,12,18)), B8*'Loan Tape'!I9*months/12 ), 0) | L8: =B8+J8+K8 | M8: =MAX(G8-J8,0) | N8: =L8-M8 | O8: =IFERROR(N8/B8,0)
A9: ='Loan Tape'!A10 | B9: ='Loan Tape'!D10 | C9: ='Loan Tape'!B10*(1-IF(AND('Control Panel'!$B$15="YES",'Loan Tape'!W10<>"Full"),0.05,0)) | D9: ='FF Calculations'!F9 | E9: =IFERROR( LET( region,'Loan Tape'!M10, prop_val,C9, london_thresh,'Parameter Tables'!$G$36, south_thresh,'Parameter Tables'!$G$35, north_thresh,'Parameter Tables'!$G$34, threshold,IF(region="Greater London",london_thresh, IF(OR(region="South East",region="South West"),south_thresh,north_thresh) ), IF(prop_val>threshold,(prop_val-threshold)*0.20,0) ), 0) | F9: =0.45 | G9: =(C9-E9)*(1-F9) | H9: =IFERROR( IF('Loan Tape'!U10="First",5000,7000), 5000) | I9: =G9*0.03 | J9: =H9+I9 | K9: =IFERROR( LET( is_btl,'Loan Tape'!K10="BTL", is_subsequent,'Loan Tape'!U10<>"First", months,IF(is_subsequent,21,IF(is_btl,12,18)), B9*'Loan Tape'!I10*months/12 ), 0) | L9: =B9+J9+K9 | M9: =MAX(G9-J9,0) | N9: =L9-M9 | O9: =IFERROR(N9/B9,0)
A10: ='Loan Tape'!A11 | B10: ='Loan Tape'!D11 | C10: ='Loan Tape'!B11*(1-IF(AND('Control Panel'!$B$15="YES",'Loan Tape'!W11<>"Full"),0.05,0)) | D10: ='FF Calculations'!F10 | E10: =IFERROR( LET( region,'Loan Tape'!M11, prop_val,C10, london_thresh,'Parameter Tables'!$G$36, south_thresh,'Parameter Tables'!$G$35, north_thresh,'Parameter Tables'!$G$34, threshold,IF(region="Greater London",london_thresh, IF(OR(region="South East",region="South West"),south_thresh,north_thresh) ), IF(prop_val>threshold,(prop_val-threshold)*0.20,0) ), 0) | F10: =0.45 | G10: =(C10-E10)*(1-F10) | H10: =IFERROR( IF('Loan Tape'!U11="First",5000,7000), 5000) | I10: =G10*0.03 | J10: =H10+I10 | K10: =IFERROR( LET( is_btl,'Loan Tape'!K11="BTL", is_subsequent,'Loan Tape'!U11<>"First", months,IF(is_subsequent,21,IF(is_btl,12,18)), B10*'Loan Tape'!I11*months/12 ), 0) | L10: =B10+J10+K10 | M10: =MAX(G10-J10,0) | N10: =L10-M10 | O10: =IFERROR(N10/B10,0)
A11: ='Loan Tape'!A12 | B11: ='Loan Tape'!D12 | C11: ='Loan Tape'!B12*(1-IF(AND('Control Panel'!$B$15="YES",'Loan Tape'!W12<>"Full"),0.05,0)) | D11: ='FF Calculations'!F11 | E11: =IFERROR( LET( region,'Loan Tape'!M12, prop_val,C11, london_thresh,'Parameter Tables'!$G$36, south_thresh,'Parameter Tables'!$G$35, north_thresh,'Parameter Tables'!$G$34, threshold,IF(region="Greater London",london_thresh, IF(OR(region="South East",region="South West"),south_thresh,north_thresh) ), IF(prop_val>threshold,(prop_val-threshold)*0.20,0) ), 0) | F11: =0.45 | G11: =(C11-E11)*(1-F11) | H11: =IFERROR( IF('Loan Tape'!U12="First",5000,7000), 5000) | I11: =G11*0.03 | J11: =H11+I11 | K11: =IFERROR( LET( is_btl,'Loan Tape'!K12="BTL", is_subsequent,'Loan Tape'!U12<>"First", months,IF(is_subsequent,21,IF(is_btl,12,18)), B11*'Loan Tape'!I12*months/12 ), 0) | L11: =B11+J11+K11 | M11: =MAX(G11-J11,0) | N11: =L11-M11 | O11: =IFERROR(N11/B11,0)
A12: ='Loan Tape'!A13 | B12: ='Loan Tape'!D13 | C12: ='Loan Tape'!B13*(1-IF(AND('Control Panel'!$B$15="YES",'Loan Tape'!W13<>"Full"),0.05,0)) | D12: ='FF Calculations'!F12 | E12: =IFERROR( LET( region,'Loan Tape'!M13, prop_val,C12, london_thresh,'Parameter Tables'!$G$36, south_thresh,'Parameter Tables'!$G$35, north_thresh,'Parameter Tables'!$G$34, threshold,IF(region="Greater London",london_thresh, IF(OR(region="South East",region="South West"),south_thresh,north_thresh) ), IF(prop_val>threshold,(prop_val-threshold)*0.20,0) ), 0) | F12: =0.45 | G12: =(C12-E12)*(1-F12) | H12: =IFERROR( IF('Loan Tape'!U13="First",5000,7000), 5000) | I12: =G12*0.03 | J12: =H12+I12 | K12: =IFERROR( LET( is_btl,'Loan Tape'!K13="BTL", is_subsequent,'Loan Tape'!U13<>"First", months,IF(is_subsequent,21,IF(is_btl,12,18)), B12*'Loan Tape'!I13*months/12 ), 0) | L12: =B12+J12+K12 | M12: =MAX(G12-J12,0) | N12: =L12-M12 | O12: =IFERROR(N12/B12,0)
A13: ='Loan Tape'!A14 | B13: ='Loan Tape'!D14 | C13: ='Loan Tape'!B14*(1-IF(AND('Control Panel'!$B$15="YES",'Loan Tape'!W14<>"Full"),0.05,0)) | D13: ='FF Calculations'!F13 | E13: =IFERROR( LET( region,'Loan Tape'!M14, prop_val,C13, london_thresh,'Parameter Tables'!$G$36, south_thresh,'Parameter Tables'!$G$35, north_thresh,'Parameter Tables'!$G$34, threshold,IF(region="Greater London",london_thresh, IF(OR(region="South East",region="South West"),south_thresh,north_thresh) ), IF(prop_val>threshold,(prop_val-threshold)*0.20,0) ), 0) | F13: =0.45 | G13: =(C13-E13)*(1-F13) | H13: =IFERROR( IF('Loan Tape'!U14="First",5000,7000), 5000) | I13: =G13*0.03 | J13: =H13+I13 | K13: =IFERROR( LET( is_btl,'Loan Tape'!K14="BTL", is_subsequent,'Loan Tape'!U14<>"First", months,IF(is_subsequent,21,IF(is_btl,12,18)), B13*'Loan Tape'!I14*months/12 ), 0) | L13: =B13+J13+K13 | M13: =MAX(G13-J13,0) | N13: =L13-M13 | O13: =IFERROR(N13/B13,0)
