Workbook

Sheet Control Panel
A1: S&P WAFF/WALS MODEL - CONTROL PANEL
A2: Version 2.0 - Complete S&P Exclusion Logic | Rating-Driven | BoE Field Mapping
A3: Created: 14-Jan-2026 11:40
A5: MODEL SETTINGS | E5: POOL STATISTICS
A6: Jurisdiction | B6: UK | C6: Select: UK, Ireland, or Netherlands
A7: Parameter | B7: Value | C7: Description | E7: Metric | F7: Value | G7: Note
A8: Target Rating Level | B8: AAA | C8: Drives Base FF, MVD, FSD, Stress Multiple | E8: Loan Count | F8: =COUNTA('Loan Tape (S&P)'!A:A)-1 | G8: After BoE conversion
A9: Analysis Date | B9: 46036.487 | C9: For seasoning and CCJ age calculations | E9: Total Balance | F9: =SUM('Loan Tape (S&P)'!B:B) | G9: £ millions
A10: Portfolio Cutoff Date | B10: 46036.487 | C10: Loan tape as-of date | E10: Avg S&P LTV | F10: =AVERAGE('FF Calculations'!E:E) | G10: Pool average
A11: OLTV Weight | B11: 0.8 | C11: S&P LTV: OLTV weight (typically 80%) | E11: Pool WAFF (%) | F11: =SUMPRODUCT('FF Calculations'!Z5:Z104,'FF Calculations'!B5:B104)/SUM('FF Calculations'!B5:B104) | G11: Balance-weighted FF
A12: CLTV Weight | B12: =VLOOKUP($B$6,'Jurisdiction Parameters'!$A:$B,2,FALSE) | C12: S&P LTV: CLTV weight (typically 20%)
A13: Originator Adjustment | B13: =VLOOKUP($B$6,'Jurisdiction Parameters'!$A:$C,3,FALSE) | C13: Global originator quality (0.70-1.30)
A15: RATING-DRIVEN PARAMETERS (AUTO) | E15: QUICK START GUIDE
A17: Parameter | B17: Value | C17: Source | E17: 1. Input loan data in Loan Tape (BoE) using Bank of England codes
A18: Base FF (%) | B18: =VLOOKUP($B$8,'Rating Parameters'!$A$6:$C$17,2,FALSE) | C18: From Rating Parameters | E18: 2. Data auto-converts to Loan Tape (S&P) format
A19: MVD (%) | B19: =VLOOKUP($B$8,'Rating Parameters'!$A$6:$C$17,3,FALSE) | C19: Market Value Decline | E19: 3. Select target rating level above (drives FF/MVD/FSD)
A20: FSD (%) | B20: =VLOOKUP($B$8,'Rating Parameters'!$A$6:$D$17,4,FALSE) | C20: Forced Sale Discount | E20: 4. Set originator adjustment (0.70-1.30, default 1.00)
A21: Stress Multiple | B21: =VLOOKUP($B$8,'Rating Parameters'!$F$6:$G$17,2,FALSE) | C21: For CE calculation | E21: 5. Review FF Calculations for loan-level results
E22: 6. Check Pool WAFF in statistics panel
E24: CRITICAL NOTES:
E25: • BTL identified from BV27 (Occupancy), not BV29 (Payment Method)
E26: • All S&P exclusion rules automatically applied
E27: • Joint borrower logic uses minimum of joint vs individual
E28: • Self-cert vs income: uses higher (not both)

Sheet Jurisdiction Parameters
A1: JURISDICTION-SPECIFIC PARAMETERS
A2: All jurisdiction-specific values - Model references this sheet dynamically
A4: Jurisdiction | B4: OLTV Weight | C4: CLTV Weight | D4: Valuation Haircut | E4: Interest Cost (BTL) | F4: Seasoning Periods | G4: Income Mult Threshold 1 | H4: Income Mult Threshold 2 | I4: Income Mult Joint Threshold 1 | J4: Income Mult Joint Threshold 2 | K4: Arrears 1mo Mult | L4: Arrears 2mo Mult | M4: Arrears 3mo Mult | N4: Foreclosure Cost % | O4: LTV Curve Reference | P4: Regional Adj Enabled
A5: UK | B5: 0.8 | C5: 0.2 | D5: 0.05 | E5: 0.055 | F5: 18 | G5: 5 | H5: 3.5 | I5: 3.25 | J5: 2.75 | K5: 2.5 | L5: 5 | M5: 100 | N5: 0.08 | O5: LTV Curve UK | P5: Yes
A6: Ireland | B6: 0.75 | C6: 0.25 | D6: 0.07 | E6: 0.06 | F6: 24 | G6: 4.5 | H6: 3 | I6: 3 | J6: 2.5 | K6: 3 | L6: 6 | M6: 100 | N6: 0.1 | O6: LTV Curve Ireland | P6: Yes
A7: Netherlands | B7: 0.8 | C7: 0.2 | D7: 0.04 | E7: 0.05 | F7: 12 | G7: 6 | H7: 4 | I7: 4 | J7: 3 | K7: 2 | L7: 4 | M7: 100 | N7: 0.07 | O7: LTV Curve Netherlands | P7: No

Sheet Rating Parameters
A1: RATING-DRIVEN PARAMETERS
A3: All parameters that vary by target rating level
A5: Rating | B5: Base FF (%) | C5: MVD (%) | D5: FSD (%) | E5: Source | F5: Rating | G5: Stress Multiple
A6: AAA | B6: 0.12 | C6: 0.45 | D6: 0.15 | E6: Table 72 / S&P MVD assumptions | F6: AAA | G6: 14
A7: AA+ | B7: 0.105 | C7: 0.42 | D7: 0.14 | E7: Interpolated | F7: AA+ | G7: 12
A8: AA | B8: 0.08 | C8: 0.4 | D8: 0.13 | E8: Table 72 | F8: AA | G8: 10.5
A9: AA- | B9: 0.07 | C9: 0.37 | D9: 0.12 | E9: Interpolated | F9: AA- | G9: 9
A10: A+ | B10: 0.065 | C10: 0.34 | D10: 0.11 | E10: Interpolated | F10: A+ | G10: 7.5
A11: A | B11: 0.06 | C11: 0.32 | D11: 0.1 | E11: Table 72 | F11: A | G11: 6.5
A12: A- | B12: 0.055 | C12: 0.3 | D12: 0.1 | E12: Interpolated | F12: A- | G12: 5.5
A13: BBB+ | B13: 0.05 | C13: 0.27 | D13: 0.09 | E13: Interpolated | F13: BBB+ | G13: 4.5
A14: BBB | B14: 0.04 | C14: 0.25 | D14: 0.08 | E14: Table 72 | F14: BBB | G14: 4
A15: BBB- | B15: 0.035 | C15: 0.22 | D15: 0.08 | E15: Interpolated | F15: BBB- | G15: 3.5
A16: BB | B16: 0.02 | C16: 0.2 | D16: 0.07 | E16: Table 72 | F16: BB | G16: 3
A17: B | B17: 0.015 | C17: 0.18 | D17: 0.07 | E17: Table 72 | F17: B | G17: 2.5

Sheet LTV Curve
A1: S&P UK LTV CURVE - TYPE 2 FULL RECOURSE (131 Points)
A3: LTV % | B3: FF Multiplier | C3: Named Range | D3: Notes
A4: 0.2 | B4: 0.2889 | C4: LTV_20 | D4: Minimum LTV in curve
A5: 0.21 | B5: 0.2907 | C5: LTV_21
A6: 0.22 | B6: 0.2925 | C6: LTV_22
A7: 0.23 | B7: 0.2945 | C7: LTV_23
A8: 0.24 | B8: 0.2966 | C8: LTV_24
A9: 0.25 | B9: 0.2988 | C9: LTV_25
A10: 0.26 | B10: 0.3011 | C10: LTV_26
A11: 0.27 | B11: 0.3037 | C11: LTV_27
A12: 0.28 | B12: 0.3063 | C12: LTV_28
A13: 0.29 | B13: 0.3092 | C13: LTV_29
A14: 0.3 | B14: 0.3122 | C14: LTV_30
A15: 0.31 | B15: 0.3155 | C15: LTV_31
A16: 0.32 | B16: 0.3189 | C16: LTV_32
... A53: 0.69 | B53: 0.8368 | C53: LTV_69
A54: 0.7 | B54: 0.8739 | C54: LTV_70 | D54: Archetypal (1.0x multiplier at 73% per curve)
A55: 0.71 | B55: 0.9134 | C55: LTV_71
A56: 0.72 | B56: 0.9553 | C56: LTV_72
A57: 0.73 | B57: 1 | C57: LTV_73
A58: 0.74 | B58: 1.0475 | C58: LTV_74
A59: 0.75 | B59: 1.098 | C59: LTV_75
A60: 0.76 | B60: 1.1518 | C60: LTV_76
A61: 0.77 | B61: 1.2089 | C61: LTV_77
A62: 0.78 | B62: 1.2696 | C62: LTV_78
A63: 0.79 | B63: 1.3341 | C63: LTV_79
A64: 0.8 | B64: 1.4025 | C64: LTV_80
A65: 0.81 | B65: 1.4751 | C65: LTV_81
A66: 0.82 | B66: 1.552 | C66: LTV_82
... A133: 1.49 | B133: 4.02 | C133: LTV_149
A134: 1.5 | B134: 4.02 | C134: LTV_150 | D134: Maximum LTV (cap at 4.02x)

Sheet FF Parameters
A1: FORECLOSURE FREQUENCY ADJUSTMENT PARAMETERS
A2: All S&P Table 73 adjustments - Used by FF Calculations via VLOOKUP
A4: INCOME MULTIPLE ADJUSTMENTS
A5: Min Multiple | B5: Max Multiple | C5: Adjustment | D5: Notes
A6: 0 | B6: 3.5 | C6: 1 | D6: Low income multiple - no adjustment
A7: 3.5 | B7: 5 | C7: 1.2 | D7: Moderate stretch - 20% increase
A8: 5 | B8: 999 | C8: 1.5 | D8: High stretch - 50% increase
A10: BTL DSCR ADJUSTMENTS
A11: Min DSCR | B11: Max DSCR | C11: Adjustment | D11: Notes
A12: 0 | B12: 1 | C12: 1.55 | D12: DSCR < 1.0 - highest risk
A13: 1 | B13: 1.2 | C13: 1.45 | D13: DSCR 1.0-1.2 - marginal coverage
A14: 1.2 | B14: 1.35 | C14: 1.35 | D14: DSCR 1.2-1.35 - adequate coverage
A15: 1.35 | B15: 999 | C15: 1.25 | D15: DSCR > 1.35 - strong coverage
A17: LIEN POSITION ADJUSTMENTS
A18: Lien Position | B18: Adjustment | C18: Notes
A19: First | B19: 1 | C19: First lien - baseline
A20: Second | B20: 1.5 | C20: Second lien - 50% increase
A21: Third | B21: 1.7 | C21: Third+ lien - 70% increase
A23: ARREARS ADJUSTMENTS
A24: Min Months | B24: Max Months | C24: Adjustment | D24: Notes
A25: 0 | B25: 0 | C25: 1 | D25: Current - no arrears
A26: 1 | B26: 1 | C26: 2.5 | D26: 1 month - moderate risk
A27: 2 | B27: 2 | C27: 5 | D27: 2 months - high risk
A28: 3 | B28: 999 | C28: 100 | D28: 3+ months - exclude from pool
A30: SEASONING CREDITS (PERFORMING ONLY)
A31: Min Years | B31: Max Years | C31: Adjustment | D31: Notes
A32: 0 | B32: 5 | C32: 1 | D32: 0-5 years - no credit
A33: 5 | B33: 6 | C33: 0.75 | D33: 5-6 years - 25% credit
A34: 6 | B34: 7 | C34: 0.7 | D34: 6-7 years - 30% credit
A35: 7 | B35: 8 | C35: 0.65 | D35: 7-8 years - 35% credit
A36: 8 | B36: 9 | C36: 0.6 | D36: 8-9 years - 40% credit
A37: 9 | B37: 10 | C37: 0.55 | D37: 9-10 years - 45% credit
A38: 10 | B38: 999 | C38: 0.5 | D38: 10+ years - 50% credit
A40: INTEREST ONLY ADJUSTMENTS (NON-BTL)
A41: Min Years to Mat | B41: Max Years to Mat | C41: Adjustment | D41: Notes
A42: 0 | B42: 5 | C42: 1.25 | D42: <5 years - highest risk
A43: 5 | B43: 15 | C43: 1.25 | D43: 5-15 years - high risk
A44: 15 | B44: 25 | C44: 1.2 | D44: 15-25 years - moderate risk
A45: 25 | B45: 999 | C45: 1.1 | D45: >25 years - lower risk
A47: CCJ COUNT ADJUSTMENTS
...

Sheet FF Adj Parameters
A1: FF ADJUSTMENT MULTIPLIERS - ALL VALUES
A2: Complete parameter table for all FF adjustments - NO HARDCODING
A4: INCOME MULTIPLE ADJUSTMENTS
A5: Multiple Range | B5: Multiplier | C5: Description
A6: <=3.5 (or <=2.75 joint) | B6: 1 | C6: Low risk
A7: >3.5 to 5.0 (or >2.75 to 3.25 joint) | B7: 1.2 | C7: Medium risk
A8: >5.0 (or >3.25 joint) | B8: 1.5 | C8: High risk
A10: BTL DSCR ADJUSTMENTS
A11: DSCR Range | B11: Multiplier | C11: Description
A12: No rental (=0) | B12: 1.7 | C12: No income verification
A13: <1.00 | B13: 1.55 | C13: Inadequate coverage
A14: 1.00 to <1.20 | B14: 1.45 | C14: Minimal coverage
A15: 1.20 to <1.35 | B15: 1.35 | C15: Adequate coverage
A16: >=1.35 | B16: 1.25 | C16: Strong coverage
A18: LIEN POSITION ADJUSTMENTS
A19: Lien Position | B19: Multiplier | C19: Description
A20: First | B20: 1 | C20: First lien baseline
A21: Second | B21: 1.5 | C21: Second lien premium
A22: Third+ | B22: 1.7 | C22: Third+ lien high risk
A24: LOAN PURPOSE ADJUSTMENTS
A25: Purpose | B25: Multiplier | C25: Description
A26: Purchase | B26: 1 | C26: Baseline
A27: Remortgage | B27: 1 | C27: No adjustment
A28: Cash-out | B28: 1.2 | C28: Increased risk
A30: SEASONING ADJUSTMENTS (PERFORMING ONLY)
A31: Years Seasoned | B31: Multiplier | C31: Description
A32: <5 years | B32: 1 | C32: No credit
A33: 5-6 years | B33: 0.75 | C33: 25% credit
A34: 6-7 years | B34: 0.7 | C34: 30% credit
A35: 7-8 years | B35: 0.65 | C35: 35% credit
A36: 8-9 years | B36: 0.6 | C36: 40% credit
A37: 9-10 years | B37: 0.55 | C37: 45% credit
A38: >10 years | B38: 0.5 | C38: 50% credit
A40: PRODUCT FEATURE ADJUSTMENTS
A41: Feature | B41: Multiplier | C41: Notes
A42: First Time Buyer (<18mo) | B42: 1.1 | C42: Seasoning <18 months only
A43: Help to Buy | B43: 1.35 | C43: Excludes FTB and Payment Shock
A44: Shared Ownership | B44: 1.2 | C44: Partial ownership risk
A45: Right to Buy | B45: 1.05 | C45: Ex-council property
A46: Payment Shock | B46: 1.1 | C46: Rate increase risk
...

Sheet LS Parameters
A1: LOSS SEVERITY ADJUSTMENT PARAMETERS
A2: S&P Table 78 & 79: Property Type and Regional Adjustments for MVD
A4: PROPERTY TYPE MVD ADJUSTMENTS (S&P Table 78)
A5: Property Type | B5: MVD Adjustment | C5: Notes
A6: House | B6: 0 | C6: Baseline - no adjustment
A7: Flat | B7: 0.05 | C7: +5% MVD for flats (higher volatility)
A8: Bungalow | B8: -0.02 | C8: -2% MVD for bungalows (stable)
A9: Maisonette | B9: 0.03 | C9: +3% MVD for maisonettes
A10: Other | B10: 0.05 | C10: +5% MVD for other property types
A12: REGIONAL MVD ADJUSTMENTS (S&P Table 79 - Optional)
A13: Region | B13: MVD Adjustment | C13: Notes
A14: London | B14: -0.03 | C14: -3% MVD (more liquid market)
A15: South East | B15: -0.02 | C15: -2% MVD
A16: East | B16: -0.01 | C16: -1% MVD
A17: South West | B17: 0 | C17: Baseline
A18: West Midlands | B18: 0.01 | C18: +1% MVD
A19: East Midlands | B19: 0.01 | C19: +1% MVD
A20: North West | B20: 0.02 | C20: +2% MVD
A21: Yorkshire | B21: 0.02 | C21: +2% MVD
A22: North East | B22: 0.03 | C22: +3% MVD (less liquid)
A23: Wales | B23: 0.02 | C23: +2% MVD
A24: Scotland | B24: 0.01 | C24: +1% MVD
A25: Northern Ireland | B25: 0.03 | C25: +3% MVD
A28: FORECLOSURE COSTS
A29: Cost Component | B29: % of Property Value | C29: Notes
A30: Legal & Professional Fees | B30: 0.03 | C30: Solicitors, surveyors, court costs
A31: Maintenance & Repairs | B31: 0.02 | C31: Property upkeep during foreclosure
A32: Sales Costs | B32: 0.02 | C32: Estate agent, marketing
A33: Holding Costs | B33: 0.01 | C33: Utilities, insurance, security
A34: TOTAL Foreclosure Costs | B34: 0.08 | C34: Sum of all components

Sheet BoE Mapping
A1: BANK OF ENGLAND TO S&P FIELD MAPPING & CONVERSION
A2: Complete PRA110 field mapping with conversion formulas
A4: BoE Code | B4: BoE Field Name | C4: BoE Value/Code | D4: S&P Field | E4: S&P Value | F4: Conversion Formula
A5: BV1 | B5: Loan Identifier | C5: Direct | D5: loan_id | E5: Same | F5: =BoE!A[row]
F6: ='Loan Tape (BoE)'!A5
A7: BV5 | B7: Current Loan Balance | C7: Direct | D7: current_balance | E7: Same | F7: =BoE!B[row]
A8: BV6 | B8: Original Balance | C8: Direct | D8: original_balance | E8: Same | F8: ='Loan Tape (BoE)'!B5
A9: BV7 | B9: Current Property Value | C9: Direct | D9: property_value_current | E9: Indexed | F9: ='Loan Tape (BoE)'!C5
A10: BV8 | B10: Original Property Value | C10: Direct | D10: property_value_original | E10: Same | F10: ='Loan Tape (BoE)'!D5*(1+regional_HPI_factor)
F11: ='Loan Tape (BoE)'!E5
A12: BV11 | B12: Origination Date | C12: Direct | D12: origination_date | E12: Same | F12: =BoE!F[row]
A13: BV12 | B13: Maturity Date | C13: Direct | D13: maturity_date | E13: Same | F13: =BoE!G[row]
F14: ='Loan Tape (BoE)'!F5
A15: BV13 | B15: Current Interest Rate | C15: Direct | D15: interest_rate | E15: Same | F15: ='Loan Tape (BoE)'!G5
A17: BV22 | B17: Property Type | C17: 1 | D17: property_type | E17: House | F17: =IFS(BoE!I[row]=1,"House",BoE!I[row]=2,"Flat",BoE!I[row]=3,"Bungalow",BoE!I[row]=4,"Maisonette")
A18: BV22 | B18: Property Type | C18: 2 | D18: property_type | E18: Flat | F18: ='Loan Tape (BoE)'!H5
A19: BV22 | B19: Property Type | C19: 3 | D19: property_type | E19: Bungalow
A20: BV22 | B20: Property Type | C20: 4 | D20: property_type | E20: Maisonette
F21: =IFS(I5=1,"House",I5=2,"Flat",I5=3,"Bungalow",I5=4,"Maisonette")
A22: BV23 | B22: Region | C22: Direct | D22: region | E22: Same | F22: =BoE!J[row]
A23: BV24 | B23: Postcode | C23: Direct | D23: postcode | E23: Same | F23: =BoE!K[row]
A25: BV27 | B25: Occupancy Status | C25: 1 | D25: occupancy_type | E25: Owner Occupied | F25: =IFS(BoE!L[row]=1,"Owner Occupied",BoE!L[row]=2,"BTL",BoE!L[row]=3,"Second Home",BoE!L[row]=4,"Investment")
A26: BV27 | B26: Occupancy Status | C26: 2 | D26: occupancy_type | E26: BTL | F26: ='Loan Tape (BoE)'!J5
A27: BV27 | B27: Occupancy Status | C27: 3 | D27: occupancy_type | E27: Second Home | F27: ='Loan Tape (BoE)'!K5
A28: BV27 | B28: Occupancy Status | C28: 4 | D28: occupancy_type | E28: Investment
A30: BV28 | B30: Loan Purpose | C30: 1 | D30: loan_purpose | E30: Purchase | F30: =IFS(BoE!M[row]=1,"Purchase",BoE!M[row]=2,"Remortgage",OR(BoE!M[row]=3,BoE!M[row]=4),"Cash-out")
A31: BV28 | B31: Loan Purpose | C31: 2 | D31: loan_purpose | E31: Remortgage | F31: =IFS(L5=1,"Owner Occupied",L5=2,"BTL",L5=3,"Second Home",L5=4,"Investment")
A32: BV28 | B32: Loan Purpose | C32: 3 | D32: loan_purpose | E32: Cash-out | F32: Further advance
A33: BV28 | B33: Loan Purpose | C33: 4 | D33: loan_purpose | E33: Cash-out | F33: Debt consolidation
A35: BV29 | B35: Payment Method | C35: 1 | D35: product_type | E35: Repayment | F35: =IFS(BoE!N[row]=1,"Repayment",BoE!N[row]=2,"Interest Only",BoE!N[row]=3,"Part & Part")
A36: BV29 | B36: Payment Method | C36: 2 | D36: product_type | E36: Interest Only | F36: =IFS(M5=1,"Purchase",M5=2,"Remortgage",OR(M5=3,M5=4),"Cash-out")
A37: BV29 | B37: Payment Method | C37: 3 | D37: product_type | E37: Part & Part | F37: Mixed repayment/IO
A39: BV33 | B39: Right to Buy | C39: 1 | D39: right_to_buy_flag | E39: Yes | F39: =IF(BoE!O[row]=1,"Yes","No")
A40: BV33 | B40: Right to Buy | C40: 2 | D40: right_to_buy_flag | E40: No
F41: =IFS(N5=1,"Repayment",N5=2,"Interest Only",N5=3,"Part & Part")
A42: BV34 | B42: Shared Ownership | C42: 1 | D42: shared_ownership_flag | E42: Yes | F42: =IF(BoE!P[row]=1,"Yes","No")
A43: BV34 | B43: Shared Ownership | C43: 2 | D43: shared_ownership_flag | E43: No | F43: LTV uses mortgage portion only
A45: BV35 | B45: Help to Buy | C45: 1 | D45: help_to_buy_flag | E45: Yes | F45: =IF(BoE!Q[row]=1,"Yes","No")
A46: BV35 | B46: Help to Buy | C46: 2 | D46: help_to_buy_flag | E46: No | F46: Excludes FTB & payment shock adj
A48: BV40 | B48: Borrower 1 Income | C48: Direct | D48: borrower1_income | E48: Same | F48: =BoE!R[row]
...

Sheet Loan Tape (BoE)
A1: LOAN TAPE - BANK OF ENGLAND PRA110 FORMAT (INPUT SHEET)
A2: Enter loan data in yellow cells using Bank of England field codes and values
A4: BV1 | B4: BV5 | C4: BV6 | D4: BV7 | E4: BV8 | F4: BV11 | G4: BV12 | H4: BV13 | I4: BV22 | J4: BV23 | K4: BV24 | L4: BV27 | M4: BV28 | N4: BV29 | O4: BV33 | P4: BV34 | Q4: BV35 | R4: BV40 | S4: BV41 | T4: BV42 | U4: BV45 | V4: BV46 | W4: BV50 | X4: BV51 | Y4: BV55 | Z4: BV56 | AA4: BV57 | AB4: BV58 | AC4: BV59 | AD4: BV60 | AE4: BV61 | AF4: BV65 | AG4: BV66 | AH4: BV67 | AI4: BV68 | AJ4: BV70 | AK4: BV71 | AL4: BV72 | AM4: BV75 | AN4: BV76 | AO4: BV80 | AP4: BV85 | AQ4: BV90 | AR4: BV91
A5: Loan ID | B5: Current Balance (£) | C5: Original Balance (£) | D5: Current Property Value (£) | E5: Original Property Value (£) | F5: Origination Date | G5: Maturity Date | H5: Current Interest Rate (%) | I5: Property Type (1-4) | J5: Region | K5: Postcode | L5: Occupancy Status (1-4) | M5: Loan Purpose (1-4) | N5: Payment Method (1-3) | O5: Right to Buy (1-2) | P5: Shared Ownership (1-2) | Q5: Help to Buy (1-2) | R5: Borrower 1 Income (£) | S5: Borrower 2 Income (£) | T5: Number of Borrowers (1-2) | U5: Employ Status Borr1 (1-4) | V5: Employ Status Borr2 (1-4) | W5: Credit Score Borr1 | X5: Credit Score Borr2 | Y5: CCJ Count Borr1 | Z5: CCJ Count Borr2 | AA5: CCJ Value Borr1 (£) | AB5: CCJ Value Borr2 (£) | AC5: CCJ Date Borr1 | AD5: CCJ Date Borr2 | AE5: Arrears Balance (£) | AF5: Bankruptcy Flag (1-2) | AG5: Bankruptcy Date | AH5: IVA Flag (1-2) | AI5: Prior Repossession (1-2) | AJ5: Self-Certified (1-2) | AK5: First Time Buyer (1-2) | AL5: Payment Shock (1-2) | AM5: Reperforming (1-2) | AN5: Date Last 90+ dpd | AO5: Lien Position (1/2/3+) | AP5: Valuation Method (1-3) | AQ5: Commercial Property (1-2) | AR5: Rental Income Annual (£)

Sheet Loan Tape (S&P)
A1: LOAN TAPE - S&P FORMAT (AUTO-CONVERTED FROM BoE)
A2: Auto-populated from Loan Tape (BoE) using conversion formulas - DO NOT EDIT
A4: loan_id | B4: current_balance | C4: original_balance | D4: property_value_current | E4: property_value_original | F4: origination_date | G4: maturity_date | H4: interest_rate | I4: property_type | J4: region | K4: postcode | L4: occupancy_type | M4: loan_purpose | N4: product_type | O4: right_to_buy_flag | P4: shared_ownership_flag | Q4: help_to_buy_flag | R4: borrower1_income | S4: borrower2_income | T4: num_borrowers | U4: total_income | V4: employment_status_borr1 | W4: employment_status_borr2 | X4: self_employed_flag | Y4: credit_score_borr1 | Z4: credit_score_borr2 | AA4: credit_score | AB4: ccj_count_borr1 | AC4: ccj_count_borr2 | AD4: ccj_count | AE4: ccj_value_borr1 | AF4: ccj_value_borr2 | AG4: ccj_total_value | AH4: ccj_date_most_recent | AI4: arrears_balance | AJ4: monthly_payment | AK4: arrears_months | AL4: bankruptcy_flag | AM4: iva_flag | AN4: prior_repossession_flag | AO4: self_certified_flag | AP4: first_time_buyer_flag | AQ4: payment_shock_flag | AR4: reperforming_flag | AS4: date_last_90dpd | AT4: lien_position | AU4: valuation_type | AV4: commercial_property_flag | AW4: rental_income_annual
A5: ='Loan Tape (BoE)'!A6 | B5: ='Loan Tape (BoE)'!B6 | C5: ='Loan Tape (BoE)'!C6 | D5: ='Loan Tape (BoE)'!D6 | E5: ='Loan Tape (BoE)'!E6 | F5: ='Loan Tape (BoE)'!F6 | G5: ='Loan Tape (BoE)'!G6 | H5: ='Loan Tape (BoE)'!H6/100 | I5: =IFERROR(IFS('Loan Tape (BoE)'!I6=1,"House",'Loan Tape (BoE)'!I6=2,"Flat",'Loan Tape (BoE)'!I6=3,"Bungalow",'Loan Tape (BoE)'!I6=4,"Maisonette"),"") | J5: ='Loan Tape (BoE)'!J6 | K5: ='Loan Tape (BoE)'!K6 | L5: =IFERROR(IFS('Loan Tape (BoE)'!L6=1,"Owner Occupied",'Loan Tape (BoE)'!L6=2,"BTL",'Loan Tape (BoE)'!L6=3,"Second Home",'Loan Tape (BoE)'!L6=4,"Investment"),"") | M5: =IFERROR(IFS('Loan Tape (BoE)'!M6=1,"Purchase",'Loan Tape (BoE)'!M6=2,"Remortgage",OR('Loan Tape (BoE)'!M6=3,'Loan Tape (BoE)'!M6=4),"Cash-out"),"") | N5: =IFERROR(IFS('Loan Tape (BoE)'!N6=1,"Repayment",'Loan Tape (BoE)'!N6=2,"Interest Only",'Loan Tape (BoE)'!N6=3,"Part & Part"),"") | O5: =IF('Loan Tape (BoE)'!O6=1,"Yes","No") | P5: =IF('Loan Tape (BoE)'!P6=1,"Yes","No") | Q5: =IF('Loan Tape (BoE)'!Q6=1,"Yes","No") | R5: ='Loan Tape (BoE)'!R6 | S5: ='Loan Tape (BoE)'!S6 | T5: ='Loan Tape (BoE)'!T6 | U5: =R5+S5 | V5: =IFERROR(IFS('Loan Tape (BoE)'!U6=1,"Employed",'Loan Tape (BoE)'!U6=2,"Self-Employed",'Loan Tape (BoE)'!U6=3,"Unemployed",'Loan Tape (BoE)'!U6=4,"Retired"),"") | W5: =IFERROR(IFS('Loan Tape (BoE)'!V6=1,"Employed",'Loan Tape (BoE)'!V6=2,"Self-Employed",'Loan Tape (BoE)'!V6=3,"Unemployed",'Loan Tape (BoE)'!V6=4,"Retired"),"") | X5: =IF(OR(V5="Self-Employed",W5="Self-Employed"),"Yes","No") | Y5: ='Loan Tape (BoE)'!W6 | Z5: ='Loan Tape (BoE)'!X6 | AA5: =IF(T5=1,Y5,MIN(Y5,Z5)) | AB5: ='Loan Tape (BoE)'!Y6 | AC5: ='Loan Tape (BoE)'!Z6 | AD5: =AB5+AC5 | AE5: ='Loan Tape (BoE)'!AA6 | AF5: ='Loan Tape (BoE)'!AB6 | AG5: =AE5+AF5 | AH5: =MAX('Loan Tape (BoE)'!AC6,'Loan Tape (BoE)'!AD6) | AI5: ='Loan Tape (BoE)'!AE6 | AJ5: =B5*H5/12 | AK5: =IF(AJ5>0,AI5/AJ5,0) | AL5: =IF('Loan Tape (BoE)'!AF6=1,"Yes","No") | AM5: =IF('Loan Tape (BoE)'!AH6=1,"Yes","No") | AN5: =IF('Loan Tape (BoE)'!AI6=1,"Yes","No") | AO5: =IF('Loan Tape (BoE)'!AJ6=1,"Yes","No")
A6: ='Loan Tape (BoE)'!A7 | B6: ='Loan Tape (BoE)'!B7 | C6: ='Loan Tape (BoE)'!C7 | D6: ='Loan Tape (BoE)'!D7 | E6: ='Loan Tape (BoE)'!E7 | F6: ='Loan Tape (BoE)'!F7 | G6: ='Loan Tape (BoE)'!G7 | H6: ='Loan Tape (BoE)'!H7/100 | I6: =IFERROR(IFS('Loan Tape (BoE)'!I7=1,"House",'Loan Tape (BoE)'!I7=2,"Flat",'Loan Tape (BoE)'!I7=3,"Bungalow",'Loan Tape (BoE)'!I7=4,"Maisonette"),"") | J6: ='Loan Tape (BoE)'!J7 | K6: ='Loan Tape (BoE)'!K7 | L6: =IFERROR(IFS('Loan Tape (BoE)'!L7=1,"Owner Occupied",'Loan Tape (BoE)'!L7=2,"BTL",'Loan Tape (BoE)'!L7=3,"Second Home",'Loan Tape (BoE)'!L7=4,"Investment"),"") | M6: =IFERROR(IFS('Loan Tape (BoE)'!M7=1,"Purchase",'Loan Tape (BoE)'!M7=2,"Remortgage",OR('Loan Tape (BoE)'!M7=3,'Loan Tape (BoE)'!M7=4),"Cash-out"),"") | N6: =IFERROR(IFS('Loan Tape (BoE)'!N7=1,"Repayment",'Loan Tape (BoE)'!N7=2,"Interest Only",'Loan Tape (BoE)'!N7=3,"Part & Part"),"") | O6: =IF('Loan Tape (BoE)'!O7=1,"Yes","No") | P6: =IF('Loan Tape (BoE)'!P7=1,"Yes","No") | Q6: =IF('Loan Tape (BoE)'!Q7=1,"Yes","No") | R6: ='Loan Tape (BoE)'!R7 | S6: ='Loan Tape (BoE)'!S7 | T6: ='Loan Tape (BoE)'!T7 | U6: =R6+S6 | V6: =IFERROR(IFS('Loan Tape (BoE)'!U7=1,"Employed",'Loan Tape (BoE)'!U7=2,"Self-Employed",'Loan Tape (BoE)'!U7=3,"Unemployed",'Loan Tape (BoE)'!U7=4,"Retired"),"") | W6: =IFERROR(IFS('Loan Tape (BoE)'!V7=1,"Employed",'Loan Tape (BoE)'!V7=2,"Self-Employed",'Loan Tape (BoE)'!V7=3,"Unemployed",'Loan Tape (BoE)'!V7=4,"Retired"),"") | X6: =IF(OR(V6="Self-Employed",W6="Self-Employed"),"Yes","No") | Y6: ='Loan Tape (BoE)'!W7 | Z6: ='Loan Tape (BoE)'!X7 | AA6: =IF(T6=1,Y6,MIN(Y6,Z6)) | AB6: ='Loan Tape (BoE)'!Y7 | AC6: ='Loan Tape (BoE)'!Z7 | AD6: =AB6+AC6 | AE6: ='Loan Tape (BoE)'!AA7 | AF6: ='Loan Tape (BoE)'!AB7 | AG6: =AE6+AF6 | AH6: =MAX('Loan Tape (BoE)'!AC7,'Loan Tape (BoE)'!AD7) | AI6: ='Loan Tape (BoE)'!AE7 | AJ6: =B6*H6/12 | AK6: =IF(AJ6>0,AI6/AJ6,0) | AL6: =IF('Loan Tape (BoE)'!AF7=1,"Yes","No") | AM6: =IF('Loan Tape (BoE)'!AH7=1,"Yes","No") | AN6: =IF('Loan Tape (BoE)'!AI7=1,"Yes","No") | AO6: =IF('Loan Tape (BoE)'!AJ7=1,"Yes","No")
A7: ='Loan Tape (BoE)'!A8 | B7: ='Loan Tape (BoE)'!B8 | C7: ='Loan Tape (BoE)'!C8 | D7: ='Loan Tape (BoE)'!D8 | E7: ='Loan Tape (BoE)'!E8 | F7: ='Loan Tape (BoE)'!F8 | G7: ='Loan Tape (BoE)'!G8 | H7: ='Loan Tape (BoE)'!H8/100 | I7: =IFERROR(IFS('Loan Tape (BoE)'!I8=1,"House",'Loan Tape (BoE)'!I8=2,"Flat",'Loan Tape (BoE)'!I8=3,"Bungalow",'Loan Tape (BoE)'!I8=4,"Maisonette"),"") | J7: ='Loan Tape (BoE)'!J8 | K7: ='Loan Tape (BoE)'!K8 | L7: =IFERROR(IFS('Loan Tape (BoE)'!L8=1,"Owner Occupied",'Loan Tape (BoE)'!L8=2,"BTL",'Loan Tape (BoE)'!L8=3,"Second Home",'Loan Tape (BoE)'!L8=4,"Investment"),"") | M7: =IFERROR(IFS('Loan Tape (BoE)'!M8=1,"Purchase",'Loan Tape (BoE)'!M8=2,"Remortgage",OR('Loan Tape (BoE)'!M8=3,'Loan Tape (BoE)'!M8=4),"Cash-out"),"") | N7: =IFERROR(IFS('Loan Tape (BoE)'!N8=1,"Repayment",'Loan Tape (BoE)'!N8=2,"Interest Only",'Loan Tape (BoE)'!N8=3,"Part & Part"),"") | O7: =IF('Loan Tape (BoE)'!O8=1,"Yes","No") | P7: =IF('Loan Tape (BoE)'!P8=1,"Yes","No") | Q7: =IF('Loan Tape (BoE)'!Q8=1,"Yes","No") | R7: ='Loan Tape (BoE)'!R8 | S7: ='Loan Tape (BoE)'!S8 | T7: ='Loan Tape (BoE)'!T8 | U7: =R7+S7 | V7: =IFERROR(IFS('Loan Tape (BoE)'!U8=1,"Employed",'Loan Tape (BoE)'!U8=2,"Self-Employed",'Loan Tape (BoE)'!U8=3,"Unemployed",'Loan Tape (BoE)'!U8=4,"Retired"),"") | W7: =IFERROR(IFS('Loan Tape (BoE)'!V8=1,"Employed",'Loan Tape (BoE)'!V8=2,"Self-Employed",'Loan Tape (BoE)'!V8=3,"Unemployed",'Loan Tape (BoE)'!V8=4,"Retired"),"") | X7: =IF(OR(V7="Self-Employed",W7="Self-Employed"),"Yes","No") | Y7: ='Loan Tape (BoE)'!W8 | Z7: ='Loan Tape (BoE)'!X8 | AA7: =IF(T7=1,Y7,MIN(Y7,Z7)) | AB7: ='Loan Tape (BoE)'!Y8 | AC7: ='Loan Tape (BoE)'!Z8 | AD7: =AB7+AC7 | AE7: ='Loan Tape (BoE)'!AA8 | AF7: ='Loan Tape (BoE)'!AB8 | AG7: =AE7+AF7 | AH7: =MAX('Loan Tape (BoE)'!AC8,'Loan Tape (BoE)'!AD8) | AI7: ='Loan Tape (BoE)'!AE8 | AJ7: =B7*H7/12 | AK7: =IF(AJ7>0,AI7/AJ7,0) | AL7: =IF('Loan Tape (BoE)'!AF8=1,"Yes","No") | AM7: =IF('Loan Tape (BoE)'!AH8=1,"Yes","No") | AN7: =IF('Loan Tape (BoE)'!AI8=1,"Yes","No") | AO7: =IF('Loan Tape (BoE)'!AJ8=1,"Yes","No")
A8: ='Loan Tape (BoE)'!A9 | B8: ='Loan Tape (BoE)'!B9 | C8: ='Loan Tape (BoE)'!C9 | D8: ='Loan Tape (BoE)'!D9 | E8: ='Loan Tape (BoE)'!E9 | F8: ='Loan Tape (BoE)'!F9 | G8: ='Loan Tape (BoE)'!G9 | H8: ='Loan Tape (BoE)'!H9/100 | I8: =IFERROR(IFS('Loan Tape (BoE)'!I9=1,"House",'Loan Tape (BoE)'!I9=2,"Flat",'Loan Tape (BoE)'!I9=3,"Bungalow",'Loan Tape (BoE)'!I9=4,"Maisonette"),"") | J8: ='Loan Tape (BoE)'!J9 | K8: ='Loan Tape (BoE)'!K9 | L8: =IFERROR(IFS('Loan Tape (BoE)'!L9=1,"Owner Occupied",'Loan Tape (BoE)'!L9=2,"BTL",'Loan Tape (BoE)'!L9=3,"Second Home",'Loan Tape (BoE)'!L9=4,"Investment"),"") | M8: =IFERROR(IFS('Loan Tape (BoE)'!M9=1,"Purchase",'Loan Tape (BoE)'!M9=2,"Remortgage",OR('Loan Tape (BoE)'!M9=3,'Loan Tape (BoE)'!M9=4),"Cash-out"),"") | N8: =IFERROR(IFS('Loan Tape (BoE)'!N9=1,"Repayment",'Loan Tape (BoE)'!N9=2,"Interest Only",'Loan Tape (BoE)'!N9=3,"Part & Part"),"") | O8: =IF('Loan Tape (BoE)'!O9=1,"Yes","No") | P8: =IF('Loan Tape (BoE)'!P9=1,"Yes","No") | Q8: =IF('Loan Tape (BoE)'!Q9=1,"Yes","No") | R8: ='Loan Tape (BoE)'!R9 | S8: ='Loan Tape (BoE)'!S9 | T8: ='Loan Tape (BoE)'!T9 | U8: =R8+S8 | V8: =IFERROR(IFS('Loan Tape (BoE)'!U9=1,"Employed",'Loan Tape (BoE)'!U9=2,"Self-Employed",'Loan Tape (BoE)'!U9=3,"Unemployed",'Loan Tape (BoE)'!U9=4,"Retired"),"") | W8: =IFERROR(IFS('Loan Tape (BoE)'!V9=1,"Employed",'Loan Tape (BoE)'!V9=2,"Self-Employed",'Loan Tape (BoE)'!V9=3,"Unemployed",'Loan Tape (BoE)'!V9=4,"Retired"),"") | X8: =IF(OR(V8="Self-Employed",W8="Self-Employed"),"Yes","No") | Y8: ='Loan Tape (BoE)'!W9 | Z8: ='Loan Tape (BoE)'!X9 | AA8: =IF(T8=1,Y8,MIN(Y8,Z8)) | AB8: ='Loan Tape (BoE)'!Y9 | AC8: ='Loan Tape (BoE)'!Z9 | AD8: =AB8+AC8 | AE8: ='Loan Tape (BoE)'!AA9 | AF8: ='Loan Tape (BoE)'!AB9 | AG8: =AE8+AF8 | AH8: =MAX('Loan Tape (BoE)'!AC9,'Loan Tape (BoE)'!AD9) | AI8: ='Loan Tape (BoE)'!AE9 | AJ8: =B8*H8/12 | AK8: =IF(AJ8>0,AI8/AJ8,0) | AL8: =IF('Loan Tape (BoE)'!AF9=1,"Yes","No") | AM8: =IF('Loan Tape (BoE)'!AH9=1,"Yes","No") | AN8: =IF('Loan Tape (BoE)'!AI9=1,"Yes","No") | AO8: =IF('Loan Tape (BoE)'!AJ9=1,"Yes","No")
A9: ='Loan Tape (BoE)'!A10 | B9: ='Loan Tape (BoE)'!B10 | C9: ='Loan Tape (BoE)'!C10 | D9: ='Loan Tape (BoE)'!D10 | E9: ='Loan Tape (BoE)'!E10 | F9: ='Loan Tape (BoE)'!F10 | G9: ='Loan Tape (BoE)'!G10 | H9: ='Loan Tape (BoE)'!H10/100 | I9: =IFERROR(IFS('Loan Tape (BoE)'!I10=1,"House",'Loan Tape (BoE)'!I10=2,"Flat",'Loan Tape (BoE)'!I10=3,"Bungalow",'Loan Tape (BoE)'!I10=4,"Maisonette"),"") | J9: ='Loan Tape (BoE)'!J10 | K9: ='Loan Tape (BoE)'!K10 | L9: =IFERROR(IFS('Loan Tape (BoE)'!L10=1,"Owner Occupied",'Loan Tape (BoE)'!L10=2,"BTL",'Loan Tape (BoE)'!L10=3,"Second Home",'Loan Tape (BoE)'!L10=4,"Investment"),"") | M9: =IFERROR(IFS('Loan Tape (BoE)'!M10=1,"Purchase",'Loan Tape (BoE)'!M10=2,"Remortgage",OR('Loan Tape (BoE)'!M10=3,'Loan Tape (BoE)'!M10=4),"Cash-out"),"") | N9: =IFERROR(IFS('Loan Tape (BoE)'!N10=1,"Repayment",'Loan Tape (BoE)'!N10=2,"Interest Only",'Loan Tape (BoE)'!N10=3,"Part & Part"),"") | O9: =IF('Loan Tape (BoE)'!O10=1,"Yes","No") | P9: =IF('Loan Tape (BoE)'!P10=1,"Yes","No") | Q9: =IF('Loan Tape (BoE)'!Q10=1,"Yes","No") | R9: ='Loan Tape (BoE)'!R10 | S9: ='Loan Tape (BoE)'!S10 | T9: ='Loan Tape (BoE)'!T10 | U9: =R9+S9 | V9: =IFERROR(IFS('Loan Tape (BoE)'!U10=1,"Employed",'Loan Tape (BoE)'!U10=2,"Self-Employed",'Loan Tape (BoE)'!U10=3,"Unemployed",'Loan Tape (BoE)'!U10=4,"Retired"),"") | W9: =IFERROR(IFS('Loan Tape (BoE)'!V10=1,"Employed",'Loan Tape (BoE)'!V10=2,"Self-Employed",'Loan Tape (BoE)'!V10=3,"Unemployed",'Loan Tape (BoE)'!V10=4,"Retired"),"") | X9: =IF(OR(V9="Self-Employed",W9="Self-Employed"),"Yes","No") | Y9: ='Loan Tape (BoE)'!W10 | Z9: ='Loan Tape (BoE)'!X10 | AA9: =IF(T9=1,Y9,MIN(Y9,Z9)) | AB9: ='Loan Tape (BoE)'!Y10 | AC9: ='Loan Tape (BoE)'!Z10 | AD9: =AB9+AC9 | AE9: ='Loan Tape (BoE)'!AA10 | AF9: ='Loan Tape (BoE)'!AB10 | AG9: =AE9+AF9 | AH9: =MAX('Loan Tape (BoE)'!AC10,'Loan Tape (BoE)'!AD10) | AI9: ='Loan Tape (BoE)'!AE10 | AJ9: =B9*H9/12 | AK9: =IF(AJ9>0,AI9/AJ9,0) | AL9: =IF('Loan Tape (BoE)'!AF10=1,"Yes","No") | AM9: =IF('Loan Tape (BoE)'!AH10=1,"Yes","No") | AN9: =IF('Loan Tape (BoE)'!AI10=1,"Yes","No") | AO9: =IF('Loan Tape (BoE)'!AJ10=1,"Yes","No")
A10: ='Loan Tape (BoE)'!A11 | B10: ='Loan Tape (BoE)'!B11 | C10: ='Loan Tape (BoE)'!C11 | D10: ='Loan Tape (BoE)'!D11 | E10: ='Loan Tape (BoE)'!E11 | F10: ='Loan Tape (BoE)'!F11 | G10: ='Loan Tape (BoE)'!G11 | H10: ='Loan Tape (BoE)'!H11/100 | I10: =IFERROR(IFS('Loan Tape (BoE)'!I11=1,"House",'Loan Tape (BoE)'!I11=2,"Flat",'Loan Tape (BoE)'!I11=3,"Bungalow",'Loan Tape (BoE)'!I11=4,"Maisonette"),"") | J10: ='Loan Tape (BoE)'!J11 | K10: ='Loan Tape (BoE)'!K11 | L10: =IFERROR(IFS('Loan Tape (BoE)'!L11=1,"Owner Occupied",'Loan Tape (BoE)'!L11=2,"BTL",'Loan Tape (BoE)'!L11=3,"Second Home",'Loan Tape (BoE)'!L11=4,"Investment"),"") | M10: =IFERROR(IFS('Loan Tape (BoE)'!M11=1,"Purchase",'Loan Tape (BoE)'!M11=2,"Remortgage",OR('Loan Tape (BoE)'!M11=3,'Loan Tape (BoE)'!M11=4),"Cash-out"),"") | N10: =IFERROR(IFS('Loan Tape (BoE)'!N11=1,"Repayment",'Loan Tape (BoE)'!N11=2,"Interest Only",'Loan Tape (BoE)'!N11=3,"Part & Part"),"") | O10: =IF('Loan Tape (BoE)'!O11=1,"Yes","No") | P10: =IF('Loan Tape (BoE)'!P11=1,"Yes","No") | Q10: =IF('Loan Tape (BoE)'!Q11=1,"Yes","No") | R10: ='Loan Tape (BoE)'!R11 | S10: ='Loan Tape (BoE)'!S11 | T10: ='Loan Tape (BoE)'!T11 | U10: =R10+S10 | V10: =IFERROR(IFS('Loan Tape (BoE)'!U11=1,"Employed",'Loan Tape (BoE)'!U11=2,"Self-Employed",'Loan Tape (BoE)'!U11=3,"Unemployed",'Loan Tape (BoE)'!U11=4,"Retired"),"") | W10: =IFERROR(IFS('Loan Tape (BoE)'!V11=1,"Employed",'Loan Tape (BoE)'!V11=2,"Self-Employed",'Loan Tape (BoE)'!V11=3,"Unemployed",'Loan Tape (BoE)'!V11=4,"Retired"),"") | X10: =IF(OR(V10="Self-Employed",W10="Self-Employed"),"Yes","No") | Y10: ='Loan Tape (BoE)'!W11 | Z10: ='Loan Tape (BoE)'!X11 | AA10: =IF(T10=1,Y10,MIN(Y10,Z10)) | AB10: ='Loan Tape (BoE)'!Y11 | AC10: ='Loan Tape (BoE)'!Z11 | AD10: =AB10+AC10 | AE10: ='Loan Tape (BoE)'!AA11 | AF10: ='Loan Tape (BoE)'!AB11 | AG10: =AE10+AF10 | AH10: =MAX('Loan Tape (BoE)'!AC11,'Loan Tape (BoE)'!AD11) | AI10: ='Loan Tape (BoE)'!AE11 | AJ10: =B10*H10/12 | AK10: =IF(AJ10>0,AI10/AJ10,0) | AL10: =IF('Loan Tape (BoE)'!AF11=1,"Yes","No") | AM10: =IF('Loan Tape (BoE)'!AH11=1,"Yes","No") | AN10: =IF('Loan Tape (BoE)'!AI11=1,"Yes","No") | AO10: =IF('Loan Tape (BoE)'!AJ11=1,"Yes","No")
A11: ='Loan Tape (BoE)'!A12 | B11: ='Loan Tape (BoE)'!B12 | C11: ='Loan Tape (BoE)'!C12 | D11: ='Loan Tape (BoE)'!D12 | E11: ='Loan Tape (BoE)'!E12 | F11: ='Loan Tape (BoE)'!F12 | G11: ='Loan Tape (BoE)'!G12 | H11: ='Loan Tape (BoE)'!H12/100 | I11: =IFERROR(IFS('Loan Tape (BoE)'!I12=1,"House",'Loan Tape (BoE)'!I12=2,"Flat",'Loan Tape (BoE)'!I12=3,"Bungalow",'Loan Tape (BoE)'!I12=4,"Maisonette"),"") | J11: ='Loan Tape (BoE)'!J12 | K11: ='Loan Tape (BoE)'!K12 | L11: =IFERROR(IFS('Loan Tape (BoE)'!L12=1,"Owner Occupied",'Loan Tape (BoE)'!L12=2,"BTL",'Loan Tape (BoE)'!L12=3,"Second Home",'Loan Tape (BoE)'!L12=4,"Investment"),"") | M11: =IFERROR(IFS('Loan Tape (BoE)'!M12=1,"Purchase",'Loan Tape (BoE)'!M12=2,"Remortgage",OR('Loan Tape (BoE)'!M12=3,'Loan Tape (BoE)'!M12=4),"Cash-out"),"") | N11: =IFERROR(IFS('Loan Tape (BoE)'!N12=1,"Repayment",'Loan Tape (BoE)'!N12=2,"Interest Only",'Loan Tape (BoE)'!N12=3,"Part & Part"),"") | O11: =IF('Loan Tape (BoE)'!O12=1,"Yes","No") | P11: =IF('Loan Tape (BoE)'!P12=1,"Yes","No") | Q11: =IF('Loan Tape (BoE)'!Q12=1,"Yes","No") | R11: ='Loan Tape (BoE)'!R12 | S11: ='Loan Tape (BoE)'!S12 | T11: ='Loan Tape (BoE)'!T12 | U11: =R11+S11 | V11: =IFERROR(IFS('Loan Tape (BoE)'!U12=1,"Employed",'Loan Tape (BoE)'!U12=2,"Self-Employed",'Loan Tape (BoE)'!U12=3,"Unemployed",'Loan Tape (BoE)'!U12=4,"Retired"),"") | W11: =IFERROR(IFS('Loan Tape (BoE)'!V12=1,"Employed",'Loan Tape (BoE)'!V12=2,"Self-Employed",'Loan Tape (BoE)'!V12=3,"Unemployed",'Loan Tape (BoE)'!V12=4,"Retired"),"") | X11: =IF(OR(V11="Self-Employed",W11="Self-Employed"),"Yes","No") | Y11: ='Loan Tape (BoE)'!W12 | Z11: ='Loan Tape (BoE)'!X12 | AA11: =IF(T11=1,Y11,MIN(Y11,Z11)) | AB11: ='Loan Tape (BoE)'!Y12 | AC11: ='Loan Tape (BoE)'!Z12 | AD11: =AB11+AC11 | AE11: ='Loan Tape (BoE)'!AA12 | AF11: ='Loan Tape (BoE)'!AB12 | AG11: =AE11+AF11 | AH11: =MAX('Loan Tape (BoE)'!AC12,'Loan Tape (BoE)'!AD12) | AI11: ='Loan Tape (BoE)'!AE12 | AJ11: =B11*H11/12 | AK11: =IF(AJ11>0,AI11/AJ11,0) | AL11: =IF('Loan Tape (BoE)'!AF12=1,"Yes","No") | AM11: =IF('Loan Tape (BoE)'!AH12=1,"Yes","No") | AN11: =IF('Loan Tape (BoE)'!AI12=1,"Yes","No") | AO11: =IF('Loan Tape (BoE)'!AJ12=1,"Yes","No")
A12: ='Loan Tape (BoE)'!A13 | B12: ='Loan Tape (BoE)'!B13 | C12: ='Loan Tape (BoE)'!C13 | D12: ='Loan Tape (BoE)'!D13 | E12: ='Loan Tape (BoE)'!E13 | F12: ='Loan Tape (BoE)'!F13 | G12: ='Loan Tape (BoE)'!G13 | H12: ='Loan Tape (BoE)'!H13/100 | I12: =IFERROR(IFS('Loan Tape (BoE)'!I13=1,"House",'Loan Tape (BoE)'!I13=2,"Flat",'Loan Tape (BoE)'!I13=3,"Bungalow",'Loan Tape (BoE)'!I13=4,"Maisonette"),"") | J12: ='Loan Tape (BoE)'!J13 | K12: ='Loan Tape (BoE)'!K13 | L12: =IFERROR(IFS('Loan Tape (BoE)'!L13=1,"Owner Occupied",'Loan Tape (BoE)'!L13=2,"BTL",'Loan Tape (BoE)'!L13=3,"Second Home",'Loan Tape (BoE)'!L13=4,"Investment"),"") | M12: =IFERROR(IFS('Loan Tape (BoE)'!M13=1,"Purchase",'Loan Tape (BoE)'!M13=2,"Remortgage",OR('Loan Tape (BoE)'!M13=3,'Loan Tape (BoE)'!M13=4),"Cash-out"),"") | N12: =IFERROR(IFS('Loan Tape (BoE)'!N13=1,"Repayment",'Loan Tape (BoE)'!N13=2,"Interest Only",'Loan Tape (BoE)'!N13=3,"Part & Part"),"") | O12: =IF('Loan Tape (BoE)'!O13=1,"Yes","No") | P12: =IF('Loan Tape (BoE)'!P13=1,"Yes","No") | Q12: =IF('Loan Tape (BoE)'!Q13=1,"Yes","No") | R12: ='Loan Tape (BoE)'!R13 | S12: ='Loan Tape (BoE)'!S13 | T12: ='Loan Tape (BoE)'!T13 | U12: =R12+S12 | V12: =IFERROR(IFS('Loan Tape (BoE)'!U13=1,"Employed",'Loan Tape (BoE)'!U13=2,"Self-Employed",'Loan Tape (BoE)'!U13=3,"Unemployed",'Loan Tape (BoE)'!U13=4,"Retired"),"") | W12: =IFERROR(IFS('Loan Tape (BoE)'!V13=1,"Employed",'Loan Tape (BoE)'!V13=2,"Self-Employed",'Loan Tape (BoE)'!V13=3,"Unemployed",'Loan Tape (BoE)'!V13=4,"Retired"),"") | X12: =IF(OR(V12="Self-Employed",W12="Self-Employed"),"Yes","No") | Y12: ='Loan Tape (BoE)'!W13 | Z12: ='Loan Tape (BoE)'!X13 | AA12: =IF(T12=1,Y12,MIN(Y12,Z12)) | AB12: ='Loan Tape (BoE)'!Y13 | AC12: ='Loan Tape (BoE)'!Z13 | AD12: =AB12+AC12 | AE12: ='Loan Tape (BoE)'!AA13 | AF12: ='Loan Tape (BoE)'!AB13 | AG12: =AE12+AF12 | AH12: =MAX('Loan Tape (BoE)'!AC13,'Loan Tape (BoE)'!AD13) | AI12: ='Loan Tape (BoE)'!AE13 | AJ12: =B12*H12/12 | AK12: =IF(AJ12>0,AI12/AJ12,0) | AL12: =IF('Loan Tape (BoE)'!AF13=1,"Yes","No") | AM12: =IF('Loan Tape (BoE)'!AH13=1,"Yes","No") | AN12: =IF('Loan Tape (BoE)'!AI13=1,"Yes","No") | AO12: =IF('Loan Tape (BoE)'!AJ13=1,"Yes","No")
A13: ='Loan Tape (BoE)'!A14 | B13: ='Loan Tape (BoE)'!B14 | C13: ='Loan Tape (BoE)'!C14 | D13: ='Loan Tape (BoE)'!D14 | E13: ='Loan Tape (BoE)'!E14 | F13: ='Loan Tape (BoE)'!F14 | G13: ='Loan Tape (BoE)'!G14 | H13: ='Loan Tape (BoE)'!H14/100 | I13: =IFERROR(IFS('Loan Tape (BoE)'!I14=1,"House",'Loan Tape (BoE)'!I14=2,"Flat",'Loan Tape (BoE)'!I14=3,"Bungalow",'Loan Tape (BoE)'!I14=4,"Maisonette"),"") | J13: ='Loan Tape (BoE)'!J14 | K13: ='Loan Tape (BoE)'!K14 | L13: =IFERROR(IFS('Loan Tape (BoE)'!L14=1,"Owner Occupied",'Loan Tape (BoE)'!L14=2,"BTL",'Loan Tape (BoE)'!L14=3,"Second Home",'Loan Tape (BoE)'!L14=4,"Investment"),"") | M13: =IFERROR(IFS('Loan Tape (BoE)'!M14=1,"Purchase",'Loan Tape (BoE)'!M14=2,"Remortgage",OR('Loan Tape (BoE)'!M14=3,'Loan Tape (BoE)'!M14=4),"Cash-out"),"") | N13: =IFERROR(IFS('Loan Tape (BoE)'!N14=1,"Repayment",'Loan Tape (BoE)'!N14=2,"Interest Only",'Loan Tape (BoE)'!N14=3,"Part & Part"),"") | O13: =IF('Loan Tape (BoE)'!O14=1,"Yes","No") | P13: =IF('Loan Tape (BoE)'!P14=1,"Yes","No") | Q13: =IF('Loan Tape (BoE)'!Q14=1,"Yes","No") | R13: ='Loan Tape (BoE)'!R14 | S13: ='Loan Tape (BoE)'!S14 | T13: ='Loan Tape (BoE)'!T14 | U13: =R13+S13 | V13: =IFERROR(IFS('Loan Tape (BoE)'!U14=1,"Employed",'Loan Tape (BoE)'!U14=2,"Self-Employed",'Loan Tape (BoE)'!U14=3,"Unemployed",'Loan Tape (BoE)'!U14=4,"Retired"),"") | W13: =IFERROR(IFS('Loan Tape (BoE)'!V14=1,"Employed",'Loan Tape (BoE)'!V14=2,"Self-Employed",'Loan Tape (BoE)'!V14=3,"Unemployed",'Loan Tape (BoE)'!V14=4,"Retired"),"") | X13: =IF(OR(V13="Self-Employed",W13="Self-Employed"),"Yes","No") | Y13: ='Loan Tape (BoE)'!W14 | Z13: ='Loan Tape (BoE)'!X14 | AA13: =IF(T13=1,Y13,MIN(Y13,Z13)) | AB13: ='Loan Tape (BoE)'!Y14 | AC13: ='Loan Tape (BoE)'!Z14 | AD13: =AB13+AC13 | AE13: ='Loan Tape (BoE)'!AA14 | AF13: ='Loan Tape (BoE)'!AB14 | AG13: =AE13+AF13 | AH13: =MAX('Loan Tape (BoE)'!AC14,'Loan Tape (BoE)'!AD14) | AI13: ='Loan Tape (BoE)'!AE14 | AJ13: =B13*H13/12 | AK13: =IF(AJ13>0,AI13/AJ13,0) | AL13: =IF('Loan Tape (BoE)'!AF14=1,"Yes","No") | AM13: =IF('Loan Tape (BoE)'!AH14=1,"Yes","No") | AN13: =IF('Loan Tape (BoE)'!AI14=1,"Yes","No") | AO13: =IF('Loan Tape (BoE)'!AJ14=1,"Yes","No")
A14: ='Loan Tape (BoE)'!A15 | B14: ='Loan Tape (BoE)'!B15 | C14: ='Loan Tape (BoE)'!C15 | D14: ='Loan Tape (BoE)'!D15 | E14: ='Loan Tape (BoE)'!E15 | F14: ='Loan Tape (BoE)'!F15 | G14: ='Loan Tape (BoE)'!G15 | H14: ='Loan Tape (BoE)'!H15/100 | I14: =IFERROR(IFS('Loan Tape (BoE)'!I15=1,"House",'Loan Tape (BoE)'!I15=2,"Flat",'Loan Tape (BoE)'!I15=3,"Bungalow",'Loan Tape (BoE)'!I15=4,"Maisonette"),"") | J14: ='Loan Tape (BoE)'!J15 | K14: ='Loan Tape (BoE)'!K15 | L14: =IFERROR(IFS('Loan Tape (BoE)'!L15=1,"Owner Occupied",'Loan Tape (BoE)'!L15=2,"BTL",'Loan Tape (BoE)'!L15=3,"Second Home",'Loan Tape (BoE)'!L15=4,"Investment"),"") | M14: =IFERROR(IFS('Loan Tape (BoE)'!M15=1,"Purchase",'Loan Tape (BoE)'!M15=2,"Remortgage",OR('Loan Tape (BoE)'!M15=3,'Loan Tape (BoE)'!M15=4),"Cash-out"),"") | N14: =IFERROR(IFS('Loan Tape (BoE)'!N15=1,"Repayment",'Loan Tape (BoE)'!N15=2,"Interest Only",'Loan Tape (BoE)'!N15=3,"Part & Part"),"") | O14: =IF('Loan Tape (BoE)'!O15=1,"Yes","No") | P14: =IF('Loan Tape (BoE)'!P15=1,"Yes","No") | Q14: =IF('Loan Tape (BoE)'!Q15=1,"Yes","No") | R14: ='Loan Tape (BoE)'!R15 | S14: ='Loan Tape (BoE)'!S15 | T14: ='Loan Tape (BoE)'!T15 | U14: =R14+S14 | V14: =IFERROR(IFS('Loan Tape (BoE)'!U15=1,"Employed",'Loan Tape (BoE)'!U15=2,"Self-Employed",'Loan Tape (BoE)'!U15=3,"Unemployed",'Loan Tape (BoE)'!U15=4,"Retired"),"") | W14: =IFERROR(IFS('Loan Tape (BoE)'!V15=1,"Employed",'Loan Tape (BoE)'!V15=2,"Self-Employed",'Loan Tape (BoE)'!V15=3,"Unemployed",'Loan Tape (BoE)'!V15=4,"Retired"),"") | X14: =IF(OR(V14="Self-Employed",W14="Self-Employed"),"Yes","No") | Y14: ='Loan Tape (BoE)'!W15 | Z14: ='Loan Tape (BoE)'!X15 | AA14: =IF(T14=1,Y14,MIN(Y14,Z14)) | AB14: ='Loan Tape (BoE)'!Y15 | AC14: ='Loan Tape (BoE)'!Z15 | AD14: =AB14+AC14 | AE14: ='Loan Tape (BoE)'!AA15 | AF14: ='Loan Tape (BoE)'!AB15 | AG14: =AE14+AF14 | AH14: =MAX('Loan Tape (BoE)'!AC15,'Loan Tape (BoE)'!AD15) | AI14: ='Loan Tape (BoE)'!AE15 | AJ14: =B14*H14/12 | AK14: =IF(AJ14>0,AI14/AJ14,0) | AL14: =IF('Loan Tape (BoE)'!AF15=1,"Yes","No") | AM14: =IF('Loan Tape (BoE)'!AH15=1,"Yes","No") | AN14: =IF('Loan Tape (BoE)'!AI15=1,"Yes","No") | AO14: =IF('Loan Tape (BoE)'!AJ15=1,"Yes","No")
A15: ='Loan Tape (BoE)'!A16 | B15: ='Loan Tape (BoE)'!B16 | C15: ='Loan Tape (BoE)'!C16 | D15: ='Loan Tape (BoE)'!D16 | E15: ='Loan Tape (BoE)'!E16 | F15: ='Loan Tape (BoE)'!F16 | G15: ='Loan Tape (BoE)'!G16 | H15: ='Loan Tape (BoE)'!H16/100 | I15: =IFERROR(IFS('Loan Tape (BoE)'!I16=1,"House",'Loan Tape (BoE)'!I16=2,"Flat",'Loan Tape (BoE)'!I16=3,"Bungalow",'Loan Tape (BoE)'!I16=4,"Maisonette"),"") | J15: ='Loan Tape (BoE)'!J16 | K15: ='Loan Tape (BoE)'!K16 | L15: =IFERROR(IFS('Loan Tape (BoE)'!L16=1,"Owner Occupied",'Loan Tape (BoE)'!L16=2,"BTL",'Loan Tape (BoE)'!L16=3,"Second Home",'Loan Tape (BoE)'!L16=4,"Investment"),"") | M15: =IFERROR(IFS('Loan Tape (BoE)'!M16=1,"Purchase",'Loan Tape (BoE)'!M16=2,"Remortgage",OR('Loan Tape (BoE)'!M16=3,'Loan Tape (BoE)'!M16=4),"Cash-out"),"") | N15: =IFERROR(IFS('Loan Tape (BoE)'!N16=1,"Repayment",'Loan Tape (BoE)'!N16=2,"Interest Only",'Loan Tape (BoE)'!N16=3,"Part & Part"),"") | O15: =IF('Loan Tape (BoE)'!O16=1,"Yes","No") | P15: =IF('Loan Tape (BoE)'!P16=1,"Yes","No") | Q15: =IF('Loan Tape (BoE)'!Q16=1,"Yes","No") | R15: ='Loan Tape (BoE)'!R16 | S15: ='Loan Tape (BoE)'!S16 | T15: ='Loan Tape (BoE)'!T16 | U15: =R15+S15 | V15: =IFERROR(IFS('Loan Tape (BoE)'!U16=1,"Employed",'Loan Tape (BoE)'!U16=2,"Self-Employed",'Loan Tape (BoE)'!U16=3,"Unemployed",'Loan Tape (BoE)'!U16=4,"Retired"),"") | W15: =IFERROR(IFS('Loan Tape (BoE)'!V16=1,"Employed",'Loan Tape (BoE)'!V16=2,"Self-Employed",'Loan Tape (BoE)'!V16=3,"Unemployed",'Loan Tape (BoE)'!V16=4,"Retired"),"") | X15: =IF(OR(V15="Self-Employed",W15="Self-Employed"),"Yes","No") | Y15: ='Loan Tape (BoE)'!W16 | Z15: ='Loan Tape (BoE)'!X16 | AA15: =IF(T15=1,Y15,MIN(Y15,Z15)) | AB15: ='Loan Tape (BoE)'!Y16 | AC15: ='Loan Tape (BoE)'!Z16 | AD15: =AB15+AC15 | AE15: ='Loan Tape (BoE)'!AA16 | AF15: ='Loan Tape (BoE)'!AB16 | AG15: =AE15+AF15 | AH15: =MAX('Loan Tape (BoE)'!AC16,'Loan Tape (BoE)'!AD16) | AI15: ='Loan Tape (BoE)'!AE16 | AJ15: =B15*H15/12 | AK15: =IF(AJ15>0,AI15/AJ15,0) | AL15: =IF('Loan Tape (BoE)'!AF16=1,"Yes","No") | AM15: =IF('Loan Tape (BoE)'!AH16=1,"Yes","No") | AN15: =IF('Loan Tape (BoE)'!AI16=1,"Yes","No") | AO15: =IF('Loan Tape (BoE)'!AJ16=1,"Yes","No")
A16: ='Loan Tape (BoE)'!A17 | B16: ='Loan Tape (BoE)'!B17 | C16: ='Loan Tape (BoE)'!C17 | D16: ='Loan Tape (BoE)'!D17 | E16: ='Loan Tape (BoE)'!E17 | F16: ='Loan Tape (BoE)'!F17 | G16: ='Loan Tape (BoE)'!G17 | H16: ='Loan Tape (BoE)'!H17/100 | I16: =IFERROR(IFS('Loan Tape (BoE)'!I17=1,"House",'Loan Tape (BoE)'!I17=2,"Flat",'Loan Tape (BoE)'!I17=3,"Bungalow",'Loan Tape (BoE)'!I17=4,"Maisonette"),"") | J16: ='Loan Tape (BoE)'!J17 | K16: ='Loan Tape (BoE)'!K17 | L16: =IFERROR(IFS('Loan Tape (BoE)'!L17=1,"Owner Occupied",'Loan Tape (BoE)'!L17=2,"BTL",'Loan Tape (BoE)'!L17=3,"Second Home",'Loan Tape (BoE)'!L17=4,"Investment"),"") | M16: =IFERROR(IFS('Loan Tape (BoE)'!M17=1,"Purchase",'Loan Tape (BoE)'!M17=2,"Remortgage",OR('Loan Tape (BoE)'!M17=3,'Loan Tape (BoE)'!M17=4),"Cash-out"),"") | N16: =IFERROR(IFS('Loan Tape (BoE)'!N17=1,"Repayment",'Loan Tape (BoE)'!N17=2,"Interest Only",'Loan Tape (BoE)'!N17=3,"Part & Part"),"") | O16: =IF('Loan Tape (BoE)'!O17=1,"Yes","No") | P16: =IF('Loan Tape (BoE)'!P17=1,"Yes","No") | Q16: =IF('Loan Tape (BoE)'!Q17=1,"Yes","No") | R16: ='Loan Tape (BoE)'!R17 | S16: ='Loan Tape (BoE)'!S17 | T16: ='Loan Tape (BoE)'!T17 | U16: =R16+S16 | V16: =IFERROR(IFS('Loan Tape (BoE)'!U17=1,"Employed",'Loan Tape (BoE)'!U17=2,"Self-Employed",'Loan Tape (BoE)'!U17=3,"Unemployed",'Loan Tape (BoE)'!U17=4,"Retired"),"") | W16: =IFERROR(IFS('Loan Tape (BoE)'!V17=1,"Employed",'Loan Tape (BoE)'!V17=2,"Self-Employed",'Loan Tape (BoE)'!V17=3,"Unemployed",'Loan Tape (BoE)'!V17=4,"Retired"),"") | X16: =IF(OR(V16="Self-Employed",W16="Self-Employed"),"Yes","No") | Y16: ='Loan Tape (BoE)'!W17 | Z16: ='Loan Tape (BoE)'!X17 | AA16: =IF(T16=1,Y16,MIN(Y16,Z16)) | AB16: ='Loan Tape (BoE)'!Y17 | AC16: ='Loan Tape (BoE)'!Z17 | AD16: =AB16+AC16 | AE16: ='Loan Tape (BoE)'!AA17 | AF16: ='Loan Tape (BoE)'!AB17 | AG16: =AE16+AF16 | AH16: =MAX('Loan Tape (BoE)'!AC17,'Loan Tape (BoE)'!AD17) | AI16: ='Loan Tape (BoE)'!AE17 | AJ16: =B16*H16/12 | AK16: =IF(AJ16>0,AI16/AJ16,0) | AL16: =IF('Loan Tape (BoE)'!AF17=1,"Yes","No") | AM16: =IF('Loan Tape (BoE)'!AH17=1,"Yes","No") | AN16: =IF('Loan Tape (BoE)'!AI17=1,"Yes","No") | AO16: =IF('Loan Tape (BoE)'!AJ17=1,"Yes","No")
... A104: ='Loan Tape (BoE)'!A105 | B104: ='Loan Tape (BoE)'!B105 | C104: ='Loan Tape (BoE)'!C105 | D104: ='Loan Tape (BoE)'!D105 | E104: ='Loan Tape (BoE)'!E105 | F104: ='Loan Tape (BoE)'!F105 | G104: ='Loan Tape (BoE)'!G105 | H104: ='Loan Tape (BoE)'!H105/100 | I104: =IFERROR(IFS('Loan Tape (BoE)'!I105=1,"House",'Loan Tape (BoE)'!I105=2,"Flat",'Loan Tape (BoE)'!I105=3,"Bungalow",'Loan Tape (BoE)'!I105=4,"Maisonette"),"") | J104: ='Loan Tape (BoE)'!J105 | K104: ='Loan Tape (BoE)'!K105 | L104: =IFERROR(IFS('Loan Tape (BoE)'!L105=1,"Owner Occupied",'Loan Tape (BoE)'!L105=2,"BTL",'Loan Tape (BoE)'!L105=3,"Second Home",'Loan Tape (BoE)'!L105=4,"Investment"),"") | M104: =IFERROR(IFS('Loan Tape (BoE)'!M105=1,"Purchase",'Loan Tape (BoE)'!M105=2,"Remortgage",OR('Loan Tape (BoE)'!M105=3,'Loan Tape (BoE)'!M105=4),"Cash-out"),"") | N104: =IFERROR(IFS('Loan Tape (BoE)'!N105=1,"Repayment",'Loan Tape (BoE)'!N105=2,"Interest Only",'Loan Tape (BoE)'!N105=3,"Part & Part"),"") | O104: =IF('Loan Tape (BoE)'!O105=1,"Yes","No") | P104: =IF('Loan Tape (BoE)'!P105=1,"Yes","No") | Q104: =IF('Loan Tape (BoE)'!Q105=1,"Yes","No") | R104: ='Loan Tape (BoE)'!R105 | S104: ='Loan Tape (BoE)'!S105 | T104: ='Loan Tape (BoE)'!T105 | U104: =R104+S104 | V104: =IFERROR(IFS('Loan Tape (BoE)'!U105=1,"Employed",'Loan Tape (BoE)'!U105=2,"Self-Employed",'Loan Tape (BoE)'!U105=3,"Unemployed",'Loan Tape (BoE)'!U105=4,"Retired"),"") | W104: =IFERROR(IFS('Loan Tape (BoE)'!V105=1,"Employed",'Loan Tape (BoE)'!V105=2,"Self-Employed",'Loan Tape (BoE)'!V105=3,"Unemployed",'Loan Tape (BoE)'!V105=4,"Retired"),"") | X104: =IF(OR(V104="Self-Employed",W104="Self-Employed"),"Yes","No") | Y104: ='Loan Tape (BoE)'!W105 | Z104: ='Loan Tape (BoE)'!X105 | AA104: =IF(T104=1,Y104,MIN(Y104,Z104)) | AB104: ='Loan Tape (BoE)'!Y105 | AC104: ='Loan Tape (BoE)'!Z105 | AD104: =AB104+AC104 | AE104: ='Loan Tape (BoE)'!AA105 | AF104: ='Loan Tape (BoE)'!AB105 | AG104: =AE104+AF104 | AH104: =MAX('Loan Tape (BoE)'!AC105,'Loan Tape (BoE)'!AD105) | AI104: ='Loan Tape (BoE)'!AE105 | AJ104: =B104*H104/12 | AK104: =IF(AJ104>0,AI104/AJ104,0) | AL104: =IF('Loan Tape (BoE)'!AF105=1,"Yes","No") | AM104: =IF('Loan Tape (BoE)'!AH105=1,"Yes","No") | AN104: =IF('Loan Tape (BoE)'!AI105=1,"Yes","No") | AO104: =IF('Loan Tape (BoE)'!AJ105=1,"Yes","No")

Sheet FF Calculations
A1: FORECLOSURE FREQUENCY CALCULATIONS - FULL S&P METHODOLOGY
A2: Complete adjustment sequence with all S&P exclusion rules applied
A4: Loan ID | B4: Balance | C4: OLTV % | D4: CLTV % | E4: S&P LTV % | F4: LTV Mult | G4: Orig Adj | H4: Income Mult Adj | I4: BTL/DSCR Adj | J4: Lien Adj | K4: Purpose Adj | L4: Arrears Adj | M4: Seasoning Adj | N4: FTB Adj | O4: HTB Adj | P4: Shared Own Adj | Q4: RTB Adj | R4: Self-Cert Adj | S4: Payment Shock Adj | T4: IO Adj | U4: Self-Emp Adj | V4: Commercial Adj | W4: CCJ Adj | X4: Bankruptcy Adj | Y4: Reperform Adj | Z4: Adjusted FF %
A5: ='Loan Tape (S&P)'!A5 | B5: ='Loan Tape (S&P)'!B5 | C5: =IFERROR('Loan Tape (S&P)'!C5/'Loan Tape (S&P)'!E5,0) | D5: =IFERROR( 'Loan Tape (S&P)'!B5/ ('Loan Tape (S&P)'!D5* (1-IF('Loan Tape (S&P)'!AT5<>"Full", VLOOKUP('Control Panel'!$B$6,'Jurisdiction Parameters'!$A:$D,4,FALSE), 0))), 0) | E5: =('Control Panel'!$B$12*C5)+('Control Panel'!$B$13*D5) | F5: =IFERROR( LET( juris,'Control Panel'!$B$6, ltv_val,E5, IF(juris="UK", VLOOKUP(ltv_val,'LTV Curve UK'!$A:$B,2,TRUE), IF(juris="Ireland", VLOOKUP(ltv_val,'LTV Curve Ireland'!$A:$B,2,TRUE), VLOOKUP(ltv_val,'LTV Curve Netherlands'!$A:$B,2,TRUE) ) ) ), 1) | G5: ='Control Panel'!$B$14 | H5: =IFERROR( LET( is_btl,'Loan Tape (S&P)'!L5="BTL", seasoning_months,('Control Panel'!$B$10-'Loan Tape (S&P)'!F5)*12, threshold_months,VLOOKUP('Control Panel'!$B$6,'Jurisdiction Parameters'!$A:$F,6,FALSE), num_borr,'Loan Tape (S&P)'!T5, balance,'Loan Tape (S&P)'!B5, borr1_inc,'Loan Tape (S&P)'!R5, borr2_inc,'Loan Tape (S&P)'!S5, total_inc,'Loan Tape (S&P)'!U5, thresh_high,VLOOKUP('Control Panel'!$B$6,'Jurisdiction Parameters'!$A:$G,7,FALSE), thresh_med,VLOOKUP('Control Panel'!$B$6,'Jurisdiction Parameters'!$A:$H,8,FALSE), thresh_joint_high,VLOOKUP('Control Panel'!$B$6,'Jurisdiction Parameters'!$A:$I,9,FALSE), thresh_joint_med,VLOOKUP('Control Panel'!$B$6,'Jurisdiction Parameters'!$A:$J,10,FALSE), mult_high,VLOOKUP("High",'FF Adj Parameters'!$C$6:$C$8&'FF Adj Parameters'!$B$6:$B$8,2,FALSE), mult_med,VLOOKUP("Medium",'FF Adj Parameters'!$C$6:$C$8&'FF Adj Parameters'!$B$6:$B$8,2,FALSE), IF(is_btl,1.00, IF(seasoning_months>threshold_months,1.00, LET( single_mult,balance/borr1_inc, single_adj,IF(single_mult>thresh_high,1.50,IF(single_mult>thresh_med,1.20,1.00)), joint_mult,balance/total_inc, joint_adj,IF(joint_mult>thresh_joint_high,1.50,IF(joint_mult>thresh_joint_med,1.20,1.00)), borr1_mult,balance/borr1_inc, borr1_adj,IF(borr1_mult>thresh_high,1.50,IF(borr1_mult>thresh_med,1.20,1.00)), borr2_mult,IF(num_borr=2,balance/borr2_inc,999), borr2_adj,IF(num_borr=2,IF(borr2_mult>thresh_high,1.50,IF(borr2_mult>thresh_med,1.20,1.00)),1.00), IF(num_borr=1,single_adj,MIN(joint_adj,borr1_adj,borr2_adj)) ) ) ) ), 1) | I5: =IFERROR( IF('Loan Tape (S&P)'!L5="BTL", LET( rental,'Loan Tape (S&P)'!AV5, balance,'Loan Tape (S&P)'!B5, int_rate,VLOOKUP('Control Panel'!$B$6,'Jurisdiction Parameters'!$A:$E,5,FALSE), int_cost,balance*int_rate, dscr,rental/int_cost, IF(rental=0, INDEX('FF Adj Parameters'!$B$12:$B$16,1), IF(dscr>=1.35, INDEX('FF Adj Parameters'!$B$12:$B$16,5), IF(dscr>=1.20, INDEX('FF Adj Parameters'!$B$12:$B$16,4), IF(dscr>=1.00, INDEX('FF Adj Parameters'!$B$12:$B$16,3), INDEX('FF Adj Parameters'!$B$12:$B$16,2) ) ) ) ) ), 1.00), 1) | J5: =IFERROR( IF('Loan Tape (S&P)'!AS5="First", INDEX('FF Adj Parameters'!$B$20:$B$22,1), IF('Loan Tape (S&P)'!AS5="Second", INDEX('FF Adj Parameters'!$B$20:$B$22,2), INDEX('FF Adj Parameters'!$B$20:$B$22,3) ) ), 1) | K5: =IFERROR( IF('Loan Tape (S&P)'!AS5<>"First",1.00, IF('Loan Tape (S&P)'!M5="Cash-out", INDEX('FF Adj Parameters'!$B$26:$B$28,3), 1.00) ), 1) | L5: =IFERROR( LET( arr_months,'Loan Tape (S&P)'!AK5, arr_3mo,VLOOKUP('Control Panel'!$B$6,'Jurisdiction Parameters'!$A:$M,13,FALSE), arr_2mo,VLOOKUP('Control Panel'!$B$6,'Jurisdiction Parameters'!$A:$L,12,FALSE), arr_1mo,VLOOKUP('Control Panel'!$B$6,'Jurisdiction Parameters'!$A:$K,11,FALSE), IF(arr_months>=3,arr_3mo, IF(arr_months>=2,arr_2mo, IF(arr_months>=1,arr_1mo,1.00) ) ) ), 1) | M5: =IFERROR( IF('Loan Tape (S&P)'!AK5=0, LET( years,('Control Panel'!$B$10-'Loan Tape (S&P)'!F5)/365.25, IF(years>10,INDEX('FF Adj Parameters'!$B$32:$B$38,7), IF(years>9,INDEX('FF Adj Parameters'!$B$32:$B$38,6), IF(years>8,INDEX('FF Adj Parameters'!$B$32:$B$38,5), IF(years>7,INDEX('FF Adj Parameters'!$B$32:$B$38,4), IF(years>6,INDEX('FF Adj Parameters'!$B$32:$B$38,3), IF(years>5,INDEX('FF Adj Parameters'!$B$32:$B$38,2),1.00) ) ) ) ) ) ), 1.00), 1) | N5: =IFERROR( LET( is_btl,'Loan Tape (S&P)'!L5="BTL", is_htb,'Loan Tape (S&P)'!Q5="Yes", is_ftb,'Loan Tape (S&P)'!AP5="Yes", seasoning_months,('Control Panel'!$B$10-'Loan Tape (S&P)'!F5)*12, threshold_months,VLOOKUP('Control Panel'!$B$6,'Jurisdiction Parameters'!$A:$F,6,FALSE), ftb_mult,INDEX('FF Adj Parameters'!$B$42:$B$47,1), IF(OR(is_btl,is_htb),1.00, IF(AND(is_ftb,seasoning_months<=threshold_months),ftb_mult,1.00) ) ), 1) | O5: =IF('Loan Tape (S&P)'!Q5="Yes", INDEX('FF Adj Parameters'!$B$42:$B$47,2), 1.00) | P5: =IF('Loan Tape (S&P)'!P5="Yes", INDEX('FF Adj Parameters'!$B$42:$B$47,3), 1.00) | Q5: =IF('Loan Tape (S&P)'!O5="Yes", INDEX('FF Adj Parameters'!$B$42:$B$47,4), 1.00) | R5: =IFERROR( LET( is_btl,'Loan Tape (S&P)'!L5="BTL", is_self_cert,'Loan Tape (S&P)'!AO5="Yes", is_performing,'Loan Tape (S&P)'!AK5=0, IF(OR(is_btl,NOT(is_self_cert)),1.00, IF(is_performing, LET( months,('Control Panel'!$B$10-'Loan Tape (S&P)'!F5)*12, factor,IF(months<=12,INDEX('FF Adj Parameters'!$B$62:$B$68,1), IF(months<=24,INDEX('FF Adj Parameters'!$B$62:$B$68,2), IF(months<=36,INDEX('FF Adj Parameters'!$B$62:$B$68,3), IF(months<=48,INDEX('FF Adj Parameters'!$B$62:$B$68,4), IF(months<=60,INDEX('FF Adj Parameters'!$B$62:$B$68,5), IF(months<=72,INDEX('FF Adj Parameters'!$B$62:$B$68,6), INDEX('FF Adj Parameters'!$B$62:$B$68,7) ) ) ) ) ) ), 1+(0.50*factor) ), 1.50) ) ), 1) | S5: =IF('Loan Tape (S&P)'!Q5="Yes",1.00, IF('Loan Tape (S&P)'!AQ5="Yes", INDEX('FF Adj Parameters'!$B$42:$B$47,5), 1.00)) | T5: =IFERROR( IF('Loan Tape (S&P)'!N5<>"Interest Only",1.00, IF('Loan Tape (S&P)'!L5="BTL",1.00, LET( years_to_mat,('Loan Tape (S&P)'!G5-'Control Panel'!$B$10)/365.25, IF(years_to_mat>25,INDEX('FF Adj Parameters'!$B$51:$B$54,1), IF(years_to_mat>=15,INDEX('FF Adj Parameters'!$B$51:$B$54,2), IF(years_to_mat>=5,INDEX('FF Adj Parameters'!$B$51:$B$54,3), INDEX('FF Adj Parameters'!$B$51:$B$54,4) ) ) ) ) ) ), 1) | U5: =IF('Loan Tape (S&P)'!L5="BTL",1.00, IF('Loan Tape (S&P)'!X5="Yes", INDEX('FF Adj Parameters'!$B$58:$B$58,1), 1.00)) | V5: =IF('Loan Tape (S&P)'!AU5="Yes", INDEX('FF Adj Parameters'!$B$42:$B$47,6), 1.00) | W5: =IFERROR( LET( ccj_count,'Loan Tape (S&P)'!AD5, ccj_value,'Loan Tape (S&P)'!AG5, ccj_date,'Loan Tape (S&P)'!AH5, years_since,('Control Panel'!$B$10-ccj_date)/365.25, IF(ccj_count=0,1.00, IF(years_since>6,1.075, LET( is_recent,years_since<1, count_col,IF(is_recent,2,3), count_adj,INDEX('FF Parameters'!$B$49:$D$54,MATCH(ccj_count,'FF Parameters'!$A$49:$A$54,1),count_col), value_adj,IF(ccj_value>=10000,MAX(count_adj,4.00),IF(ccj_value>=5000,MAX(count_adj,2.50),count_adj)), value_adj ) ) ) ), 1) | X5: =1.00 | Y5: =IFERROR( IF('Loan Tape (S&P)'!AR5="Yes", LET( months_since,('Control Panel'!$B$10-'Loan Tape (S&P)'!AS5)/30.44, IF(months_since<=12,INDEX('FF Adj Parameters'!$B$86:$B$89,1), IF(months_since<=24,INDEX('FF Adj Parameters'!$B$86:$B$89,2), IF(months_since<=36,INDEX('FF Adj Parameters'!$B$86:$B$89,3), INDEX('FF Adj Parameters'!$B$86:$B$89,4) ) ) ) ), 1.00), 1) | Z5: =IFERROR( IF(L5>=100,1.00, 'Control Panel'!$B$18*F5*G5*MAX(H5,R5)*I5*J5*K5*L5*M5*N5*O5*P5*Q5*S5*T5*U5*V5*W5*X5*Y5 ), 0)
