Workbook

Sheet Control Panel
A1: S&P WAFF/WALS MODEL - CONTROL PANEL
A2: Version 2.0 - Complete S&P Exclusion Logic | Rating-Driven | BoE Field Mapping
A3: Created: 14-Jan-2026 11:40
A5: MODEL SETTINGS | E5: POOL STATISTICS
A6: Jurisdiction | B6: UK | C6: Select: UK, Ireland, or Netherlands
A7: Parameter | B7: Value | C7: Description | E7: Metric | F7: Value | G7: Note
A8: Target Rating Level | B8: AAA | C8: Drives Base FF, MVD, FSD, Stress Multiple | E8: Loan Count | F8: =COUNTA('Loan Tape (S&P)'!A:A)-1 | G8: After BoE conversion
A9: Analysis Date | B9: 46036.487 | C9: For seasoning and CCJ age calculations | E9: Total Balance | F9: =SUM('Loan Tape (S&P)'!B:B) | G9: £ millions
A10: Portfolio Cutoff Date | B10: 46036.487 | C10: Loan tape as-of date | E10: Avg S&P LTV | F10: =AVERAGE('FF Calculations'!E:E) | G10: Pool average
A11: OLTV Weight | B11: 0.8 | C11: S&P LTV: OLTV weight (typically 80%) | E11: Pool WAFF (%) | F11: =SUMPRODUCT('FF Calculations'!Z5:Z104,'FF Calculations'!B5:B104)/SUM('FF Calculations'!B5:B104) | G11: Balance-weighted FF
A12: CLTV Weight | B12: =VLOOKUP($B$6,'Jurisdiction Parameters'!$A:$B,2,FALSE) | C12: S&P LTV: CLTV weight (typically 20%)
A13: Originator Adjustment | B13: =VLOOKUP($B$6,'Jurisdiction Parameters'!$A:$C,3,FALSE) | C13: Global originator quality (0.70-1.30)
A15: RATING-DRIVEN PARAMETERS (AUTO) | E15: QUICK START GUIDE
A17: Parameter | B17: Value | C17: Source | E17: 1. Input loan data in Loan Tape (BoE) using Bank of England codes
A18: Base FF (%) | B18: =VLOOKUP($B$8,'Rating Parameters'!$A$6:$C$17,2,FALSE) | C18: From Rating Parameters | E18: 2. Data auto-converts to Loan Tape (S&P) format
A19: MVD (%) | B19: =VLOOKUP($B$8,'Rating Parameters'!$A$6:$C$17,3,FALSE) | C19: Market Value Decline | E19: 3. Select target rating level above (drives FF/MVD/FSD)
A20: FSD (%) | B20: =VLOOKUP($B$8,'Rating Parameters'!$A$6:$D$17,4,FALSE) | C20: Forced Sale Discount | E20: 4. Set originator adjustment (0.70-1.30, default 1.00)
A21: Stress Multiple | B21: =VLOOKUP($B$8,'Rating Parameters'!$F$6:$G$17,2,FALSE) | C21: For CE calculation | E21: 5. Review FF Calculations for loan-level results
E22: 6. Check Pool WAFF in statistics panel
E24: CRITICAL NOTES:
E25: • BTL identified from BV27 (Occupancy), not BV29 (Payment Method)
E26: • All S&P exclusion rules automatically applied
E27: • Joint borrower logic uses minimum of joint vs individual
E28: • Self-cert vs income: uses higher (not both)

Sheet BoE Auto-Mapper
A1: BOE AUTO-MAPPER CONFIGURATION
A2: This sheet defines the mapping from Bank of England PRA110 codes to S&P format fields
A4: AR Code | B4: BoE Description | C4: S&P Column | D4: S&P Field Name | E4: Data Type | F4: Conversion Rule
A5: AR1 | B5: Pool Cut-off Date | D5: Pool Cut-off Date | E5: Date | F5: Date
A6: AR2 | B6: Pool Identifier | D6: Pool Identifier | E6: Text/Numeric | F6: Direct
A7: AR3 | B7: Loan Identifier | C7: A | D7: Loan Identifier | E7: Text/Numeric | F7: Direct
A8: AR5 | B8: Originator | C8: B | D8: Originator | E8: Text | F8: Direct
A9: AR19 | B9: Number of Debtors | C9: AA | D9: Number of Debtors | E9: Numeric | F9: Direct
A10: AR21 | B10: Borrower's Employment Status | C10: W | D10: Employment Status | E10: List | F10: Code_Lookup
A11: AR22 | B11: First-time Buyer | C11: U | D11: First Time Buyer | E11: Y / N / ND | F11: YN_Convert
A12: AR23 | B12: Right to Buy | C12: V | D12: Right to Buy | E12: Y / N / ND | F12: YN_Convert
A13: AR26 | B13: Primary Income | C13: Y | D13: Primary Income | E13: Numeric | F13: Direct
A14: AR27 | B14: Income Verification for Primary Income | C14: X | D14: Income Verification | E14: List | F14: Code_Lookup
A15: AR28 | B15: Secondary Income | C15: Z | D15: Secondary Income | E15: Numeric | F15: Direct
A16: AR31 | B16: Number of County Court Judgements or equivalent - Satisfied | C16: AD | D16: CCJ Satisfied | E16: Numeric | F16: Direct
A17: AR33 | B17: Number of County Court Judgements or equivalent - Unsatisfied | C17: AE | D17: CCJ Unsatisfied | E17: Numeric | F17: Direct
A18: AR35 | B18: Last County Court Judgements or equivalent – Date | C18: AF | D18: Last CCJ Date | E18: Date / ND | F18: Date
... A48: AR173 | B48: Performance Arrangement | C48: AR | D48: Performance Arrangement | E48: Date | F48: Date

Sheet Loan Tape (BoE Raw)
A1: AR1 | B1: AR2 | C1: AR3 | D1: AR4 | E1: AR5 | F1: AR6 | G1: AR7 | H1: AR8 | I1: AR9 | J1: AR10 | K1: AR11 | L1: AR12 | M1: AR13 | N1: AR14 | O1: AR15 | P1: AR16 | Q1: AR17 | R1: AR18 | S1: AR19 | T1: AR20 | U1: AR21 | V1: AR22 | W1: AR23 | X1: AR24 | Y1: AR25 | Z1: AR26 | AA1: AR27 | AB1: AR28 | AC1: AR29 | AD1: AR30 | AE1: AR31 | AF1: AR32 | AG1: AR33 | AH1: AR34 | AI1: AR35 | AJ1: AR36 | AK1: AR37 | AL1: AR38 | AM1: AR39 | AN1: AR40 | AO1: AR41 | AP1: AR42 | AQ1: AR43 | AR1: AR44 | AS1: AR45 | AT1: AR46 | AU1: AR47 | AV1: AR48 | AW1: AR49 | AX1: AR50 | AY1: AR51 | AZ1: AR52 | BA1: AR53 | BB1: AR54 | BC1: AR55 | BD1: AR56 | BE1: AR57 | BF1: AR58 | BG1: AR59 | BH1: AR60 | BI1: AR61 | BJ1: AR62 | BK1: AR63 | BL1: AR64 | BM1: AR65 | BN1: AR66 | BO1: AR67 | BP1: AR68 | BQ1: AR69 | BR1: AR70 | BS1: AR71 | BT1: AR72 | BU1: AR73 | BV1: AR74 | BW1: AR75 | BX1: AR76 | BY1: AR77 | BZ1: AR78 | CA1: AR79 | CB1: AR80 | CC1: AR81 | CD1: AR82 | CE1: AR83 | CF1: AR84 | CG1: AR85 | CH1: AR86 | CI1: AR87 | CJ1: AR88 | CK1: AR89 | CL1: AR90 | CM1: AR91 | CN1: AR92 | CO1: AR93 | CP1: AR94 | CQ1: AR95 | CR1: AR96 | CS1: AR97 | CT1: AR98 | CU1: AR99 | CV1: AR100 | CW1: AR101 | CX1: AR102 | CY1: AR103 | CZ1: AR104 | DA1: AR105 | DB1: AR106 | DC1: AR107 | DD1: AR108 | DE1: AR109 | DF1: AR110 | DG1: AR111 | DH1: AR112 | DI1: AR113 | DJ1: AR114 | DK1: AR115 | DL1: AR116 | DM1: AR117 | DN1: AR118 | DO1: AR119 | DP1: AR120 | DQ1: AR121 | DR1: AR122 | DS1: AR123 | DT1: AR124 | DU1: AR125 | DV1: AR126 | DW1: AR127 | DX1: AR128 | DY1: AR129 | DZ1: AR130 | EA1: AR131 | EB1: AR132 | EC1: AR133 | ED1: AR134 | EE1: AR135 | EF1: AR136 | EG1: AR137 | EH1: AR138 | EI1: AR139 | EJ1: AR140 | EK1: AR141 | EL1: AR142 | EM1: AR143 | EN1: AR144 | EO1: AR145 | EP1: AR146 | EQ1: AR147 | ER1: AR148 | ES1: AR149 | ET1: AR150 | EU1: AR151 | EV1: AR152 | EW1: AR153 | EX1: AR154 | EY1: AR155 | EZ1: AR156 | FA1: AR157 | FB1: AR158 | FC1: AR159 | FD1: AR160 | FE1: AR161 | FF1: AR162 | FG1: AR163 | FH1: AR164 | FI1: AR165 | FJ1: AR166 | FK1: AR167 | FL1: AR168 | FM1: AR169 | FN1: AR170 | FO1: AR171 | FP1: AR172 | FQ1: AR173 | FR1: AR174 | FS1: AR175 | FT1: AR176 | FU1: AR177 | FV1: AR178 | FW1: AR179 | FX1: AR180 | FY1: AR181 | FZ1: AR182 | GA1: AR183 | GB1: AR184 | GC1: AR185 | GD1: AR186 | GE1: AR187 | GF1: AR188 | GG1: AR189 | GH1: AR190 | GI1: AR191 | GJ1: AR192 | GK1: AR193 | GL1: AR194 | GM1: AR195 | GN1: AR196 | GO1: AR197 | GP1: AR198 | GQ1: AR199 | GR1: AR200 | GS1: AR201 | GT1: AR202 | GU1: AR203 | GV1: AR204 | GW1: AR205 | GX1: AR206 | GY1: AR207 | GZ1: AR208 | HA1: AR209 | HB1: AR210 | HC1: AR211 | HD1: AR213 | HE1: AR214 | HF1: AR215 | HG1: AR216 | HH1: AR217 | HI1: AR218 | HJ1: AR220 | HK1: AR221 | HL1: AR222 | HM1: AR223 | HN1: AR224 | HO1: AR225 | HP1: AR226 | HQ1: AR227 | HR1: AR228 | HS1: AR230 | HT1: AR231 | HU1: AR232 | HV1: AR233 | HW1: AR234 | HX1: AR235 | HY1: AR236
A2: Pool Cut-off Date | B2: Pool Identifier | C2: Loan Identifier | D2: Regulated Loan | E2: Originator | F2: Servicer Identifier | G2: Borrower Identifier | H2: Property Identifier | I2: Blank | J2: Blank | K2: Blank | L2: Blank | M2: Blank | N2: Blank | O2: Borrower Type | P2: Foreign National | Q2: Borrower Credit Quality | R2: Borrower Year of Birth | S2: Number of Debtors | T2: Second Applicant Year of Birth | U2: Borrower's Employment Status | V2: First-time Buyer | W2: Right to Buy | X2: Right to Buy Price | Y2: Class of Borrower | Z2: Primary Income | AA2: Income Verification for Primary Income | AB2: Secondary Income | AC2: Income Verification for Secondary Income | AD2: Resident | AE2: Number of County Court Judgements or equivalent - Satisfied | AF2: Value of County Court Judgements or equivalent - Satisfied | AG2: Number of County Court Judgements or equivalent - Unsatisfied | AH2: Value of County Court Judgements or equivalent - Unsatisfied | AI2: Last County Court Judgements or equivalent – Date | AJ2: Bankruptcy or Individual Voluntary Arrangement Flag | AK2: Bureau Krediet Registratie 1 to 10 - Credit Type | AL2: Bureau Krediet Registratie 1 to 10- Registration Date | AM2: Bureau Krediet Registratie 1 to 10 - Arrears Code | AN2: Bureau Krediet Registratie 1 to 10 - Credit Amount | AO2: Bureau Krediet Registratie 1 to 10 - Is Coding Cured? | AP2: Bureau Krediet Registratie 1 to 10 - Number of Months Since Cured | AQ2: Bureau Score Provider | AR2: Bureau Score Type | AS2: Bureau Score Date | AT2: Bureau Score Value | AU2: Prior Repossessions | AV2: Previous Mortgage Arrears 0-6 Months | AW2: Previous Mortgage Arrears 6+ Months | AX2: Internal Rating | AY2: Blank | AZ2: Blank | BA2: Blank | BB2: Blank | BC2: Loan Origination Date | BD2: Date of Loan Maturity | BE2: Account Status Date | BF2: Origination Channel / Arranging Bank or Division | BG2: Purpose | BH2: Shared Ownership | BI2: Loan Term | BJ2: Principal Grace Period | BK2: Amount Guaranteed | BL2: Subsidy | BM2: Loan Currency Denomination | BN2: Original Balance | BO2: Current Balance | BP2: Fractioned / Subrogated Loans | BQ2: Repayment Method | BR2: Payment Frequency | BS2: Payment Due | BT2: Payment Type | BU2: Debt to Income | BV2: Type of Guarantee Provider | BW2: Guarantee Provider | BX2: Income Guarantor | BY2: Subsidy Received | BZ2: Mortgage Indemnity Guarantee Provider | CA2: Mortgage Indemnity Guarantee Attachment Point | CB2: Prior Balances | CC2: Other Prior Balances | CD2: Pari Passu Loans | CE2: Subordinated Claims | CF2: Lien | CG2: Retained Amount | CH2: Retained Amount Date | CI2: Maximum Balance | CJ2: Further Loan Advance | CK2: Further Loan Advance Date | CL2: Flexible Loan Amount | CM2: Further Advances | CN2: Length of Payment Holiday | CO2: Subsidy Period | CP2: Mortgage Inscription | CQ2: Mortgage Mandate | CR2: Deed of Postponement? | CS2: Pre-payment Amount | CT2: Pre-payment Date | CU2: Pre-payment Penalties | CV2: Cumulative Pre-payments | CW2: Amount of pre-payments allowed per year | CX2: Offset Savings Balance | CY2: Original Percentage Owned | CZ2: Current Percentage Owned | DA2: Help to Buy Scheme Type | DB2: Blank | DC2: Interest Rate Type | DD2: Current Interest Rate Index | DE2: Current Interest Rate | DF2: Current Interest Rate Margin | DG2: Interest Rate Reset Interval | DH2: Interest Cap Rate | DI2: Interest Revision Date 1 | DJ2: Revision Margin 2 | DK2: Interest Revision Date 2 | DL2: Revision Margin 3 | DM2: Interest Revision Date 3 | DN2: Revised Interest Rate Index | DO2: Revised Interest Rate Margin | DP2: Final Margin | DQ2: Final Step Date | DR2: Restructuring Arrangement | DS2: Forbearance Type | DT2: Blank | DU2: Blank | DV2: Blank | DW2: Blank | DX2: Geographic Region | DY2: Property Postcode | DZ2: Occupancy Type | EA2: Property Type | EB2: New Property | EC2: Construction Year | ED2: Property Rating | EE2: Original Loan to Value | EF2: Valuation Amount | EG2: Original Valuation Type | EH2: Valuation Date | EI2: Confidence Interval for Original Automated Valuation Model Valuation | EJ2: Provider of Original Automated Valuation Model Valuation | EK2: Current Loan to Value | EL2: Purchase Price | EM2: Current Valuation Amount | EN2: Current Valuation Type | EO2: Current Valuation Date | EP2: Confidence Interval for Current Automated Valuation Model Valuation | EQ2: Provider of Current Automated Valuation Model Valuation | ER2: Property Value at Time of Latest Loan Advance | ES2: Indexed Foreclosure Value | ET2: Ipoteca | EU2: Date of Sale | EV2: Additional Collateral | EW2: Additional Collateral Provider | EX2: Gross Annual Rental Income | EY2: Number of Buy to Let Properties | EZ2: Debt Service Coverage Ratio | FA2: Additional Collateral Value | FB2: Real Estate Owned | FC2: Is Property Transferability Limited | FD2: Time Until Declassification | FE2: Blank | FF2: Current Energy Performance Certificate Value | FG2: Potential Energy Performance Certificate Value | FH2: Exemption from Energy Efficiency Regulation | FI2: Blank | FJ2: Account Status | FK2: Date Last Current | FL2: Date Last in Arrears | FM2: Arrears Balance | FN2: Number Months in Arrears | FO2: Arrears 1 Month Ago | FP2: Arrears 2 Months Ago | FQ2: Performance Arrangement | FR2: Litigation | FS2: Redemption Date | FT2: Months in Arrears Prior | FU2: Default or Foreclosure | FV2: Date of Default | FW2: Sale Price | FX2: Loss on Sale | FY2: Cumulative Recoveries | FZ2: Professional Negligence Recoveries | GA2: Loan flagged as Contencioso | GB2: Blank | GC2: Blank | GD2: Blank | GE2: Blank | GF2: Blank | GG2: Second Borrower's Employment Status | GH2: Class of Second Borrower | GI2: Resident (Second Borrower) | GJ2: Number of County Court Judgements or equivalent - Satisfied (Second Borrower) | GK2: Value of County Court Judgements or equivalent - Satisfied (Second Borrower) | GL2: Number of County Court Judgements or equivalent - Unsatisfied (Second Borrower) | GM2: Value of County Court Judgements or equivalent - Unsatisfied (Second Borrower) | GN2: Last County Court Judgements or equivalent – Date (Second Borrower) | GO2: Bankruptcy or Individual Voluntary Arrangement Flag (Second Borrower) | GP2: Bureau Krediet Registratie 1 to 10 - Credit Type (Second Borrower) | GQ2: Bureau Krediet Registratie 1 to 10- Registration Date (Second Borrower) | GR2: Bureau Krediet Registratie 1 to 10 - Arrears Code (Second Borrower) | GS2: Bureau Krediet Registratie 1 to 10 - Credit Amount (Second Borrower) | GT2: Bureau Krediet Registratie 1 to 10 - Is Coding Cured? (Second Borrower) | GU2: Bureau Krediet Registratie 1 to 10 - Number of Months Since Cured (Second Borrower) | GV2: Bureau Score Provider (Second Borrower) | GW2: Bureau Score Type (Second Borrower) | GX2: Bureau Score Date (Second Borrower) | GY2: Bureau Score Value (Second Borrower) | GZ2: Prior Repossessions (Second Borrower) | HA2: Previous Mortgage Arrears 0-6 Months (Second Borrower) | HB2: Previous Mortgage Arrears 6+ Months (Second Borrower) | HC2: Bureau Krediet Registratie 1 to 10 - Credit Type (Primary Borrower - At Origination) | HD2: Bureau Krediet Registratie 1 to 10 - Arrears Code (Primary Borrower - At Origination) | HE2: Bureau Krediet Registratie 1 to 10 - Credit Amount (Primary Borrower - At Origination) | HF2: Bureau Krediet Registratie 1 to 10 - Is Coding Cured? (Primary Borrower - At Origination) | HG2: Bureau Krediet Registratie 1 to 10 - Number of Months Since Cured (Primary Borrower - At Origination) | HH2: Bureau Score Provider (Primary Borrower - At Origination) | HI2: Bureau Score Type (Primary Borrower - At Origination) | HJ2: Bureau Score Value (Primary Borrower - At Origination) | HK2: Bureau Krediet Registratie 1 to 10 - Credit Type (Secondary Borrower - At Origination) | HL2: Bureau Krediet Registratie 1 to 10- Registration Date (Secondary Borrower - At Origination) | HM2: Bureau Krediet Registratie 1 to 10 - Arrears Code (Secondary Borrower - At Origination) | HN2: Bureau Krediet Registratie 1 to 10 - Credit Amount (Secondary Borrower - At Origination) | HO2: Bureau Krediet Registratie 1 to 10 - Is Coding Cured? (Secondary Borrower - At Origination) | HP2: Bureau Krediet Registratie 1 to 10 - Number of Months Since Cured (Secondary Borrower - At Origination) | HQ2: Bureau Score Provider (Secondary Borrower - At Origination) | HR2: Bureau Score Type (Secondary Borrower - At Origination) | HS2: Bureau Score Value (Secondary Borrower - At Origination) | HT2: Borrower Type (Secondary Borrower) | HU2: Foreign National (Secondary Borrower) | HV2: Borrower Credit Quality (Secondary Borrower) | HW2: First-time Buyer (Secondary Borrower) | HX2: Bankruptcy or Individual Voluntary Arrangement Flag | HY2: Bankruptcy or Individual Voluntary Arrangement Flag (Second Borrower)
A10: • Do NOT delete or modify the BoE field codes in your headers
A11: • Dates should be in a recognizable format (DD/MM/YYYY or Excel date serial)
A12: • Numeric codes will be automatically converted to text descriptions
A13: • Empty cells are allowed for optional fields
A16: BV1 (Loan ID) | B16: BV5 (Balance) | C16: BV12 (Property Type) | D16: BV27 (Occupancy) | E16: BV29 (Payment) | F16: BV25 (Rate Type) | G16: BV48 (Perf Arr) | H16: BV49 (Perf Date) | I16: BV50 (Last 90+ Date) | J16: ...more BoE fields...
A17: [Paste your loan tape starting here - replace this sample data]

Sheet AR Data Dictionary
A1: BANK OF ENGLAND AR FIELD DATA DICTIONARY
A2: Complete reference for all 175 AR field codes from BoE PRA110 template
A3: Total AR Fields: 175 | Mapped in Model: 40 | Unmapped: 135
A5: AR Code | B5: Field Name | C5: Category | D5: Priority | E5: Tag | F5: Mapped in Model
A6: AR1 | B6: Pool Cut-off Date | C6: Core | D6: Mandatory | E6: dynamic | F6: NO
A7: AR2 | B7: Pool Identifier | C7: Core | D7: Mandatory | E7: static | F7: NO
A8: AR3 | B8: Loan Identifier | C8: Core | D8: Mandatory | E8: static | F8: YES
A9: AR4 | B9: Regulated Loan | C9: Core | D9: Optional | E9: static | F9: NO
A10: AR5 | B10: Originator | C10: Core | D10: Mandatory | E10: static | F10: YES
A11: AR6 | B11: Servicer Identifier | C11: Core | D11: Mandatory | E11: static | F11: NO
A12: AR7 | B12: Borrower Identifier | C12: Core | D12: Mandatory | E12: static | F12: NO
A13: AR8 | B13: Property Identifier | C13: Core | D13: Mandatory | E13: static | F13: NO
A14: AR9 | B14: Blank | C14: Core | F14: NO
A15: AR10 | B15: Blank | C15: Core | F15: NO
A16: AR11 | B16: Blank | C16: Core | F16: NO
A17: AR12 | B17: Blank | C17: Core | F17: NO
A18: AR13 | B18: Blank | C18: Core | F18: NO
A19: AR14 | B19: Blank | C19: Core | F19: NO
A20: AR15 | B20: Borrower Type | C20: Borrower Information | D20: Optional | E20: static | F20: NO
A21: AR16 | B21: Foreign National | C21: Borrower Information | D21: Optional | E21: static | F21: NO
A22: AR17 | B22: Borrower Credit Quality | C22: Borrower Information | D22: Optional | E22: static | F22: NO
A23: AR18 | B23: Borrower Year of Birth | C23: Borrower Information | D23: Optional | E23: static | F23: NO
A24: AR19 | B24: Number of Debtors | C24: Borrower Information | D24: Mandatory | E24: static | F24: NO
A25: AR20 | B25: Second Applicant Year of Birth | C25: Borrower Information | D25: Optional | E25: static | F25: NO
A26: AR21 | B26: Borrower's Employment Status | C26: Borrower Information | D26: Mandatory | E26: static | F26: NO
A27: AR22 | B27: First-time Buyer | C27: Borrower Information | D27: Optional | E27: static | F27: YES
A28: AR23 | B28: Right to Buy | C28: Borrower Information | D28: Optional | E28: static | F28: YES
A29: AR24 | B29: Right to Buy Price | C29: Borrower Information | D29: Optional | E29: static | F29: NO
A30: AR25 | B30: Class of Borrower | C30: Borrower Information | D30: Optional | E30: static | F30: NO
A31: AR26 | B31: Primary Income | C31: Borrower Information | D31: Mandatory | E31: static | F31: YES
... A55: AR50 | B55: Internal Rating | C55: Borrower Information | D55: Optional | E55: dynamic | F55: NO
A56: AR51 | B56: Blank | C56: Borrower Information | F56: NO
A57: AR52 | B57: Blank | C57: Borrower Information | F57: NO
A58: AR53 | B58: Blank | C58: Borrower Information | F58: NO
A59: AR54 | B59: Blank | C59: Borrower Information | F59: NO
A60: AR55 | B60: Loan Origination Date | C60: Loan Characteristics | D60: Mandatory | E60: static | F60: YES
A61: AR56 | B61: Date of Loan Maturity | C61: Loan Characteristics | D61: Mandatory | E61: dynamic | F61: YES
A62: AR57 | B62: Account Status Date | C62: Loan Characteristics | D62: Mandatory | E62: static | F62: NO
A63: AR58 | B63: Origination Channel / Arranging Bank or Division | C63: Loan Characteristics | D63: Mandatory | E63: static | F63: NO
A64: AR59 | B64: Purpose | C64: Loan Characteristics | D64: Mandatory | E64: static | F64: YES
...

Sheet Jurisdiction Parameters
A1: JURISDICTION-SPECIFIC PARAMETERS
A2: All jurisdiction-specific values - Model references this sheet dynamically
A4: Jurisdiction | B4: OLTV Weight | C4: CLTV Weight | D4: Valuation Haircut | E4: Interest Cost (BTL) | F4: Seasoning Periods | G4: Income Mult Threshold 1 | H4: Income Mult Threshold 2 | I4: Income Mult Joint Threshold 1 | J4: Income Mult Joint Threshold 2 | K4: Arrears 1mo Mult | L4: Arrears 2mo Mult | M4: Arrears 3mo Mult | N4: Foreclosure Cost % | O4: LTV Curve Reference | P4: Regional Adj Enabled | Q4: Reperform Threshold (Years)
A5: UK | B5: 0.8 | C5: 0.2 | D5: 0.05 | E5: 0.055 | F5: 18 | G5: 5 | H5: 3.5 | I5: 3.25 | J5: 2.75 | K5: 2.5 | L5: 5 | M5: 100 | N5: 0.08 | O5: LTV Curve UK | P5: Yes | Q5: 3
A6: Ireland | B6: 0.75 | C6: 0.25 | D6: 0.07 | E6: 0.06 | F6: 24 | G6: 4.5 | H6: 3 | I6: 3 | J6: 2.5 | K6: 3 | L6: 6 | M6: 100 | N6: 0.1 | O6: LTV Curve Ireland | P6: Yes | Q6: 3
A7: Netherlands | B7: 0.8 | C7: 0.2 | D7: 0.04 | E7: 0.05 | F7: 12 | G7: 6 | H7: 4 | I7: 4 | J7: 3 | K7: 2 | L7: 4 | M7: 100 | N7: 0.07 | O7: LTV Curve Netherlands | P7: No | Q7: 3

Sheet Rating Parameters
A1: RATING-DRIVEN PARAMETERS
A3: All parameters that vary by target rating level
A5: Rating | B5: Base FF (%) | C5: MVD (%) | D5: FSD (%) | E5: Source | F5: Rating | G5: Stress Multiple
A6: AAA | B6: 0.12 | C6: 0.45 | D6: 0.15 | E6: Table 72 / S&P MVD assumptions | F6: AAA | G6: 14
A7: AA+ | B7: 0.105 | C7: 0.42 | D7: 0.14 | E7: Interpolated | F7: AA+ | G7: 12
A8: AA | B8: 0.08 | C8: 0.4 | D8: 0.13 | E8: Table 72 | F8: AA | G8: 10.5
A9: AA- | B9: 0.07 | C9: 0.37 | D9: 0.12 | E9: Interpolated | F9: AA- | G9: 9
A10: A+ | B10: 0.065 | C10: 0.34 | D10: 0.11 | E10: Interpolated | F10: A+ | G10: 7.5
A11: A | B11: 0.06 | C11: 0.32 | D11: 0.1 | E11: Table 72 | F11: A | G11: 6.5
A12: A- | B12: 0.055 | C12: 0.3 | D12: 0.1 | E12: Interpolated | F12: A- | G12: 5.5
A13: BBB+ | B13: 0.05 | C13: 0.27 | D13: 0.09 | E13: Interpolated | F13: BBB+ | G13: 4.5
A14: BBB | B14: 0.04 | C14: 0.25 | D14: 0.08 | E14: Table 72 | F14: BBB | G14: 4
A15: BBB- | B15: 0.035 | C15: 0.22 | D15: 0.08 | E15: Interpolated | F15: BBB- | G15: 3.5
A16: BB | B16: 0.02 | C16: 0.2 | D16: 0.07 | E16: Table 72 | F16: BB | G16: 3
A17: B | B17: 0.015 | C17: 0.18 | D17: 0.07 | E17: Table 72 | F17: B | G17: 2.5

Sheet LTV Curve
A1: S&P UK LTV CURVE - TYPE 2 FULL RECOURSE (131 Points)
A3: LTV % | B3: FF Multiplier | C3: Named Range | D3: Notes
A4: 0.2 | B4: 0.2889 | C4: LTV_20 | D4: Minimum LTV in curve
A5: 0.21 | B5: 0.2907 | C5: LTV_21
A6: 0.22 | B6: 0.2925 | C6: LTV_22
A7: 0.23 | B7: 0.2945 | C7: LTV_23
A8: 0.24 | B8: 0.2966 | C8: LTV_24
A9: 0.25 | B9: 0.2988 | C9: LTV_25
A10: 0.26 | B10: 0.3011 | C10: LTV_26
A11: 0.27 | B11: 0.3037 | C11: LTV_27
A12: 0.28 | B12: 0.3063 | C12: LTV_28
A13: 0.29 | B13: 0.3092 | C13: LTV_29
A14: 0.3 | B14: 0.3122 | C14: LTV_30
A15: 0.31 | B15: 0.3155 | C15: LTV_31
A16: 0.32 | B16: 0.3189 | C16: LTV_32
... A53: 0.69 | B53: 0.8368 | C53: LTV_69
A54: 0.7 | B54: 0.8739 | C54: LTV_70 | D54: Archetypal (1.0x multiplier at 73% per curve)
A55: 0.71 | B55: 0.9134 | C55: LTV_71
A56: 0.72 | B56: 0.9553 | C56: LTV_72
A57: 0.73 | B57: 1 | C57: LTV_73
A58: 0.74 | B58: 1.0475 | C58: LTV_74
A59: 0.75 | B59: 1.098 | C59: LTV_75
A60: 0.76 | B60: 1.1518 | C60: LTV_76
A61: 0.77 | B61: 1.2089 | C61: LTV_77
A62: 0.78 | B62: 1.2696 | C62: LTV_78
A63: 0.79 | B63: 1.3341 | C63: LTV_79
A64: 0.8 | B64: 1.4025 | C64: LTV_80
A65: 0.81 | B65: 1.4751 | C65: LTV_81
A66: 0.82 | B66: 1.552 | C66: LTV_82
... A133: 1.49 | B133: 4.02 | C133: LTV_149
A134: 1.5 | B134: 4.02 | C134: LTV_150 | D134: Maximum LTV (cap at 4.02x)

Sheet FF Adj Parameters
A1: FF ADJUSTMENT PARAMETERS - COMPLETE LOOKUP TABLES
A3: SEASONING ADJUSTMENTS
A4: Threshold (Years)
A5: 5 | B5: 1 | C5: <5 years - No credit
A6: 6 | B6: 0.75 | C6: 5-6 years - 25% credit
A7: 7 | B7: 0.7 | C7: 6-7 years - 30% credit
A8: 8 | B8: 0.65 | C8: 7-8 years - 35% credit
A9: 9 | B9: 0.6 | C9: 8-9 years - 40% credit
A10: 10
A11: 999 | B11: 0.5 | C11: >10 years - 50% credit
A13: INCOME MULTIPLE ADJUSTMENTS
A14: Threshold | B14: Multiplier | C14: Description
A15: 3.5 | B15: 1 | C15: ≤3.5 single or ≤2.75 joint
A16: 5 | B16: 1.2 | C16: >3.5 to 5.0 single or >2.75 to 3.25 joint
A17: 999 | B17: 1.5 | C17: >5.0 single or >3.25 joint
A19: BTL DSCR ADJUSTMENTS
A20: DSCR Threshold | B20: Multiplier | C20: Description
A21: 0 | B21: 1.7 | C21: No rental income
A22: 1 | B22: 1.55 | C22: <1.00 - Inadequate
A23: 1.2 | B23: 1.45 | C23: 1.00-1.20 - Minimal
A24: 1.35
A25: 999 | B25: 1.25 | C25: ≥1.35 - Strong
A27: INTEREST ONLY ADJUSTMENTS (NON-BTL)
A28: Years to Maturity | B28: Multiplier | C28: Description
A29: 5 | B29: 1.25 | C29: <5 years
A30: 15
A31: 25 | B31: 1.2 | C31: 15-25 years
A32: 999 | B32: 1.1 | C32: >25 years
A34: FIXED ADJUSTMENT MULTIPLIERS
A35: Adjustment Type | B35: Multiplier | C35: Notes
A36: First Time Buyer | B36: 1.1 | C36: If seasoning <18 months
A37: Help to Buy | B37: 1 | C37: No adjustment per S&P
A38: Shared Ownership | B38: 1.15 | C38: Complexity premium
A39: Right to Buy | B39: 1.2 | C39: Discount unwind risk
A40: Self-Certification
A41: Payment Shock | B41: 1.1 | C41: Fixed rate <60mo to maturity
A42: Self-Employed | B42: 1.15 | C42: Income stability risk
A43: Commercial Property | B43: 1.85 | C43: Commercial use risk
A44: CCJ | B44: 1.3 | C44: County Court Judgment
A45: Bankruptcy | B45: 4 | C45: Floor at 0.50
...

Sheet LS Parameters
A1: LOSS SEVERITY ADJUSTMENT PARAMETERS
A2: S&P Table 78 & 79: Property Type and Regional Adjustments for MVD
A4: PROPERTY TYPE MVD ADJUSTMENTS (S&P Table 78)
A5: Property Type | B5: MVD Adjustment | C5: Notes
A6: House | B6: 0 | C6: Baseline - no adjustment
A7: Flat | B7: 0.05 | C7: +5% MVD for flats (higher volatility)
A8: Bungalow | B8: -0.02 | C8: -2% MVD for bungalows (stable)
A9: Maisonette | B9: 0.03 | C9: +3% MVD for maisonettes
A10: Other | B10: 0.05 | C10: +5% MVD for other property types
A12: REGIONAL MVD ADJUSTMENTS (S&P Table 79 - Optional)
A13: Region | B13: MVD Adjustment | C13: Notes
A14: London | B14: -0.03 | C14: -3% MVD (more liquid market)
A15: South East | B15: -0.02 | C15: -2% MVD
A16: East | B16: -0.01 | C16: -1% MVD
A17: South West | B17: 0 | C17: Baseline
A18: West Midlands | B18: 0.01 | C18: +1% MVD
A19: East Midlands | B19: 0.01 | C19: +1% MVD
A20: North West | B20: 0.02 | C20: +2% MVD
A21: Yorkshire | B21: 0.02 | C21: +2% MVD
A22: North East | B22: 0.03 | C22: +3% MVD (less liquid)
A23: Wales | B23: 0.02 | C23: +2% MVD
A24: Scotland | B24: 0.01 | C24: +1% MVD
A25: Northern Ireland | B25: 0.03 | C25: +3% MVD
A28: FORECLOSURE COSTS
A29: Cost Component | B29: % of Property Value | C29: Notes
A30: Legal & Professional Fees | B30: 0.03 | C30: Solicitors, surveyors, court costs
A31: Maintenance & Repairs | B31: 0.02 | C31: Property upkeep during foreclosure
A32: Sales Costs | B32: 0.02 | C32: Estate agent, marketing
A33: Holding Costs | B33: 0.01 | C33: Utilities, insurance, security
A34: TOTAL Foreclosure Costs | B34: 0.08 | C34: Sum of all components

Sheet BoE Mapping
A1: AR Code | B1: BoE Field Name | C1: S&P Field Name | D1: Conversion Notes
A2: AR3 | B2: Loan Identifier | C2: Loan ID | D2: Direct mapping
A3: AR5 | B3: Originator | C3: Originator | D3: Direct mapping
A4: AR55 | B4: Loan Origination Date | C4: Origination Date | D4: Date format
A5: AR56 | B5: Date of Loan Maturity | C5: Maturity Date | D5: Date format
A6: AR66 | B6: Original Balance | C6: Original Balance | D6: Currency
A7: AR67 | B7: Current Balance | C7: Current Balance | D7: Currency
A8: AR131 | B8: Property Type | C8: Property Type | D8: Code: 1=House, 2=Flat, 3=Bungalow, 4=Maisonette
A9: AR130 | B9: Occupancy Type | C9: Occupancy Status | D9: Code: 1=Owner Occ, 2=BTL, 3=Second Home, 4=Investment
A10: AR107 | B10: Interest Rate Type | C10: Interest Rate Type | D10: Code: 1=Fixed, 2=Variable, 3=Tracker
A11: AR109 | B11: Current Interest Rate | C11: Interest Rate | D11: Percentage
A12: AR69 | B12: Repayment Method | C12: Payment Method | D12: Code: 1=Repayment, 2=IO, 3=Part & Part
... A30: AR173 | B30: Performance Arrangement | C30: Performance Arrangement | D30: Code: 1,2=Yes, other=No

Sheet Loan Tape (BoE)
A1: LOAN TAPE - BANK OF ENGLAND PRA110 FORMAT (INPUT SHEET)
A2: Enter loan data in yellow cells using Bank of England field codes and values
A3: AR3 | B3: AR5 | C3: AR131 | D3: AR66 | E3: AR136 | F3: AR143 | G3: AR128 | H3: AR129 | I3: AR135 | J3: AR141 | K3: AR55 | L3: AR56 | M3: AR67 | N3: AR130 | O3: AR109 | P3: AR69 | Q3: AR84 | R3: AR59 | S3: AR60 | T3: AR105 | U3: AR22 | V3: AR23 | W3: AR21 | X3: AR27 | Y3: AR26 | Z3: AR28 | AA3: AR73 | AB3: AR31 | AC3: AR33 | AD3: AR35 | AE3: AR36 | AF3: AR47 | AG3: AR166 | AH3: AR154 | AI3: AR156 | AJ3: AR169 | AK3: AR170 | AL3: AR167 | AM3: AR168 | AN3: AR107 | AO3: AR173
A4: Loan ID | B4: Originator | C4: Property Type | D4: Original Balance | E4: Orig Property Val | F4: Curr Property Val | G4: Region | H4: Postcode | I4: Orig LTV % | J4: Curr LTV % | K4: Orig Date | L4: Maturity Date | M4: Current Balance | N4: Occupancy | O4: Interest Rate | P4: Payment Method | Q4: Lien | R4: Purpose | S4: Shared Own | T4: Help to Buy | U4: FTB | V4: Right to Buy | W4: Employment | X4: Income Verif | Y4: Primary Income | Z4: Secondary Income | AA4: DTI | AB4: CCJ Sat | AC4: CCJ Unsat | AD4: CCJ Date | AE4: Bankruptcy | AF4: Prior Repos | AG4: Account Status | AH4: Rental Income | AI4: DSCR | AJ4: Arrears Bal | AK4: Mths Arrears | AL4: Date Last Curr | AM4: Date Last Arr | AN4: Rate Type | AO4: Perf Arrange | AP4: BV85 | AQ4: BV90 | AR4: BV91
A5: Loan ID | B5: Current Balance (£) | C5: Original Balance (£) | D5: Current Property Value (£) | E5: Original Property Value (£) | F5: Origination Date | G5: Maturity Date | H5: Current Interest Rate (%) | I5: Property Type (1-4) | J5: Region | K5: Postcode | L5: Occupancy Status (1-4) | M5: Loan Purpose (1-4) | N5: Payment Method (1-3) | O5: Right to Buy (1-2) | P5: Shared Ownership (1-2) | Q5: Help to Buy (1-2) | R5: Borrower 1 Income (£) | S5: Borrower 2 Income (£) | T5: Number of Borrowers (1-2) | U5: Employ Status Borr1 (1-4) | V5: Employ Status Borr2 (1-4) | W5: Credit Score Borr1 | X5: Credit Score Borr2 | Y5: CCJ Count Borr1 | Z5: CCJ Count Borr2 | AA5: CCJ Value Borr1 (£) | AB5: CCJ Value Borr2 (£) | AC5: CCJ Date Borr1 | AD5: CCJ Date Borr2 | AE5: Arrears Balance (£) | AF5: Bankruptcy Flag (1-2) | AG5: Bankruptcy Date | AH5: IVA Flag (1-2) | AI5: Prior Repossession (1-2) | AJ5: Self-Certified (1-2) | AK5: First Time Buyer (1-2) | AL5: Payment Shock (1-2) | AM5: Reperforming (1-2) | AN5: Date Last 90+ dpd | AO5: Lien Position (1/2/3+) | AP5: Valuation Method (1-3) | AQ5: Commercial Property (1-2) | AR5: Rental Income Annual (£)

Sheet Loan Tape (S&P)
A1: LOAN TAPE - S&P FORMAT (AUTO-CONVERTED FROM BoE)
A2: Auto-populated from Loan Tape (BoE) using conversion formulas - DO NOT EDIT
A3: AR3 | B3: AR5 | C3: AR131 | D3: AR66 | E3: AR136 | F3: AR143 | G3: AR128 | H3: AR129 | I3: AR135 | J3: AR141 | K3: AR55 | L3: AR56 | M3: AR67 | N3: AR130 | O3: AR109 | P3: AR69 | Q3: AR84 | R3: AR59 | S3: AR60 | T3: AR105 | U3: AR22 | V3: AR23 | W3: AR21 | X3: AR27 | Y3: AR26 | Z3: AR28 | AA3: AR19 | AC3: AR73 | AD3: AR31 | AE3: AR33 | AF3: AR35 | AH3: AR36 | AI3: AR47 | AJ3: AR166 | AK3: AR154 | AL3: AR156 | AM3: AR169 | AN3: AR170 | AO3: AR167 | AP3: AR168 | AQ3: AR107 | AR3: AR173
A4: Loan Identifier | B4: Originator | C4: Property Type | D4: Original Balance | E4: Original Property Value | F4: Current Property Value | G4: Geographic Region | H4: Property Postcode | I4: Original LTV % | J4: Current LTV % | K4: Origination Date | L4: Maturity Date | M4: Current Balance | N4: Occupancy Type | O4: Interest Rate % | P4: Payment Method | Q4: Lien Position | R4: Loan Purpose | S4: Shared Ownership | T4: Help to Buy | U4: First Time Buyer | V4: Right to Buy | W4: Employment Status | X4: Income Verification | Y4: Primary Income | Z4: Secondary Income | AA4: Number of Debtors | AC4: Debt to Income | AD4: CCJ Satisfied | AE4: CCJ Unsatisfied | AF4: Last CCJ Date | AH4: Bankruptcy/IVA | AI4: Prior Repossession | AJ4: Account Status | AK4: Rental Income | AL4: DSCR | AM4: Arrears Balance | AN4: Months in Arrears | AO4: Date Last Current | AP4: Date Last in Arrears | AQ4: Interest Rate Type | AR4: Performance Arrangement
A5: ='Loan Tape (BoE)'!A6 | B5: =IFERROR(INDEX('FF Adj Parameters'!$A$89:$B$92,MATCH('Loan Tape (BoE)'!C5,INDEX('FF Adj Parameters'!$A$89:$B$92,,1),0),2),"Unknown") | C5: ='Loan Tape (BoE)'!C6 | D5: ='Loan Tape (BoE)'!D6 | E5: ='Loan Tape (BoE)'!E6 | F5: ='Loan Tape (BoE)'!F6 | G5: ='Loan Tape (BoE)'!G6 | H5: ='Loan Tape (BoE)'!H6/100 | I5: =IFERROR(IFS('Loan Tape (BoE)'!I6=1,"House",'Loan Tape (BoE)'!I6=2,"Flat",'Loan Tape (BoE)'!I6=3,"Bungalow",'Loan Tape (BoE)'!I6=4,"Maisonette"),"") | J5: ='Loan Tape (BoE)'!J6 | K5: ='Loan Tape (BoE)'!K6 | L5: =IFERROR(IFS('Loan Tape (BoE)'!L6=1,"Owner Occupied",'Loan Tape (BoE)'!L6=2,"BTL",'Loan Tape (BoE)'!L6=3,"Second Home",'Loan Tape (BoE)'!L6=4,"Investment"),"") | M5: =IFERROR(IFS('Loan Tape (BoE)'!M6=1,"Purchase",'Loan Tape (BoE)'!M6=2,"Remortgage",OR('Loan Tape (BoE)'!M6=3,'Loan Tape (BoE)'!M6=4),"Cash-out"),"") | N5: =IFERROR(INDEX('FF Adj Parameters'!$A$96:$B$99,MATCH('Loan Tape (BoE)'!R5,INDEX('FF Adj Parameters'!$A$96:$B$99,,1),0),2),"Unknown") | O5: =IF('Loan Tape (BoE)'!O6=1,"Yes","No") | P5: =IF('Loan Tape (BoE)'!P5=1,"Yes",IF('Loan Tape (BoE)'!P5=0,"No","")) | Q5: =IF('Loan Tape (BoE)'!Q5=1,"Yes",IF('Loan Tape (BoE)'!Q5=0,"No","")) | R5: =IF('Loan Tape (BoE)'!R5=1,"Yes",IF('Loan Tape (BoE)'!R5=0,"No","")) | S5: =IF('Loan Tape (BoE)'!S5=1,"Yes",IF('Loan Tape (BoE)'!S5=0,"No","")) | T5: =IF('Loan Tape (BoE)'!T5=1,"Yes",IF('Loan Tape (BoE)'!T5=0,"No","")) | U5: =R5+S5 | V5: =IFERROR(IFS('Loan Tape (BoE)'!U6=1,"Employed",'Loan Tape (BoE)'!U6=2,"Self-Employed",'Loan Tape (BoE)'!U6=3,"Unemployed",'Loan Tape (BoE)'!U6=4,"Retired"),"") | W5: =IFERROR(IFS('Loan Tape (BoE)'!V6=1,"Employed",'Loan Tape (BoE)'!V6=2,"Self-Employed",'Loan Tape (BoE)'!V6=3,"Unemployed",'Loan Tape (BoE)'!V6=4,"Retired"),"") | X5: =IF(OR(V5="Self-Employed",W5="Self-Employed"),"Yes","No") | Y5: ='Loan Tape (BoE)'!W6 | Z5: ='Loan Tape (BoE)'!X6 | AA5: =IF(T5=1,Y5,MIN(Y5,Z5)) | AB5: ='Loan Tape (BoE)'!Y6 | AC5: ='Loan Tape (BoE)'!Z6 | AD5: =AB5+AC5 | AE5: ='Loan Tape (BoE)'!AA6 | AF5: ='Loan Tape (BoE)'!AB6 | AG5: =AE5+AF5 | AH5: =MAX('Loan Tape (BoE)'!AC6,'Loan Tape (BoE)'!AD6) | AI5: ='Loan Tape (BoE)'!AE6 | AJ5: =B5*H5/12 | AK5: =IF(AJ5>0,AI5/AJ5,0) | AL5: =IF('Loan Tape (BoE)'!AF6=1,"Yes","No") | AM5: =IF('Loan Tape (BoE)'!AH6=1,"Yes","No") | AN5: =IF('Loan Tape (BoE)'!AI6=1,"Yes","No") | AO5: =IF('Loan Tape (BoE)'!AJ6=1,"Yes","No") | AP5: =IF(OR('Loan Tape (BoE)'!AQ5=1,'Loan Tape (BoE)'!AQ5=2),"Yes",IF('Loan Tape (BoE)'!AQ5=0,"No","")) | AQ5: =IF('Loan Tape (BoE)'!BV49_5<>"",'Loan Tape (BoE)'!BV49_5,"") | AR5: =IF('Loan Tape (BoE)'!BV50_5<>"",'Loan Tape (BoE)'!BV50_5,"") | AS5: =IFERROR(INDEX('FF Adj Parameters'!$A$103:$B$105,MATCH('Loan Tape (BoE)'!P5,INDEX('FF Adj Parameters'!$A$103:$B$105,,1),0),2),"Unknown") | AT5: =IF(N5="Interest Only",M5*O5/12,IF(AND(O5>0,ISNUMBER(O5),ISNUMBER(M5)),ABS(PMT(O5/12,AU5,-M5)),0)) | AU5: =IF(ISNUMBER(L5),MAX(0,(L5-'Control Panel'!$B$10)*12/365.25),0) | AV5: =IF(ISNUMBER(L5),IF(L5>'Control Panel'!$B$10,"Valid","Past Maturity"),"No Date") | AW5: =IF(ISNUMBER(K5),MAX(0,('Control Panel'!$B$10-K5)*12/365.25),0)
A6: ='Loan Tape (BoE)'!A7 | B6: =IFERROR(INDEX('FF Adj Parameters'!$A$89:$B$92,MATCH('Loan Tape (BoE)'!C6,INDEX('FF Adj Parameters'!$A$89:$B$92,,1),0),2),"Unknown") | C6: ='Loan Tape (BoE)'!C7 | D6: ='Loan Tape (BoE)'!D7 | E6: ='Loan Tape (BoE)'!E7 | F6: ='Loan Tape (BoE)'!F7 | G6: ='Loan Tape (BoE)'!G7 | H6: ='Loan Tape (BoE)'!H7/100 | I6: =IFERROR(IFS('Loan Tape (BoE)'!I7=1,"House",'Loan Tape (BoE)'!I7=2,"Flat",'Loan Tape (BoE)'!I7=3,"Bungalow",'Loan Tape (BoE)'!I7=4,"Maisonette"),"") | J6: ='Loan Tape (BoE)'!J7 | K6: ='Loan Tape (BoE)'!K7 | L6: =IFERROR(IFS('Loan Tape (BoE)'!L7=1,"Owner Occupied",'Loan Tape (BoE)'!L7=2,"BTL",'Loan Tape (BoE)'!L7=3,"Second Home",'Loan Tape (BoE)'!L7=4,"Investment"),"") | M6: =IFERROR(IFS('Loan Tape (BoE)'!M7=1,"Purchase",'Loan Tape (BoE)'!M7=2,"Remortgage",OR('Loan Tape (BoE)'!M7=3,'Loan Tape (BoE)'!M7=4),"Cash-out"),"") | N6: =IFERROR(INDEX('FF Adj Parameters'!$A$96:$B$99,MATCH('Loan Tape (BoE)'!R6,INDEX('FF Adj Parameters'!$A$96:$B$99,,1),0),2),"Unknown") | O6: =IF('Loan Tape (BoE)'!O7=1,"Yes","No") | P6: =IF('Loan Tape (BoE)'!P6=1,"Yes",IF('Loan Tape (BoE)'!P6=0,"No","")) | Q6: =IF('Loan Tape (BoE)'!Q6=1,"Yes",IF('Loan Tape (BoE)'!Q6=0,"No","")) | R6: =IF('Loan Tape (BoE)'!R6=1,"Yes",IF('Loan Tape (BoE)'!R6=0,"No","")) | S6: =IF('Loan Tape (BoE)'!S6=1,"Yes",IF('Loan Tape (BoE)'!S6=0,"No","")) | T6: =IF('Loan Tape (BoE)'!T6=1,"Yes",IF('Loan Tape (BoE)'!T6=0,"No","")) | U6: =R6+S6 | V6: =IFERROR(IFS('Loan Tape (BoE)'!U7=1,"Employed",'Loan Tape (BoE)'!U7=2,"Self-Employed",'Loan Tape (BoE)'!U7=3,"Unemployed",'Loan Tape (BoE)'!U7=4,"Retired"),"") | W6: =IFERROR(IFS('Loan Tape (BoE)'!V7=1,"Employed",'Loan Tape (BoE)'!V7=2,"Self-Employed",'Loan Tape (BoE)'!V7=3,"Unemployed",'Loan Tape (BoE)'!V7=4,"Retired"),"") | X6: =IF(OR(V6="Self-Employed",W6="Self-Employed"),"Yes","No") | Y6: ='Loan Tape (BoE)'!W7 | Z6: ='Loan Tape (BoE)'!X7 | AA6: =IF(T6=1,Y6,MIN(Y6,Z6)) | AB6: ='Loan Tape (BoE)'!Y7 | AC6: ='Loan Tape (BoE)'!Z7 | AD6: =AB6+AC6 | AE6: ='Loan Tape (BoE)'!AA7 | AF6: ='Loan Tape (BoE)'!AB7 | AG6: =AE6+AF6 | AH6: =MAX('Loan Tape (BoE)'!AC7,'Loan Tape (BoE)'!AD7) | AI6: ='Loan Tape (BoE)'!AE7 | AJ6: =B6*H6/12 | AK6: =IF(AJ6>0,AI6/AJ6,0) | AL6: =IF('Loan Tape (BoE)'!AF7=1,"Yes","No") | AM6: =IF('Loan Tape (BoE)'!AH7=1,"Yes","No") | AN6: =IF('Loan Tape (BoE)'!AI7=1,"Yes","No") | AO6: =IF('Loan Tape (BoE)'!AJ7=1,"Yes","No") | AP6: =IF(OR('Loan Tape (BoE)'!AQ6=1,'Loan Tape (BoE)'!AQ6=2),"Yes",IF('Loan Tape (BoE)'!AQ6=0,"No","")) | AQ6: =IF('Loan Tape (BoE)'!BV49_6<>"",'Loan Tape (BoE)'!BV49_6,"") | AR6: =IF('Loan Tape (BoE)'!BV60_6<>"",'Loan Tape (BoE)'!BV50_6,"") | AS6: =IFERROR(INDEX('FF Adj Parameters'!$A$103:$B$106,MATCH('Loan Tape (BoE)'!P6,INDEX('FF Adj Parameters'!$A$103:$B$106,,1),0),2),"Unknown") | AT6: =IF(N6="Interest Only",M5*O5/12,IF(AND(O5>0,ISNUMBER(O5),ISNUMBER(M5)),ABS(PMT(O5/12,AU5,-M5)),0)) | AU6: =IF(ISNUMBER(L6),MAX(0,(L5-'Control Panel'!$B$10)*12/365.25),0) | AV6: =IF(ISNUMBER(L6),IF(L5>'Control Panel'!$B$10,"Valid","Past Maturity"),"No Date") | AW6: =IF(ISNUMBER(K6),MAX(0,('Control Panel'!$B$10-K5)*12/365.25),0)
A7: ='Loan Tape (BoE)'!A8 | B7: =IFERROR(INDEX('FF Adj Parameters'!$A$89:$B$92,MATCH('Loan Tape (BoE)'!C7,INDEX('FF Adj Parameters'!$A$89:$B$92,,1),0),2),"Unknown") | C7: ='Loan Tape (BoE)'!C8 | D7: ='Loan Tape (BoE)'!D8 | E7: ='Loan Tape (BoE)'!E8 | F7: ='Loan Tape (BoE)'!F8 | G7: ='Loan Tape (BoE)'!G8 | H7: ='Loan Tape (BoE)'!H8/100 | I7: =IFERROR(IFS('Loan Tape (BoE)'!I8=1,"House",'Loan Tape (BoE)'!I8=2,"Flat",'Loan Tape (BoE)'!I8=3,"Bungalow",'Loan Tape (BoE)'!I8=4,"Maisonette"),"") | J7: ='Loan Tape (BoE)'!J8 | K7: ='Loan Tape (BoE)'!K8 | L7: =IFERROR(IFS('Loan Tape (BoE)'!L8=1,"Owner Occupied",'Loan Tape (BoE)'!L8=2,"BTL",'Loan Tape (BoE)'!L8=3,"Second Home",'Loan Tape (BoE)'!L8=4,"Investment"),"") | M7: =IFERROR(IFS('Loan Tape (BoE)'!M8=1,"Purchase",'Loan Tape (BoE)'!M8=2,"Remortgage",OR('Loan Tape (BoE)'!M8=3,'Loan Tape (BoE)'!M8=4),"Cash-out"),"") | N7: =IFERROR(INDEX('FF Adj Parameters'!$A$96:$B$99,MATCH('Loan Tape (BoE)'!R7,INDEX('FF Adj Parameters'!$A$96:$B$99,,1),0),2),"Unknown") | O7: =IF('Loan Tape (BoE)'!O8=1,"Yes","No") | P7: =IF('Loan Tape (BoE)'!P7=1,"Yes",IF('Loan Tape (BoE)'!P7=0,"No","")) | Q7: =IF('Loan Tape (BoE)'!Q7=1,"Yes",IF('Loan Tape (BoE)'!Q7=0,"No","")) | R7: =IF('Loan Tape (BoE)'!R7=1,"Yes",IF('Loan Tape (BoE)'!R7=0,"No","")) | S7: =IF('Loan Tape (BoE)'!S7=1,"Yes",IF('Loan Tape (BoE)'!S7=0,"No","")) | T7: =IF('Loan Tape (BoE)'!T7=1,"Yes",IF('Loan Tape (BoE)'!T7=0,"No","")) | U7: =R7+S7 | V7: =IFERROR(IFS('Loan Tape (BoE)'!U8=1,"Employed",'Loan Tape (BoE)'!U8=2,"Self-Employed",'Loan Tape (BoE)'!U8=3,"Unemployed",'Loan Tape (BoE)'!U8=4,"Retired"),"") | W7: =IFERROR(IFS('Loan Tape (BoE)'!V8=1,"Employed",'Loan Tape (BoE)'!V8=2,"Self-Employed",'Loan Tape (BoE)'!V8=3,"Unemployed",'Loan Tape (BoE)'!V8=4,"Retired"),"") | X7: =IF(OR(V7="Self-Employed",W7="Self-Employed"),"Yes","No") | Y7: ='Loan Tape (BoE)'!W8 | Z7: ='Loan Tape (BoE)'!X8 | AA7: =IF(T7=1,Y7,MIN(Y7,Z7)) | AB7: ='Loan Tape (BoE)'!Y8 | AC7: ='Loan Tape (BoE)'!Z8 | AD7: =AB7+AC7 | AE7: ='Loan Tape (BoE)'!AA8 | AF7: ='Loan Tape (BoE)'!AB8 | AG7: =AE7+AF7 | AH7: =MAX('Loan Tape (BoE)'!AC8,'Loan Tape (BoE)'!AD8) | AI7: ='Loan Tape (BoE)'!AE8 | AJ7: =B7*H7/12 | AK7: =IF(AJ7>0,AI7/AJ7,0) | AL7: =IF('Loan Tape (BoE)'!AF8=1,"Yes","No") | AM7: =IF('Loan Tape (BoE)'!AH8=1,"Yes","No") | AN7: =IF('Loan Tape (BoE)'!AI8=1,"Yes","No") | AO7: =IF('Loan Tape (BoE)'!AJ8=1,"Yes","No") | AP7: =IF(OR('Loan Tape (BoE)'!AQ7=1,'Loan Tape (BoE)'!AQ7=2),"Yes",IF('Loan Tape (BoE)'!AQ7=0,"No","")) | AQ7: =IF('Loan Tape (BoE)'!BV49_7<>"",'Loan Tape (BoE)'!BV49_7,"") | AR7: =IF('Loan Tape (BoE)'!BV70_7<>"",'Loan Tape (BoE)'!BV50_7,"") | AS7: =IFERROR(INDEX('FF Adj Parameters'!$A$103:$B$107,MATCH('Loan Tape (BoE)'!P7,INDEX('FF Adj Parameters'!$A$103:$B$107,,1),0),2),"Unknown") | AT7: =IF(N7="Interest Only",M5*O5/12,IF(AND(O5>0,ISNUMBER(O5),ISNUMBER(M5)),ABS(PMT(O5/12,AU5,-M5)),0)) | AU7: =IF(ISNUMBER(L7),MAX(0,(L5-'Control Panel'!$B$10)*12/365.25),0) | AV7: =IF(ISNUMBER(L7),IF(L5>'Control Panel'!$B$10,"Valid","Past Maturity"),"No Date") | AW7: =IF(ISNUMBER(K7),MAX(0,('Control Panel'!$B$10-K5)*12/365.25),0)
A8: ='Loan Tape (BoE)'!A9 | B8: =IFERROR(INDEX('FF Adj Parameters'!$A$89:$B$92,MATCH('Loan Tape (BoE)'!C8,INDEX('FF Adj Parameters'!$A$89:$B$92,,1),0),2),"Unknown") | C8: ='Loan Tape (BoE)'!C9 | D8: ='Loan Tape (BoE)'!D9 | E8: ='Loan Tape (BoE)'!E9 | F8: ='Loan Tape (BoE)'!F9 | G8: ='Loan Tape (BoE)'!G9 | H8: ='Loan Tape (BoE)'!H9/100 | I8: =IFERROR(IFS('Loan Tape (BoE)'!I9=1,"House",'Loan Tape (BoE)'!I9=2,"Flat",'Loan Tape (BoE)'!I9=3,"Bungalow",'Loan Tape (BoE)'!I9=4,"Maisonette"),"") | J8: ='Loan Tape (BoE)'!J9 | K8: ='Loan Tape (BoE)'!K9 | L8: =IFERROR(IFS('Loan Tape (BoE)'!L9=1,"Owner Occupied",'Loan Tape (BoE)'!L9=2,"BTL",'Loan Tape (BoE)'!L9=3,"Second Home",'Loan Tape (BoE)'!L9=4,"Investment"),"") | M8: =IFERROR(IFS('Loan Tape (BoE)'!M9=1,"Purchase",'Loan Tape (BoE)'!M9=2,"Remortgage",OR('Loan Tape (BoE)'!M9=3,'Loan Tape (BoE)'!M9=4),"Cash-out"),"") | N8: =IFERROR(INDEX('FF Adj Parameters'!$A$96:$B$99,MATCH('Loan Tape (BoE)'!R8,INDEX('FF Adj Parameters'!$A$96:$B$99,,1),0),2),"Unknown") | O8: =IF('Loan Tape (BoE)'!O9=1,"Yes","No") | P8: =IF('Loan Tape (BoE)'!P8=1,"Yes",IF('Loan Tape (BoE)'!P8=0,"No","")) | Q8: =IF('Loan Tape (BoE)'!Q8=1,"Yes",IF('Loan Tape (BoE)'!Q8=0,"No","")) | R8: =IF('Loan Tape (BoE)'!R8=1,"Yes",IF('Loan Tape (BoE)'!R8=0,"No","")) | S8: =IF('Loan Tape (BoE)'!S8=1,"Yes",IF('Loan Tape (BoE)'!S8=0,"No","")) | T8: =IF('Loan Tape (BoE)'!T8=1,"Yes",IF('Loan Tape (BoE)'!T8=0,"No","")) | U8: =R8+S8 | V8: =IFERROR(IFS('Loan Tape (BoE)'!U9=1,"Employed",'Loan Tape (BoE)'!U9=2,"Self-Employed",'Loan Tape (BoE)'!U9=3,"Unemployed",'Loan Tape (BoE)'!U9=4,"Retired"),"") | W8: =IFERROR(IFS('Loan Tape (BoE)'!V9=1,"Employed",'Loan Tape (BoE)'!V9=2,"Self-Employed",'Loan Tape (BoE)'!V9=3,"Unemployed",'Loan Tape (BoE)'!V9=4,"Retired"),"") | X8: =IF(OR(V8="Self-Employed",W8="Self-Employed"),"Yes","No") | Y8: ='Loan Tape (BoE)'!W9 | Z8: ='Loan Tape (BoE)'!X9 | AA8: =IF(T8=1,Y8,MIN(Y8,Z8)) | AB8: ='Loan Tape (BoE)'!Y9 | AC8: ='Loan Tape (BoE)'!Z9 | AD8: =AB8+AC8 | AE8: ='Loan Tape (BoE)'!AA9 | AF8: ='Loan Tape (BoE)'!AB9 | AG8: =AE8+AF8 | AH8: =MAX('Loan Tape (BoE)'!AC9,'Loan Tape (BoE)'!AD9) | AI8: ='Loan Tape (BoE)'!AE9 | AJ8: =B8*H8/12 | AK8: =IF(AJ8>0,AI8/AJ8,0) | AL8: =IF('Loan Tape (BoE)'!AF9=1,"Yes","No") | AM8: =IF('Loan Tape (BoE)'!AH9=1,"Yes","No") | AN8: =IF('Loan Tape (BoE)'!AI9=1,"Yes","No") | AO8: =IF('Loan Tape (BoE)'!AJ9=1,"Yes","No") | AP8: =IF(OR('Loan Tape (BoE)'!AQ8=1,'Loan Tape (BoE)'!AQ8=2),"Yes",IF('Loan Tape (BoE)'!AQ8=0,"No","")) | AQ8: =IF('Loan Tape (BoE)'!BV49_8<>"",'Loan Tape (BoE)'!BV49_8,"") | AR8: =IF('Loan Tape (BoE)'!BV80_8<>"",'Loan Tape (BoE)'!BV50_8,"") | AS8: =IFERROR(INDEX('FF Adj Parameters'!$A$103:$B$108,MATCH('Loan Tape (BoE)'!P8,INDEX('FF Adj Parameters'!$A$103:$B$108,,1),0),2),"Unknown") | AT8: =IF(N8="Interest Only",M5*O5/12,IF(AND(O5>0,ISNUMBER(O5),ISNUMBER(M5)),ABS(PMT(O5/12,AU5,-M5)),0)) | AU8: =IF(ISNUMBER(L8),MAX(0,(L5-'Control Panel'!$B$10)*12/365.25),0) | AV8: =IF(ISNUMBER(L8),IF(L5>'Control Panel'!$B$10,"Valid","Past Maturity"),"No Date") | AW8: =IF(ISNUMBER(K8),MAX(0,('Control Panel'!$B$10-K5)*12/365.25),0)
A9: ='Loan Tape (BoE)'!A10 | B9: =IFERROR(INDEX('FF Adj Parameters'!$A$89:$B$92,MATCH('Loan Tape (BoE)'!C9,INDEX('FF Adj Parameters'!$A$89:$B$92,,1),0),2),"Unknown") | C9: ='Loan Tape (BoE)'!C10 | D9: ='Loan Tape (BoE)'!D10 | E9: ='Loan Tape (BoE)'!E10 | F9: ='Loan Tape (BoE)'!F10 | G9: ='Loan Tape (BoE)'!G10 | H9: ='Loan Tape (BoE)'!H10/100 | I9: =IFERROR(IFS('Loan Tape (BoE)'!I10=1,"House",'Loan Tape (BoE)'!I10=2,"Flat",'Loan Tape (BoE)'!I10=3,"Bungalow",'Loan Tape (BoE)'!I10=4,"Maisonette"),"") | J9: ='Loan Tape (BoE)'!J10 | K9: ='Loan Tape (BoE)'!K10 | L9: =IFERROR(IFS('Loan Tape (BoE)'!L10=1,"Owner Occupied",'Loan Tape (BoE)'!L10=2,"BTL",'Loan Tape (BoE)'!L10=3,"Second Home",'Loan Tape (BoE)'!L10=4,"Investment"),"") | M9: =IFERROR(IFS('Loan Tape (BoE)'!M10=1,"Purchase",'Loan Tape (BoE)'!M10=2,"Remortgage",OR('Loan Tape (BoE)'!M10=3,'Loan Tape (BoE)'!M10=4),"Cash-out"),"") | N9: =IFERROR(INDEX('FF Adj Parameters'!$A$96:$B$99,MATCH('Loan Tape (BoE)'!R9,INDEX('FF Adj Parameters'!$A$96:$B$99,,1),0),2),"Unknown") | O9: =IF('Loan Tape (BoE)'!O10=1,"Yes","No") | P9: =IF('Loan Tape (BoE)'!P9=1,"Yes",IF('Loan Tape (BoE)'!P9=0,"No","")) | Q9: =IF('Loan Tape (BoE)'!Q9=1,"Yes",IF('Loan Tape (BoE)'!Q9=0,"No","")) | R9: =IF('Loan Tape (BoE)'!R9=1,"Yes",IF('Loan Tape (BoE)'!R9=0,"No","")) | S9: =IF('Loan Tape (BoE)'!S9=1,"Yes",IF('Loan Tape (BoE)'!S9=0,"No","")) | T9: =IF('Loan Tape (BoE)'!T9=1,"Yes",IF('Loan Tape (BoE)'!T9=0,"No","")) | U9: =R9+S9 | V9: =IFERROR(IFS('Loan Tape (BoE)'!U10=1,"Employed",'Loan Tape (BoE)'!U10=2,"Self-Employed",'Loan Tape (BoE)'!U10=3,"Unemployed",'Loan Tape (BoE)'!U10=4,"Retired"),"") | W9: =IFERROR(IFS('Loan Tape (BoE)'!V10=1,"Employed",'Loan Tape (BoE)'!V10=2,"Self-Employed",'Loan Tape (BoE)'!V10=3,"Unemployed",'Loan Tape (BoE)'!V10=4,"Retired"),"") | X9: =IF(OR(V9="Self-Employed",W9="Self-Employed"),"Yes","No") | Y9: ='Loan Tape (BoE)'!W10 | Z9: ='Loan Tape (BoE)'!X10 | AA9: =IF(T9=1,Y9,MIN(Y9,Z9)) | AB9: ='Loan Tape (BoE)'!Y10 | AC9: ='Loan Tape (BoE)'!Z10 | AD9: =AB9+AC9 | AE9: ='Loan Tape (BoE)'!AA10 | AF9: ='Loan Tape (BoE)'!AB10 | AG9: =AE9+AF9 | AH9: =MAX('Loan Tape (BoE)'!AC10,'Loan Tape (BoE)'!AD10) | AI9: ='Loan Tape (BoE)'!AE10 | AJ9: =B9*H9/12 | AK9: =IF(AJ9>0,AI9/AJ9,0) | AL9: =IF('Loan Tape (BoE)'!AF10=1,"Yes","No") | AM9: =IF('Loan Tape (BoE)'!AH10=1,"Yes","No") | AN9: =IF('Loan Tape (BoE)'!AI10=1,"Yes","No") | AO9: =IF('Loan Tape (BoE)'!AJ10=1,"Yes","No") | AP9: =IF(OR('Loan Tape (BoE)'!AQ9=1,'Loan Tape (BoE)'!AQ9=2),"Yes",IF('Loan Tape (BoE)'!AQ9=0,"No","")) | AQ9: =IF('Loan Tape (BoE)'!BV49_9<>"",'Loan Tape (BoE)'!BV49_9,"") | AR9: =IF('Loan Tape (BoE)'!BV90_9<>"",'Loan Tape (BoE)'!BV50_9,"") | AS9: =IFERROR(INDEX('FF Adj Parameters'!$A$103:$B$109,MATCH('Loan Tape (BoE)'!P9,INDEX('FF Adj Parameters'!$A$103:$B$109,,1),0),2),"Unknown") | AT9: =IF(N9="Interest Only",M5*O5/12,IF(AND(O5>0,ISNUMBER(O5),ISNUMBER(M5)),ABS(PMT(O5/12,AU5,-M5)),0)) | AU9: =IF(ISNUMBER(L9),MAX(0,(L5-'Control Panel'!$B$10)*12/365.25),0) | AV9: =IF(ISNUMBER(L9),IF(L5>'Control Panel'!$B$10,"Valid","Past Maturity"),"No Date") | AW9: =IF(ISNUMBER(K9),MAX(0,('Control Panel'!$B$10-K5)*12/365.25),0)
A10: ='Loan Tape (BoE)'!A11 | B10: =IFERROR(INDEX('FF Adj Parameters'!$A$89:$B$92,MATCH('Loan Tape (BoE)'!C10,INDEX('FF Adj Parameters'!$A$89:$B$92,,1),0),2),"Unknown") | C10: ='Loan Tape (BoE)'!C11 | D10: ='Loan Tape (BoE)'!D11 | E10: ='Loan Tape (BoE)'!E11 | F10: ='Loan Tape (BoE)'!F11 | G10: ='Loan Tape (BoE)'!G11 | H10: ='Loan Tape (BoE)'!H11/100 | I10: =IFERROR(IFS('Loan Tape (BoE)'!I11=1,"House",'Loan Tape (BoE)'!I11=2,"Flat",'Loan Tape (BoE)'!I11=3,"Bungalow",'Loan Tape (BoE)'!I11=4,"Maisonette"),"") | J10: ='Loan Tape (BoE)'!J11 | K10: ='Loan Tape (BoE)'!K11 | L10: =IFERROR(IFS('Loan Tape (BoE)'!L11=1,"Owner Occupied",'Loan Tape (BoE)'!L11=2,"BTL",'Loan Tape (BoE)'!L11=3,"Second Home",'Loan Tape (BoE)'!L11=4,"Investment"),"") | M10: =IFERROR(IFS('Loan Tape (BoE)'!M11=1,"Purchase",'Loan Tape (BoE)'!M11=2,"Remortgage",OR('Loan Tape (BoE)'!M11=3,'Loan Tape (BoE)'!M11=4),"Cash-out"),"") | N10: =IFERROR(INDEX('FF Adj Parameters'!$A$96:$B$99,MATCH('Loan Tape (BoE)'!R10,INDEX('FF Adj Parameters'!$A$96:$B$99,,1),0),2),"Unknown") | O10: =IF('Loan Tape (BoE)'!O11=1,"Yes","No") | P10: =IF('Loan Tape (BoE)'!P10=1,"Yes",IF('Loan Tape (BoE)'!P10=0,"No","")) | Q10: =IF('Loan Tape (BoE)'!Q10=1,"Yes",IF('Loan Tape (BoE)'!Q10=0,"No","")) | R10: =IF('Loan Tape (BoE)'!R10=1,"Yes",IF('Loan Tape (BoE)'!R10=0,"No","")) | S10: =IF('Loan Tape (BoE)'!S10=1,"Yes",IF('Loan Tape (BoE)'!S10=0,"No","")) | T10: =IF('Loan Tape (BoE)'!T10=1,"Yes",IF('Loan Tape (BoE)'!T10=0,"No","")) | U10: =R10+S10 | V10: =IFERROR(IFS('Loan Tape (BoE)'!U11=1,"Employed",'Loan Tape (BoE)'!U11=2,"Self-Employed",'Loan Tape (BoE)'!U11=3,"Unemployed",'Loan Tape (BoE)'!U11=4,"Retired"),"") | W10: =IFERROR(IFS('Loan Tape (BoE)'!V11=1,"Employed",'Loan Tape (BoE)'!V11=2,"Self-Employed",'Loan Tape (BoE)'!V11=3,"Unemployed",'Loan Tape (BoE)'!V11=4,"Retired"),"") | X10: =IF(OR(V10="Self-Employed",W10="Self-Employed"),"Yes","No") | Y10: ='Loan Tape (BoE)'!W11 | Z10: ='Loan Tape (BoE)'!X11 | AA10: =IF(T10=1,Y10,MIN(Y10,Z10)) | AB10: ='Loan Tape (BoE)'!Y11 | AC10: ='Loan Tape (BoE)'!Z11 | AD10: =AB10+AC10 | AE10: ='Loan Tape (BoE)'!AA11 | AF10: ='Loan Tape (BoE)'!AB11 | AG10: =AE10+AF10 | AH10: =MAX('Loan Tape (BoE)'!AC11,'Loan Tape (BoE)'!AD11) | AI10: ='Loan Tape (BoE)'!AE11 | AJ10: =B10*H10/12 | AK10: =IF(AJ10>0,AI10/AJ10,0) | AL10: =IF('Loan Tape (BoE)'!AF11=1,"Yes","No") | AM10: =IF('Loan Tape (BoE)'!AH11=1,"Yes","No") | AN10: =IF('Loan Tape (BoE)'!AI11=1,"Yes","No") | AO10: =IF('Loan Tape (BoE)'!AJ11=1,"Yes","No") | AP10: =IF(OR('Loan Tape (BoE)'!AQ10=1,'Loan Tape (BoE)'!AQ10=2),"Yes",IF('Loan Tape (BoE)'!AQ10=0,"No","")) | AQ10: =IF('Loan Tape (BoE)'!BV49_10<>"",'Loan Tape (BoE)'!BV49_10,"") | AR10: =IF('Loan Tape (BoE)'!BV100_10<>"",'Loan Tape (BoE)'!BV50_10,"") | AS10: =IFERROR(INDEX('FF Adj Parameters'!$A$103:$B$1010,MATCH('Loan Tape (BoE)'!P10,INDEX('FF Adj Parameters'!$A$103:$B$1010,,1),0),2),"Unknown") | AT10: =IF(N10="Interest Only",M5*O5/12,IF(AND(O5>0,ISNUMBER(O5),ISNUMBER(M5)),ABS(PMT(O5/12,AU5,-M5)),0)) | AU10: =IF(ISNUMBER(L10),MAX(0,(L5-'Control Panel'!$B$10)*12/365.25),0) | AV10: =IF(ISNUMBER(L10),IF(L5>'Control Panel'!$B$10,"Valid","Past Maturity"),"No Date") | AW10: =IF(ISNUMBER(K10),MAX(0,('Control Panel'!$B$10-K5)*12/365.25),0)
A11: ='Loan Tape (BoE)'!A12 | B11: =IFERROR(INDEX('FF Adj Parameters'!$A$89:$B$92,MATCH('Loan Tape (BoE)'!C11,INDEX('FF Adj Parameters'!$A$89:$B$92,,1),0),2),"Unknown") | C11: ='Loan Tape (BoE)'!C12 | D11: ='Loan Tape (BoE)'!D12 | E11: ='Loan Tape (BoE)'!E12 | F11: ='Loan Tape (BoE)'!F12 | G11: ='Loan Tape (BoE)'!G12 | H11: ='Loan Tape (BoE)'!H12/100 | I11: =IFERROR(IFS('Loan Tape (BoE)'!I12=1,"House",'Loan Tape (BoE)'!I12=2,"Flat",'Loan Tape (BoE)'!I12=3,"Bungalow",'Loan Tape (BoE)'!I12=4,"Maisonette"),"") | J11: ='Loan Tape (BoE)'!J12 | K11: ='Loan Tape (BoE)'!K12 | L11: =IFERROR(IFS('Loan Tape (BoE)'!L12=1,"Owner Occupied",'Loan Tape (BoE)'!L12=2,"BTL",'Loan Tape (BoE)'!L12=3,"Second Home",'Loan Tape (BoE)'!L12=4,"Investment"),"") | M11: =IFERROR(IFS('Loan Tape (BoE)'!M12=1,"Purchase",'Loan Tape (BoE)'!M12=2,"Remortgage",OR('Loan Tape (BoE)'!M12=3,'Loan Tape (BoE)'!M12=4),"Cash-out"),"") | N11: =IFERROR(INDEX('FF Adj Parameters'!$A$96:$B$99,MATCH('Loan Tape (BoE)'!R11,INDEX('FF Adj Parameters'!$A$96:$B$99,,1),0),2),"Unknown") | O11: =IF('Loan Tape (BoE)'!O12=1,"Yes","No") | P11: =IF('Loan Tape (BoE)'!P11=1,"Yes",IF('Loan Tape (BoE)'!P11=0,"No","")) | Q11: =IF('Loan Tape (BoE)'!Q11=1,"Yes",IF('Loan Tape (BoE)'!Q11=0,"No","")) | R11: =IF('Loan Tape (BoE)'!R11=1,"Yes",IF('Loan Tape (BoE)'!R11=0,"No","")) | S11: =IF('Loan Tape (BoE)'!S11=1,"Yes",IF('Loan Tape (BoE)'!S11=0,"No","")) | T11: =IF('Loan Tape (BoE)'!T11=1,"Yes",IF('Loan Tape (BoE)'!T11=0,"No","")) | U11: =R11+S11 | V11: =IFERROR(IFS('Loan Tape (BoE)'!U12=1,"Employed",'Loan Tape (BoE)'!U12=2,"Self-Employed",'Loan Tape (BoE)'!U12=3,"Unemployed",'Loan Tape (BoE)'!U12=4,"Retired"),"") | W11: =IFERROR(IFS('Loan Tape (BoE)'!V12=1,"Employed",'Loan Tape (BoE)'!V12=2,"Self-Employed",'Loan Tape (BoE)'!V12=3,"Unemployed",'Loan Tape (BoE)'!V12=4,"Retired"),"") | X11: =IF(OR(V11="Self-Employed",W11="Self-Employed"),"Yes","No") | Y11: ='Loan Tape (BoE)'!W12 | Z11: ='Loan Tape (BoE)'!X12 | AA11: =IF(T11=1,Y11,MIN(Y11,Z11)) | AB11: ='Loan Tape (BoE)'!Y12 | AC11: ='Loan Tape (BoE)'!Z12 | AD11: =AB11+AC11 | AE11: ='Loan Tape (BoE)'!AA12 | AF11: ='Loan Tape (BoE)'!AB12 | AG11: =AE11+AF11 | AH11: =MAX('Loan Tape (BoE)'!AC12,'Loan Tape (BoE)'!AD12) | AI11: ='Loan Tape (BoE)'!AE12 | AJ11: =B11*H11/12 | AK11: =IF(AJ11>0,AI11/AJ11,0) | AL11: =IF('Loan Tape (BoE)'!AF12=1,"Yes","No") | AM11: =IF('Loan Tape (BoE)'!AH12=1,"Yes","No") | AN11: =IF('Loan Tape (BoE)'!AI12=1,"Yes","No") | AO11: =IF('Loan Tape (BoE)'!AJ12=1,"Yes","No") | AP11: =IF(OR('Loan Tape (BoE)'!AQ11=1,'Loan Tape (BoE)'!AQ11=2),"Yes",IF('Loan Tape (BoE)'!AQ11=0,"No","")) | AQ11: =IF('Loan Tape (BoE)'!BV49_11<>"",'Loan Tape (BoE)'!BV49_11,"") | AR11: =IF('Loan Tape (BoE)'!BV110_11<>"",'Loan Tape (BoE)'!BV50_11,"") | AS11: =IFERROR(INDEX('FF Adj Parameters'!$A$103:$B$1011,MATCH('Loan Tape (BoE)'!P11,INDEX('FF Adj Parameters'!$A$103:$B$1011,,1),0),2),"Unknown") | AT11: =IF(N11="Interest Only",M5*O5/12,IF(AND(O5>0,ISNUMBER(O5),ISNUMBER(M5)),ABS(PMT(O5/12,AU5,-M5)),0)) | AU11: =IF(ISNUMBER(L11),MAX(0,(L5-'Control Panel'!$B$10)*12/365.25),0) | AV11: =IF(ISNUMBER(L11),IF(L5>'Control Panel'!$B$10,"Valid","Past Maturity"),"No Date") | AW11: =IF(ISNUMBER(K11),MAX(0,('Control Panel'!$B$10-K5)*12/365.25),0)
A12: ='Loan Tape (BoE)'!A13 | B12: =IFERROR(INDEX('FF Adj Parameters'!$A$89:$B$92,MATCH('Loan Tape (BoE)'!C12,INDEX('FF Adj Parameters'!$A$89:$B$92,,1),0),2),"Unknown") | C12: ='Loan Tape (BoE)'!C13 | D12: ='Loan Tape (BoE)'!D13 | E12: ='Loan Tape (BoE)'!E13 | F12: ='Loan Tape (BoE)'!F13 | G12: ='Loan Tape (BoE)'!G13 | H12: ='Loan Tape (BoE)'!H13/100 | I12: =IFERROR(IFS('Loan Tape (BoE)'!I13=1,"House",'Loan Tape (BoE)'!I13=2,"Flat",'Loan Tape (BoE)'!I13=3,"Bungalow",'Loan Tape (BoE)'!I13=4,"Maisonette"),"") | J12: ='Loan Tape (BoE)'!J13 | K12: ='Loan Tape (BoE)'!K13 | L12: =IFERROR(IFS('Loan Tape (BoE)'!L13=1,"Owner Occupied",'Loan Tape (BoE)'!L13=2,"BTL",'Loan Tape (BoE)'!L13=3,"Second Home",'Loan Tape (BoE)'!L13=4,"Investment"),"") | M12: =IFERROR(IFS('Loan Tape (BoE)'!M13=1,"Purchase",'Loan Tape (BoE)'!M13=2,"Remortgage",OR('Loan Tape (BoE)'!M13=3,'Loan Tape (BoE)'!M13=4),"Cash-out"),"") | N12: =IFERROR(INDEX('FF Adj Parameters'!$A$96:$B$99,MATCH('Loan Tape (BoE)'!R12,INDEX('FF Adj Parameters'!$A$96:$B$99,,1),0),2),"Unknown") | O12: =IF('Loan Tape (BoE)'!O13=1,"Yes","No") | P12: =IF('Loan Tape (BoE)'!P12=1,"Yes",IF('Loan Tape (BoE)'!P12=0,"No","")) | Q12: =IF('Loan Tape (BoE)'!Q12=1,"Yes",IF('Loan Tape (BoE)'!Q12=0,"No","")) | R12: =IF('Loan Tape (BoE)'!R12=1,"Yes",IF('Loan Tape (BoE)'!R12=0,"No","")) | S12: =IF('Loan Tape (BoE)'!S12=1,"Yes",IF('Loan Tape (BoE)'!S12=0,"No","")) | T12: =IF('Loan Tape (BoE)'!T12=1,"Yes",IF('Loan Tape (BoE)'!T12=0,"No","")) | U12: =R12+S12 | V12: =IFERROR(IFS('Loan Tape (BoE)'!U13=1,"Employed",'Loan Tape (BoE)'!U13=2,"Self-Employed",'Loan Tape (BoE)'!U13=3,"Unemployed",'Loan Tape (BoE)'!U13=4,"Retired"),"") | W12: =IFERROR(IFS('Loan Tape (BoE)'!V13=1,"Employed",'Loan Tape (BoE)'!V13=2,"Self-Employed",'Loan Tape (BoE)'!V13=3,"Unemployed",'Loan Tape (BoE)'!V13=4,"Retired"),"") | X12: =IF(OR(V12="Self-Employed",W12="Self-Employed"),"Yes","No") | Y12: ='Loan Tape (BoE)'!W13 | Z12: ='Loan Tape (BoE)'!X13 | AA12: =IF(T12=1,Y12,MIN(Y12,Z12)) | AB12: ='Loan Tape (BoE)'!Y13 | AC12: ='Loan Tape (BoE)'!Z13 | AD12: =AB12+AC12 | AE12: ='Loan Tape (BoE)'!AA13 | AF12: ='Loan Tape (BoE)'!AB13 | AG12: =AE12+AF12 | AH12: =MAX('Loan Tape (BoE)'!AC13,'Loan Tape (BoE)'!AD13) | AI12: ='Loan Tape (BoE)'!AE13 | AJ12: =B12*H12/12 | AK12: =IF(AJ12>0,AI12/AJ12,0) | AL12: =IF('Loan Tape (BoE)'!AF13=1,"Yes","No") | AM12: =IF('Loan Tape (BoE)'!AH13=1,"Yes","No") | AN12: =IF('Loan Tape (BoE)'!AI13=1,"Yes","No") | AO12: =IF('Loan Tape (BoE)'!AJ13=1,"Yes","No") | AP12: =IF(OR('Loan Tape (BoE)'!AQ12=1,'Loan Tape (BoE)'!AQ12=2),"Yes",IF('Loan Tape (BoE)'!AQ12=0,"No","")) | AQ12: =IF('Loan Tape (BoE)'!BV49_12<>"",'Loan Tape (BoE)'!BV49_12,"") | AR12: =IF('Loan Tape (BoE)'!BV120_12<>"",'Loan Tape (BoE)'!BV50_12,"") | AS12: =IFERROR(INDEX('FF Adj Parameters'!$A$103:$B$1012,MATCH('Loan Tape (BoE)'!P12,INDEX('FF Adj Parameters'!$A$103:$B$1012,,1),0),2),"Unknown") | AT12: =IF(N12="Interest Only",M5*O5/12,IF(AND(O5>0,ISNUMBER(O5),ISNUMBER(M5)),ABS(PMT(O5/12,AU5,-M5)),0)) | AU12: =IF(ISNUMBER(L12),MAX(0,(L5-'Control Panel'!$B$10)*12/365.25),0) | AV12: =IF(ISNUMBER(L12),IF(L5>'Control Panel'!$B$10,"Valid","Past Maturity"),"No Date") | AW12: =IF(ISNUMBER(K12),MAX(0,('Control Panel'!$B$10-K5)*12/365.25),0)
