Workbook

Sheet ReadMe
B1: Tranching Framework & Optimisation — Excel Model (no macros)
B3: What this workbook does | C3: Implements a transparent tranching / credit-enhancement framework (BOTE-style) and a cashflow engine for a simple amortising pool. Includes an optimisation worksheet set up for Excel Solver (you run Solver in Excel).
B4: How to use (quick) | C4: 1) Go to Inputs and edit BLUE cells. 2) Review Cashflow_Asset and Cashflow_Waterfall for monthly results. 3) Check Tranche_Metrics for credit enhancement (CE), expected loss (E(L)), and rating-factor tests. 4) Go to Optimisation and follow the Solver setup instructions to size tranches / coupons to your objective.
B5: Model scope / limitations | C5: This is a simplified template intended for learning and prototyping. It assumes: a homogeneous amortising pool, CPR/CDR style prepay/default, single recovery lag, sequential-pay waterfall, and simple reserve mechanics. For complex structures (multiple triggers, pro-rata, turbo, step-ups, etc.), extend the waterfall logic.
B6: Color conventions | C6: BLUE text = user inputs. BLACK text = formulas. GREEN text = links across sheets. YELLOW fill = key assumptions.
B8: Sheets
B9: Inputs | C9: Deal/pool assumptions, tranche design variables, rating-factor table.
B10: Cashflow_Asset | C10: Monthly pool cashflows: scheduled amortisation, prepayments, defaults, recoveries, fees.
B11: Cashflow_Waterfall | C11: Monthly liability waterfall: interest, principal paydown, reserve, residual to equity.
B12: Tranche_Metrics | C12: Credit enhancement, BOTE-style tests, PV metrics and IRRs.
B13: Optimisation | C13: Solver-ready objective & constraints with instructions.

Sheet Inputs
B1: Inputs (edit BLUE cells)
B3: Pool assumptions
B4: Initial Pool Balance | C4: 100000000 | D4: Currency
B5: WAC (annual) % | C5: 0.12 | D5: Decimal
B6: WAM (months) | C6: 60 | D6: Months
B7: Servicing fee (annual) % | C7: 0.01 | D7: Decimal
B8: CPR (annual) % | C8: 0.06 | D8: Decimal
B9: CDR (annual) % | C9: 0.03 | D9: Decimal
B10: Severity (loss given default) % | C10: 0.6 | D10: Decimal
B11: Recovery lag (months) | C11: 6 | D11: Months
B12: Discount rate for PV (annual) % | C12: 0.08 | D12: Decimal
B14: Tranche design variables (decision variables for Solver)
B15: Class A % of NoteBase | C15: 0.8 | D15: Decision var
B16: Class B % of NoteBase | C16: 0.15 | D16: Decision var
B17: Residual % (unused NoteBase) | C17: =MAX(0,1-$C$15-$C$16) | D17: Residual = 1 - A - B
B18: Class A coupon (annual) % | C18: 0.055 | D18: Decision var
B19: Class B coupon (annual) % | C19: 0.095 | D19: Decision var
B20: Reserve fund (initial) % of pool | C20: 0.01 | D20: Decision var
B21: Overcollateralisation (OC) % of pool | C21: 0 | D21: Decision var
B23: Target rating factors (BOTE-style: CE / E(L))
B24: Rating | C24: Factor n | D24: Notes
B25: Aaa/AAA | C25: 5 | D25: Illustrative factor
B26: Aa/AA | C26: 4 | D26: Illustrative factor
B27: A | C27: 3 | D27: Illustrative factor
B28: Baa/BBB | C28: 1.75 | D28: Illustrative mid-point
B29: Ba/BB | C29: 1.25 | D29: Illustrative
B31: Chosen rating targets for constraints
B32: Target rating for Class A | C32: AAA | D32: Set factor via lookup
B33: Target rating for Class B | C33: BBB | D33: Set factor via lookup
B34: Factor for Class A | C34: =XLOOKUP($C$32,$B$25:$B$29,$C$25:$C$29)
B35: Factor for Class B | C35: =XLOOKUP($C$33,$B$25:$B$29,$C$25:$C$29)
B38: Waterfall toggles
B39: Turbo: use excess interest to pay down Class A (1=yes,0=no) | C39: 1 | D39: Decision var (optional)

Sheet Cashflow_Asset
B1: Asset cashflow engine (monthly)
B2: Parameters (linked) | C2: =Inputs!$C$5/12 | D2: Monthly rate (WAC/12) | E2: =1-(1-Inputs!$C$8)^(1/12) | F2: SMM | G2: =1-(1-Inputs!$C$9)^(1/12) | H2: MDR | I2: =Inputs!$C$10 | J2: Severity | K2: =Inputs!$C$11 | L2: Recovery lag (m)
B3: Month | C3: Beg Bal | D3: Sched Pmt | E3: Interest | F3: Sched Prin | G3: Prepay | H3: Default | I3: Recovery | J3: Loss | K3: Serv Fee | L3: Net Cash | M3: End Bal | O3: Summary
B4: 1 | C4: =Inputs!$C$4 | D4: =IF($B4<=Inputs!$C$6,-PMT(Inputs!$C$5/12,Inputs!$C$6,Inputs!$C$4),0) | E4: =IF($B4<=Inputs!$C$6+Inputs!$C$11,$C4*Inputs!$C$5/12,0) | F4: =IF($B4<=Inputs!$C$6,MAX(0,$D4-$E4),0) | G4: =IF($B4<=Inputs!$C$6,MAX(0,($C4-$F4))*(1-(1-Inputs!$C$8)^(1/12)),0) | H4: =IF($B4<=Inputs!$C$6,MAX(0,($C4-$F4-$G4))*(1-(1-Inputs!$C$9)^(1/12)),0) | I4: =IF($B4>Inputs!$C$11,INDEX($H:$H,ROW()-Inputs!$C$11)* (1-Inputs!$C$10),0) | J4: =$H4*Inputs!$C$10 | K4: =IF($B4<=Inputs!$C$6+Inputs!$C$11,$C4*Inputs!$C$7/12,0) | L4: =IF($B4<=Inputs!$C$6+Inputs!$C$11,$E4+$F4+$G4+$I4-$K4,0) | M4: =IF($B4<=Inputs!$C$6,MAX(0,$C4-$F4-$G4-$H4),0) | O4: Cum Gross Defaults | P4: =SUM($H4:$H363)
B5: 2 | C5: =IF($B5<=Inputs!$C$6+Inputs!$C$11,$M4,"") | D5: =IF($B5<=Inputs!$C$6,-PMT(Inputs!$C$5/12,Inputs!$C$6,Inputs!$C$4),0) | E5: =IF($B5<=Inputs!$C$6+Inputs!$C$11,$C5*Inputs!$C$5/12,0) | F5: =IF($B5<=Inputs!$C$6,MAX(0,$D5-$E5),0) | G5: =IF($B5<=Inputs!$C$6,MAX(0,($C5-$F5))*(1-(1-Inputs!$C$8)^(1/12)),0) | H5: =IF($B5<=Inputs!$C$6,MAX(0,($C5-$F5-$G5))*(1-(1-Inputs!$C$9)^(1/12)),0) | I5: =IF($B5>Inputs!$C$11,INDEX($H:$H,ROW()-Inputs!$C$11)* (1-Inputs!$C$10),0) | J5: =$H5*Inputs!$C$10 | K5: =IF($B5<=Inputs!$C$6+Inputs!$C$11,$C5*Inputs!$C$7/12,0) | L5: =IF($B5<=Inputs!$C$6+Inputs!$C$11,$E5+$F5+$G5+$I5-$K5,0) | M5: =IF($B5<=Inputs!$C$6,MAX(0,$C5-$F5-$G5-$H5),0) | O5: Cum Losses (gross) | P5: =SUM($J4:$J363)
B6: 3 | C6: =IF($B6<=Inputs!$C$6+Inputs!$C$11,$M5,"") | D6: =IF($B6<=Inputs!$C$6,-PMT(Inputs!$C$5/12,Inputs!$C$6,Inputs!$C$4),0) | E6: =IF($B6<=Inputs!$C$6+Inputs!$C$11,$C6*Inputs!$C$5/12,0) | F6: =IF($B6<=Inputs!$C$6,MAX(0,$D6-$E6),0) | G6: =IF($B6<=Inputs!$C$6,MAX(0,($C6-$F6))*(1-(1-Inputs!$C$8)^(1/12)),0) | H6: =IF($B6<=Inputs!$C$6,MAX(0,($C6-$F6-$G6))*(1-(1-Inputs!$C$9)^(1/12)),0) | I6: =IF($B6>Inputs!$C$11,INDEX($H:$H,ROW()-Inputs!$C$11)* (1-Inputs!$C$10),0) | J6: =$H6*Inputs!$C$10 | K6: =IF($B6<=Inputs!$C$6+Inputs!$C$11,$C6*Inputs!$C$7/12,0) | L6: =IF($B6<=Inputs!$C$6+Inputs!$C$11,$E6+$F6+$G6+$I6-$K6,0) | M6: =IF($B6<=Inputs!$C$6,MAX(0,$C6-$F6-$G6-$H6),0) | O6: Cum Recoveries | P6: =SUM($I4:$I363)
B7: 4 | C7: =IF($B7<=Inputs!$C$6+Inputs!$C$11,$M6,"") | D7: =IF($B7<=Inputs!$C$6,-PMT(Inputs!$C$5/12,Inputs!$C$6,Inputs!$C$4),0) | E7: =IF($B7<=Inputs!$C$6+Inputs!$C$11,$C7*Inputs!$C$5/12,0) | F7: =IF($B7<=Inputs!$C$6,MAX(0,$D7-$E7),0) | G7: =IF($B7<=Inputs!$C$6,MAX(0,($C7-$F7))*(1-(1-Inputs!$C$8)^(1/12)),0) | H7: =IF($B7<=Inputs!$C$6,MAX(0,($C7-$F7-$G7))*(1-(1-Inputs!$C$9)^(1/12)),0) | I7: =IF($B7>Inputs!$C$11,INDEX($H:$H,ROW()-Inputs!$C$11)* (1-Inputs!$C$10),0) | J7: =$H7*Inputs!$C$10 | K7: =IF($B7<=Inputs!$C$6+Inputs!$C$11,$C7*Inputs!$C$7/12,0) | L7: =IF($B7<=Inputs!$C$6+Inputs!$C$11,$E7+$F7+$G7+$I7-$K7,0) | M7: =IF($B7<=Inputs!$C$6,MAX(0,$C7-$F7-$G7-$H7),0) | O7: Cum Expected Loss (net) | P7: =SUM($J4:$J363)
B8: 5 | C8: =IF($B8<=Inputs!$C$6+Inputs!$C$11,$M7,"") | D8: =IF($B8<=Inputs!$C$6,-PMT(Inputs!$C$5/12,Inputs!$C$6,Inputs!$C$4),0) | E8: =IF($B8<=Inputs!$C$6+Inputs!$C$11,$C8*Inputs!$C$5/12,0) | F8: =IF($B8<=Inputs!$C$6,MAX(0,$D8-$E8),0) | G8: =IF($B8<=Inputs!$C$6,MAX(0,($C8-$F8))*(1-(1-Inputs!$C$8)^(1/12)),0) | H8: =IF($B8<=Inputs!$C$6,MAX(0,($C8-$F8-$G8))*(1-(1-Inputs!$C$9)^(1/12)),0) | I8: =IF($B8>Inputs!$C$11,INDEX($H:$H,ROW()-Inputs!$C$11)* (1-Inputs!$C$10),0) | J8: =$H8*Inputs!$C$10 | K8: =IF($B8<=Inputs!$C$6+Inputs!$C$11,$C8*Inputs!$C$7/12,0) | L8: =IF($B8<=Inputs!$C$6+Inputs!$C$11,$E8+$F8+$G8+$I8-$K8,0) | M8: =IF($B8<=Inputs!$C$6,MAX(0,$C8-$F8-$G8-$H8),0) | O8: E(L) % of initial | P8: =$P7/Inputs!$C$4
B9: 6 | C9: =IF($B9<=Inputs!$C$6+Inputs!$C$11,$M8,"") | D9: =IF($B9<=Inputs!$C$6,-PMT(Inputs!$C$5/12,Inputs!$C$6,Inputs!$C$4),0) | E9: =IF($B9<=Inputs!$C$6+Inputs!$C$11,$C9*Inputs!$C$5/12,0) | F9: =IF($B9<=Inputs!$C$6,MAX(0,$D9-$E9),0) | G9: =IF($B9<=Inputs!$C$6,MAX(0,($C9-$F9))*(1-(1-Inputs!$C$8)^(1/12)),0) | H9: =IF($B9<=Inputs!$C$6,MAX(0,($C9-$F9-$G9))*(1-(1-Inputs!$C$9)^(1/12)),0) | I9: =IF($B9>Inputs!$C$11,INDEX($H:$H,ROW()-Inputs!$C$11)* (1-Inputs!$C$10),0) | J9: =$H9*Inputs!$C$10 | K9: =IF($B9<=Inputs!$C$6+Inputs!$C$11,$C9*Inputs!$C$7/12,0) | L9: =IF($B9<=Inputs!$C$6+Inputs!$C$11,$E9+$F9+$G9+$I9-$K9,0) | M9: =IF($B9<=Inputs!$C$6,MAX(0,$C9-$F9-$G9-$H9),0) | O9: Pool Avg Life (yrs) | P9: =SUMPRODUCT($B4:$B363,($F4:$F363+$G4:$G363+$H4:$H363)) / (SUM($F4:$F363)+SUM($G4:$G363)+SUM($H4:$H363)) / 12
B10: 7 | C10: =IF($B10<=Inputs!$C$6+Inputs!$C$11,$M9,"") | D10: =IF($B10<=Inputs!$C$6,-PMT(Inputs!$C$5/12,Inputs!$C$6,Inputs!$C$4),0) | E10: =IF($B10<=Inputs!$C$6+Inputs!$C$11,$C10*Inputs!$C$5/12,0) | F10: =IF($B10<=Inputs!$C$6,MAX(0,$D10-$E10),0) | G10: =IF($B10<=Inputs!$C$6,MAX(0,($C10-$F10))*(1-(1-Inputs!$C$8)^(1/12)),0) | H10: =IF($B10<=Inputs!$C$6,MAX(0,($C10-$F10-$G10))*(1-(1-Inputs!$C$9)^(1/12)),0) | I10: =IF($B10>Inputs!$C$11,INDEX($H:$H,ROW()-Inputs!$C$11)* (1-Inputs!$C$10),0) | J10: =$H10*Inputs!$C$10 | K10: =IF($B10<=Inputs!$C$6+Inputs!$C$11,$C10*Inputs!$C$7/12,0) | L10: =IF($B10<=Inputs!$C$6+Inputs!$C$11,$E10+$F10+$G10+$I10-$K10,0) | M10: =IF($B10<=Inputs!$C$6,MAX(0,$C10-$F10-$G10-$H10),0)
B11: 8 | C11: =IF($B11<=Inputs!$C$6+Inputs!$C$11,$M10,"") | D11: =IF($B11<=Inputs!$C$6,-PMT(Inputs!$C$5/12,Inputs!$C$6,Inputs!$C$4),0) | E11: =IF($B11<=Inputs!$C$6+Inputs!$C$11,$C11*Inputs!$C$5/12,0) | F11: =IF($B11<=Inputs!$C$6,MAX(0,$D11-$E11),0) | G11: =IF($B11<=Inputs!$C$6,MAX(0,($C11-$F11))*(1-(1-Inputs!$C$8)^(1/12)),0) | H11: =IF($B11<=Inputs!$C$6,MAX(0,($C11-$F11-$G11))*(1-(1-Inputs!$C$9)^(1/12)),0) | I11: =IF($B11>Inputs!$C$11,INDEX($H:$H,ROW()-Inputs!$C$11)* (1-Inputs!$C$10),0) | J11: =$H11*Inputs!$C$10 | K11: =IF($B11<=Inputs!$C$6+Inputs!$C$11,$C11*Inputs!$C$7/12,0) | L11: =IF($B11<=Inputs!$C$6+Inputs!$C$11,$E11+$F11+$G11+$I11-$K11,0) | M11: =IF($B11<=Inputs!$C$6,MAX(0,$C11-$F11-$G11-$H11),0)
B12: 9 | C12: =IF($B12<=Inputs!$C$6+Inputs!$C$11,$M11,"") | D12: =IF($B12<=Inputs!$C$6,-PMT(Inputs!$C$5/12,Inputs!$C$6,Inputs!$C$4),0) | E12: =IF($B12<=Inputs!$C$6+Inputs!$C$11,$C12*Inputs!$C$5/12,0) | F12: =IF($B12<=Inputs!$C$6,MAX(0,$D12-$E12),0) | G12: =IF($B12<=Inputs!$C$6,MAX(0,($C12-$F12))*(1-(1-Inputs!$C$8)^(1/12)),0) | H12: =IF($B12<=Inputs!$C$6,MAX(0,($C12-$F12-$G12))*(1-(1-Inputs!$C$9)^(1/12)),0) | I12: =IF($B12>Inputs!$C$11,INDEX($H:$H,ROW()-Inputs!$C$11)* (1-Inputs!$C$10),0) | J12: =$H12*Inputs!$C$10 | K12: =IF($B12<=Inputs!$C$6+Inputs!$C$11,$C12*Inputs!$C$7/12,0) | L12: =IF($B12<=Inputs!$C$6+Inputs!$C$11,$E12+$F12+$G12+$I12-$K12,0) | M12: =IF($B12<=Inputs!$C$6,MAX(0,$C12-$F12-$G12-$H12),0)
B13: 10 | C13: =IF($B13<=Inputs!$C$6+Inputs!$C$11,$M12,"") | D13: =IF($B13<=Inputs!$C$6,-PMT(Inputs!$C$5/12,Inputs!$C$6,Inputs!$C$4),0) | E13: =IF($B13<=Inputs!$C$6+Inputs!$C$11,$C13*Inputs!$C$5/12,0) | F13: =IF($B13<=Inputs!$C$6,MAX(0,$D13-$E13),0) | G13: =IF($B13<=Inputs!$C$6,MAX(0,($C13-$F13))*(1-(1-Inputs!$C$8)^(1/12)),0) | H13: =IF($B13<=Inputs!$C$6,MAX(0,($C13-$F13-$G13))*(1-(1-Inputs!$C$9)^(1/12)),0) | I13: =IF($B13>Inputs!$C$11,INDEX($H:$H,ROW()-Inputs!$C$11)* (1-Inputs!$C$10),0) | J13: =$H13*Inputs!$C$10 | K13: =IF($B13<=Inputs!$C$6+Inputs!$C$11,$C13*Inputs!$C$7/12,0) | L13: =IF($B13<=Inputs!$C$6+Inputs!$C$11,$E13+$F13+$G13+$I13-$K13,0) | M13: =IF($B13<=Inputs!$C$6,MAX(0,$C13-$F13-$G13-$H13),0)
B14: 11 | C14: =IF($B14<=Inputs!$C$6+Inputs!$C$11,$M13,"") | D14: =IF($B14<=Inputs!$C$6,-PMT(Inputs!$C$5/12,Inputs!$C$6,Inputs!$C$4),0) | E14: =IF($B14<=Inputs!$C$6+Inputs!$C$11,$C14*Inputs!$C$5/12,0) | F14: =IF($B14<=Inputs!$C$6,MAX(0,$D14-$E14),0) | G14: =IF($B14<=Inputs!$C$6,MAX(0,($C14-$F14))*(1-(1-Inputs!$C$8)^(1/12)),0) | H14: =IF($B14<=Inputs!$C$6,MAX(0,($C14-$F14-$G14))*(1-(1-Inputs!$C$9)^(1/12)),0) | I14: =IF($B14>Inputs!$C$11,INDEX($H:$H,ROW()-Inputs!$C$11)* (1-Inputs!$C$10),0) | J14: =$H14*Inputs!$C$10 | K14: =IF($B14<=Inputs!$C$6+Inputs!$C$11,$C14*Inputs!$C$7/12,0) | L14: =IF($B14<=Inputs!$C$6+Inputs!$C$11,$E14+$F14+$G14+$I14-$K14,0) | M14: =IF($B14<=Inputs!$C$6,MAX(0,$C14-$F14-$G14-$H14),0)
B15: 12 | C15: =IF($B15<=Inputs!$C$6+Inputs!$C$11,$M14,"") | D15: =IF($B15<=Inputs!$C$6,-PMT(Inputs!$C$5/12,Inputs!$C$6,Inputs!$C$4),0) | E15: =IF($B15<=Inputs!$C$6+Inputs!$C$11,$C15*Inputs!$C$5/12,0) | F15: =IF($B15<=Inputs!$C$6,MAX(0,$D15-$E15),0) | G15: =IF($B15<=Inputs!$C$6,MAX(0,($C15-$F15))*(1-(1-Inputs!$C$8)^(1/12)),0) | H15: =IF($B15<=Inputs!$C$6,MAX(0,($C15-$F15-$G15))*(1-(1-Inputs!$C$9)^(1/12)),0) | I15: =IF($B15>Inputs!$C$11,INDEX($H:$H,ROW()-Inputs!$C$11)* (1-Inputs!$C$10),0) | J15: =$H15*Inputs!$C$10 | K15: =IF($B15<=Inputs!$C$6+Inputs!$C$11,$C15*Inputs!$C$7/12,0) | L15: =IF($B15<=Inputs!$C$6+Inputs!$C$11,$E15+$F15+$G15+$I15-$K15,0) | M15: =IF($B15<=Inputs!$C$6,MAX(0,$C15-$F15-$G15-$H15),0)
B16: 13 | C16: =IF($B16<=Inputs!$C$6+Inputs!$C$11,$M15,"") | D16: =IF($B16<=Inputs!$C$6,-PMT(Inputs!$C$5/12,Inputs!$C$6,Inputs!$C$4),0) | E16: =IF($B16<=Inputs!$C$6+Inputs!$C$11,$C16*Inputs!$C$5/12,0) | F16: =IF($B16<=Inputs!$C$6,MAX(0,$D16-$E16),0) | G16: =IF($B16<=Inputs!$C$6,MAX(0,($C16-$F16))*(1-(1-Inputs!$C$8)^(1/12)),0) | H16: =IF($B16<=Inputs!$C$6,MAX(0,($C16-$F16-$G16))*(1-(1-Inputs!$C$9)^(1/12)),0) | I16: =IF($B16>Inputs!$C$11,INDEX($H:$H,ROW()-Inputs!$C$11)* (1-Inputs!$C$10),0) | J16: =$H16*Inputs!$C$10 | K16: =IF($B16<=Inputs!$C$6+Inputs!$C$11,$C16*Inputs!$C$7/12,0) | L16: =IF($B16<=Inputs!$C$6+Inputs!$C$11,$E16+$F16+$G16+$I16-$K16,0) | M16: =IF($B16<=Inputs!$C$6,MAX(0,$C16-$F16-$G16-$H16),0)
B17: 14 | C17: =IF($B17<=Inputs!$C$6+Inputs!$C$11,$M16,"") | D17: =IF($B17<=Inputs!$C$6,-PMT(Inputs!$C$5/12,Inputs!$C$6,Inputs!$C$4),0) | E17: =IF($B17<=Inputs!$C$6+Inputs!$C$11,$C17*Inputs!$C$5/12,0) | F17: =IF($B17<=Inputs!$C$6,MAX(0,$D17-$E17),0) | G17: =IF($B17<=Inputs!$C$6,MAX(0,($C17-$F17))*(1-(1-Inputs!$C$8)^(1/12)),0) | H17: =IF($B17<=Inputs!$C$6,MAX(0,($C17-$F17-$G17))*(1-(1-Inputs!$C$9)^(1/12)),0) | I17: =IF($B17>Inputs!$C$11,INDEX($H:$H,ROW()-Inputs!$C$11)* (1-Inputs!$C$10),0) | J17: =$H17*Inputs!$C$10 | K17: =IF($B17<=Inputs!$C$6+Inputs!$C$11,$C17*Inputs!$C$7/12,0) | L17: =IF($B17<=Inputs!$C$6+Inputs!$C$11,$E17+$F17+$G17+$I17-$K17,0) | M17: =IF($B17<=Inputs!$C$6,MAX(0,$C17-$F17-$G17-$H17),0)
B18: 15 | C18: =IF($B18<=Inputs!$C$6+Inputs!$C$11,$M17,"") | D18: =IF($B18<=Inputs!$C$6,-PMT(Inputs!$C$5/12,Inputs!$C$6,Inputs!$C$4),0) | E18: =IF($B18<=Inputs!$C$6+Inputs!$C$11,$C18*Inputs!$C$5/12,0) | F18: =IF($B18<=Inputs!$C$6,MAX(0,$D18-$E18),0) | G18: =IF($B18<=Inputs!$C$6,MAX(0,($C18-$F18))*(1-(1-Inputs!$C$8)^(1/12)),0) | H18: =IF($B18<=Inputs!$C$6,MAX(0,($C18-$F18-$G18))*(1-(1-Inputs!$C$9)^(1/12)),0) | I18: =IF($B18>Inputs!$C$11,INDEX($H:$H,ROW()-Inputs!$C$11)* (1-Inputs!$C$10),0) | J18: =$H18*Inputs!$C$10 | K18: =IF($B18<=Inputs!$C$6+Inputs!$C$11,$C18*Inputs!$C$7/12,0) | L18: =IF($B18<=Inputs!$C$6+Inputs!$C$11,$E18+$F18+$G18+$I18-$K18,0) | M18: =IF($B18<=Inputs!$C$6,MAX(0,$C18-$F18-$G18-$H18),0)
B19: 16 | C19: =IF($B19<=Inputs!$C$6+Inputs!$C$11,$M18,"") | D19: =IF($B19<=Inputs!$C$6,-PMT(Inputs!$C$5/12,Inputs!$C$6,Inputs!$C$4),0) | E19: =IF($B19<=Inputs!$C$6+Inputs!$C$11,$C19*Inputs!$C$5/12,0) | F19: =IF($B19<=Inputs!$C$6,MAX(0,$D19-$E19),0) | G19: =IF($B19<=Inputs!$C$6,MAX(0,($C19-$F19))*(1-(1-Inputs!$C$8)^(1/12)),0) | H19: =IF($B19<=Inputs!$C$6,MAX(0,($C19-$F19-$G19))*(1-(1-Inputs!$C$9)^(1/12)),0) | I19: =IF($B19>Inputs!$C$11,INDEX($H:$H,ROW()-Inputs!$C$11)* (1-Inputs!$C$10),0) | J19: =$H19*Inputs!$C$10 | K19: =IF($B19<=Inputs!$C$6+Inputs!$C$11,$C19*Inputs!$C$7/12,0) | L19: =IF($B19<=Inputs!$C$6+Inputs!$C$11,$E19+$F19+$G19+$I19-$K19,0) | M19: =IF($B19<=Inputs!$C$6,MAX(0,$C19-$F19-$G19-$H19),0)
B20: 17 | C20: =IF($B20<=Inputs!$C$6+Inputs!$C$11,$M19,"") | D20: =IF($B20<=Inputs!$C$6,-PMT(Inputs!$C$5/12,Inputs!$C$6,Inputs!$C$4),0) | E20: =IF($B20<=Inputs!$C$6+Inputs!$C$11,$C20*Inputs!$C$5/12,0) | F20: =IF($B20<=Inputs!$C$6,MAX(0,$D20-$E20),0) | G20: =IF($B20<=Inputs!$C$6,MAX(0,($C20-$F20))*(1-(1-Inputs!$C$8)^(1/12)),0) | H20: =IF($B20<=Inputs!$C$6,MAX(0,($C20-$F20-$G20))*(1-(1-Inputs!$C$9)^(1/12)),0) | I20: =IF($B20>Inputs!$C$11,INDEX($H:$H,ROW()-Inputs!$C$11)* (1-Inputs!$C$10),0) | J20: =$H20*Inputs!$C$10 | K20: =IF($B20<=Inputs!$C$6+Inputs!$C$11,$C20*Inputs!$C$7/12,0) | L20: =IF($B20<=Inputs!$C$6+Inputs!$C$11,$E20+$F20+$G20+$I20-$K20,0) | M20: =IF($B20<=Inputs!$C$6,MAX(0,$C20-$F20-$G20-$H20),0)
B21: 18 | C21: =IF($B21<=Inputs!$C$6+Inputs!$C$11,$M20,"") | D21: =IF($B21<=Inputs!$C$6,-PMT(Inputs!$C$5/12,Inputs!$C$6,Inputs!$C$4),0) | E21: =IF($B21<=Inputs!$C$6+Inputs!$C$11,$C21*Inputs!$C$5/12,0) | F21: =IF($B21<=Inputs!$C$6,MAX(0,$D21-$E21),0) | G21: =IF($B21<=Inputs!$C$6,MAX(0,($C21-$F21))*(1-(1-Inputs!$C$8)^(1/12)),0) | H21: =IF($B21<=Inputs!$C$6,MAX(0,($C21-$F21-$G21))*(1-(1-Inputs!$C$9)^(1/12)),0) | I21: =IF($B21>Inputs!$C$11,INDEX($H:$H,ROW()-Inputs!$C$11)* (1-Inputs!$C$10),0) | J21: =$H21*Inputs!$C$10 | K21: =IF($B21<=Inputs!$C$6+Inputs!$C$11,$C21*Inputs!$C$7/12,0) | L21: =IF($B21<=Inputs!$C$6+Inputs!$C$11,$E21+$F21+$G21+$I21-$K21,0) | M21: =IF($B21<=Inputs!$C$6,MAX(0,$C21-$F21-$G21-$H21),0)
... B363: 360 | C363: =IF($B363<=Inputs!$C$6+Inputs!$C$11,$M362,"") | D363: =IF($B363<=Inputs!$C$6,-PMT(Inputs!$C$5/12,Inputs!$C$6,Inputs!$C$4),0) | E363: =IF($B363<=Inputs!$C$6+Inputs!$C$11,$C363*Inputs!$C$5/12,0) | F363: =IF($B363<=Inputs!$C$6,MAX(0,$D363-$E363),0) | G363: =IF($B363<=Inputs!$C$6,MAX(0,($C363-$F363))*(1-(1-Inputs!$C$8)^(1/12)),0) | H363: =IF($B363<=Inputs!$C$6,MAX(0,($C363-$F363-$G363))*(1-(1-Inputs!$C$9)^(1/12)),0) | I363: =IF($B363>Inputs!$C$11,INDEX($H:$H,ROW()-Inputs!$C$11)* (1-Inputs!$C$10),0) | J363: =$H363*Inputs!$C$10 | K363: =IF($B363<=Inputs!$C$6+Inputs!$C$11,$C363*Inputs!$C$7/12,0) | L363: =IF($B363<=Inputs!$C$6+Inputs!$C$11,$E363+$F363+$G363+$I363-$K363,0) | M363: =IF($B363<=Inputs!$C$6,MAX(0,$C363-$F363-$G363-$H363),0)

Sheet Cashflow_Waterfall
B1: Liability waterfall (sequential-pay, reserve & equity cushion)
B2: Setup (linked to Inputs) | C2: Pool | D2: =Inputs!$C$4 | E2: Reserve % | F2: =Inputs!$C$20 | G2: OC % | H2: =Inputs!$C$21 | I2: A % (NoteBase) | J2: =Inputs!$C$16 | K2: B % (NoteBase) | L2: =Inputs!$C$17 | M2: A coupon | N2: =Inputs!$C$18 | O2: B coupon | P2: =Inputs!$C$19 | Q2: Turbo | R2: =Inputs!$C$39
B3: Derived | C3: Reserve cash | D3: =Inputs!$C$4*Inputs!$C$20 | E3: Total Assets @t0 | F3: =Inputs!$C$4+$D$3 | G3: NoteBase | H3: =Inputs!$C$4*(1-Inputs!$C$21) | I3: Class A init | J3: =$H$3*Inputs!$C$16 | K3: Class B init | L3: =$H$3*Inputs!$C$17 | M3: Equity cushion init | N3: =$F$3-$J$3-$L$3 | O3: Check (>=0) | P3: =IF($N$3>=0,"OK","NEGATIVE")
B5: Month | C5: Avail Int | D5: Avail Prin | E5: Loss (net) | F5: Reserve Beg | G5: Reserve End | H5: EqCush Beg | I5: EqCush Used | J5: EqCush End | K5: A Beg | L5: A Int Due | M5: A Int Paid | N5: A Prin Paid | O5: A Loss | P5: A End | Q5: B Beg | R5: B Int Due | S5: B Int Paid | T5: B Prin Paid | U5: B Loss | V5: B End | W5: Excess Int (post reserve) | X5: Turbo Prin | Y5: Equity Dist (cash)
B6: 1 | C6: =IF($B6<=Inputs!$C$6+Inputs!$C$11,Cashflow_Asset!$E4-Cashflow_Asset!$K4,0) | D6: =IF($B6<=Inputs!$C$6+Inputs!$C$11,Cashflow_Asset!$F4+Cashflow_Asset!$G4+Cashflow_Asset!$I4,0) | E6: =IF($B6<=Inputs!$C$6+Inputs!$C$11,Cashflow_Asset!$J4,0) | F6: =$D$3 | G6: =(MAX(0,$F6-MAX(0,($M6+$S6)-$C6)))+MIN(MAX(0,$D$3-(MAX(0,$F6-MAX(0,($M6+$S6)-$C6)))),MAX(0,MAX(0,($C6+$F6)-$M6)-$S6)) | H6: =$N$3 | I6: =MIN($E6,$H6) | J6: =$H6-$I6 | K6: =$J$3 | L6: =$K6*Inputs!$C$18/12 | M6: =MIN(($C6+$F6),$L6) | N6: =MIN(($D6+$X6),MAX(0,$K6-$O6)) | O6: =MIN(MAX(0,MAX(0,$E6-$I6)-$U6),$K6) | P6: =MAX(0,$K6-$O6)-$N6 | Q6: =$L$3 | R6: =$Q6*Inputs!$C$19/12 | S6: =MIN(MAX(0,($C6+$F6)-$M6),$R6) | T6: =MIN(MAX(0,($D6+$X6)-$N6),MAX(0,$Q6-$U6)) | U6: =MIN(MAX(0,$E6-$I6),$Q6) | V6: =MAX(0,$Q6-$U6)-$T6 | W6: =MAX(0,MAX(0,($C6+$F6)-$M6)-$S6)-MIN(MAX(0,$D$3-(MAX(0,$F6-MAX(0,($M6+$S6)-$C6)))),MAX(0,MAX(0,($C6+$F6)-$M6)-$S6)) | X6: =IF(Inputs!$C$39=1,$W6,0) | Y6: =IF(Inputs!$C$39=0,$W6,0)+MAX(0,MAX(0,($D6+$X6)-$N6)-$T6)
B7: 2 | C7: =IF($B7<=Inputs!$C$6+Inputs!$C$11,Cashflow_Asset!$E5-Cashflow_Asset!$K5,0) | D7: =IF($B7<=Inputs!$C$6+Inputs!$C$11,Cashflow_Asset!$F5+Cashflow_Asset!$G5+Cashflow_Asset!$I5,0) | E7: =IF($B7<=Inputs!$C$6+Inputs!$C$11,Cashflow_Asset!$J5,0) | F7: =$G6 | G7: =(MAX(0,$F7-MAX(0,($M7+$S7)-$C7)))+MIN(MAX(0,$D$3-(MAX(0,$F7-MAX(0,($M7+$S7)-$C7)))),MAX(0,MAX(0,($C7+$F7)-$M7)-$S7)) | H7: =$J6 | I7: =MIN($E7,$H7) | J7: =$H7-$I7 | K7: =$P6 | L7: =$K7*Inputs!$C$18/12 | M7: =MIN(($C7+$F7),$L7) | N7: =MIN(($D7+$X7),MAX(0,$K7-$O7)) | O7: =MIN(MAX(0,MAX(0,$E7-$I7)-$U7),$K7) | P7: =MAX(0,$K7-$O7)-$N7 | Q7: =$V6 | R7: =$Q7*Inputs!$C$19/12 | S7: =MIN(MAX(0,($C7+$F7)-$M7),$R7) | T7: =MIN(MAX(0,($D7+$X7)-$N7),MAX(0,$Q7-$U7)) | U7: =MIN(MAX(0,$E7-$I7),$Q7) | V7: =MAX(0,$Q7-$U7)-$T7 | W7: =MAX(0,MAX(0,($C7+$F7)-$M7)-$S7)-MIN(MAX(0,$D$3-(MAX(0,$F7-MAX(0,($M7+$S7)-$C7)))),MAX(0,MAX(0,($C7+$F7)-$M7)-$S7)) | X7: =IF(Inputs!$C$39=1,$W7,0) | Y7: =IF(Inputs!$C$39=0,$W7,0)+MAX(0,MAX(0,($D7+$X7)-$N7)-$T7)
B8: 3 | C8: =IF($B8<=Inputs!$C$6+Inputs!$C$11,Cashflow_Asset!$E6-Cashflow_Asset!$K6,0) | D8: =IF($B8<=Inputs!$C$6+Inputs!$C$11,Cashflow_Asset!$F6+Cashflow_Asset!$G6+Cashflow_Asset!$I6,0) | E8: =IF($B8<=Inputs!$C$6+Inputs!$C$11,Cashflow_Asset!$J6,0) | F8: =$G7 | G8: =(MAX(0,$F8-MAX(0,($M8+$S8)-$C8)))+MIN(MAX(0,$D$3-(MAX(0,$F8-MAX(0,($M8+$S8)-$C8)))),MAX(0,MAX(0,($C8+$F8)-$M8)-$S8)) | H8: =$J7 | I8: =MIN($E8,$H8) | J8: =$H8-$I8 | K8: =$P7 | L8: =$K8*Inputs!$C$18/12 | M8: =MIN(($C8+$F8),$L8) | N8: =MIN(($D8+$X8),MAX(0,$K8-$O8)) | O8: =MIN(MAX(0,MAX(0,$E8-$I8)-$U8),$K8) | P8: =MAX(0,$K8-$O8)-$N8 | Q8: =$V7 | R8: =$Q8*Inputs!$C$19/12 | S8: =MIN(MAX(0,($C8+$F8)-$M8),$R8) | T8: =MIN(MAX(0,($D8+$X8)-$N8),MAX(0,$Q8-$U8)) | U8: =MIN(MAX(0,$E8-$I8),$Q8) | V8: =MAX(0,$Q8-$U8)-$T8 | W8: =MAX(0,MAX(0,($C8+$F8)-$M8)-$S8)-MIN(MAX(0,$D$3-(MAX(0,$F8-MAX(0,($M8+$S8)-$C8)))),MAX(0,MAX(0,($C8+$F8)-$M8)-$S8)) | X8: =IF(Inputs!$C$39=1,$W8,0) | Y8: =IF(Inputs!$C$39=0,$W8,0)+MAX(0,MAX(0,($D8+$X8)-$N8)-$T8)
B9: 4 | C9: =IF($B9<=Inputs!$C$6+Inputs!$C$11,Cashflow_Asset!$E7-Cashflow_Asset!$K7,0) | D9: =IF($B9<=Inputs!$C$6+Inputs!$C$11,Cashflow_Asset!$F7+Cashflow_Asset!$G7+Cashflow_Asset!$I7,0) | E9: =IF($B9<=Inputs!$C$6+Inputs!$C$11,Cashflow_Asset!$J7,0) | F9: =$G8 | G9: =(MAX(0,$F9-MAX(0,($M9+$S9)-$C9)))+MIN(MAX(0,$D$3-(MAX(0,$F9-MAX(0,($M9+$S9)-$C9)))),MAX(0,MAX(0,($C9+$F9)-$M9)-$S9)) | H9: =$J8 | I9: =MIN($E9,$H9) | J9: =$H9-$I9 | K9: =$P8 | L9: =$K9*Inputs!$C$18/12 | M9: =MIN(($C9+$F9),$L9) | N9: =MIN(($D9+$X9),MAX(0,$K9-$O9)) | O9: =MIN(MAX(0,MAX(0,$E9-$I9)-$U9),$K9) | P9: =MAX(0,$K9-$O9)-$N9 | Q9: =$V8 | R9: =$Q9*Inputs!$C$19/12 | S9: =MIN(MAX(0,($C9+$F9)-$M9),$R9) | T9: =MIN(MAX(0,($D9+$X9)-$N9),MAX(0,$Q9-$U9)) | U9: =MIN(MAX(0,$E9-$I9),$Q9) | V9: =MAX(0,$Q9-$U9)-$T9 | W9: =MAX(0,MAX(0,($C9+$F9)-$M9)-$S9)-MIN(MAX(0,$D$3-(MAX(0,$F9-MAX(0,($M9+$S9)-$C9)))),MAX(0,MAX(0,($C9+$F9)-$M9)-$S9)) | X9: =IF(Inputs!$C$39=1,$W9,0) | Y9: =IF(Inputs!$C$39=0,$W9,0)+MAX(0,MAX(0,($D9+$X9)-$N9)-$T9)
B10: 5 | C10: =IF($B10<=Inputs!$C$6+Inputs!$C$11,Cashflow_Asset!$E8-Cashflow_Asset!$K8,0) | D10: =IF($B10<=Inputs!$C$6+Inputs!$C$11,Cashflow_Asset!$F8+Cashflow_Asset!$G8+Cashflow_Asset!$I8,0) | E10: =IF($B10<=Inputs!$C$6+Inputs!$C$11,Cashflow_Asset!$J8,0) | F10: =$G9 | G10: =(MAX(0,$F10-MAX(0,($M10+$S10)-$C10)))+MIN(MAX(0,$D$3-(MAX(0,$F10-MAX(0,($M10+$S10)-$C10)))),MAX(0,MAX(0,($C10+$F10)-$M10)-$S10)) | H10: =$J9 | I10: =MIN($E10,$H10) | J10: =$H10-$I10 | K10: =$P9 | L10: =$K10*Inputs!$C$18/12 | M10: =MIN(($C10+$F10),$L10) | N10: =MIN(($D10+$X10),MAX(0,$K10-$O10)) | O10: =MIN(MAX(0,MAX(0,$E10-$I10)-$U10),$K10) | P10: =MAX(0,$K10-$O10)-$N10 | Q10: =$V9 | R10: =$Q10*Inputs!$C$19/12 | S10: =MIN(MAX(0,($C10+$F10)-$M10),$R10) | T10: =MIN(MAX(0,($D10+$X10)-$N10),MAX(0,$Q10-$U10)) | U10: =MIN(MAX(0,$E10-$I10),$Q10) | V10: =MAX(0,$Q10-$U10)-$T10 | W10: =MAX(0,MAX(0,($C10+$F10)-$M10)-$S10)-MIN(MAX(0,$D$3-(MAX(0,$F10-MAX(0,($M10+$S10)-$C10)))),MAX(0,MAX(0,($C10+$F10)-$M10)-$S10)) | X10: =IF(Inputs!$C$39=1,$W10,0) | Y10: =IF(Inputs!$C$39=0,$W10,0)+MAX(0,MAX(0,($D10+$X10)-$N10)-$T10)
B11: 6 | C11: =IF($B11<=Inputs!$C$6+Inputs!$C$11,Cashflow_Asset!$E9-Cashflow_Asset!$K9,0) | D11: =IF($B11<=Inputs!$C$6+Inputs!$C$11,Cashflow_Asset!$F9+Cashflow_Asset!$G9+Cashflow_Asset!$I9,0) | E11: =IF($B11<=Inputs!$C$6+Inputs!$C$11,Cashflow_Asset!$J9,0) | F11: =$G10 | G11: =(MAX(0,$F11-MAX(0,($M11+$S11)-$C11)))+MIN(MAX(0,$D$3-(MAX(0,$F11-MAX(0,($M11+$S11)-$C11)))),MAX(0,MAX(0,($C11+$F11)-$M11)-$S11)) | H11: =$J10 | I11: =MIN($E11,$H11) | J11: =$H11-$I11 | K11: =$P10 | L11: =$K11*Inputs!$C$18/12 | M11: =MIN(($C11+$F11),$L11) | N11: =MIN(($D11+$X11),MAX(0,$K11-$O11)) | O11: =MIN(MAX(0,MAX(0,$E11-$I11)-$U11),$K11) | P11: =MAX(0,$K11-$O11)-$N11 | Q11: =$V10 | R11: =$Q11*Inputs!$C$19/12 | S11: =MIN(MAX(0,($C11+$F11)-$M11),$R11) | T11: =MIN(MAX(0,($D11+$X11)-$N11),MAX(0,$Q11-$U11)) | U11: =MIN(MAX(0,$E11-$I11),$Q11) | V11: =MAX(0,$Q11-$U11)-$T11 | W11: =MAX(0,MAX(0,($C11+$F11)-$M11)-$S11)-MIN(MAX(0,$D$3-(MAX(0,$F11-MAX(0,($M11+$S11)-$C11)))),MAX(0,MAX(0,($C11+$F11)-$M11)-$S11)) | X11: =IF(Inputs!$C$39=1,$W11,0) | Y11: =IF(Inputs!$C$39=0,$W11,0)+MAX(0,MAX(0,($D11+$X11)-$N11)-$T11)
B12: 7 | C12: =IF($B12<=Inputs!$C$6+Inputs!$C$11,Cashflow_Asset!$E10-Cashflow_Asset!$K10,0) | D12: =IF($B12<=Inputs!$C$6+Inputs!$C$11,Cashflow_Asset!$F10+Cashflow_Asset!$G10+Cashflow_Asset!$I10,0) | E12: =IF($B12<=Inputs!$C$6+Inputs!$C$11,Cashflow_Asset!$J10,0) | F12: =$G11 | G12: =(MAX(0,$F12-MAX(0,($M12+$S12)-$C12)))+MIN(MAX(0,$D$3-(MAX(0,$F12-MAX(0,($M12+$S12)-$C12)))),MAX(0,MAX(0,($C12+$F12)-$M12)-$S12)) | H12: =$J11 | I12: =MIN($E12,$H12) | J12: =$H12-$I12 | K12: =$P11 | L12: =$K12*Inputs!$C$18/12 | M12: =MIN(($C12+$F12),$L12) | N12: =MIN(($D12+$X12),MAX(0,$K12-$O12)) | O12: =MIN(MAX(0,MAX(0,$E12-$I12)-$U12),$K12) | P12: =MAX(0,$K12-$O12)-$N12 | Q12: =$V11 | R12: =$Q12*Inputs!$C$19/12 | S12: =MIN(MAX(0,($C12+$F12)-$M12),$R12) | T12: =MIN(MAX(0,($D12+$X12)-$N12),MAX(0,$Q12-$U12)) | U12: =MIN(MAX(0,$E12-$I12),$Q12) | V12: =MAX(0,$Q12-$U12)-$T12 | W12: =MAX(0,MAX(0,($C12+$F12)-$M12)-$S12)-MIN(MAX(0,$D$3-(MAX(0,$F12-MAX(0,($M12+$S12)-$C12)))),MAX(0,MAX(0,($C12+$F12)-$M12)-$S12)) | X12: =IF(Inputs!$C$39=1,$W12,0) | Y12: =IF(Inputs!$C$39=0,$W12,0)+MAX(0,MAX(0,($D12+$X12)-$N12)-$T12)
B13: 8 | C13: =IF($B13<=Inputs!$C$6+Inputs!$C$11,Cashflow_Asset!$E11-Cashflow_Asset!$K11,0) | D13: =IF($B13<=Inputs!$C$6+Inputs!$C$11,Cashflow_Asset!$F11+Cashflow_Asset!$G11+Cashflow_Asset!$I11,0) | E13: =IF($B13<=Inputs!$C$6+Inputs!$C$11,Cashflow_Asset!$J11,0) | F13: =$G12 | G13: =(MAX(0,$F13-MAX(0,($M13+$S13)-$C13)))+MIN(MAX(0,$D$3-(MAX(0,$F13-MAX(0,($M13+$S13)-$C13)))),MAX(0,MAX(0,($C13+$F13)-$M13)-$S13)) | H13: =$J12 | I13: =MIN($E13,$H13) | J13: =$H13-$I13 | K13: =$P12 | L13: =$K13*Inputs!$C$18/12 | M13: =MIN(($C13+$F13),$L13) | N13: =MIN(($D13+$X13),MAX(0,$K13-$O13)) | O13: =MIN(MAX(0,MAX(0,$E13-$I13)-$U13),$K13) | P13: =MAX(0,$K13-$O13)-$N13 | Q13: =$V12 | R13: =$Q13*Inputs!$C$19/12 | S13: =MIN(MAX(0,($C13+$F13)-$M13),$R13) | T13: =MIN(MAX(0,($D13+$X13)-$N13),MAX(0,$Q13-$U13)) | U13: =MIN(MAX(0,$E13-$I13),$Q13) | V13: =MAX(0,$Q13-$U13)-$T13 | W13: =MAX(0,MAX(0,($C13+$F13)-$M13)-$S13)-MIN(MAX(0,$D$3-(MAX(0,$F13-MAX(0,($M13+$S13)-$C13)))),MAX(0,MAX(0,($C13+$F13)-$M13)-$S13)) | X13: =IF(Inputs!$C$39=1,$W13,0) | Y13: =IF(Inputs!$C$39=0,$W13,0)+MAX(0,MAX(0,($D13+$X13)-$N13)-$T13)
B14: 9 | C14: =IF($B14<=Inputs!$C$6+Inputs!$C$11,Cashflow_Asset!$E12-Cashflow_Asset!$K12,0) | D14: =IF($B14<=Inputs!$C$6+Inputs!$C$11,Cashflow_Asset!$F12+Cashflow_Asset!$G12+Cashflow_Asset!$I12,0) | E14: =IF($B14<=Inputs!$C$6+Inputs!$C$11,Cashflow_Asset!$J12,0) | F14: =$G13 | G14: =(MAX(0,$F14-MAX(0,($M14+$S14)-$C14)))+MIN(MAX(0,$D$3-(MAX(0,$F14-MAX(0,($M14+$S14)-$C14)))),MAX(0,MAX(0,($C14+$F14)-$M14)-$S14)) | H14: =$J13 | I14: =MIN($E14,$H14) | J14: =$H14-$I14 | K14: =$P13 | L14: =$K14*Inputs!$C$18/12 | M14: =MIN(($C14+$F14),$L14) | N14: =MIN(($D14+$X14),MAX(0,$K14-$O14)) | O14: =MIN(MAX(0,MAX(0,$E14-$I14)-$U14),$K14) | P14: =MAX(0,$K14-$O14)-$N14 | Q14: =$V13 | R14: =$Q14*Inputs!$C$19/12 | S14: =MIN(MAX(0,($C14+$F14)-$M14),$R14) | T14: =MIN(MAX(0,($D14+$X14)-$N14),MAX(0,$Q14-$U14)) | U14: =MIN(MAX(0,$E14-$I14),$Q14) | V14: =MAX(0,$Q14-$U14)-$T14 | W14: =MAX(0,MAX(0,($C14+$F14)-$M14)-$S14)-MIN(MAX(0,$D$3-(MAX(0,$F14-MAX(0,($M14+$S14)-$C14)))),MAX(0,MAX(0,($C14+$F14)-$M14)-$S14)) | X14: =IF(Inputs!$C$39=1,$W14,0) | Y14: =IF(Inputs!$C$39=0,$W14,0)+MAX(0,MAX(0,($D14+$X14)-$N14)-$T14)
B15: 10 | C15: =IF($B15<=Inputs!$C$6+Inputs!$C$11,Cashflow_Asset!$E13-Cashflow_Asset!$K13,0) | D15: =IF($B15<=Inputs!$C$6+Inputs!$C$11,Cashflow_Asset!$F13+Cashflow_Asset!$G13+Cashflow_Asset!$I13,0) | E15: =IF($B15<=Inputs!$C$6+Inputs!$C$11,Cashflow_Asset!$J13,0) | F15: =$G14 | G15: =(MAX(0,$F15-MAX(0,($M15+$S15)-$C15)))+MIN(MAX(0,$D$3-(MAX(0,$F15-MAX(0,($M15+$S15)-$C15)))),MAX(0,MAX(0,($C15+$F15)-$M15)-$S15)) | H15: =$J14 | I15: =MIN($E15,$H15) | J15: =$H15-$I15 | K15: =$P14 | L15: =$K15*Inputs!$C$18/12 | M15: =MIN(($C15+$F15),$L15) | N15: =MIN(($D15+$X15),MAX(0,$K15-$O15)) | O15: =MIN(MAX(0,MAX(0,$E15-$I15)-$U15),$K15) | P15: =MAX(0,$K15-$O15)-$N15 | Q15: =$V14 | R15: =$Q15*Inputs!$C$19/12 | S15: =MIN(MAX(0,($C15+$F15)-$M15),$R15) | T15: =MIN(MAX(0,($D15+$X15)-$N15),MAX(0,$Q15-$U15)) | U15: =MIN(MAX(0,$E15-$I15),$Q15) | V15: =MAX(0,$Q15-$U15)-$T15 | W15: =MAX(0,MAX(0,($C15+$F15)-$M15)-$S15)-MIN(MAX(0,$D$3-(MAX(0,$F15-MAX(0,($M15+$S15)-$C15)))),MAX(0,MAX(0,($C15+$F15)-$M15)-$S15)) | X15: =IF(Inputs!$C$39=1,$W15,0) | Y15: =IF(Inputs!$C$39=0,$W15,0)+MAX(0,MAX(0,($D15+$X15)-$N15)-$T15)
B16: 11 | C16: =IF($B16<=Inputs!$C$6+Inputs!$C$11,Cashflow_Asset!$E14-Cashflow_Asset!$K14,0) | D16: =IF($B16<=Inputs!$C$6+Inputs!$C$11,Cashflow_Asset!$F14+Cashflow_Asset!$G14+Cashflow_Asset!$I14,0) | E16: =IF($B16<=Inputs!$C$6+Inputs!$C$11,Cashflow_Asset!$J14,0) | F16: =$G15 | G16: =(MAX(0,$F16-MAX(0,($M16+$S16)-$C16)))+MIN(MAX(0,$D$3-(MAX(0,$F16-MAX(0,($M16+$S16)-$C16)))),MAX(0,MAX(0,($C16+$F16)-$M16)-$S16)) | H16: =$J15 | I16: =MIN($E16,$H16) | J16: =$H16-$I16 | K16: =$P15 | L16: =$K16*Inputs!$C$18/12 | M16: =MIN(($C16+$F16),$L16) | N16: =MIN(($D16+$X16),MAX(0,$K16-$O16)) | O16: =MIN(MAX(0,MAX(0,$E16-$I16)-$U16),$K16) | P16: =MAX(0,$K16-$O16)-$N16 | Q16: =$V15 | R16: =$Q16*Inputs!$C$19/12 | S16: =MIN(MAX(0,($C16+$F16)-$M16),$R16) | T16: =MIN(MAX(0,($D16+$X16)-$N16),MAX(0,$Q16-$U16)) | U16: =MIN(MAX(0,$E16-$I16),$Q16) | V16: =MAX(0,$Q16-$U16)-$T16 | W16: =MAX(0,MAX(0,($C16+$F16)-$M16)-$S16)-MIN(MAX(0,$D$3-(MAX(0,$F16-MAX(0,($M16+$S16)-$C16)))),MAX(0,MAX(0,($C16+$F16)-$M16)-$S16)) | X16: =IF(Inputs!$C$39=1,$W16,0) | Y16: =IF(Inputs!$C$39=0,$W16,0)+MAX(0,MAX(0,($D16+$X16)-$N16)-$T16)
B17: 12 | C17: =IF($B17<=Inputs!$C$6+Inputs!$C$11,Cashflow_Asset!$E15-Cashflow_Asset!$K15,0) | D17: =IF($B17<=Inputs!$C$6+Inputs!$C$11,Cashflow_Asset!$F15+Cashflow_Asset!$G15+Cashflow_Asset!$I15,0) | E17: =IF($B17<=Inputs!$C$6+Inputs!$C$11,Cashflow_Asset!$J15,0) | F17: =$G16 | G17: =(MAX(0,$F17-MAX(0,($M17+$S17)-$C17)))+MIN(MAX(0,$D$3-(MAX(0,$F17-MAX(0,($M17+$S17)-$C17)))),MAX(0,MAX(0,($C17+$F17)-$M17)-$S17)) | H17: =$J16 | I17: =MIN($E17,$H17) | J17: =$H17-$I17 | K17: =$P16 | L17: =$K17*Inputs!$C$18/12 | M17: =MIN(($C17+$F17),$L17) | N17: =MIN(($D17+$X17),MAX(0,$K17-$O17)) | O17: =MIN(MAX(0,MAX(0,$E17-$I17)-$U17),$K17) | P17: =MAX(0,$K17-$O17)-$N17 | Q17: =$V16 | R17: =$Q17*Inputs!$C$19/12 | S17: =MIN(MAX(0,($C17+$F17)-$M17),$R17) | T17: =MIN(MAX(0,($D17+$X17)-$N17),MAX(0,$Q17-$U17)) | U17: =MIN(MAX(0,$E17-$I17),$Q17) | V17: =MAX(0,$Q17-$U17)-$T17 | W17: =MAX(0,MAX(0,($C17+$F17)-$M17)-$S17)-MIN(MAX(0,$D$3-(MAX(0,$F17-MAX(0,($M17+$S17)-$C17)))),MAX(0,MAX(0,($C17+$F17)-$M17)-$S17)) | X17: =IF(Inputs!$C$39=1,$W17,0) | Y17: =IF(Inputs!$C$39=0,$W17,0)+MAX(0,MAX(0,($D17+$X17)-$N17)-$T17)
B18: 13 | C18: =IF($B18<=Inputs!$C$6+Inputs!$C$11,Cashflow_Asset!$E16-Cashflow_Asset!$K16,0) | D18: =IF($B18<=Inputs!$C$6+Inputs!$C$11,Cashflow_Asset!$F16+Cashflow_Asset!$G16+Cashflow_Asset!$I16,0) | E18: =IF($B18<=Inputs!$C$6+Inputs!$C$11,Cashflow_Asset!$J16,0) | F18: =$G17 | G18: =(MAX(0,$F18-MAX(0,($M18+$S18)-$C18)))+MIN(MAX(0,$D$3-(MAX(0,$F18-MAX(0,($M18+$S18)-$C18)))),MAX(0,MAX(0,($C18+$F18)-$M18)-$S18)) | H18: =$J17 | I18: =MIN($E18,$H18) | J18: =$H18-$I18 | K18: =$P17 | L18: =$K18*Inputs!$C$18/12 | M18: =MIN(($C18+$F18),$L18) | N18: =MIN(($D18+$X18),MAX(0,$K18-$O18)) | O18: =MIN(MAX(0,MAX(0,$E18-$I18)-$U18),$K18) | P18: =MAX(0,$K18-$O18)-$N18 | Q18: =$V17 | R18: =$Q18*Inputs!$C$19/12 | S18: =MIN(MAX(0,($C18+$F18)-$M18),$R18) | T18: =MIN(MAX(0,($D18+$X18)-$N18),MAX(0,$Q18-$U18)) | U18: =MIN(MAX(0,$E18-$I18),$Q18) | V18: =MAX(0,$Q18-$U18)-$T18 | W18: =MAX(0,MAX(0,($C18+$F18)-$M18)-$S18)-MIN(MAX(0,$D$3-(MAX(0,$F18-MAX(0,($M18+$S18)-$C18)))),MAX(0,MAX(0,($C18+$F18)-$M18)-$S18)) | X18: =IF(Inputs!$C$39=1,$W18,0) | Y18: =IF(Inputs!$C$39=0,$W18,0)+MAX(0,MAX(0,($D18+$X18)-$N18)-$T18)
... B365: 360 | C365: =IF($B365<=Inputs!$C$6+Inputs!$C$11,Cashflow_Asset!$E363-Cashflow_Asset!$K363,0) | D365: =IF($B365<=Inputs!$C$6+Inputs!$C$11,Cashflow_Asset!$F363+Cashflow_Asset!$G363+Cashflow_Asset!$I363,0) | E365: =IF($B365<=Inputs!$C$6+Inputs!$C$11,Cashflow_Asset!$J363,0) | F365: =$G364 | G365: =(MAX(0,$F365-MAX(0,($M365+$S365)-$C365)))+MIN(MAX(0,$D$3-(MAX(0,$F365-MAX(0,($M365+$S365)-$C365)))),MAX(0,MAX(0,($C365+$F365)-$M365)-$S365)) | H365: =$J364 | I365: =MIN($E365,$H365) | J365: =$H365-$I365 | K365: =$P364 | L365: =$K365*Inputs!$C$18/12 | M365: =MIN(($C365+$F365),$L365) | N365: =MIN(($D365+$X365),MAX(0,$K365-$O365)) | O365: =MIN(MAX(0,MAX(0,$E365-$I365)-$U365),$K365) | P365: =MAX(0,$K365-$O365)-$N365 | Q365: =$V364 | R365: =$Q365*Inputs!$C$19/12 | S365: =MIN(MAX(0,($C365+$F365)-$M365),$R365) | T365: =MIN(MAX(0,($D365+$X365)-$N365),MAX(0,$Q365-$U365)) | U365: =MIN(MAX(0,$E365-$I365),$Q365) | V365: =MAX(0,$Q365-$U365)-$T365 | W365: =MAX(0,MAX(0,($C365+$F365)-$M365)-$S365)-MIN(MAX(0,$D$3-(MAX(0,$F365-MAX(0,($M365+$S365)-$C365)))),MAX(0,MAX(0,($C365+$F365)-$M365)-$S365)) | X365: =IF(Inputs!$C$39=1,$W365,0) | Y365: =IF(Inputs!$C$39=0,$W365,0)+MAX(0,MAX(0,($D365+$X365)-$N365)-$T365)

Sheet Tranche_Metrics
B1: Tranche metrics, credit enhancement & rating tests
B3: Key deal-level outputs | H3: Equity cashflows (for IRR)
B4: Pool balance | C4: =Inputs!$C$4 | H4: t=0 | I4: =-Cashflow_Waterfall!$N$3
B5: Reserve cash (t0) | C5: =Inputs!$C$4*Inputs!$C$20 | H5: 1 | I5: =Cashflow_Waterfall!$Y$6
B6: Total assets (t0) | C6: =Inputs!$C$4*(1+Inputs!$C$20) | H6: 2 | I6: =Cashflow_Waterfall!$Y$7
B7: E(L) % (from asset engine) | C7: =Cashflow_Asset!$P$8 | H7: 3 | I7: =Cashflow_Waterfall!$Y$8
B8: Expected loss amount | C8: =SUM(Cashflow_Asset!$J$4:$J$364) | H8: 4 | I8: =Cashflow_Waterfall!$Y$9
H9: 5 | I9: =Cashflow_Waterfall!$Y$10
B10: Capital stack @ closing (from waterfall setup) | H10: 6 | I10: =Cashflow_Waterfall!$Y$11
B11: Class A initial | C11: =Cashflow_Waterfall!$J$3 | H11: 7 | I11: =Cashflow_Waterfall!$Y$12
B12: Class B initial | C12: =Cashflow_Waterfall!$L$3 | H12: 8 | I12: =Cashflow_Waterfall!$Y$13
B13: Equity cushion initial | C13: =Cashflow_Waterfall!$N$3 | H13: 9 | I13: =Cashflow_Waterfall!$Y$14
B14: Check: assets - (A+B+equity) | C14: =Cashflow_Waterfall!$F$3-(Cashflow_Waterfall!$J$3+Cashflow_Waterfall!$L$3+Cashflow_Waterfall!$N$3) | H14: 10 | I14: =Cashflow_Waterfall!$Y$15
H15: 11 | I15: =Cashflow_Waterfall!$Y$16
B16: Credit enhancement (CE) ratios (BOTE-style) | H16: 12 | I16: =Cashflow_Waterfall!$Y$17
B17: CE for Class A (t0): (Total assets - Class A) / Pool | C17: =(Cashflow_Waterfall!$F$3-Cashflow_Waterfall!$J$3)/Inputs!$C$4 | H17: 13 | I17: =Cashflow_Waterfall!$Y$18
B18: CE for Class B (t0): (Total assets - A - B) / Pool | C18: =(Cashflow_Waterfall!$F$3-Cashflow_Waterfall!$J$3-Cashflow_Waterfall!$L$3)/Inputs!$C$4 | H18: 14 | I18: =Cashflow_Waterfall!$Y$19
B19: CE/E(L) for Class A | C19: =$C$17/$C$6 | H19: 15 | I19: =Cashflow_Waterfall!$Y$20
B20: CE/E(L) for Class B | C20: =$C$18/$C$6 | H20: 16 | I20: =Cashflow_Waterfall!$Y$21
H21: 17 | I21: =Cashflow_Waterfall!$Y$22
B22: Target factor for Class A (from Inputs) | C22: =Inputs!$C$34 | H22: 18 | I22: =Cashflow_Waterfall!$Y$23
B23: Pass? (Class A) | C23: =IF($C$19>=$C$22,"PASS","FAIL") | H23: 19 | I23: =Cashflow_Waterfall!$Y$24
B24: Target factor for Class B (from Inputs) | C24: =Inputs!$C$35 | H24: 20 | I24: =Cashflow_Waterfall!$Y$25
B25: Pass? (Class B) | C25: =IF($C$20>=$C$24,"PASS","FAIL") | H25: 21 | I25: =Cashflow_Waterfall!$Y$26
H26: 22 | I26: =Cashflow_Waterfall!$Y$27
B27: Economics | H27: 23 | I27: =Cashflow_Waterfall!$Y$28
B28: WA note coupon (A,B) | C28: =(Cashflow_Waterfall!$J$3*Inputs!$C$18+Cashflow_Waterfall!$L$3*Inputs!$C$19)/(Cashflow_Waterfall!$J$3+Cashflow_Waterfall!$L$3) | H28: 24 | I28: =Cashflow_Waterfall!$Y$29
B29: Equity initial investment (assumed = equity cushion) | C29: =Cashflow_Waterfall!$N$3 | H29: 25 | I29: =Cashflow_Waterfall!$Y$30
H30: 26 | I30: =Cashflow_Waterfall!$Y$31
H31: 27 | I31: =Cashflow_Waterfall!$Y$32
H32: 28 | I32: =Cashflow_Waterfall!$Y$33
H33: 29 | I33: =Cashflow_Waterfall!$Y$34
H34: 30 | I34: =Cashflow_Waterfall!$Y$35
H35: 31 | I35: =Cashflow_Waterfall!$Y$36
H36: 32 | I36: =Cashflow_Waterfall!$Y$37
H37: 33 | I37: =Cashflow_Waterfall!$Y$38
H38: 34 | I38: =Cashflow_Waterfall!$Y$39
H39: 35 | I39: =Cashflow_Waterfall!$Y$40
H40: 36 | I40: =Cashflow_Waterfall!$Y$41
H41: 37 | I41: =Cashflow_Waterfall!$Y$42
...

Sheet Optimisation
B1: Optimisation (use Excel Solver)
B3: What is optimised here? | C3: You choose an objective and run Solver to change the BLUE decision variables on the Inputs sheet.
B5: Objective candidates (pick ONE for Solver)
B6: 1) Minimise WA note coupon (A,B) | C6: =Tranche_Metrics!$C$28
B7: 2) Maximise Equity annual IRR | C7: =Tranche_Metrics!$I$127
B9: Decision variables (edit on Inputs sheet)
B10: Class A % of NoteBase | C10: =Inputs!$C$15
B11: Class B % of NoteBase | C11: =Inputs!$C$16
B12: Class A coupon | C12: =Inputs!$C$18
B13: Class B coupon | C13: =Inputs!$C$19
B14: Reserve % | C14: =Inputs!$C$20
B15: OC % | C15: =Inputs!$C$21
B16: Turbo (0/1) | C16: =Inputs!$C$39
B18: Constraint checks (Solver constraints reference these)
B19: A% + B% | C19: =Inputs!$C$15+Inputs!$C$16 | D19: <= 1.00 | E19: =IF($C19<=1,"OK","FAIL")
B20: Equity cushion (must be >= 0) | C20: =Cashflow_Waterfall!$N$3 | D20: >= 0 | E20: =IF($C20>=0,"OK","FAIL")
B21: Class A CE/E(L) >= target | C21: =Tranche_Metrics!$C$19 | D21: >= Tranche_Metrics target | E21: =Tranche_Metrics!$C$23
B22: Class B CE/E(L) >= target | C22: =Tranche_Metrics!$C$20 | D22: >= Tranche_Metrics target | E22: =Tranche_Metrics!$C$25
B23: Excess spread (annual) = WAC - servicing - WA coupons | C23: =Inputs!$C$5-Inputs!$C$7-(Tranche_Metrics!$C$28) | D23: >= 0 | E23: =IF($C23>=0,"OK","FAIL")
B25: Solver setup (example)
B26: Open Excel → Data → Solver.
B27: Set Objective: choose either cell C6 (minimise WA note coupon) or C7 (maximise Equity IRR).
B28: To minimise WA coupon: set 'Min'. To maximise IRR: set 'Max'.
B29: By Changing Variable Cells: Inputs!C16:C21 (and Inputs!C18:C19). Optional: Inputs!C39 for turbo.
B30: Add Constraints (minimum set):
B31: • Inputs!C16 + Inputs!C17 <= 1
B32: • Cashflow_Waterfall!N3 >= 0
B33: • Tranche_Metrics CE/E(L) for A >= factor target (Inputs provides the factor via rating lookup)
B34: • Tranche_Metrics CE/E(L) for B >= factor target
B35: • (Optional) Excess spread >= 0
B36: Choose a solving method (GRG Nonlinear is usually fine here) and click Solve.
